File: chapter 4/force/mini_patrick.is_tens_RawData/Specimen_RawData_5.csv
Time,Extension,Load
(s),(mm),(N)
"0.00000","-153.60716","0.00526"
"0.07600","-153.60741","-0.01634"
"0.16000","-153.60738","0.01731"
"0.22900","-153.60735","-0.00180"
"0.31600","-153.60732","-0.00337"
"0.38400","-153.60730","0.01297"
"0.46500","-153.60727","0.01801"
"0.53500","-153.60722","-0.00346"
"0.61100","-153.60722","0.01040"
"0.71000","-153.60719","-0.00898"
"0.79000","-153.60719","0.01489"
"0.87600","-153.60719","-0.00404"
"0.94500","-153.60719","0.00077"
"1.01800","-153.60719","-0.00563"
"1.08200","-153.60719","0.00308"
"1.15000","-153.60719","0.01579"
"1.23700","-153.60719","0.01474"
"1.32400","-153.60719","0.01374"
"1.38400","-153.60719","-0.00600"
"1.47500","-153.60719","0.01344"
"1.55700","-153.60719","0.01743"
"1.63500","-153.60719","-0.00630"
"1.72400","-153.60719","0.00155"
"1.78700","-153.60719","0.01254"
"1.85800","-153.60719","0.01015"
"1.94100","-153.60719","-0.00522"
"2.02000","-153.60719","0.00419"
"2.07900","-153.60719","0.01227"
"2.16700","-153.60719","-0.00312"
"2.22000","-153.60719","-0.01623"
"2.28600","-153.60719","0.01359"
"2.35400","-153.60719","-0.00667"
"2.43000","-153.60719","0.02438"
"2.51200","-153.60719","-0.00590"
"2.57100","-153.60719","0.02245"
"2.63700","-153.60719","0.01147"
"2.70100","-153.60719","0.01053"
"2.77800","-153.60719","-0.00348"
"2.86500","-153.60719","-0.01219"
"2.93800","-153.60719","0.01376"
"3.01800","-153.60719","-0.01431"
"3.09800","-153.60719","0.00752"
"3.16600","-153.60719","0.00964"
"3.24900","-153.60719","0.00252"
"3.33800","-153.60719","0.00894"
"3.42400","-153.60719","0.00561"
"3.47400","-153.60719","-0.00723"
"3.55200","-153.60719","-0.00606"
"3.62900","-153.60719","-0.00502"
"3.71000","-153.60719","-0.00300"
"3.78800","-153.60719","0.01633"
"3.87300","-153.60719","0.01180"
"3.92700","-153.60719","0.01827"
"4.01600","-153.60719","0.01702"
"4.09000","-153.60719","0.01515"
"4.16500","-153.60719","0.00874"
"4.22600","-153.60719","0.00997"
"4.33200","-153.60719","0.01013"
"4.41800","-153.60719","0.00182"
"4.51200","-153.60719","0.00079"
"4.58400","-153.60719","0.00922"
"4.64400","-153.60719","0.00712"
"4.70500","-153.60719","0.00107"
"4.78000","-153.60719","-0.00601"
"4.84500","-153.60719","-0.00288"
"4.91800","-153.60719","0.01582"
"5.00500","-153.60719","0.00862"
"5.09100","-153.60719","-0.01064"
"5.17100","-153.60719","0.00809"
"5.25900","-153.60719","0.02222"
"5.30500","-153.60719","0.01061"
"5.38900","-153.60719","-0.00533"
"5.45900","-153.60719","0.01688"
"5.52700","-153.60719","0.00495"
"5.59000","-153.60719","-0.00316"
"5.67500","-153.60719","0.00829"
"5.76400","-153.60719","0.00491"
"5.82700","-153.60719","0.00331"
"5.89300","-153.60719","0.02478"
"5.96700","-153.60719","0.00184"
"6.04500","-153.60719","0.02866"
"6.11700","-153.60719","0.00539"
"6.18900","-153.60719","-0.02156"
"6.25200","-153.60719","0.00110"
"6.32400","-153.60719","0.01526"
"6.40800","-153.60719","0.00197"
"6.49300","-153.60719","-0.01102"
"6.56100","-153.60719","0.00324"
"6.63700","-153.60719","-0.00076"
"6.72900","-153.60719","0.01398"
"6.81200","-153.60719","0.00570"
"6.90400","-153.60719","0.00720"
"6.99400","-153.60719","-0.00550"
"7.07400","-153.60719","0.00603"
"7.14500","-153.60719","0.01120"
"7.21900","-153.60719","0.00291"
"7.29800","-153.60719","0.00474"
"7.38200","-153.60719","0.00898"
"7.45600","-153.60719","-0.00693"
"7.50400","-153.60719","-0.00116"
"7.61100","-153.60719","-0.00006"
"7.70500","-153.60719","0.01061"
"7.76100","-153.60719","-0.00152"
"7.85200","-153.60719","-0.00275"
"7.93100","-153.60719","0.00825"
"7.99900","-153.60719","0.00239"
"8.07100","-153.60719","-0.00083"
"8.15800","-153.60719","0.01420"
"8.24600","-153.60719","0.00227"
"8.30800","-153.60719","-0.00138"
"8.36700","-153.60719","-0.00903"
"8.45600","-153.60719","-0.00148"
"8.53100","-153.60719","-0.00039"
"8.61200","-153.60719","0.01380"
"8.69000","-153.60719","0.01429"
"8.78200","-153.60719","0.00387"
"8.84800","-153.60719","-0.00105"
"8.91900","-153.60719","0.00131"
"9.00300","-153.60719","0.00273"
"9.09000","-153.60719","0.01381"
"9.17900","-153.60719","0.00576"
"9.25700","-153.60719","-0.00126"
"9.32400","-153.60719","0.01252"
"9.39900","-153.60719","0.00795"
"9.48400","-153.60719","-0.00964"
"9.56500","-153.60719","0.01412"
"9.62900","-153.60719","0.01050"
"9.72800","-153.60719","-0.00040"
"9.80500","-153.60719","-0.00129"
"9.87300","-153.60719","0.00577"
"9.94100","-153.60719","0.00563"
"10.02500","-153.60719","0.01408"
"10.09800","-153.60719","-0.00639"
"10.18500","-153.60719","-0.01197"
"10.25700","-153.60719","-0.00665"
"10.32600","-153.60719","0.00504"
"10.39400","-153.60719","0.01253"
"10.46000","-153.60719","-0.01191"
"10.52300","-153.60719","0.00528"
"10.60000","-153.60719","-0.00306"
"10.68300","-153.60719","0.01275"
"10.76400","-153.60719","-0.00172"
"10.84900","-153.60719","0.01662"
"10.93000","-153.60719","-0.00611"
"11.00700","-153.60719","-0.01031"
"11.07000","-153.60719","-0.00438"
"11.14200","-153.60719","-0.01681"
"11.21200","-153.60719","-0.00665"
"11.29800","-153.60719","-0.00387"
"11.35800","-153.60719","0.02072"
"11.43500","-153.60719","-0.00555"
"11.52500","-153.60719","0.00361"
"11.60600","-153.60719","0.00026"
"11.68000","-153.60719","0.00177"
"11.74300","-153.60719","-0.01437"
"11.81500","-153.60719","0.00190"
"11.89300","-153.60719","0.01461"
"11.96500","-153.60719","-0.00502"
"12.03200","-153.60719","0.02602"
"12.08300","-153.60719","0.02027"
"12.17000","-153.60719","0.01094"
"12.24700","-153.60719","0.02218"
"12.33300","-153.60719","0.01270"
"12.41400","-153.60719","-0.00425"
"12.48700","-153.60719","-0.00018"
"12.56500","-153.60719","0.01606"
"12.65500","-153.60719","0.00344"
"12.72400","-153.60719","-0.00441"
"12.77100","-153.60719","-0.00317"
"12.83400","-153.60719","-0.00758"
"12.90200","-153.60719","0.00264"
"12.96800","-153.60719","-0.00147"
"13.02100","-153.60719","0.00476"
"13.08500","-153.60719","-0.00002"
"13.13800","-153.60719","-0.00564"
"13.22800","-153.60719","-0.00441"
"13.31200","-153.60719","-0.00717"
"13.39600","-153.60719","-0.00683"
"13.46400","-153.60719","0.00181"
"13.54600","-153.60719","0.00684"
"13.63700","-153.60719","-0.00312"
"13.68300","-153.60719","0.01163"
"13.74000","-153.60719","0.01519"
"13.82500","-153.60719","0.01366"
"13.89400","-153.60719","0.00452"
"13.94700","-153.60719","0.02325"
"14.02400","-153.60719","0.00849"
"14.09000","-153.60719","-0.00317"
"14.17000","-153.60719","0.01073"
"14.24500","-153.60719","-0.00146"
"14.31000","-153.60719","0.01609"
"14.41000","-153.60719","0.00017"
"14.47800","-153.60719","0.00754"
"14.54900","-153.60719","0.00305"
"14.63600","-153.60719","-0.00075"
"14.70300","-153.60719","-0.00398"
"14.75100","-153.60719","0.00296"
"14.83300","-153.60719","0.01603"
"14.91700","-153.60719","0.00049"
"15.00100","-153.60719","0.00109"
"15.06900","-153.60719","-0.00387"
"15.14000","-153.60719","0.00837"
"15.20600","-153.60719","-0.00895"
"15.28400","-153.60719","-0.00168"
"15.33700","-153.60719","0.01905"
"15.41700","-153.60719","-0.00409"
"15.48500","-153.60719","-0.00112"
"15.57000","-153.60719","0.00599"
"15.65600","-153.60719","-0.00254"
"15.74600","-153.60719","0.01005"
"15.80300","-153.60719","-0.00388"
"15.87000","-153.60719","-0.01004"
"15.94600","-153.60719","0.01004"
"16.02500","-153.60719","0.00007"
"16.10100","-153.60719","0.00630"
"16.17700","-153.60719","0.00240"
"16.25500","-153.60719","0.00554"
"16.33400","-153.60719","0.00868"
"16.40500","-153.60719","0.00860"
"16.49600","-153.60719","0.00740"
"16.60000","-153.60719","0.00399"
"16.69700","-153.60719","0.01780"
"16.75300","-153.60719","-0.00492"
"16.82900","-153.60719","0.00077"
"16.91300","-153.60719","0.00404"
"16.99000","-153.60719","0.01078"
"17.07800","-153.60719","-0.01278"
"17.16000","-153.60719","0.00075"
"17.24200","-153.60719","0.00850"
"17.33400","-153.60719","0.00753"
"17.40300","-153.60719","-0.00082"
"17.48000","-153.60719","-0.00095"
"17.55400","-153.60719","-0.00044"
"17.67000","-153.60719","0.01321"
"17.74200","-153.60719","-0.00453"
"17.83800","-153.60719","-0.01285"
"17.91200","-153.60719","-0.00594"
"17.97700","-153.60719","0.01339"
"18.05400","-153.60719","0.00126"
"18.14100","-153.60719","0.01077"
"18.22700","-153.60719","-0.00047"
"18.30400","-153.60719","0.01099"
"18.36100","-153.60719","0.01453"
"18.43800","-153.60719","0.01929"
"18.51100","-153.60719","0.01044"
"18.58600","-153.60719","0.01060"
"18.65400","-153.60719","-0.00357"
"18.71900","-153.60719","-0.00147"
"18.79200","-153.60719","0.01969"
"18.86900","-153.60719","0.01569"
"18.96500","-153.60719","0.01199"
"19.03700","-153.60719","-0.00256"
"19.11100","-153.60719","0.01037"
"19.18100","-153.60719","0.01130"
"19.23300","-153.60719","0.01408"
"19.30000","-153.60719","0.00427"
"19.37700","-153.60719","0.00508"
"19.44100","-153.60719","0.00557"
"19.50100","-153.60719","0.00539"
"19.56300","-153.60719","0.00919"
"19.64300","-153.60719","0.01658"
"19.72500","-153.60719","0.00402"
"19.81200","-153.60719","-0.01538"
"19.87800","-153.60719","0.00057"
"19.95800","-153.60719","0.00562"
"20.02500","-153.60719","-0.00974"
"20.08400","-153.60719","0.00847"
"20.16400","-153.60719","-0.00119"
"20.24100","-153.60719","-0.00775"
"20.32400","-153.60719","0.01553"
"20.41000","-153.60719","0.00217"
"20.49900","-153.60719","0.00680"
"20.56600","-153.60719","0.01136"
"20.64200","-153.60719","0.01416"
"20.72700","-153.60719","0.00919"
"20.79700","-153.60719","0.00823"
"20.86400","-153.60719","0.00590"
"20.94200","-153.60719","-0.00892"
"21.01300","-153.60719","0.01641"
"21.09700","-153.60719","0.00223"
"21.17200","-153.60719","0.01521"
"21.25400","-153.60719","-0.00594"
"21.34200","-153.60719","0.00370"
"21.41900","-153.60719","0.00870"
"21.48800","-153.60719","0.01550"
"21.54800","-153.60719","-0.00185"
"21.63000","-153.60719","0.00889"
"21.72700","-153.60719","-0.00810"
"21.82100","-153.60719","0.00520"
"21.88500","-153.60719","0.02163"
"21.95600","-153.60719","0.00829"
"22.02700","-153.60719","-0.00170"
"22.12300","-153.60719","0.01711"
"22.19300","-153.60719","0.02270"
"22.26700","-153.60719","0.00090"
"22.36700","-153.60719","0.00496"
"22.44500","-153.60719","0.01832"
"22.52800","-153.60719","0.00344"
"22.60200","-153.60719","-0.00284"
"22.69200","-153.60719","-0.00144"
"22.77200","-153.60719","0.00522"
"22.84700","-153.60719","-0.00277"
"22.92100","-153.60719","-0.01272"
"22.99400","-153.60719","0.00693"
"23.06900","-153.60719","0.01176"
"23.14500","-153.60719","-0.00336"
"23.22500","-153.60719","-0.01022"
"23.31600","-153.60719","0.00250"
"23.40000","-153.60719","0.00473"
"23.48400","-153.60719","-0.01405"
"23.53800","-153.60719","0.01746"
"23.59900","-153.60719","0.01714"
"23.69000","-153.60719","-0.00749"
"23.77500","-153.60719","0.01421"
"23.86300","-153.60719","0.01753"
"23.95100","-153.60719","0.01269"
"24.01400","-153.60719","-0.00195"
"24.09900","-153.60719","-0.00955"
"24.21000","-153.60719","-0.00207"
"24.30400","-153.60719","-0.01178"
"24.39500","-153.60719","-0.00022"
"24.48500","-153.60719","0.01711"
"24.56800","-153.60719","0.00323"
"24.64500","-153.60719","-0.00911"
"24.71000","-153.60719","-0.00821"
"24.78000","-153.60719","0.00621"
"24.86100","-153.60719","0.00248"
"24.94300","-153.60719","0.01220"
"25.01400","-153.60719","-0.00301"
"25.09200","-153.60719","-0.01271"
"25.16000","-153.60719","0.01157"
"25.21000","-153.60719","-0.00412"
"25.29700","-153.60719","0.00854"
"25.36900","-153.60719","-0.00309"
"25.45200","-153.60719","0.00473"
"25.55500","-153.60719","0.01129"
"25.61800","-153.60719","0.01235"
"25.71400","-153.60719","0.00385"
"25.78800","-153.60719","0.00320"
"25.85800","-153.60719","0.00665"
"25.92700","-153.60719","0.01400"
"26.01200","-153.60719","0.00432"
"26.07300","-153.60719","-0.00453"
"26.14000","-153.60719","0.00523"
"26.23600","-153.60719","-0.00404"
"26.32000","-153.60719","0.00954"
"26.38200","-153.60719","0.01120"
"26.47700","-153.60719","-0.00129"
"26.54600","-153.60719","0.00748"
"26.62600","-153.60719","0.00196"
"26.70700","-153.60719","-0.00469"
"26.76800","-153.60719","0.00109"
"26.86900","-153.60719","-0.00483"
"26.94400","-153.60719","-0.01448"
"27.00900","-153.60719","-0.00280"
"27.09300","-153.60719","-0.00033"
"27.15200","-153.60719","0.01323"
"27.23700","-153.60719","0.00116"
"27.31300","-153.60719","-0.00473"
"27.37900","-153.60719","-0.00204"
"27.46000","-153.60719","0.00726"
"27.51700","-153.60719","-0.01040"
"27.60400","-153.60719","-0.00082"
"27.65600","-153.60719","-0.01111"
"27.72500","-153.60719","-0.01302"
"27.79500","-153.60719","-0.00306"
"27.87800","-153.60719","-0.00526"
"27.93900","-153.60719","0.01028"
"28.01200","-153.60719","0.00883"
"28.07100","-153.60719","-0.00995"
"28.18500","-153.60719","0.01008"
"28.26300","-153.60719","0.01516"
"28.32200","-153.60719","0.00534"
"28.41800","-153.60719","0.00048"
"28.45100","-153.60719","0.20732"
"28.49300","-153.60719","0.22080"
"28.55000","-153.60719","0.04036"
"28.62700","-153.60719","-0.03883"
"28.69000","-153.60719","0.02072"
"28.75600","-153.60719","-0.01889"
"28.82400","-153.60719","-0.10195"
"28.88900","-153.60719","-0.11305"
"28.91200","-153.60719","0.09204"
"28.96200","-153.60719","0.15424"
"29.00500","-153.60719","-0.02892"
"29.08200","-153.60719","0.05491"
"29.14000","-153.60719","0.02119"
"29.19500","-153.60719","-0.05651"
"29.25000","-153.60719","0.03892"
"29.30300","-153.60719","-0.11205"
"29.35900","-153.60719","-0.14191"
"29.41900","-153.60719","-0.12945"
"29.44300","-153.60719","-0.33246"
"29.48800","-153.60719","-0.18475"
"29.52300","-153.60719","-0.16969"
"29.59400","-153.60719","-0.21852"
"29.68400","-153.60719","-0.24898"
"29.76300","-153.60719","-0.36320"
"29.82100","-153.60719","-0.41106"
"29.86600","-153.60719","-0.48862"
"29.92300","-153.60719","-0.44172"
"29.98000","-153.60719","-0.39367"
"30.04700","-153.60719","-0.52668"
"30.10000","-153.60719","-0.41088"
"30.17000","-153.60719","-0.49775"
"30.24600","-153.60719","-0.45850"
"30.32100","-153.60719","-0.50842"
"30.39600","-153.60719","-0.51584"
"30.48200","-153.60719","-0.57944"
"30.55300","-153.60719","-0.70579"
"30.61200","-153.60719","-0.68181"
"30.67700","-153.60719","-0.76540"
"30.73900","-153.60719","-0.70333"
"30.83300","-153.60719","-0.75730"
"30.89400","-153.60719","-0.80068"
"30.95600","-153.60719","-0.74328"
"31.02900","-153.60719","-0.65839"
"31.07700","-153.60719","-0.69149"
"31.10700","-153.60719","-0.49653"
"31.12800","-153.60719","-0.28606"
"31.15900","-153.60719","-0.07764"
"31.19200","-153.60719","-0.22668"
"31.24300","-153.60719","-0.23016"
"31.31700","-153.60719","-0.22013"
"31.37100","-153.60719","-0.26190"
"31.39400","-153.60719","-0.46546"
"31.43900","-153.60719","-0.36103"
"31.50500","-153.60719","-0.30896"
"31.55400","-153.60719","-0.18408"
"31.60600","-153.60719","-0.23469"
"31.66300","-153.60719","-0.31831"
"31.71700","-153.60719","-0.19464"
"31.79900","-153.60719","-0.14627"
"31.86100","-153.60719","-0.29899"
"31.90700","-153.60719","-0.17156"
"31.97400","-153.60719","-0.05820"
"32.05100","-153.60719","0.00590"
"32.12700","-153.60719","-0.04006"
"32.20800","-153.60719","0.00665"
"32.28400","-153.60719","-0.00049"
"32.34800","-153.60719","-0.00350"
"32.42200","-153.60719","-0.01222"
"32.49400","-153.60719","0.00480"
"32.57200","-153.60719","-0.01296"
"32.65100","-153.60719","-0.00735"
"32.72400","-153.60719","0.00115"
"32.78900","-153.60719","-0.01414"
"32.87000","-153.60719","-0.02169"
"32.94800","-153.60719","0.01215"
"33.02900","-153.60719","-0.00631"
"33.10700","-153.60719","0.00467"
"33.18700","-153.60719","0.00321"
"33.26600","-153.60719","0.01578"
"33.34400","-153.60719","-0.00685"
"33.42400","-153.60719","0.00793"
"33.49900","-153.60719","-0.00944"
"33.59200","-153.60719","-0.00947"
"33.66300","-153.60719","-0.01173"
"33.74500","-153.60719","0.02163"
"33.83100","-153.60719","-0.00212"
"33.90900","-153.60719","0.00487"
"33.98200","-153.60719","-0.00199"
"34.05400","-153.60719","0.00142"
"34.13300","-153.60719","0.00172"
"34.20900","-153.60719","-0.00757"
"34.28800","-153.60719","-0.00821"
"34.35100","-153.60719","0.00452"
"34.45600","-153.60719","0.01122"
"34.53500","-153.60719","-0.00705"
"34.62400","-153.60719","-0.00889"
"34.70000","-153.60719","0.00330"
"34.77900","-153.60719","-0.00451"
"34.87900","-153.60719","0.01696"
"34.96900","-153.60719","0.00724"
"35.04900","-153.60719","-0.01383"
"35.13200","-153.60719","0.01488"
"35.20200","-153.60719","-0.00723"
"35.29000","-153.60719","0.00180"
"35.35200","-153.60719","-0.01736"
"35.41700","-153.60719","-0.03765"
"35.48200","-153.60719","0.00486"
"35.57600","-153.60719","0.00310"
"35.66900","-153.60719","-0.00867"
"35.74100","-153.60719","0.00837"
"35.80200","-153.60719","0.01815"
"35.87100","-153.60719","0.00831"
"35.94600","-153.60719","-0.00413"
"36.00500","-153.60719","0.00619"
"36.07400","-153.60719","0.00784"
"36.14100","-153.60719","-0.03029"
"36.20800","-153.60719","-0.00107"
"36.27700","-153.60719","0.01463"
"36.36300","-153.60719","0.00443"
"36.43800","-153.60719","-0.00050"
"36.49400","-153.60719","0.00695"
"36.56500","-153.60719","-0.00038"
"36.63300","-153.60719","0.01000"
"36.70900","-153.60719","0.00656"
"36.76500","-153.60719","-0.00851"
"36.83600","-153.60719","0.01984"
"36.91800","-153.60719","-0.02455"
"36.97300","-153.60719","-0.00551"
"37.05500","-153.60719","-0.00620"
"37.14000","-153.60719","-0.00145"
"37.23000","-153.60719","-0.00185"
"37.32400","-153.60719","-0.00370"
"37.38300","-153.60719","0.01709"
"37.47300","-153.60719","-0.00109"
"37.56200","-153.60719","-0.00156"
"37.63500","-153.60719","0.00615"
"37.71800","-153.60719","0.00388"
"37.78600","-153.60719","0.00805"
"37.85100","-153.60719","0.01134"
"37.93100","-153.60719","0.00053"
"38.00100","-153.60719","0.00942"
"38.06000","-153.60719","-0.01014"
"38.13400","-153.60719","-0.00538"
"38.21400","-153.60719","0.00370"
"38.29600","-153.60719","-0.00129"
"38.37700","-153.60719","-0.00507"
"38.47600","-153.60719","-0.01105"
"38.57100","-153.60719","0.01220"
"38.66000","-153.60719","0.00254"
"38.75200","-153.60719","0.00813"
"38.80900","-153.60719","-0.00129"
"38.89900","-153.60719","-0.02410"
"38.97900","-153.60719","-0.04985"
"39.04800","-153.60719","-0.03975"
"39.11100","-153.60719","-0.03938"
"39.18700","-153.60719","-0.02990"
"39.25900","-153.60719","-0.02112"
"39.34300","-153.60719","-0.04568"
"39.40200","-153.60719","-0.01428"
"39.47800","-153.60719","-0.02239"
"39.54400","-153.60719","-0.03670"
"39.62700","-153.60719","-0.02303"
"39.70000","-153.60719","-0.02412"
"39.76000","-153.60719","-0.02808"
"39.84700","-153.60719","-0.00878"
"39.93900","-153.60719","-0.02080"
"40.01500","-153.60719","-0.01600"
"40.10900","-153.60719","-0.00943"
"40.19200","-153.60719","-0.01774"
"40.27300","-153.60719","-0.02043"
"40.35700","-153.60719","-0.01771"
"40.43000","-153.60719","0.00178"
"40.51400","-153.60719","-0.00005"
"40.60100","-153.60719","-0.00537"
"40.68200","-153.60719","-0.01058"
"40.75700","-153.60719","-0.00137"
"40.84300","-153.60719","-0.00625"
"40.91900","-153.60719","-0.00686"
"40.97700","-153.60719","-0.00736"
"41.04400","-153.60719","-0.01045"
"41.11300","-153.60719","-0.01002"
"41.16500","-153.60719","0.00575"
"41.24500","-153.60719","0.00709"
"41.32600","-153.60719","0.00206"
"41.40300","-153.60719","-0.00385"
"41.50500","-153.60719","-0.00550"
"41.58000","-153.60719","0.00615"
"41.69200","-153.60719","-0.01075"
"41.77800","-153.60719","0.01208"
"41.85100","-153.60719","0.00609"
"41.92200","-153.60719","0.00627"
"41.99600","-153.60719","-0.01177"
"42.06900","-153.60719","0.00611"
"42.14400","-153.60719","0.00751"
"42.21000","-153.60719","-0.00383"
"42.29500","-153.60719","0.00445"
"42.37900","-153.60719","-0.01830"
"42.44600","-153.60719","0.00025"
"42.52500","-153.60719","-0.00265"
"42.59400","-153.60719","-0.01013"
"42.66400","-153.60719","-0.00394"
"42.74900","-153.60719","-0.00007"
"42.83800","-153.60719","-0.00490"
"42.92400","-153.60719","0.00199"
"43.00200","-153.60719","-0.00674"
"43.07900","-153.60719","-0.00316"
"43.15900","-153.60719","-0.00320"
"43.23200","-153.60719","0.00381"
"43.29600","-153.60719","-0.01110"
"43.35700","-153.60719","-0.00120"
"43.43800","-153.60719","-0.06399"
"43.48700","-153.60719","-0.11766"
"43.58100","-153.60719","-0.09524"
"43.65800","-153.60719","-0.09323"
"43.72900","-153.60719","-0.08235"
"43.78500","-153.60719","-0.07167"
"43.84300","-153.60719","-0.08102"
"43.92800","-153.60719","-0.06698"
"44.00000","-153.60719","-0.06168"
"44.07400","-153.60719","-0.07017"
"44.13500","-153.60719","-0.06496"
"44.21000","-153.60719","-0.05108"
"44.28300","-153.60719","-0.07185"
"44.34200","-153.60719","-0.03639"
"44.42900","-153.60719","-0.04702"
"44.53000","-153.60719","-0.04092"
"44.61300","-153.60719","-0.04739"
"44.70800","-153.60719","-0.02355"
"44.79800","-153.60719","-0.04988"
"44.85900","-153.60719","-0.05157"
"44.95500","-153.60719","-0.04559"
"45.01200","-153.60719","-0.02950"
"45.11500","-153.60719","-0.03355"
"45.19400","-153.60719","-0.01634"
"45.27400","-153.60719","-0.03737"
"45.34400","-153.60719","-0.02566"
"45.42000","-153.60719","-0.03067"
"45.50600","-153.60719","-0.03727"
"45.60100","-153.60719","-0.02510"
"45.66000","-153.60719","-0.02827"
"45.73900","-153.60719","-0.02044"
"45.81800","-153.60719","-0.01610"
"45.89700","-153.60719","-0.03429"
"45.98600","-153.60719","-0.03593"
"46.05000","-153.60719","-0.02348"
"46.14000","-153.60719","-0.02762"
"46.19500","-153.60719","-0.01981"
"46.29100","-153.60719","-0.02600"
"46.36400","-153.60719","-0.00858"
"46.45400","-153.60719","-0.01293"
"46.54800","-153.60719","-0.03642"
"46.61700","-153.60719","-0.01808"
"46.70800","-153.60719","-0.01616"
"46.78400","-153.60719","-0.01769"
"46.85900","-153.60719","-0.02459"
"46.94100","-153.60719","-0.00678"
"47.01100","-153.60719","-0.03608"
"47.08500","-153.60719","-0.00643"
"47.14500","-153.60719","-0.02411"
"47.21700","-153.60719","-0.01681"
"47.30500","-153.60719","0.00773"
"47.37100","-153.60719","-0.02304"
"47.44900","-153.60719","-0.07176"
"47.50000","-153.60719","-0.23335"
"47.56200","-153.60719","-0.21938"
"47.64700","-153.60719","-0.19484"
"47.71200","-153.60719","-0.16240"
"47.79300","-153.60719","-0.17453"
"47.87100","-153.60719","-0.16427"
"47.96900","-153.60719","-0.15058"
"48.05700","-153.60719","-0.13819"
"48.12900","-153.60719","-0.10945"
"48.20700","-153.60719","-0.11387"
"48.28700","-153.60719","-0.11919"
"48.37900","-153.60719","-0.09698"
"48.46000","-153.60719","-0.10124"
"48.54600","-153.60719","-0.09102"
"48.65500","-153.60719","-0.09372"
"48.71800","-153.60719","-0.09249"
"48.76900","-153.60719","-0.09458"
"48.82800","-153.60719","-0.07350"
"48.90100","-153.60719","-0.06311"
"48.98400","-153.60719","-0.08237"
"49.05600","-153.60719","-0.06618"
"49.14600","-153.60719","-0.06844"
"49.22000","-153.60719","-0.06169"
"49.27800","-153.60719","-0.07416"
"49.36600","-153.60719","-0.05845"
"49.45500","-153.60719","-0.06538"
"49.53300","-153.60719","-0.06003"
"49.61800","-153.60719","-0.05435"
"49.68900","-153.60719","-0.05060"
"49.75900","-153.60719","-0.05498"
"49.84400","-153.60719","-0.04010"
"49.90000","-153.60719","-0.07280"
"49.97100","-153.60719","-0.03399"
"50.05300","-153.60719","-0.05250"
"50.14000","-153.60719","-0.04615"
"50.21300","-153.60719","-0.04694"
"50.28100","-153.60719","-0.03056"
"50.35700","-153.60719","-0.04921"
"50.44000","-153.60719","-0.04778"
"50.52000","-153.60719","-0.04632"
"50.60700","-153.60719","-0.03395"
"50.68200","-153.60719","-0.04496"
"50.77500","-153.60719","-0.03762"
"50.86500","-153.60719","-0.03772"
"50.93600","-153.60719","-0.03406"
"51.02800","-153.60719","-0.04213"
"51.09000","-153.60719","-0.22641"
"51.12500","-153.60719","-0.40173"
"51.17300","-153.60719","-0.47660"
"51.23800","-153.60719","-0.40970"
"51.32800","-153.60719","-0.35782"
"51.41800","-153.60719","-0.34625"
"51.49900","-153.60719","-0.33720"
"51.56700","-153.60719","-0.32619"
"51.62800","-153.60719","-0.32876"
"51.71000","-153.60719","-0.31693"
"51.80900","-153.60719","-0.30720"
"51.89200","-153.60719","-0.28432"
"51.98800","-153.60719","-0.27827"
"52.05900","-153.60719","-0.25175"
"52.13400","-153.60719","-0.25973"
"52.20600","-153.60719","-0.24061"
"52.27800","-153.60719","-0.25936"
"52.34600","-153.60719","-0.24302"
"52.42800","-153.60719","-0.24264"
"52.50400","-153.60719","-0.21676"
"52.57500","-153.60719","-0.15377"
"52.64000","-153.60719","-0.17564"
"52.71200","-153.60719","-0.18347"
"52.79000","-153.60719","-0.17481"
"52.87400","-153.60719","-0.17832"
"52.94800","-153.60719","-0.18084"
"53.00200","-153.60719","-0.18534"
"53.06700","-153.60719","-0.16305"
"53.14200","-153.60719","-0.17367"
"53.22600","-153.60719","-0.15627"
"53.29900","-153.60719","-0.15803"
"53.36100","-153.60719","-0.10134"
"53.43900","-153.60719","-0.11112"
"53.51800","-153.60719","-0.12423"
"53.59800","-153.60719","-0.12700"
"53.66300","-153.60719","-0.13148"
"53.73600","-153.60719","-0.11717"
"53.82700","-153.60719","-0.12215"
"53.91400","-153.60719","-0.10653"
"53.97300","-153.60719","-0.11021"
"54.05800","-153.60719","-0.10368"
"54.12800","-153.60719","-0.11383"
"54.19200","-153.60719","-0.11321"
"54.27200","-153.60719","-0.12011"
"54.33200","-153.60719","-0.10138"
"54.41800","-153.60719","-0.09936"
"54.47300","-153.60719","-0.10630"
"54.55100","-153.60719","-0.06841"
"54.64000","-153.60719","-0.06678"
"54.72900","-153.60719","-0.07698"
"54.81700","-153.60719","-0.08101"
"54.90500","-153.60719","-0.06779"
"54.97200","-153.60719","-0.09026"
"55.05600","-153.60719","-0.06490"
"55.14900","-153.60719","-0.08311"
"55.22000","-153.60719","-0.08074"
"55.28900","-153.60719","-0.06950"
"55.38200","-153.60719","-0.06971"
"55.45700","-153.60719","-0.07758"
"55.51900","-153.60719","-0.07242"
"55.61900","-153.60719","-0.07312"
"55.70200","-153.60719","-0.07954"
"55.75400","-153.60719","-0.05477"
"55.84200","-153.60719","-0.07564"
"55.93800","-153.60719","-0.07622"
"56.02000","-153.60719","-0.06304"
"56.09100","-153.60719","-0.07645"
"56.17100","-153.60719","-0.07389"
"56.26400","-153.60719","-0.05612"
"56.34600","-153.60719","-0.08869"
"56.42100","-153.60719","-0.07170"
"56.48800","-153.60719","-0.05516"
"56.55800","-153.60719","-0.07086"
"56.63400","-153.60719","-0.05661"
"56.72300","-153.60719","-0.06678"
"56.80600","-153.60719","-0.08116"
"56.88200","-153.60719","-0.05434"
"56.96400","-153.60719","-0.02910"
"57.05900","-153.60719","-0.04461"
"57.14600","-153.60719","-0.04582"
"57.23300","-153.60719","-0.04952"
"57.31100","-153.60719","-0.04437"
"57.39300","-153.60719","-0.06301"
"57.46900","-153.60719","-0.05134"
"57.53400","-153.60719","-0.04415"
"57.60700","-153.60719","-0.05236"
"57.69800","-153.60719","-0.04947"
"57.78400","-153.60719","-0.05123"
"57.86200","-153.60719","-0.05160"
"57.92300","-153.60719","-0.04550"
"57.98500","-153.60719","-0.04295"
"58.06000","-153.60719","-0.05672"
"58.14600","-153.60719","-0.04588"
"58.21300","-153.60719","-0.05321"
"58.27100","-153.60719","-0.05036"
"58.34200","-153.60719","-0.05155"
"58.42500","-153.60719","-0.05816"
"58.49600","-153.60719","-0.05213"
"58.55900","-153.60719","-0.05477"
"58.65100","-153.60719","-0.04756"
"58.72300","-153.60719","-0.06035"
"58.79300","-153.60719","-0.04878"
"58.85600","-153.60719","-0.03339"
"58.92300","-153.60719","-0.05221"
"58.98700","-153.60719","-0.05472"
"59.04400","-153.60719","-0.05750"
"59.10100","-153.60719","-0.05252"
"59.19200","-153.60719","-0.05045"
"59.26200","-153.60719","-0.04713"
"59.34700","-153.60719","-0.05160"
"59.42800","-153.60719","-0.03697"
"59.52900","-153.60719","-0.04284"
"59.60400","-153.60719","-0.04738"
"59.66600","-153.60719","-0.05459"
"59.73600","-153.60719","-0.03258"
"59.82000","-153.60719","-0.04822"
"59.91100","-153.60719","-0.05839"
"59.97800","-153.60719","-0.04376"
"60.05900","-153.60719","-0.05224"
"60.14200","-153.60719","-0.04414"
"60.21000","-153.60719","-0.02152"
"60.26600","-153.60719","-0.05405"
"60.34300","-153.60719","-0.05917"
"60.40100","-153.60719","-0.17225"
"60.44300","-153.60719","-0.35088"
"60.52100","-153.60719","-0.33919"
"60.59100","-153.60719","-0.31598"
"60.68100","-153.60719","-0.30389"
"60.78400","-153.60719","-0.29122"
"60.86500","-153.60719","-0.28568"
"60.93200","-153.60719","-0.26581"
"61.00700","-153.60719","-0.26255"
"61.08500","-153.60719","-0.23001"
"61.15300","-153.60719","-0.26758"
"61.21400","-153.60719","-0.23941"
"61.28300","-153.60719","-0.23931"
"61.35400","-153.60719","-0.22394"
"61.43300","-153.60719","-0.23212"
"61.51700","-153.60719","-0.21350"
"61.60000","-153.60719","-0.20552"
"61.67000","-153.60719","-0.19662"
"61.72400","-153.60719","-0.22295"
"61.81100","-153.60719","-0.18837"
"61.89200","-153.60719","-0.19291"
"61.96300","-153.60719","-0.12076"
"62.06100","-153.60719","-0.14518"
"62.12600","-153.60719","-0.15469"
"62.18800","-153.60719","-0.14963"
"62.25100","-153.60719","-0.15256"
"62.34500","-153.60719","-0.15676"
"62.42000","-153.60719","-0.13952"
"62.48800","-153.60719","-0.15184"
"62.58100","-153.60719","-0.13104"
"62.65900","-153.60719","-0.14318"
"62.75700","-153.60719","-0.13687"
"62.81300","-153.60719","-0.07684"
"62.87800","-153.60719","-0.08510"
"62.95900","-153.60719","-0.08310"
"63.04600","-153.60719","-0.06491"
"63.13900","-153.60719","-0.09639"
"63.21200","-153.60719","-0.09264"
"63.29800","-153.60719","-0.08077"
"63.35100","-153.60719","-0.08347"
"63.43900","-153.60719","-0.07600"
"63.52300","-153.60719","-0.07974"
"63.58500","-153.60719","-0.09390"
"63.64800","-153.60719","-0.08616"
"63.74300","-153.60719","-0.08314"
"63.80500","-153.60719","-0.08661"
"63.88100","-153.60719","-0.08001"
"63.98400","-153.60719","-0.07789"
"64.03800","-153.60719","-0.08737"
"64.10000","-153.60719","-0.09689"
"64.18100","-153.60719","-0.19622"
"64.22800","-153.60719","-0.34255"
"64.30800","-153.60719","-0.49476"
"64.39600","-153.60719","-0.44966"
"64.45400","-153.60719","-0.42899"
"64.54200","-153.60719","-0.41810"
"64.63300","-153.60719","-0.37693"
"64.70500","-153.60719","-0.38242"
"64.77200","-153.60719","-0.36698"
"64.85300","-153.60719","-0.35757"
"64.90800","-153.60719","-0.36550"
"64.98700","-153.60719","-0.34422"
"65.05400","-153.60719","-0.32689"
"65.11700","-153.60719","-0.33465"
"65.17400","-153.60719","-0.34642"
"65.27700","-153.60719","-0.33992"
"65.34500","-153.60719","-0.31811"
"65.42300","-153.60719","-0.30112"
"65.50900","-153.60719","-0.23610"
"65.57900","-153.60719","-0.23843"
"65.65000","-153.60719","-0.24038"
"65.71200","-153.60719","-0.25002"
"65.78700","-153.60719","-0.25557"
"65.86900","-153.60719","-0.25065"
"65.95700","-153.60719","-0.24022"
"66.02500","-153.60719","-0.24855"
"66.08000","-153.60719","-0.18923"
"66.15200","-153.60719","-0.19231"
"66.24500","-153.60719","-0.19923"
"66.30700","-153.60719","-0.20497"
"66.38800","-153.60719","-0.19884"
"66.45300","-153.60719","-0.19671"
"66.52900","-153.60719","-0.21759"
"66.60100","-153.60719","-0.20966"
"66.67300","-153.60719","-0.19740"
"66.73500","-153.60719","-0.19409"
"66.79600","-153.60719","-0.19559"
"66.88300","-153.60719","-0.18329"
"67.00100","-153.60719","-0.19356"
"67.07500","-153.60719","-0.14187"
"67.16500","-153.60719","-0.14491"
"67.24900","-153.60719","-0.16370"
"67.33100","-153.60719","-0.13333"
"67.40500","-153.60719","-0.17220"
"67.47400","-153.60719","-0.13202"
"67.53300","-153.60719","-0.14511"
"67.60900","-153.60719","-0.16030"
"67.68600","-153.60719","-0.15798"
"67.75300","-153.60719","-0.14627"
"67.82700","-153.60719","-0.15604"
"67.89900","-153.60719","-0.15833"
"67.99400","-153.60719","-0.15578"
"68.08000","-153.60719","-0.15498"
"68.16500","-153.60719","-0.14952"
"68.23500","-153.60719","-0.15639"
"68.31900","-153.60719","-0.15332"
"68.38400","-153.60719","-0.16907"
"68.47300","-153.60719","-0.15867"
"68.54600","-153.60719","-0.15871"
"68.61100","-153.60719","-0.17089"
"68.67400","-153.60719","-0.15619"
"68.74100","-153.60719","-0.14295"
"68.82200","-153.60719","-0.14101"
"68.91300","-153.60719","-0.14597"
"68.99900","-153.60719","-0.14985"
"69.05900","-153.60719","-0.15193"
"69.14800","-153.60719","-0.14592"
"69.22500","-153.60719","-0.13139"
"69.31000","-153.60719","-0.16087"
"69.37800","-153.60719","-0.15095"
"69.44300","-153.60719","-0.13515"
"69.53800","-153.60719","-0.15746"
"69.60500","-153.60719","-0.14737"
"69.69000","-153.60719","-0.14983"
"69.74200","-153.60719","-0.10090"
"69.82700","-153.60719","-0.11049"
"69.92200","-153.60719","-0.12515"
"69.99000","-153.60719","-0.11817"
"70.05900","-153.60719","-0.12538"
"70.11700","-153.60719","-0.10598"
"70.18100","-153.60719","-0.11381"
"70.26400","-153.60719","-0.12401"
"70.32900","-153.60719","-0.14537"
"70.38700","-153.60719","-0.11879"
"70.46500","-153.60719","-0.11630"
"70.53400","-153.60719","-0.11895"
"70.60900","-153.60719","-0.13709"
"70.67200","-153.60719","-0.12244"
"70.73600","-153.60719","-0.12925"
"70.81200","-153.60719","-0.13349"
"70.89300","-153.60719","-0.13009"
"70.97700","-153.60719","-0.12475"
"71.05100","-153.60719","-0.10803"
"71.11000","-153.60719","-0.11738"
"71.18400","-153.60719","-0.13129"
"71.26100","-153.60719","-0.12547"
"71.35500","-153.60719","-0.14917"
"71.43000","-153.60719","-0.17245"
"71.48800","-153.60719","-0.21463"
"71.52500","-153.60719","-0.39332"
"71.56400","-153.60719","-0.56306"
"71.59400","-153.60719","-0.80010"
"71.63100","-153.60719","-0.71367"
"71.64600","-153.60719","-0.48626"
"71.66300","-153.60719","-0.27412"
"71.68700","-153.60719","-0.06118"
"71.73500","-153.60719","-0.08138"
"71.80200","-153.60719","0.02424"
"71.89700","-153.60719","-0.00354"
"71.97200","-153.60719","0.02206"
"72.03100","-153.60719","-0.03058"
"72.07500","-153.60719","-0.34386"
"72.10200","-153.60719","-0.42051"
"72.11800","-153.60719","-0.19307"
"72.14300","-153.60719","0.00718"
"72.22400","-153.60719","0.02187"
"72.28400","-153.60719","0.01585"
"72.36000","-153.60719","0.01464"
"72.43500","-153.60719","0.01996"
"72.50300","-153.60719","0.02109"
"72.59100","-153.60719","0.01783"
"72.68000","-153.60719","0.02160"
"72.77100","-153.60719","0.01635"
"72.82600","-153.60719","0.01307"
"72.87200","-153.60719","-0.08811"
"72.93100","-153.60719","-0.00259"
"73.00600","-153.60719","0.00370"
"73.08300","-153.60719","0.01854"
"73.14500","-153.60719","0.01373"
"73.20100","-153.60719","-0.01429"
"73.28300","-153.60719","-0.01173"
"73.36200","-153.60719","-0.01273"
"73.44600","-153.60719","-0.01391"
"73.52400","-153.60719","-0.00758"
"73.62500","-153.60719","0.00475"
"73.69300","-153.60719","-0.01963"
"73.79100","-153.60719","-0.00785"
"73.86000","-153.60719","-0.02655"
"73.92600","-153.60719","-0.00574"
"74.00400","-153.60719","-0.00230"
"74.09300","-153.60719","-0.00098"
"74.16800","-153.60719","-0.01008"
"74.24900","-153.60719","-0.01959"
"74.31600","-153.60719","-0.01329"
"74.39000","-153.60719","-0.00874"
"74.47000","-153.60719","-0.02418"
"74.55300","-153.60719","0.00454"
"74.63100","-153.60719","-0.00517"
"74.70900","-153.60719","-0.01109"
"74.79300","-153.60719","0.00515"
"74.88900","-153.60719","-0.00351"
"74.96400","-153.60719","-0.00551"
"75.07400","-153.60719","0.01360"
"75.13600","-153.60719","-0.01879"
"75.21300","-153.60719","-0.00010"
"75.29100","-153.60719","-0.01106"
"75.36300","-153.60719","-0.00020"
"75.44600","-153.60719","-0.02548"
"75.51900","-153.60719","-0.00821"
"75.57500","-153.60719","-0.01702"
"75.65300","-153.60719","-0.00794"
"75.71600","-153.60719","-0.00600"
"75.77600","-153.60719","-0.00567"
"75.85300","-153.60719","-0.00882"
"75.92700","-153.60719","0.00679"
"76.01200","-153.60719","-0.00348"
"76.08300","-153.60719","-0.01368"
"76.14300","-153.60719","0.00283"
"76.21900","-153.60719","0.00328"
"76.29900","-153.60719","-0.00090"
"76.36600","-153.60719","0.00000"
"76.43200","-153.60719","-0.00035"
"76.49400","-153.60719","-0.02732"
"76.56500","-153.60719","-0.00806"
"76.62800","-153.60719","-0.00725"
"76.68500","-153.60719","-0.01442"
"76.76900","-153.60719","-0.00952"
"76.83900","-153.60719","-0.00348"
"76.91700","-153.60719","-0.00149"
"76.99000","-153.60719","-0.00034"
"77.06900","-153.60719","0.00073"
"77.13000","-153.60719","-0.01207"
"77.20200","-153.60719","-0.00978"
"77.27100","-153.60719","0.00111"
"77.34300","-153.60719","-0.01705"
"77.43100","-153.60719","-0.03491"
"77.48300","-153.60719","-0.21962"
"77.51700","-153.60719","-0.39084"
"77.57300","-153.60719","-0.56475"
"77.64300","-153.60719","-0.50523"
"77.72200","-153.60719","-0.46110"
"77.80500","-153.60719","-0.43112"
"77.88400","-153.60719","-0.40408"
"77.96300","-153.60719","-0.40025"
"78.03800","-153.60719","-0.38069"
"78.12400","-153.60719","-0.38014"
"78.21200","-153.60719","-0.36447"
"78.29300","-153.60719","-0.35268"
"78.36400","-153.60719","-0.35097"
"78.46800","-153.60719","-0.34111"
"78.52600","-153.60719","-0.33654"
"78.59500","-153.60719","-0.30324"
"78.67900","-153.60719","-0.30139"
"78.75000","-153.60719","-0.28607"
"78.82700","-153.60719","-0.29580"
"78.90900","-153.60719","-0.29690"
"78.97100","-153.60719","-0.27173"
"79.05300","-153.60719","-0.26959"
"79.12900","-153.60719","-0.26747"
"79.19100","-153.60719","-0.26749"
"79.26700","-153.60719","-0.21277"
"79.32100","-153.60719","-0.22691"
"79.40400","-153.60719","-0.24035"
"79.47200","-153.60719","-0.22856"
"79.53100","-153.60719","-0.22662"
"79.60600","-153.60719","-0.22520"
"79.68500","-153.60719","-0.22138"
"79.77600","-153.60719","-0.23049"
"79.85100","-153.60719","-0.22670"
"79.92400","-153.60719","-0.20203"
"80.01700","-153.60719","-0.18931"
"80.11500","-153.60719","-0.18728"
"80.19700","-153.60719","-0.18179"
"80.27500","-153.60719","-0.18689"
"80.35400","-153.60719","-0.18267"
"80.43600","-153.60719","-0.19809"
"80.51300","-153.60719","-0.19000"
"80.57500","-153.60719","-0.18704"
"80.64200","-153.60719","-0.19891"
"80.71400","-153.60719","-0.17385"
"80.79200","-153.60719","-0.17880"
"80.86400","-153.60719","-0.16767"
"80.92000","-153.60719","-0.17201"
"80.99900","-153.60719","-0.15558"
"81.06800","-153.60719","-0.14480"
"81.14500","-153.60719","-0.15163"
"81.21300","-153.60719","-0.15789"
"81.27900","-153.60719","-0.16942"
"81.35800","-153.60719","-0.15848"
"81.44800","-153.60719","-0.16114"
"81.52500","-153.60719","-0.15212"
"81.60600","-153.60719","-0.16557"
"81.69600","-153.60719","-0.15698"
"81.77300","-153.60719","-0.14885"
"81.83800","-153.60719","-0.16302"
"81.91500","-153.60719","-0.16193"
"81.98600","-153.60719","-0.16523"
"82.06300","-153.60719","-0.15173"
"82.12900","-153.60719","-0.15257"
"82.22300","-153.60719","-0.16651"
"82.29100","-153.60719","-0.15730"
"82.36000","-153.60719","-0.16949"
"82.42300","-153.60719","-0.15137"
"82.49900","-153.60719","-0.15116"
"82.57500","-153.60719","-0.13418"
"82.64700","-153.60719","-0.14396"
"82.70600","-153.60719","-0.15349"
"82.76500","-153.60719","-0.13288"
"82.82600","-153.60719","-0.14032"
"82.91600","-153.60719","-0.14067"
"82.98800","-153.60719","-0.13213"
"83.07700","-153.60719","-0.13716"
"83.16400","-153.60719","-0.13800"
"83.23300","-153.60719","-0.12155"
"83.31400","-153.60719","-0.16436"
"83.38400","-153.60719","-0.11553"
"83.44900","-153.60719","-0.12517"
"83.52100","-153.60719","-0.12035"
"83.58200","-153.60719","-0.12955"
"83.65600","-153.60719","-0.13626"
"83.72500","-153.60719","-0.22824"
"83.77100","-153.60719","-0.39715"
"83.82600","-153.60719","-0.38810"
"83.85700","-153.60719","-0.18918"
"83.89800","-153.60719","-0.00900"
"83.96800","-153.60719","0.02016"
"84.05800","-153.60719","0.02105"
"84.15300","-153.60719","0.01748"
"84.21900","-153.60719","-0.11276"
"84.28800","-153.60719","-0.17400"
"84.32900","-153.60719","-0.03998"
"84.40000","-153.60719","-0.00023"
"84.45600","-153.60719","0.01292"
"84.52400","-153.60719","0.01291"
"84.59300","-153.60719","0.01242"
"84.70200","-153.60719","0.01471"
"84.78100","-153.60719","-0.00139"
"84.83300","-153.60719","0.01044"
"84.91600","-153.60719","0.02448"
"85.00100","-153.60719","0.01830"
"85.08500","-153.60719","0.00093"
"85.18000","-153.60719","0.02520"
"85.23300","-153.60719","-0.01788"
"85.30700","-153.60719","-0.01258"
"85.35900","-153.60719","-0.01775"
"85.46100","-153.60719","-0.01382"
"85.54200","-153.60719","-0.03288"
"85.63600","-153.60719","-0.01930"
"85.71400","-153.60719","-0.02323"
"85.77200","-153.60719","-0.02141"
"85.84300","-153.60719","-0.01399"
"85.93100","-153.60719","-0.02152"
"86.02400","-153.60719","0.00106"
"86.09100","-153.60719","-0.02743"
"86.18700","-153.60719","-0.01534"
"86.27500","-153.60719","-0.03048"
"86.35200","-153.60719","-0.00312"
"86.41700","-153.60719","-0.03077"
"86.49400","-153.60719","-0.00347"
"86.60000","-153.60719","-0.01354"
"86.68400","-153.60719","-0.01669"
"86.77700","-153.60719","-0.02549"
"86.85800","-153.60719","-0.01270"
"86.94600","-153.60719","-0.03988"
"87.03000","-153.60719","-0.00470"
"87.10300","-153.60719","-0.00980"
"87.17900","-153.60719","-0.01292"
"87.24700","-153.60719","-0.02033"
"87.30400","-153.60719","-0.02609"
"87.37200","-153.60719","-0.01323"
"87.46200","-153.60719","-0.02959"
"87.52800","-153.60719","-0.02313"
"87.60000","-153.60719","-0.01917"
"87.67700","-153.60719","-0.00910"
"87.72600","-153.60719","-0.01833"
"87.79600","-153.60719","-0.02489"
"87.88100","-153.60719","-0.00935"
"87.96100","-153.60719","-0.01964"
"88.04300","-153.60719","-0.01807"
"88.12000","-153.60719","-0.02048"
"88.18600","-153.60719","-0.01349"
"88.27300","-153.60719","-0.01860"
"88.34900","-153.60719","-0.01331"
"88.42000","-153.60719","-0.01372"
"88.49100","-153.60719","-0.01281"
"88.57200","-153.60719","-0.02005"
"88.63800","-153.60719","-0.04499"
"88.72600","-153.60719","-0.01982"
"88.80100","-153.60719","-0.02353"
"88.86700","-153.60719","-0.03259"
"88.94000","-153.60719","-0.01768"
"89.01100","-153.60719","-0.02787"
"89.08500","-153.60719","-0.03018"
"89.16500","-153.60719","-0.01905"
"89.23600","-153.60719","-0.02137"
"89.30800","-153.60719","-0.01555"
"89.41100","-153.60719","-0.01557"
"89.48400","-153.60719","-0.02843"
"89.55800","-153.60719","-0.02131"
"89.62500","-153.60719","-0.02084"
"89.70700","-153.60719","-0.02567"
"89.78100","-153.60719","-0.01626"
"89.85000","-153.60719","-0.00948"
"89.93100","-153.60719","-0.01001"
"90.03200","-153.60719","-0.02324"
"90.09400","-153.60719","-0.01070"
"90.15900","-153.60719","-0.02022"
"90.23700","-153.60719","-0.01345"
"90.31200","-153.60719","-0.07460"
"90.35500","-153.60719","-0.26814"
"90.40300","-153.60719","-0.45998"
"90.45900","-153.60719","-0.50390"
"90.52500","-153.60719","-0.51644"
"90.59600","-153.60719","-0.54327"
"90.69600","-153.60719","-0.49301"
"90.76500","-153.60719","-0.48388"
"90.84400","-153.60719","-0.47101"
"90.92400","-153.60719","-0.45863"
"91.01800","-153.60719","-0.47278"
"91.09800","-153.60719","-0.43802"
"91.17000","-153.60719","-0.44157"
"91.24400","-153.60719","-0.42086"
"91.32100","-153.60719","-0.41530"
"91.39400","-153.60719","-0.40412"
"91.46300","-153.60719","-0.39860"
"91.54900","-153.60719","-0.37199"
"91.62000","-153.60719","-0.38720"
"91.70800","-153.60719","-0.38543"
"91.78100","-153.60719","-0.35955"
"91.84900","-153.60719","-0.36498"
"91.94600","-153.60719","-0.35467"
"92.00700","-153.60719","-0.34413"
"92.09000","-153.60719","-0.32607"
"92.16600","-153.60719","-0.33101"
"92.24900","-153.60719","-0.31554"
"92.34300","-153.60719","-0.31098"
"92.42300","-153.60719","-0.31636"
"92.51400","-153.60719","-0.29229"
"92.57800","-153.60719","-0.28933"
"92.64000","-153.60719","-0.29495"
"92.70800","-153.60719","-0.28166"
"92.79300","-153.60719","-0.27799"
"92.88100","-153.60719","-0.27856"
"92.94200","-153.60719","-0.29005"
"93.00700","-153.60719","-0.27413"
"93.08200","-153.60719","-0.26593"
"93.17500","-153.60719","-0.26130"
"93.24900","-153.60719","-0.24198"
"93.31400","-153.60719","-0.21941"
"93.37200","-153.60719","-0.22330"
"93.45900","-153.60719","-0.23180"
"93.54500","-153.60719","-0.23636"
"93.64100","-153.60719","-0.22459"
"93.70800","-153.60719","-0.23695"
"93.79100","-153.60719","-0.22344"
"93.85900","-153.60719","-0.23798"
"93.93100","-153.60719","-0.23242"
"94.00700","-153.60719","-0.23055"
"94.07100","-153.60719","-0.22255"
"94.15300","-153.60719","-0.24051"
"94.21700","-153.60719","-0.22771"
"94.30800","-153.60719","-0.22413"
"94.37700","-153.60719","-0.21615"
"94.45300","-153.60719","-0.21287"
"94.53500","-153.60719","-0.23409"
"94.60800","-153.60719","-0.21860"
"94.68200","-153.60719","-0.22725"
"94.74500","-153.60719","-0.23043"
"94.81600","-153.60719","-0.22213"
"94.90000","-153.60719","-0.21479"
"94.98100","-153.60719","-0.21580"
"95.06700","-153.60719","-0.15082"
"95.14400","-153.60719","-0.16984"
"95.23100","-153.60719","-0.14823"
"95.30100","-153.60719","-0.16895"
"95.36700","-153.60719","-0.19826"
"95.43800","-153.60719","-0.16876"
"95.50900","-153.60719","-0.17276"
"95.59300","-153.60719","-0.17678"
"95.69600","-153.60719","-0.18838"
"95.80400","-153.60719","-0.17469"
"95.90100","-153.60719","-0.17868"
"95.97300","-153.60719","-0.17784"
"96.08200","-153.60719","-0.18770"
"96.16300","-153.60719","-0.18060"
"96.23600","-153.60719","-0.19241"
"96.30700","-153.60719","-0.18629"
"96.39400","-153.60719","-0.18023"
"96.45000","-153.60719","-0.19500"
"96.51200","-153.60719","-0.20047"
"96.56500","-153.60719","-0.18170"
"96.66000","-153.60719","-0.17511"
"96.72300","-153.60719","-0.17741"
"96.79500","-153.60719","-0.17388"
"96.89700","-153.60719","-0.17091"
"96.99500","-153.60719","-0.17996"
"97.07100","-153.60719","-0.18984"
"97.16700","-153.60719","-0.16439"
"97.25300","-153.60719","-0.17241"
"97.34400","-153.60719","-0.16904"
"97.42800","-153.60719","-0.17745"
"97.47900","-153.60719","-0.19529"
"97.54900","-153.60719","-0.16752"
"97.61900","-153.60719","-0.17823"
"97.70400","-153.60719","-0.17402"
"97.78000","-153.60719","-0.17206"
"97.85500","-153.60719","-0.19520"
"97.93200","-153.60719","-0.15938"
"98.01600","-153.60719","-0.18047"
"98.11600","-153.60719","-0.18259"
"98.18000","-153.60719","-0.18433"
"98.25800","-153.60719","-0.17346"
"98.33500","-153.60719","-0.17008"
"98.41000","-153.60719","-0.17013"
"98.47600","-153.60719","-0.17261"
"98.56600","-153.60719","-0.17447"
"98.64600","-153.60719","-0.14849"
"98.71800","-153.60719","-0.17738"
"98.79600","-153.60719","-0.17720"
"98.87300","-153.60719","-0.17435"
"98.94100","-153.60719","-0.16555"
"99.00000","-153.60719","-0.14484"
"99.06200","-153.60719","-0.15617"
"99.13500","-153.60719","-0.18607"
"99.20800","-153.60719","-0.17098"
"99.31200","-153.60719","-0.16940"
"99.39700","-153.60719","-0.17262"
"99.47500","-153.60719","-0.16644"
"99.53800","-153.60719","-0.16939"
"99.60700","-153.60719","-0.17029"
"99.68800","-153.60719","-0.14810"
"99.75800","-153.60719","-0.13569"
"99.82000","-153.60719","-0.12991"
"99.90400","-153.60719","-0.14034"
"99.97000","-153.60719","-0.11163"
"100.04100","-153.60719","-0.13081"
"100.12400","-153.60719","-0.14333"
"100.19100","-153.60719","-0.14006"
"100.25100","-153.60719","-0.13339"
"100.32400","-153.60719","-0.12922"
"100.39200","-153.60719","-0.13428"
"100.48300","-153.60719","-0.14694"
"100.56300","-153.60719","-0.13471"
"100.62200","-153.60719","-0.14669"
"100.71000","-153.60719","-0.13336"
"100.79100","-153.60719","-0.14117"
"100.85900","-153.60719","-0.12503"
"100.94600","-153.60719","-0.12585"
"101.02700","-153.60719","-0.11097"
"101.10100","-153.60719","-0.13839"
"101.18800","-153.60719","-0.13766"
"101.25900","-153.60719","-0.13932"
"101.34900","-153.60719","-0.14733"
"101.43500","-153.60719","-0.14142"
"101.47700","-153.60719","-0.13760"
"101.54900","-153.60719","-0.12504"
"101.62800","-153.60719","-0.14488"
"101.68200","-153.60719","-0.14536"
"101.74900","-153.60719","-0.13836"
"101.80700","-153.60719","-0.13897"
"101.87200","-153.60719","-0.14963"
"101.93400","-153.60719","-0.12262"
"102.00100","-153.60719","-0.14545"
"102.08000","-153.60719","-0.14357"
"102.13500","-153.60719","-0.13193"
"102.24000","-153.60719","-0.14440"
"102.30300","-153.60719","-0.13286"
"102.37700","-153.60719","-0.14468"
"102.44600","-153.60719","-0.14374"
"102.52400","-153.60719","-0.13495"
"102.59700","-153.60719","-0.13801"
"102.66100","-153.60719","-0.15096"
"102.73300","-153.60719","-0.14215"
"102.81500","-153.60719","-0.13242"
"102.89900","-153.60719","-0.14002"
"102.96600","-153.60719","-0.14064"
"103.04100","-153.60719","-0.15183"
"103.10500","-153.60719","-0.14989"
"103.18600","-153.60719","-0.12324"
"103.25900","-153.60719","-0.14058"
"103.33300","-153.60719","-0.10846"
"103.39200","-153.60719","-0.12305"
"103.49000","-153.60719","-0.13707"
"103.56300","-153.60719","-0.13760"
"103.65200","-153.60719","-0.12305"
"103.73000","-153.60719","-0.13636"
"103.79700","-153.60719","-0.14154"
"103.84000","-153.60719","-0.14215"