File: chapter 4/force/mini_patrick.is_tens_RawData/Specimen_RawData_6.csv
Time,Extension,Load
(s),(mm),(N)
"0.00000","-153.87355","0.00408"
"0.05100","-153.87367","-0.00797"
"0.09400","-153.87367","0.00153"
"0.14800","-153.87367","0.00984"
"0.18500","-153.87364","-0.00288"
"0.23600","-153.87364","-0.00816"
"0.28200","-153.87364","0.00488"
"0.33100","-153.87363","0.00707"
"0.37800","-153.87361","-0.00419"
"0.42200","-153.87361","0.01125"
"0.45200","-153.87361","0.00725"
"0.49300","-153.87361","-0.00428"
"0.54100","-153.87361","0.01777"
"0.59100","-153.87360","0.00225"
"0.64100","-153.87360","0.00235"
"0.68300","-153.87360","0.02114"
"0.72400","-153.87360","-0.01234"
"0.75800","-153.87360","-0.00229"
"0.80900","-153.87360","0.01074"
"0.84100","-153.87360","0.00963"
"0.87000","-153.87360","-0.01134"
"0.90900","-153.87355","-0.00805"
"0.95600","-153.87355","-0.00883"
"1.00700","-153.87355","-0.01146"
"1.05500","-153.87355","0.00494"
"1.10800","-153.87355","0.01108"
"1.14600","-153.87355","0.00473"
"1.18200","-153.87355","0.00918"
"1.21500","-153.87355","-0.00453"
"1.24800","-153.87355","0.01242"
"1.30200","-153.87355","0.00935"
"1.35600","-153.87355","0.00426"
"1.38500","-153.87355","-0.00016"
"1.43500","-153.87355","0.00425"
"1.48500","-153.87355","-0.01523"
"1.52700","-153.87355","-0.00722"
"1.57700","-153.87355","-0.01753"
"1.61500","-153.87355","0.00654"
"1.66000","-153.87355","0.00087"
"1.69800","-153.87355","0.00092"
"1.74100","-153.87355","-0.00906"
"1.78300","-153.87355","-0.00041"
"1.82600","-153.87355","0.01403"
"1.87800","-153.87355","0.00910"
"1.92200","-153.87355","0.00662"
"1.95400","-153.87355","-0.00362"
"1.99700","-153.87355","-0.00263"
"2.04500","-153.87355","-0.00313"
"2.07900","-153.87355","-0.00649"
"2.10400","-153.87355","-0.00932"
"2.15300","-153.87355","-0.00695"
"2.19900","-153.87355","-0.00426"
"2.23200","-153.87355","-0.01450"
"2.26700","-153.87355","-0.01601"
"2.32300","-153.87355","-0.00928"
"2.36100","-153.87355","-0.00762"
"2.40600","-153.87355","0.01154"
"2.46500","-153.87355","-0.00115"
"2.52700","-153.87355","-0.01107"
"2.57100","-153.87355","0.00289"
"2.61600","-153.87355","-0.00527"
"2.64500","-153.87355","-0.00399"
"2.67100","-153.87355","0.00109"
"2.71100","-153.87355","-0.01880"
"2.75500","-153.87355","0.00207"
"2.80600","-153.87355","0.01447"
"2.84700","-153.87355","0.00231"
"2.89900","-153.87355","0.00305"
"2.93600","-153.87355","-0.01211"
"2.97200","-153.87355","-0.00094"
"3.02400","-153.87355","-0.00189"
"3.04800","-153.87355","0.02732"
"3.08400","-153.87355","0.01123"
"3.11900","-153.87355","0.01686"
"3.17800","-153.87355","0.01245"
"3.20700","-153.87355","-0.00052"
"3.25300","-153.87355","0.00677"
"3.29700","-153.87355","-0.01180"
"3.34200","-153.87355","-0.00359"
"3.37700","-153.87355","-0.00530"
"3.41900","-153.87355","0.00373"
"3.46000","-153.87355","-0.00078"
"3.51100","-153.87355","0.00670"
"3.55500","-153.87355","-0.00271"
"3.59600","-153.87355","0.00242"
"3.64200","-153.87355","-0.00171"
"3.67300","-153.87355","-0.01353"
"3.72300","-153.87355","-0.01201"
"3.75600","-153.87355","0.00525"
"3.79500","-153.87355","0.00575"
"3.83200","-153.87355","0.00511"
"3.87500","-153.87355","0.00444"
"3.91400","-153.87355","0.00456"
"3.96600","-153.87355","-0.01180"
"3.99700","-153.87355","-0.00350"
"4.03900","-153.87355","0.02450"
"4.06900","-153.87355","-0.01520"
"4.11100","-153.87355","-0.01085"
"4.14700","-153.87355","0.00551"
"4.21600","-153.87355","-0.00704"
"4.25500","-153.87355","0.00228"
"4.28600","-153.87355","-0.01044"
"4.34000","-153.87355","-0.00482"
"4.39100","-153.87355","-0.00782"
"4.43300","-153.87355","-0.00230"
"4.48500","-153.87355","0.00053"
"4.52500","-153.87355","-0.00606"
"4.56300","-153.87355","0.00787"
"4.60800","-153.87355","-0.00226"
"4.66500","-153.87355","0.01259"
"4.71600","-153.87355","0.00210"
"4.76300","-153.87355","-0.01845"
"4.79900","-153.87355","0.01726"
"4.84300","-153.87355","0.00636"
"4.87400","-153.87355","0.00861"
"4.91800","-153.87355","-0.00260"
"4.94500","-153.87355","-0.00418"
"4.99200","-153.87355","0.00263"
"5.04100","-153.87355","0.00337"
"5.08000","-153.87355","0.01860"
"5.11200","-153.87355","-0.00560"
"5.15400","-153.87355","0.00679"
"5.20200","-153.87355","-0.00409"
"5.24100","-153.87355","-0.00155"
"5.28800","-153.87355","0.01253"
"5.30700","-153.87355","-0.00247"
"5.34200","-153.87355","-0.00327"
"5.37900","-153.87355","0.00046"
"5.42800","-153.87355","0.00645"
"5.49100","-153.87355","0.01140"
"5.53800","-153.87355","-0.01080"
"5.57300","-153.87355","0.00805"
"5.59100","-153.87355","-0.00233"
"5.63800","-153.87355","-0.00722"
"5.69700","-153.87355","0.00675"
"5.74200","-153.87355","-0.00459"
"5.77400","-153.87355","0.01733"
"5.82200","-153.87355","0.00564"
"5.86700","-153.87355","-0.00948"
"5.92600","-153.87355","-0.00067"
"5.98400","-153.87355","-0.00504"
"6.04100","-153.87355","-0.00254"
"6.08300","-153.87355","0.01465"
"6.11200","-153.87355","-0.00629"
"6.16500","-153.87355","0.00825"
"6.18900","-153.87355","-0.01557"
"6.22900","-153.87355","-0.01923"
"6.25300","-153.87355","-0.00988"
"6.29600","-153.87355","0.00145"
"6.33900","-153.87355","-0.00094"
"6.38200","-153.87355","-0.01024"
"6.43000","-153.87355","0.00024"
"6.46800","-153.87355","0.01391"
"6.51300","-153.87355","0.00191"
"6.55500","-153.87355","0.00046"
"6.60700","-153.87355","-0.01178"
"6.64600","-153.87355","0.00176"
"6.68000","-153.87355","-0.00569"
"6.74300","-153.87355","-0.01072"
"6.77500","-153.87355","0.01027"
"6.81900","-153.87355","0.00205"
"6.87000","-153.87355","0.01135"
"6.92200","-153.87355","0.00139"
"6.97400","-153.87355","0.00101"
"7.01200","-153.87355","-0.01047"
"7.05100","-153.87355","-0.01373"
"7.08900","-153.87355","-0.00959"
"7.13000","-153.87355","-0.00727"
"7.16700","-153.87355","0.00386"
"7.21500","-153.87355","0.00402"
"7.27400","-153.87355","-0.00227"
"7.31200","-153.87355","-0.00431"
"7.35700","-153.87355","-0.00146"
"7.39700","-153.87355","0.01652"
"7.43900","-153.87355","-0.00235"
"7.48300","-153.87355","0.00309"
"7.54200","-153.87355","-0.00330"
"7.58100","-153.87355","0.00528"
"7.63100","-153.87355","-0.01243"
"7.69100","-153.87355","-0.01566"
"7.72500","-153.87355","-0.02737"
"7.78100","-153.87355","-0.01381"
"7.82200","-153.87355","-0.02777"
"7.87200","-153.87355","-0.02331"
"7.91500","-153.87355","-0.01042"
"7.96600","-153.87355","-0.00510"
"8.02100","-153.87355","-0.01838"
"8.05900","-153.87355","-0.02137"
"8.11100","-153.87355","-0.00871"
"8.16800","-153.87355","0.00668"
"8.21000","-153.87355","-0.02127"
"8.25100","-153.87355","-0.00904"
"8.29500","-153.87355","-0.02469"
"8.32900","-153.87355","0.00024"
"8.36900","-153.87355","0.00345"
"8.40500","-153.87355","-0.01422"
"8.44200","-153.87355","-0.00628"
"8.46500","-153.87355","-0.00972"
"8.51100","-153.87355","-0.00497"
"8.54800","-153.87355","-0.02639"
"8.60400","-153.87355","-0.00922"
"8.66100","-153.87355","-0.00668"
"8.71700","-153.87355","-0.00377"
"8.75500","-153.87355","-0.00427"
"8.80000","-153.87355","-0.01556"
"8.85400","-153.87355","-0.01486"
"8.89000","-153.87355","-0.01686"
"8.94100","-153.87355","-0.01863"
"8.97500","-153.87355","0.00813"
"9.01300","-153.87355","-0.01322"
"9.04300","-153.87355","-0.00328"
"9.08100","-153.87355","0.00504"
"9.11700","-153.87355","-0.00228"
"9.15800","-153.87355","-0.00682"
"9.21000","-153.87355","-0.01591"
"9.27100","-153.87355","-0.00015"
"9.32400","-153.87355","-0.00901"
"9.36300","-153.87355","-0.00580"
"9.39100","-153.87355","-0.00493"
"9.42500","-153.87355","0.00259"
"9.46700","-153.87355","0.00628"
"9.51600","-153.87355","0.02132"
"9.54900","-153.87355","-0.00689"
"9.59800","-153.87355","-0.00408"
"9.64400","-153.87355","0.00390"
"9.69400","-153.87355","0.00083"
"9.72400","-153.87355","-0.00094"
"9.76300","-153.87355","-0.00678"
"9.80100","-153.87355","-0.00075"
"9.84200","-153.87355","-0.02105"
"9.89100","-153.87355","0.01290"
"9.93200","-153.87355","-0.00473"
"9.98100","-153.87355","0.00372"
"10.03000","-153.87355","0.00819"
"10.08600","-153.87355","-0.00535"
"10.13400","-153.87355","0.01274"
"10.17000","-153.87355","0.00954"
"10.22400","-153.87355","0.00913"
"10.26600","-153.87355","0.01664"
"10.29500","-153.87355","0.00384"
"10.34400","-153.87355","-0.01654"
"10.37300","-153.87355","0.00350"
"10.42400","-153.87355","-0.00322"
"10.47400","-153.87355","0.01092"
"10.50500","-153.87355","0.01597"
"10.53000","-153.87355","0.01296"
"10.58800","-153.87355","0.00082"
"10.62600","-153.87355","-0.00450"
"10.67400","-153.87355","-0.00628"
"10.70100","-153.87355","0.01989"
"10.74700","-153.87355","0.01513"
"10.79800","-153.87355","0.01242"
"10.84000","-153.87355","0.00987"
"10.87800","-153.87355","-0.00109"
"10.91100","-153.87355","-0.00830"
"10.94900","-153.87355","0.00000"
"10.98600","-153.87355","-0.00355"
"11.02600","-153.87355","-0.01016"
"11.08200","-153.87355","-0.00055"
"11.12200","-153.87355","-0.00126"
"11.15600","-153.87355","0.00806"
"11.19800","-153.87355","-0.00596"
"11.24300","-153.87355","-0.00764"
"11.29500","-153.87355","-0.01053"
"11.33000","-153.87355","0.00949"
"11.36900","-153.87355","0.01287"
"11.41400","-153.87355","-0.00186"
"11.45600","-153.87355","0.01254"
"11.50500","-153.87355","-0.00276"
"11.53900","-153.87355","-0.01604"
"11.57100","-153.87355","-0.01756"
"11.62500","-153.87355","0.00079"
"11.66600","-153.87355","0.00504"
"11.70000","-153.87355","-0.00128"
"11.74100","-153.87355","-0.00592"
"11.78900","-153.87355","0.00234"
"11.84700","-153.87355","-0.01482"
"11.89800","-153.87355","-0.01025"
"11.93900","-153.87355","0.00335"
"11.99000","-153.87355","-0.00362"
"12.03600","-153.87355","0.00867"
"12.07100","-153.87355","0.00390"
"12.12400","-153.87355","-0.00571"
"12.17700","-153.87355","0.00426"
"12.21800","-153.87355","0.01164"
"12.25800","-153.87355","-0.00729"
"12.29500","-153.87355","0.00230"
"12.33600","-153.87355","-0.00132"
"12.39900","-153.87355","-0.00356"
"12.44900","-153.87355","0.00536"
"12.49300","-153.87355","0.01160"
"12.54000","-153.87355","-0.00799"
"12.58500","-153.87355","-0.00187"
"12.63300","-153.87355","0.00129"
"12.68100","-153.87355","0.00055"
"12.71000","-153.87355","-0.00220"
"12.76800","-153.87355","0.00772"
"12.81200","-153.87355","-0.01069"
"12.85900","-153.87355","-0.03351"
"12.90200","-153.87355","-0.08794"
"12.94700","-153.87355","-0.06161"
"12.99900","-153.87355","-0.06171"
"13.04600","-153.87355","-0.06077"
"13.09900","-153.87355","-0.05433"
"13.13800","-153.87355","-0.06544"
"13.16200","-153.87355","-0.03845"
"13.20900","-153.87355","-0.03784"
"13.25400","-153.87355","-0.04872"
"13.29600","-153.87355","-0.03714"
"13.34400","-153.87355","-0.05261"
"13.37900","-153.87355","-0.03848"
"13.40700","-153.87355","-0.03634"
"13.45900","-153.87355","-0.03845"
"13.49900","-153.87355","-0.03475"
"13.54200","-153.87355","-0.03729"
"13.58400","-153.87355","-0.03684"
"13.63400","-153.87355","-0.02516"
"13.68200","-153.87355","-0.01948"
"13.72700","-153.87355","-0.04021"
"13.76300","-153.87355","-0.04217"
"13.80000","-153.87355","-0.04347"
"13.84100","-153.87355","-0.02658"
"13.88400","-153.87355","-0.03167"
"13.93200","-153.87355","-0.03019"
"13.96100","-153.87355","-0.02968"
"14.01900","-153.87355","-0.03357"
"14.06900","-153.87355","-0.03563"
"14.11500","-153.87355","-0.03579"
"14.15000","-153.87355","-0.01228"
"14.18500","-153.87355","-0.02249"
"14.21200","-153.87355","-0.02065"
"14.26100","-153.87355","-0.02483"
"14.31700","-153.87355","-0.02339"
"14.36000","-153.87355","-0.01353"
"14.40800","-153.87355","-0.01173"
"14.44600","-153.87355","-0.03010"
"14.49200","-153.87355","-0.01146"
"14.54500","-153.87355","-0.02906"
"14.58800","-153.87355","-0.02972"
"14.64600","-153.87355","-0.01548"
"14.69800","-153.87355","-0.02670"
"14.74100","-153.87355","-0.02677"
"14.78800","-153.87355","-0.03301"
"14.82800","-153.87355","-0.02131"
"14.87000","-153.87355","-0.01607"
"14.92300","-153.87355","-0.01390"
"14.97200","-153.87355","-0.01373"
"15.01900","-153.87355","0.01007"
"15.06600","-153.87355","-0.01121"
"15.10200","-153.87355","-0.01261"
"15.14700","-153.87355","-0.00687"
"15.19700","-153.87355","-0.00755"
"15.24300","-153.87355","-0.02532"
"15.30000","-153.87355","-0.01993"
"15.36100","-153.87355","-0.02645"
"15.40600","-153.87355","-0.01873"
"15.43100","-153.87355","-0.01842"
"15.48000","-153.87355","-0.00743"
"15.52300","-153.87355","-0.02324"
"15.56800","-153.87355","-0.00136"
"15.61600","-153.87355","-0.01389"
"15.66200","-153.87355","-0.01672"
"15.72400","-153.87355","-0.01632"
"15.77800","-153.87355","-0.02026"
"15.82500","-153.87355","-0.01251"
"15.86800","-153.87355","-0.00370"
"15.90300","-153.87355","-0.00944"
"15.94400","-153.87355","-0.00490"
"15.98800","-153.87355","-0.02904"
"16.02400","-153.87355","-0.01459"
"16.06900","-153.87355","-0.00703"
"16.11500","-153.87355","-0.01619"
"16.16600","-153.87355","-0.01491"
"16.19800","-153.87355","-0.01187"
"16.24700","-153.87355","-0.01733"
"16.29400","-153.87355","-0.01016"
"16.33900","-153.87355","-0.00498"
"16.38400","-153.87355","-0.02050"
"16.42700","-153.87355","-0.02063"
"16.46900","-153.87355","-0.01196"
"16.52700","-153.87355","-0.02117"
"16.56900","-153.87355","-0.00831"
"16.60800","-153.87355","-0.01135"
"16.64000","-153.87355","-0.01967"
"16.66600","-153.87355","-0.01697"
"16.71500","-153.87355","-0.01053"
"16.74600","-153.87355","-0.02190"
"16.80600","-153.87355","-0.02021"
"16.85800","-153.87355","-0.01122"
"16.89300","-153.87355","-0.02084"
"16.93000","-153.87355","0.00107"
"16.97800","-153.87355","-0.00468"
"17.01500","-153.87355","-0.02961"
"17.06600","-153.87355","-0.02254"
"17.10800","-153.87355","-0.01208"
"17.16000","-153.87355","-0.02207"
"17.20000","-153.87355","0.00018"
"17.22500","-153.87355","-0.01141"
"17.26600","-153.87355","-0.01528"
"17.30500","-153.87355","-0.00718"
"17.35600","-153.87355","-0.01174"
"17.39800","-153.87355","-0.00924"
"17.43900","-153.87355","-0.00830"
"17.47800","-153.87355","-0.01959"
"17.53100","-153.87355","-0.02762"
"17.57100","-153.87355","-0.00445"
"17.62200","-153.87355","-0.00992"
"17.65900","-153.87355","-0.02333"
"17.69400","-153.87355","-0.00297"
"17.74000","-153.87355","-0.01545"
"17.77900","-153.87355","-0.01296"
"17.83400","-153.87355","-0.02118"
"17.84900","-153.87355","-0.00164"
"17.89300","-153.87355","-0.02856"
"17.92300","-153.87355","0.00113"
"17.95700","-153.87355","-0.01991"
"17.99200","-153.87355","-0.00875"
"18.03400","-153.87355","-0.01879"
"18.07300","-153.87355","0.00316"
"18.11800","-153.87355","0.01052"
"18.15700","-153.87355","-0.01981"
"18.19800","-153.87355","-0.00875"
"18.23700","-153.87355","-0.01113"
"18.29100","-153.87355","-0.02909"
"18.33800","-153.87355","0.00107"
"18.37400","-153.87355","0.00456"
"18.41800","-153.87355","-0.01142"
"18.46300","-153.87355","-0.04897"
"18.50400","-153.87355","-0.13988"
"18.53900","-153.87355","-0.15957"
"18.58500","-153.87355","-0.15394"
"18.63000","-153.87355","-0.12962"
"18.68400","-153.87355","-0.11685"
"18.72700","-153.87355","-0.13244"
"18.76900","-153.87355","-0.11416"
"18.82900","-153.87355","-0.11412"
"18.86200","-153.87355","-0.10780"
"18.91200","-153.87355","-0.09452"
"18.96600","-153.87355","-0.09876"
"19.01700","-153.87355","-0.08201"
"19.04700","-153.87355","-0.08454"
"19.08600","-153.87355","-0.07895"
"19.13300","-153.87355","-0.08639"
"19.16300","-153.87355","-0.07884"
"19.21500","-153.87355","-0.08350"
"19.25100","-153.87355","-0.07297"
"19.28900","-153.87355","-0.06026"
"19.33000","-153.87355","-0.07924"
"19.38700","-153.87355","-0.07082"
"19.42200","-153.87355","-0.06615"
"19.47000","-153.87355","-0.04863"
"19.49800","-153.87355","-0.08420"
"19.53900","-153.87355","-0.06644"
"19.58100","-153.87355","-0.06816"
"19.62300","-153.87355","-0.05210"
"19.67600","-153.87355","-0.06495"
"19.73000","-153.87355","-0.05448"
"19.78100","-153.87355","-0.06407"
"19.83400","-153.87355","-0.06543"
"19.89300","-153.87355","-0.04287"
"19.93600","-153.87355","-0.06235"
"19.97000","-153.87355","-0.05136"
"20.00500","-153.87355","-0.04684"
"20.05700","-153.87355","-0.05050"
"20.10700","-153.87355","-0.04624"
"20.14800","-153.87355","-0.04311"
"20.20200","-153.87355","-0.05325"
"20.25600","-153.87355","-0.03598"
"20.29200","-153.87355","-0.03734"
"20.32800","-153.87355","-0.04613"
"20.37000","-153.87355","-0.02850"
"20.41700","-153.87355","-0.04896"
"20.47200","-153.87355","-0.04293"
"20.51100","-153.87355","-0.03069"
"20.55000","-153.87355","-0.04402"
"20.61700","-153.87355","-0.05167"
"20.66000","-153.87355","-0.03180"
"20.70500","-153.87355","-0.02495"
"20.74900","-153.87355","-0.04631"
"20.79700","-153.87355","-0.03125"
"20.85900","-153.87355","-0.02530"
"20.89800","-153.87355","-0.02978"
"20.93000","-153.87355","-0.05789"
"20.97300","-153.87355","-0.03033"
"21.01700","-153.87355","-0.04593"
"21.06300","-153.87355","-0.04229"
"21.10200","-153.87355","-0.01845"
"21.14400","-153.87355","-0.03423"
"21.16300","-153.87355","-0.03011"
"21.19600","-153.87355","-0.03357"
"21.24300","-153.87355","-0.01786"
"21.28800","-153.87355","-0.03292"
"21.32700","-153.87355","-0.02755"
"21.37300","-153.87355","-0.01784"
"21.41000","-153.87355","-0.02509"
"21.45100","-153.87355","-0.02579"
"21.50300","-153.87355","-0.05187"
"21.53200","-153.87355","-0.03198"
"21.59300","-153.87355","-0.02773"
"21.63600","-153.87355","-0.03434"
"21.67200","-153.87355","-0.03478"
"21.73100","-153.87355","-0.02090"
"21.78800","-153.87355","-0.02033"
"21.84400","-153.87355","-0.02473"
"21.87900","-153.87355","-0.03408"
"21.92000","-153.87355","-0.03016"
"21.95700","-153.87355","-0.02201"
"21.99400","-153.87355","-0.03816"
"22.02800","-153.87355","-0.02906"
"22.06600","-153.87355","-0.01478"
"22.11000","-153.87355","-0.02755"
"22.16100","-153.87355","-0.02940"
"22.19900","-153.87355","-0.02771"
"22.25100","-153.87355","-0.02645"
"22.30800","-153.87355","-0.01395"
"22.35100","-153.87355","-0.02615"
"22.40300","-153.87355","-0.01022"
"22.44200","-153.87355","-0.03543"
"22.48300","-153.87355","-0.03823"
"22.51200","-153.87355","-0.02630"
"22.55400","-153.87355","-0.02364"
"22.59500","-153.87355","-0.02984"
"22.64700","-153.87355","-0.02026"
"22.68500","-153.87355","-0.03107"
"22.72900","-153.87355","-0.03106"
"22.76900","-153.87355","-0.02561"
"22.82100","-153.87355","-0.02020"
"22.87300","-153.87355","-0.02519"
"22.92500","-153.87355","-0.02696"
"22.96900","-153.87355","-0.01407"
"23.01700","-153.87355","-0.02116"
"23.05300","-153.87355","-0.03751"
"23.09400","-153.87355","-0.05031"
"23.12900","-153.87355","-0.02498"
"23.18500","-153.87355","-0.01813"
"23.23200","-153.87355","-0.02709"
"23.27700","-153.87355","-0.01569"
"23.31300","-153.87355","-0.01010"
"23.35600","-153.87355","-0.01341"
"23.40600","-153.87355","-0.01975"
"23.44300","-153.87355","-0.03366"
"23.50100","-153.87355","-0.04204"
"23.56800","-153.87355","-0.03248"
"23.61200","-153.87355","-0.01734"
"23.63800","-153.87355","-0.02116"
"23.67500","-153.87355","-0.01087"
"23.72600","-153.87355","-0.02597"
"23.79000","-153.87355","-0.02346"
"23.85000","-153.87355","-0.01593"
"23.89900","-153.87355","-0.02039"
"23.94400","-153.87355","-0.01477"
"23.97600","-153.87355","-0.02801"
"24.02500","-153.87355","-0.01230"
"24.08100","-153.87355","-0.03278"
"24.12500","-153.87355","-0.02537"
"24.17500","-153.87355","-0.03341"
"24.22400","-153.87355","-0.03187"
"24.28200","-153.87355","-0.02558"
"24.32400","-153.87355","-0.03112"
"24.38300","-153.87355","-0.04135"
"24.42400","-153.87355","-0.01883"
"24.47700","-153.87355","-0.02910"
"24.54000","-153.87355","-0.03650"
"24.58800","-153.87355","-0.01407"
"24.62300","-153.87355","-0.00661"
"24.65600","-153.87355","-0.04029"
"24.68900","-153.87355","-0.09899"
"24.72200","-153.87355","-0.16368"
"24.74900","-153.87355","-0.25696"
"24.78700","-153.87355","-0.24340"
"24.81700","-153.87355","-0.22013"
"24.87000","-153.87355","-0.20801"
"24.91700","-153.87355","-0.19347"
"24.95900","-153.87355","-0.17835"
"24.99400","-153.87355","-0.17699"
"25.04200","-153.87355","-0.18134"
"25.09200","-153.87355","-0.15508"
"25.13000","-153.87355","-0.14045"
"25.16700","-153.87355","-0.14837"
"25.20200","-153.87355","-0.15498"
"25.23000","-153.87355","-0.12780"
"25.29300","-153.87355","-0.11354"
"25.33700","-153.87355","-0.10158"
"25.37800","-153.87355","-0.10800"
"25.43400","-153.87355","-0.09701"
"25.47400","-153.87355","-0.09609"
"25.52900","-153.87355","-0.07462"
"25.57300","-153.87355","-0.09144"
"25.60900","-153.87355","-0.06373"
"25.65000","-153.87355","-0.07485"
"25.67800","-153.87355","-0.07114"
"25.72200","-153.87355","-0.06571"
"25.77700","-153.87355","-0.06244"
"25.82000","-153.87355","-0.08237"
"25.86900","-153.87355","-0.06813"
"25.90900","-153.87355","-0.06002"
"25.94700","-153.87355","-0.06190"
"26.00300","-153.87355","-0.05355"
"26.03700","-153.87355","-0.05944"
"26.08200","-153.87355","-0.05341"
"26.11100","-153.87355","-0.06054"
"26.16200","-153.87355","-0.07179"
"26.19300","-153.87355","-0.05580"
"26.23400","-153.87355","-0.05223"
"26.27500","-153.87355","-0.04305"
"26.32100","-153.87355","-0.04953"
"26.37100","-153.87355","-0.05190"
"26.41700","-153.87355","-0.04780"
"26.47200","-153.87355","-0.05982"
"26.52200","-153.87355","-0.05367"
"26.56400","-153.87355","-0.06177"
"26.61300","-153.87355","-0.06646"
"26.65900","-153.87355","-0.04312"
"26.69600","-153.87355","-0.04136"
"26.73500","-153.87355","-0.06111"
"26.78000","-153.87355","-0.05636"
"26.82400","-153.87355","-0.05491"
"26.86400","-153.87355","-0.05600"
"26.90600","-153.87355","-0.05842"
"26.96800","-153.87355","-0.05196"
"27.03100","-153.87355","-0.04246"
"27.06400","-153.87355","-0.06754"
"27.12000","-153.87355","-0.05323"
"27.16500","-153.87355","-0.05525"
"27.22300","-153.87355","-0.04671"
"27.28300","-153.87355","-0.04921"
"27.33000","-153.87355","-0.05719"
"27.36400","-153.87355","-0.04699"
"27.41600","-153.87355","-0.04078"
"27.46400","-153.87355","-0.05618"
"27.48800","-153.87355","-0.06522"
"27.53200","-153.87355","-0.05534"
"27.56500","-153.87355","-0.05725"
"27.61400","-153.87355","-0.02330"
"27.64800","-153.87355","-0.04773"
"27.70100","-153.87355","-0.03619"
"27.75000","-153.87355","-0.04531"
"27.78000","-153.87355","-0.02990"
"27.81500","-153.87355","-0.03021"
"27.87200","-153.87355","-0.03666"
"27.91100","-153.87355","-0.03356"
"27.96400","-153.87355","-0.04342"
"28.02000","-153.87355","-0.03718"
"28.06400","-153.87355","-0.03325"
"28.11400","-153.87355","-0.04998"
"28.13800","-153.87355","-0.02333"
"28.16400","-153.87355","-0.02856"
"28.20900","-153.87355","-0.04536"
"28.24600","-153.87355","-0.03766"
"28.28400","-153.87355","-0.03740"
"28.32500","-153.87355","-0.04104"
"28.38100","-153.87355","-0.03975"
"28.43700","-153.87355","-0.02912"
"28.49100","-153.87355","-0.04609"
"28.53600","-153.87355","-0.02450"
"28.58000","-153.87355","-0.02782"
"28.62400","-153.87355","-0.04602"
"28.65900","-153.87355","-0.04200"
"28.70100","-153.87355","-0.03683"
"28.74800","-153.87355","-0.02728"
"28.79200","-153.87355","-0.03339"
"28.83400","-153.87355","-0.03087"
"28.88300","-153.87355","-0.04470"
"28.93300","-153.87355","-0.03886"
"28.98800","-153.87355","-0.02956"
"29.05200","-153.87355","-0.03307"
"29.09000","-153.87355","-0.04369"
"29.13100","-153.87355","-0.02628"
"29.17800","-153.87355","-0.03621"
"29.22100","-153.87355","-0.01895"
"29.26100","-153.87355","-0.01925"
"29.31200","-153.87355","-0.00889"
"29.36400","-153.87355","-0.02040"
"29.40200","-153.87355","-0.02549"
"29.44900","-153.87355","-0.03510"
"29.48400","-153.87355","-0.01233"
"29.51900","-153.87355","-0.01659"
"29.56200","-153.87355","-0.04114"
"29.59400","-153.87355","-0.04095"
"29.62500","-153.87355","-0.02065"
"29.67000","-153.87355","-0.01968"
"29.70700","-153.87355","-0.02831"
"29.74100","-153.87355","-0.01871"
"29.77800","-153.87355","0.00376"
"29.81400","-153.87355","-0.02529"
"29.85800","-153.87355","-0.03487"
"29.91000","-153.87355","-0.02835"
"29.95400","-153.87355","-0.02712"
"30.00700","-153.87355","-0.01234"
"30.03300","-153.87355","-0.01429"
"30.08600","-153.87355","-0.02052"
"30.14700","-153.87355","-0.01558"
"30.19500","-153.87355","-0.02473"
"30.23500","-153.87355","-0.03732"
"30.27700","-153.87355","-0.03065"
"30.32100","-153.87355","-0.02783"
"30.37900","-153.87355","-0.01796"
"30.43000","-153.87355","-0.02121"
"30.46600","-153.87355","-0.03283"
"30.50200","-153.87355","-0.02239"
"30.52600","-153.87355","-0.02862"
"30.56600","-153.87355","-0.02669"
"30.60600","-153.87355","-0.01251"
"30.65100","-153.87355","-0.01939"
"30.71200","-153.87355","-0.02659"
"30.74400","-153.87355","-0.00354"
"30.78400","-153.87355","-0.02207"
"30.82900","-153.87355","-0.02491"
"30.86600","-153.87355","-0.02109"
"30.91200","-153.87355","-0.01224"
"30.94300","-153.87355","-0.03810"
"30.98600","-153.87355","-0.01562"
"31.04600","-153.87355","-0.01543"
"31.09100","-153.87355","-0.02088"
"31.12000","-153.87355","-0.02513"
"31.16200","-153.87355","-0.02187"
"31.21200","-153.87355","-0.01339"
"31.27100","-153.87355","-0.00052"
"31.32300","-153.87355","-0.00012"
"31.37500","-153.87355","-0.02535"
"31.42100","-153.87355","-0.01917"
"31.47000","-153.87355","-0.01685"
"31.50600","-153.87355","-0.04375"
"31.54200","-153.87355","-0.06388"
"31.58100","-153.87355","-0.15578"
"31.61100","-153.87355","-0.26525"
"31.64000","-153.87355","-0.40485"
"31.67900","-153.87355","-0.34158"
"31.72600","-153.87355","-0.32007"
"31.77200","-153.87355","-0.30694"
"31.81000","-153.87355","-0.28511"
"31.86500","-153.87355","-0.29837"
"31.90600","-153.87355","-0.29062"
"31.95400","-153.87355","-0.26440"
"31.99600","-153.87355","-0.26858"
"32.04100","-153.87355","-0.23910"
"32.07300","-153.87355","-0.25386"
"32.11500","-153.87355","-0.19458"
"32.16200","-153.87355","-0.18174"
"32.20200","-153.87355","-0.16554"
"32.25000","-153.87355","-0.14414"
"32.30300","-153.87355","-0.13871"
"32.35600","-153.87355","-0.13433"
"32.39700","-153.87355","-0.13065"
"32.43400","-153.87355","-0.11875"
"32.47500","-153.87355","-0.10837"
"32.52200","-153.87355","-0.10361"
"32.55400","-153.87355","-0.08684"
"32.58900","-153.87355","-0.09443"
"32.61400","-153.87355","-0.10343"
"32.65400","-153.87355","-0.09363"
"32.70600","-153.87355","-0.09128"
"32.75200","-153.87355","-0.08263"
"32.79400","-153.87355","-0.08385"
"32.83100","-153.87355","-0.07882"
"32.88700","-153.87355","-0.06277"
"32.92900","-153.87355","-0.04616"
"32.96700","-153.87355","-0.05286"
"33.01100","-153.87355","-0.06444"
"33.04900","-153.87355","-0.06210"
"33.10100","-153.87355","-0.06722"
"33.14100","-153.87355","-0.04266"
"33.19100","-153.87355","-0.06318"
"33.22900","-153.87355","-0.05296"
"33.28300","-153.87355","-0.06286"
"33.32100","-153.87355","-0.04785"
"33.35900","-153.87355","-0.06325"
"33.39300","-153.87355","-0.03857"
"33.43900","-153.87355","-0.05445"
"33.46700","-153.87355","-0.06206"
"33.50800","-153.87355","-0.04079"
"33.54200","-153.87355","-0.04331"
"33.58700","-153.87355","-0.02706"
"33.62300","-153.87355","-0.04375"
"33.65700","-153.87355","-0.05064"
"33.70500","-153.87355","-0.04812"
"33.73900","-153.87355","-0.02947"
"33.78100","-153.87355","-0.04023"
"33.82900","-153.87355","-0.05463"
"33.86300","-153.87355","-0.04780"
"33.91200","-153.87355","-0.04104"
"33.95000","-153.87355","-0.04546"
"34.00700","-153.87355","-0.02997"
"34.05700","-153.87355","-0.03369"
"34.08800","-153.87355","-0.03756"
"34.13400","-153.87355","-0.05485"
"34.18100","-153.87355","-0.04815"
"34.22900","-153.87355","-0.02779"
"34.25700","-153.87355","-0.03714"
"34.28500","-153.87355","-0.04474"
"34.32300","-153.87355","-0.05108"
"34.36800","-153.87355","-0.03416"
"34.42400","-153.87355","-0.02590"
"34.46500","-153.87355","-0.04615"
"34.52100","-153.87355","-0.03006"
"34.56900","-153.87355","-0.03732"
"34.60900","-153.87355","-0.05949"
"34.64600","-153.87355","-0.04581"
"34.69600","-153.87355","-0.04800"
"34.75500","-153.87355","-0.04844"
"34.81500","-153.87355","-0.04586"
"34.85300","-153.87355","-0.04041"
"34.90200","-153.87355","-0.04667"
"34.95000","-153.87355","-0.03345"
"34.98500","-153.87355","-0.02953"
"35.02900","-153.87355","-0.03364"
"35.07000","-153.87355","-0.05065"
"35.10600","-153.87355","-0.02337"
"35.12800","-153.87355","-0.03268"
"35.15900","-153.87355","-0.03436"
"35.19100","-153.87355","-0.01498"
"35.24600","-153.87355","-0.02778"
"35.28200","-153.87355","-0.03415"
"35.32400","-153.87355","-0.03188"
"35.37300","-153.87355","-0.03904"
"35.41300","-153.87355","-0.03565"
"35.46200","-153.87355","-0.04238"
"35.50300","-153.87355","-0.03225"
"35.54200","-153.87355","-0.02928"
"35.59900","-153.87355","-0.03454"
"35.63100","-153.87355","-0.03661"
"35.67300","-153.87355","-0.03048"
"35.70000","-153.87355","-0.03334"
"35.73000","-153.87355","-0.03155"
"35.77000","-153.87355","-0.02857"
"35.80400","-153.87355","-0.04096"
"35.84400","-153.87355","-0.04824"
"35.90000","-153.87355","-0.03731"
"35.93300","-153.87355","-0.04379"
"35.97800","-153.87355","-0.02442"
"36.02000","-153.87355","-0.02713"
"36.05100","-153.87355","-0.03871"
"36.10800","-153.87355","-0.04092"
"36.14900","-153.87355","-0.03902"
"36.18500","-153.87355","-0.01468"
"36.24600","-153.87355","-0.04656"
"36.29200","-153.87355","-0.04574"
"36.34300","-153.87355","-0.03895"
"36.37800","-153.87355","-0.03269"
"36.43000","-153.87355","-0.03225"
"36.48600","-153.87355","-0.03993"
"36.53700","-153.87355","-0.04170"
"36.58200","-153.87355","-0.02546"
"36.62700","-153.87355","-0.04960"
"36.66500","-153.87355","-0.03420"
"36.70400","-153.87355","-0.04259"
"36.74500","-153.87355","-0.03029"
"36.80100","-153.87355","-0.03050"
"36.84900","-153.87355","-0.03767"
"36.88100","-153.87355","-0.03479"
"36.93600","-153.87355","-0.04367"
"36.98300","-153.87355","-0.03258"
"37.01900","-153.87355","-0.03098"
"37.06700","-153.87355","-0.03932"
"37.11600","-153.87355","-0.04051"
"37.16100","-153.87355","-0.01905"
"37.18700","-153.87355","-0.03769"
"37.24100","-153.87355","-0.02943"
"37.27600","-153.87355","-0.03713"
"37.32900","-153.87355","-0.04394"
"37.37900","-153.87355","-0.04179"
"37.42400","-153.87355","-0.03546"
"37.46300","-153.87355","-0.04506"
"37.50200","-153.87355","-0.04231"
"37.54700","-153.87355","-0.06173"
"37.57900","-153.87355","-0.19110"
"37.60300","-153.87355","-0.26270"
"37.64500","-153.87355","-0.36366"
"37.68400","-153.87355","-0.41735"
"37.71700","-153.87355","-0.44641"
"37.74500","-153.87355","-0.43710"
"37.78000","-153.87355","-0.41309"
"37.83700","-153.87355","-0.40897"
"37.87900","-153.87355","-0.38950"
"37.92500","-153.87355","-0.38579"
"37.95300","-153.87355","-0.38363"
"38.00500","-153.87355","-0.38021"
"38.06700","-153.87355","-0.36908"
"38.11500","-153.87355","-0.34939"
"38.15000","-153.87355","-0.33944"
"38.18800","-153.87355","-0.33387"
"38.22300","-153.87355","-0.34382"
"38.25700","-153.87355","-0.31371"
"38.28700","-153.87355","-0.27167"
"38.34000","-153.87355","-0.24339"
"38.38200","-153.87355","-0.21860"
"38.42700","-153.87355","-0.24106"
"38.45900","-153.87355","-0.20302"
"38.50100","-153.87355","-0.19040"
"38.54400","-153.87355","-0.18098"
"38.58800","-153.87355","-0.17679"
"38.61800","-153.87355","-0.18434"
"38.64500","-153.87355","-0.18656"
"38.70000","-153.87355","-0.15645"
"38.74600","-153.87355","-0.15560"
"38.78500","-153.87355","-0.15263"
"38.82600","-153.87355","-0.16405"
"38.86500","-153.87355","-0.13633"
"38.89600","-153.87355","-0.15398"
"38.94200","-153.87355","-0.14399"
"39.00100","-153.87355","-0.14048"
"39.06100","-153.87355","-0.11387"
"39.09400","-153.87355","-0.11551"
"39.14800","-153.87355","-0.12452"
"39.18800","-153.87355","-0.12281"
"39.22600","-153.87355","-0.10638"
"39.26600","-153.87355","-0.11160"
"39.31300","-153.87355","-0.08730"
"39.36500","-153.87355","-0.08497"
"39.39700","-153.87355","-0.09390"
"39.46000","-153.87355","-0.06631"
"39.50200","-153.87355","-0.08306"
"39.53700","-153.87355","-0.08998"
"39.57000","-153.87355","-0.07111"
"39.62500","-153.87355","-0.07937"
"39.67300","-153.87355","-0.06586"
"39.71600","-153.87355","-0.09045"
"39.76500","-153.87355","-0.07051"
"39.81200","-153.87355","-0.07683"
"39.86900","-153.87355","-0.08088"
"39.92000","-153.87355","-0.06294"
"39.96800","-153.87355","-0.05963"
"40.00500","-153.87355","-0.06071"
"40.06400","-153.87355","-0.07210"
"40.11600","-153.87355","-0.07537"
"40.15200","-153.87355","-0.04845"
"40.18900","-153.87355","-0.04784"
"40.22600","-153.87355","-0.05928"
"40.26900","-153.87355","-0.05852"
"40.32400","-153.87355","-0.05335"
"40.37500","-153.87355","-0.05938"
"40.42100","-153.87355","-0.05132"
"40.46700","-153.87355","-0.04291"
"40.51400","-153.87355","-0.06418"
"40.56600","-153.87355","-0.05380"
"40.61300","-153.87355","-0.03524"
"40.64200","-153.87355","-0.04242"
"40.66800","-153.87355","-0.05043"
"40.70600","-153.87355","-0.06154"
"40.75400","-153.87355","-0.04505"
"40.80700","-153.87355","-0.06298"
"40.85500","-153.87355","-0.03508"
"40.91000","-153.87355","-0.04546"
"40.95700","-153.87355","-0.04496"
"41.01100","-153.87355","-0.04941"
"41.06000","-153.87355","-0.04109"
"41.09800","-153.87355","-0.04663"
"41.14800","-153.87355","-0.04460"
"41.19300","-153.87355","-0.03221"
"41.23700","-153.87355","-0.02826"
"41.28100","-153.87355","-0.02589"
"41.31700","-153.87355","-0.03501"
"41.35700","-153.87355","-0.04554"
"41.40100","-153.87355","-0.04724"
"41.45000","-153.87355","-0.02500"
"41.49600","-153.87355","-0.03612"
"41.54400","-153.87355","-0.03886"
"41.58000","-153.87355","-0.04510"
"41.62400","-153.87355","-0.04949"
"41.65300","-153.87355","-0.03711"
"41.68800","-153.87355","-0.02845"
"41.71500","-153.87355","-0.04177"
"41.75800","-153.87355","-0.02288"
"41.79800","-153.87355","-0.01262"
"41.82700","-153.87355","-0.03824"
"41.86800","-153.87355","-0.04359"
"41.89700","-153.87355","-0.02155"
"41.94400","-153.87355","-0.04432"
"41.98400","-153.87355","-0.04131"
"42.04100","-153.87355","-0.03004"
"42.09000","-153.87355","-0.02661"
"42.14800","-153.87355","-0.04827"
"42.18600","-153.87355","-0.04437"
"42.24700","-153.87355","-0.02852"
"42.30100","-153.87355","-0.03474"
"42.35700","-153.87355","-0.03212"
"42.40000","-153.87355","-0.03000"
"42.44400","-153.87355","-0.04319"
"42.50000","-153.87355","-0.04048"
"42.54800","-153.87355","-0.03415"
"42.58900","-153.87355","-0.05037"
"42.63100","-153.87355","-0.02202"
"42.66700","-153.87355","-0.02722"
"42.69900","-153.87355","-0.02814"
"42.73400","-153.87355","-0.03249"
"42.77800","-153.87355","-0.02165"
"42.84000","-153.87355","-0.03510"
"42.87700","-153.87355","-0.01183"
"42.93100","-153.87355","-0.00999"
"42.99300","-153.87355","-0.02318"
"43.04300","-153.87355","-0.01409"
"43.09900","-153.87355","-0.01146"
"43.15700","-153.87355","-0.03282"
"43.21700","-153.87355","-0.02917"
"43.26700","-153.87355","-0.03815"
"43.30400","-153.87355","-0.01405"
"43.33500","-153.87355","-0.04051"
"43.37000","-153.87355","-0.02487"
"43.41200","-153.87355","-0.01639"
"43.47500","-153.87355","-0.03392"
"43.52500","-153.87355","-0.04039"
"43.55700","-153.87355","-0.01688"
"43.59700","-153.87355","-0.01153"
"43.62900","-153.87355","-0.03479"
"43.69300","-153.87355","-0.03878"
"43.75800","-153.87355","-0.02024"
"43.79200","-153.87355","-0.01428"
"43.82100","-153.87355","-0.02629"
"43.85200","-153.87355","-0.02368"
"43.88800","-153.87355","-0.04127"
"43.93200","-153.87355","-0.01577"
"43.98700","-153.87355","-0.01598"
"44.02400","-153.87355","-0.02716"
"44.06800","-153.87355","-0.02472"
"44.10500","-153.87355","-0.03251"
"44.15700","-153.87355","-0.04444"
"44.20700","-153.87355","-0.03236"
"44.23900","-153.87355","-0.03079"
"44.27900","-153.87355","-0.01275"
"44.33200","-153.87355","-0.00864"
"44.38000","-153.87355","-0.01209"
"44.43900","-153.87355","-0.03046"
"44.48100","-153.87355","-0.02718"
"44.51900","-153.87355","-0.03079"
"44.54900","-153.87355","-0.03381"
"44.58400","-153.87355","-0.02282"
"44.61800","-153.87355","-0.01438"
"44.65700","-153.87355","-0.04193"
"44.70900","-153.87355","-0.03218"
"44.74400","-153.87355","-0.01456"
"44.79200","-153.87355","-0.02061"
"44.84800","-153.87355","-0.02503"
"44.90000","-153.87355","-0.01290"
"44.93400","-153.87355","-0.00878"
"44.97600","-153.87355","-0.02032"
"45.01500","-153.87355","-0.01065"
"45.03900","-153.87355","-0.01439"
"45.08500","-153.87355","-0.03196"
"45.12200","-153.87355","-0.03595"
"45.16000","-153.87355","-0.02632"
"45.20500","-153.87355","-0.02757"
"45.22500","-153.87355","-0.03330"
"45.27400","-153.87355","-0.02582"
"45.32400","-153.87355","-0.01244"
"45.35800","-153.87355","-0.01289"
"45.40700","-153.87355","-0.02305"
"45.45600","-153.87355","-0.02437"
"45.50000","-153.87355","-0.01649"
"45.54400","-153.87355","-0.01718"
"45.58100","-153.87355","-0.02409"
"45.62900","-153.87355","-0.02139"
"45.68000","-153.87355","-0.01466"
"45.72900","-153.87355","-0.02779"
"45.76200","-153.87355","-0.01139"
"45.80900","-153.87355","-0.01126"
"45.83100","-153.87355","-0.02890"
"45.88700","-153.87355","-0.01799"
"45.92800","-153.87355","-0.01479"
"45.96700","-153.87355","-0.03690"
"46.00800","-153.87355","-0.02050"
"46.04600","-153.87355","-0.03476"
"46.08500","-153.87355","-0.01893"
"46.13700","-153.87355","-0.00197"
"46.18200","-153.87355","-0.02319"
"46.23100","-153.87355","-0.02558"
"46.27100","-153.87355","-0.03177"
"46.32200","-153.87355","-0.03103"
"46.37100","-153.87355","-0.03960"
"46.42200","-153.87355","-0.03708"
"46.47900","-153.87355","-0.03294"
"46.51500","-153.87355","-0.02173"
"46.55100","-153.87355","-0.02572"
"46.60600","-153.87355","-0.03113"
"46.65200","-153.87355","-0.00441"
"46.69500","-153.87355","-0.02833"
"46.73600","-153.87355","-0.03796"
"46.77900","-153.87355","-0.01215"
"46.81400","-153.87355","-0.01428"
"46.85800","-153.87355","-0.01395"
"46.89400","-153.87355","-0.01002"
"46.93900","-153.87355","-0.03443"
"46.97600","-153.87355","-0.02527"
"47.02700","-153.87355","-0.02694"
"47.06400","-153.87355","-0.01228"
"47.09100","-153.87355","-0.03383"
"47.13800","-153.87355","-0.03189"
"47.18700","-153.87355","-0.03222"
"47.23200","-153.87355","-0.02557"
"47.28300","-153.87355","-0.02843"
"47.33700","-153.87355","-0.02504"
"47.38700","-153.87355","-0.03045"
"47.45200","-153.87355","-0.03871"
"47.49200","-153.87355","-0.03609"
"47.53000","-153.87355","-0.01499"
"47.57400","-153.87355","-0.01782"
"47.62500","-153.87355","-0.01159"
"47.66800","-153.87355","-0.02723"
"47.72300","-153.87355","-0.03192"
"47.74700","-153.87355","-0.02415"
"47.79700","-153.87355","-0.02474"
"47.84600","-153.87355","-0.03260"
"47.88800","-153.87355","-0.01857"
"47.93700","-153.87355","-0.01411"
"47.98500","-153.87355","-0.00697"
"48.02700","-153.87355","-0.01940"
"48.07900","-153.87355","-0.03081"
"48.11700","-153.87355","-0.02541"
"48.16000","-153.87355","-0.03396"
"48.21800","-153.87355","-0.01983"
"48.25800","-153.87355","-0.00811"
"48.30200","-153.87355","-0.03161"
"48.34600","-153.87355","-0.02441"
"48.38900","-153.87355","-0.02948"
"48.44800","-153.87355","-0.02071"
"48.49100","-153.87355","-0.02310"
"48.52700","-153.87355","-0.02512"
"48.56600","-153.87355","-0.04022"
"48.60600","-153.87355","-0.04845"
"48.63700","-153.87355","-0.13957"
"48.66500","-153.87355","-0.22332"
"48.69200","-153.87355","-0.31594"
"48.71200","-153.87355","-0.37227"
"48.75100","-153.87355","-0.43633"
"48.79900","-153.87355","-0.47473"
"48.84200","-153.87355","-0.53560"
"48.88100","-153.87355","-0.55438"
"48.93200","-153.87355","-0.53507"
"48.99300","-153.87355","-0.52361"
"49.03200","-153.87355","-0.50593"
"49.07000","-153.87355","-0.49170"
"49.12400","-153.87355","-0.49588"
"49.16700","-153.87355","-0.46763"
"49.19700","-153.87355","-0.45455"
"49.23300","-153.87355","-0.45662"
"49.26800","-153.87355","-0.43605"
"49.30200","-153.87355","-0.42377"
"49.34500","-153.87355","-0.43033"
"49.40000","-153.87355","-0.40792"
"49.44300","-153.87355","-0.37621"
"49.46900","-153.87355","-0.37684"
"49.52700","-153.87355","-0.38000"
"49.56800","-153.87355","-0.37185"
"49.61400","-153.87355","-0.37159"
"49.65300","-153.87355","-0.35361"
"49.69100","-153.87355","-0.35956"
"49.73200","-153.87355","-0.34950"
"49.77500","-153.87355","-0.33612"
"49.82300","-153.87355","-0.33459"
"49.86600","-153.87355","-0.31262"
"49.91100","-153.87355","-0.31943"
"49.95400","-153.87355","-0.30683"
"49.98700","-153.87355","-0.31034"
"50.03600","-153.87355","-0.30171"
"50.07800","-153.87355","-0.29295"
"50.13200","-153.87355","-0.29712"
"50.18000","-153.87355","-0.28861"
"50.23700","-153.87355","-0.27784"
"50.27800","-153.87355","-0.27641"
"50.32600","-153.87355","-0.27238"
"50.37000","-153.87355","-0.26808"
"50.40800","-153.87355","-0.25672"
"50.43100","-153.87355","-0.25191"
"50.46600","-153.87355","-0.26598"
"50.49700","-153.87355","-0.24459"
"50.52100","-153.87355","-0.24728"
"50.54900","-153.87355","-0.24304"
"50.58600","-153.87355","-0.24143"
"50.63200","-153.87355","-0.25869"
"50.67800","-153.87355","-0.22283"
"50.72600","-153.87355","-0.22664"
"50.77300","-153.87355","-0.21828"
"50.81800","-153.87355","-0.22099"
"50.85700","-153.87355","-0.13275"
"50.91400","-153.87355","-0.14537"
"50.95200","-153.87355","-0.14589"
"50.99200","-153.87355","-0.13191"
"51.04400","-153.87355","-0.13967"
"51.09300","-153.87355","-0.13555"
"51.15100","-153.87355","-0.13021"
"51.20100","-153.87355","-0.12882"
"51.24500","-153.87355","-0.12316"
"51.29700","-153.87355","-0.10704"
"51.31600","-153.87355","-0.11693"
"51.36400","-153.87355","-0.09594"
"51.39700","-153.87355","-0.09428"
"51.42900","-153.87355","-0.10208"
"51.45600","-153.87355","-0.09723"
"51.49000","-153.87355","-0.08999"
"51.53500","-153.87355","-0.11241"
"51.57700","-153.87355","-0.09751"
"51.63500","-153.87355","-0.10434"
"51.66000","-153.87355","-0.08626"
"51.69700","-153.87355","-0.07192"
"51.75100","-153.87355","-0.07155"
"51.79100","-153.87355","-0.07234"
"51.84000","-153.87355","-0.07083"
"51.89000","-153.87355","-0.06833"
"51.93200","-153.87355","-0.07246"
"51.97100","-153.87355","-0.07557"
"52.00000","-153.87355","-0.06077"
"52.03400","-153.87355","-0.06901"
"52.07700","-153.87355","-0.05285"
"52.11100","-153.87355","-0.05260"
"52.16700","-153.87355","-0.06318"
"52.21500","-153.87355","-0.06476"
"52.24900","-153.87355","-0.06207"
"52.27900","-153.87355","-0.06072"
"52.31700","-153.87355","-0.05838"
"52.35700","-153.87355","-0.07564"
"52.39500","-153.87355","-0.05412"
"52.42200","-153.87355","-0.07066"
"52.45200","-153.87355","-0.05170"
"52.49600","-153.87355","-0.04066"
"52.53300","-153.87355","-0.04193"
"52.58400","-153.87355","-0.04472"
"52.62600","-153.87355","-0.04961"
"52.68300","-153.87355","-0.03211"
"52.72000","-153.87355","-0.04944"
"52.74800","-153.87355","-0.04504"
"52.78600","-153.87355","-0.04846"
"52.81800","-153.87355","-0.05873"
"52.86000","-153.87355","-0.06302"
"52.91500","-153.87355","-0.07210"
"52.95300","-153.87355","-0.05646"
"52.98000","-153.87355","-0.03323"
"53.03000","-153.87355","-0.04823"
"53.09000","-153.87355","-0.04295"
"53.13300","-153.87355","-0.04854"
"53.16800","-153.87355","-0.05342"
"53.20500","-153.87355","-0.04409"
"53.25000","-153.87355","-0.04476"
"53.29500","-153.87355","-0.05290"
"53.33000","-153.87355","-0.04631"
"53.36400","-153.87355","-0.05250"
"53.40500","-153.87355","-0.03158"
"53.43600","-153.87355","-0.06015"
"53.48100","-153.87355","-0.05237"
"53.51700","-153.87355","-0.04051"
"53.54500","-153.87355","-0.04851"
"53.59400","-153.87355","-0.04765"
"53.65100","-153.87355","-0.03354"
"53.70500","-153.87355","-0.05228"
"53.75100","-153.87355","-0.04447"
"53.79700","-153.87355","-0.05748"
"53.82900","-153.87355","-0.05365"
"53.87300","-153.87355","-0.04398"
"53.92100","-153.87355","-0.02401"
"53.95900","-153.87355","-0.03211"
"54.00700","-153.87355","-0.03751"
"54.04700","-153.87355","-0.04242"
"54.09000","-153.87355","-0.03051"
"54.13900","-153.87355","-0.03866"
"54.17300","-153.87355","-0.03737"
"54.22400","-153.87355","-0.06110"
"54.27700","-153.87355","-0.03763"
"54.32200","-153.87355","-0.03347"
"54.36800","-153.87355","-0.04475"
"54.41900","-153.87355","-0.04561"
"54.45500","-153.87355","-0.04617"
"54.50800","-153.87355","-0.02649"
"54.54900","-153.87355","-0.03569"
"54.59500","-153.87355","-0.03950"
"54.64200","-153.87355","-0.01557"
"54.67700","-153.87355","-0.04378"
"54.71700","-153.87355","-0.03388"
"54.75500","-153.87355","-0.03647"
"54.81000","-153.87355","-0.03467"
"54.85400","-153.87355","-0.04322"
"54.90000","-153.87355","-0.03350"
"54.95700","-153.87355","-0.04612"
"54.98800","-153.87355","-0.03200"
"55.04300","-153.87355","-0.02482"
"55.07800","-153.87355","-0.03795"
"55.11200","-153.87355","-0.04769"
"55.16500","-153.87355","-0.03543"
"55.20900","-153.87355","-0.02932"
"55.25800","-153.87355","-0.02869"
"55.29600","-153.87355","-0.04466"
"55.34100","-153.87355","-0.04677"
"55.39200","-153.87355","-0.04027"
"55.44600","-153.87355","-0.04701"
"55.49400","-153.87355","-0.04276"
"55.54400","-153.87355","-0.02901"
"55.58100","-153.87355","-0.02941"
"55.62800","-153.87355","-0.03476"
"55.67000","-153.87355","-0.02476"
"55.72500","-153.87355","-0.01735"
"55.75100","-153.87355","-0.03064"