File: chapter 4/force/mini_patrick.is_tens_RawData/Specimen_RawData_8.csv
Time,Extension,Load
(s),(mm),(N)
"0.00000","-152.02065","0.01617"
"0.03100","-152.02052","0.00585"
"0.06600","-152.02052","0.02310"
"0.09400","-152.02052","-0.00981"
"0.14300","-152.02052","0.00950"
"0.17900","-152.02054","0.01640"
"0.21500","-152.02054","0.00222"
"0.23800","-152.02054","0.00060"
"0.28100","-152.02054","0.00350"
"0.31900","-152.02058","-0.01168"
"0.35100","-152.02058","0.00092"
"0.38700","-152.02058","0.01421"
"0.41200","-152.02058","-0.00511"
"0.46200","-152.02058","0.00635"
"0.48400","-152.02058","0.00320"
"0.51800","-152.02061","-0.00918"
"0.55900","-152.02061","0.01084"
"0.60000","-152.02061","0.01702"
"0.63200","-152.02061","-0.00762"
"0.66300","-152.02061","-0.02027"
"0.69500","-152.02061","0.02530"
"0.72100","-152.02061","0.01663"
"0.76400","-152.02061","-0.01182"
"0.79400","-152.02061","0.00787"
"0.81500","-152.02061","-0.01367"
"0.84500","-152.02061","0.00415"
"0.88700","-152.02065","0.00354"
"0.90600","-152.02065","0.00198"
"0.93200","-152.02065","0.00301"
"0.95600","-152.02065","0.01299"
"0.98200","-152.02065","0.01137"
"1.01300","-152.02065","-0.01080"
"1.03800","-152.02065","-0.00501"
"1.08000","-152.02065","-0.00461"
"1.09900","-152.02065","0.02115"
"1.13600","-152.02065","0.00671"
"1.16600","-152.02065","-0.00034"
"1.20300","-152.02065","0.01152"
"1.24900","-152.02065","-0.00290"
"1.28800","-152.02065","-0.00537"
"1.32000","-152.02065","-0.00738"
"1.35200","-152.02065","0.00950"
"1.38100","-152.02065","-0.01204"
"1.40800","-152.02065","0.00803"
"1.44600","-152.02065","-0.00569"
"1.47500","-152.02065","-0.02060"
"1.50800","-152.02065","0.01826"
"1.52100","-152.02065","0.02180"
"1.55500","-152.02065","-0.00332"
"1.59100","-152.02065","0.00370"
"1.61900","-152.02065","0.01344"
"1.65400","-152.02065","-0.00029"
"1.67900","-152.02065","0.00184"
"1.72200","-152.02065","-0.00387"
"1.75300","-152.02065","0.00373"
"1.77500","-152.02065","0.00236"
"1.79500","-152.02065","0.00308"
"1.82200","-152.02065","0.01255"
"1.85300","-152.02065","-0.00937"
"1.88300","-152.02065","0.01985"
"1.92800","-152.02065","0.00478"
"1.96900","-152.02065","-0.00860"
"2.01100","-152.02065","-0.00483"
"2.04200","-152.02065","0.00384"
"2.07500","-152.02065","0.00753"
"2.09800","-152.02065","0.01993"
"2.12800","-152.02065","-0.00263"
"2.17000","-152.02065","-0.00362"
"2.19800","-152.02065","0.01381"
"2.25200","-152.02065","-0.00647"
"2.28700","-152.02065","-0.00284"
"2.31200","-152.02065","0.00007"
"2.34300","-152.02065","-0.00291"
"2.37100","-152.02065","-0.00844"
"2.40200","-152.02065","0.01729"
"2.44100","-152.02065","0.01039"
"2.46700","-152.02065","0.01796"
"2.49200","-152.02065","-0.01069"
"2.51900","-152.02065","0.01656"
"2.54500","-152.02065","0.00387"
"2.57900","-152.02065","0.00211"
"2.61700","-152.02065","-0.00291"
"2.66000","-152.02065","-0.00192"
"2.69000","-152.02065","-0.00521"
"2.72500","-152.02065","0.00654"
"2.76500","-152.02065","0.00644"
"2.80400","-152.02065","0.00731"
"2.84000","-152.02065","-0.01400"
"2.86800","-152.02065","0.00489"
"2.90100","-152.02065","0.01181"
"2.92800","-152.02065","-0.00154"
"2.96300","-152.02065","0.00549"
"3.00400","-152.02065","0.00130"
"3.05600","-152.02065","0.00724"
"3.07600","-152.02065","-0.00207"
"3.10700","-152.02065","0.00099"
"3.13400","-152.02065","0.02084"
"3.16500","-152.02065","-0.00054"
"3.19200","-152.02065","0.00096"
"3.22500","-152.02065","0.00168"
"3.25400","-152.02065","0.02040"
"3.28700","-152.02065","0.00553"
"3.31000","-152.02065","-0.00502"
"3.34900","-152.02065","0.00010"
"3.37300","-152.02065","0.01604"
"3.39400","-152.02065","0.01063"
"3.42200","-152.02065","0.01152"
"3.45600","-152.02065","-0.01948"
"3.48300","-152.02065","0.01957"
"3.52500","-152.02065","-0.00955"
"3.55100","-152.02065","0.01542"
"3.59400","-152.02065","0.01629"
"3.63100","-152.02065","0.00530"
"3.66700","-152.02065","-0.01555"
"3.69500","-152.02065","0.01768"
"3.74300","-152.02065","-0.00450"
"3.78100","-152.02065","-0.01366"
"3.81800","-152.02065","-0.00056"
"3.85100","-152.02065","0.00461"
"3.88300","-152.02065","-0.00584"
"3.91200","-152.02065","0.00138"
"3.93600","-152.02065","0.00543"
"3.95900","-152.02065","0.01830"
"3.99100","-152.02065","-0.00914"
"4.02600","-152.02065","0.01611"
"4.05900","-152.02065","-0.00319"
"4.08300","-152.02065","0.00337"
"4.12200","-152.02065","0.00721"
"4.15400","-152.02065","0.00803"
"4.17400","-152.02065","-0.00228"
"4.20200","-152.02065","0.00392"
"4.23700","-152.02065","0.00547"
"4.25800","-152.02065","0.00275"
"4.27100","-152.02065","0.00904"
"4.30900","-152.02065","0.00721"
"4.34100","-152.02065","0.01657"
"4.37700","-152.02065","0.01222"
"4.41700","-152.02065","-0.01435"
"4.45200","-152.02065","0.00222"
"4.49500","-152.02065","0.01423"
"4.53800","-152.02065","0.01507"
"4.57400","-152.02065","0.01047"
"4.60900","-152.02065","-0.00827"
"4.65000","-152.02065","0.00578"
"4.67100","-152.02065","0.00972"
"4.68700","-152.02065","-0.00231"
"4.71900","-152.02065","-0.00222"
"4.75000","-152.02065","0.00685"
"4.79300","-152.02065","0.00075"
"4.82100","-152.02065","-0.00115"
"4.85500","-152.02065","0.01451"
"4.88200","-152.02065","0.00440"
"4.91500","-152.02065","0.00538"
"4.93600","-152.02065","-0.00313"
"4.97700","-152.02065","-0.00214"
"5.01500","-152.02065","0.00117"
"5.04400","-152.02065","0.00386"
"5.08900","-152.02065","0.00435"
"5.11900","-152.02065","0.00284"
"5.15300","-152.02065","0.01056"
"5.19500","-152.02065","0.00732"
"5.22600","-152.02065","0.00236"
"5.25200","-152.02065","-0.00266"
"5.29100","-152.02065","-0.00407"
"5.32400","-152.02065","-0.00308"
"5.36500","-152.02065","0.01254"
"5.40000","-152.02065","0.01318"
"5.43000","-152.02065","0.00791"
"5.46100","-152.02065","0.01547"
"5.49100","-152.02065","-0.01363"
"5.52900","-152.02065","-0.01146"
"5.56800","-152.02065","-0.00895"
"5.60200","-152.02065","0.01185"
"5.64000","-152.02065","-0.00093"
"5.68000","-152.02065","0.01327"
"5.69900","-152.02065","-0.01388"
"5.74000","-152.02065","0.00574"
"5.78600","-152.02065","0.01088"
"5.81900","-152.02065","-0.00601"
"5.84500","-152.02065","-0.00362"
"5.88200","-152.02065","0.00476"
"5.89600","-152.02065","0.00007"
"5.92200","-152.02065","0.00438"
"5.94900","-152.02065","0.01266"
"5.97000","-152.02065","0.01797"
"5.99100","-152.02065","-0.00139"
"6.03100","-152.02065","0.00214"
"6.06500","-152.02065","-0.00500"
"6.10100","-152.02065","0.00008"
"6.13100","-152.02065","-0.01168"
"6.16300","-152.02065","0.01427"
"6.20200","-152.02065","0.02177"
"6.23500","-152.02065","0.00878"
"6.26600","-152.02065","-0.00385"
"6.29500","-152.02065","0.01502"
"6.32100","-152.02065","0.01018"
"6.34800","-152.02065","0.00584"
"6.37700","-152.02065","0.01293"
"6.41400","-152.02065","0.00476"
"6.45300","-152.02065","0.01879"
"6.48800","-152.02065","0.00419"
"6.51100","-152.02065","0.00465"
"6.54600","-152.02065","0.01753"
"6.57500","-152.02065","-0.00784"
"6.61300","-152.02065","0.01405"
"6.64800","-152.02065","-0.00020"
"6.68800","-152.02065","0.00514"
"6.71700","-152.02065","0.01628"
"6.74700","-152.02065","0.00840"
"6.77800","-152.02065","0.01615"
"6.80300","-152.02065","-0.00171"
"6.83200","-152.02065","0.00552"
"6.87600","-152.02065","0.01367"
"6.91100","-152.02065","0.01323"
"6.94500","-152.02065","-0.01382"
"6.97700","-152.02065","0.00439"
"7.00600","-152.02065","0.00576"
"7.04000","-152.02065","-0.00465"
"7.05700","-152.02065","0.00765"
"7.08900","-152.02065","-0.00520"
"7.13400","-152.02065","0.00149"
"7.17600","-152.02065","0.01159"
"7.20100","-152.02065","0.00579"
"7.24600","-152.02065","0.00178"
"7.28200","-152.02065","0.00758"
"7.29900","-152.02065","0.00075"
"7.31600","-152.02065","0.00465"
"7.35700","-152.02065","-0.00514"
"7.38100","-152.02065","-0.00691"
"7.41400","-152.02065","0.00058"
"7.45800","-152.02065","-0.01738"
"7.49100","-152.02065","0.01198"
"7.50900","-152.02065","-0.01109"
"7.52900","-152.02065","0.02263"
"7.55800","-152.02065","0.00380"
"7.58700","-152.02065","0.00909"
"7.60700","-152.02065","0.01149"
"7.64100","-152.02065","-0.00037"
"7.66300","-152.02065","0.01595"
"7.69600","-152.02065","0.01105"
"7.74300","-152.02065","0.00715"
"7.77600","-152.02065","0.00342"
"7.80700","-152.02065","0.00709"
"7.84700","-152.02065","0.00969"
"7.89300","-152.02065","0.01549"
"7.93300","-152.02065","0.00658"
"7.97600","-152.02065","0.00517"
"8.00800","-152.02065","-0.00327"
"8.03500","-152.02065","-0.00516"
"8.07500","-152.02065","-0.00552"
"8.11200","-152.02065","-0.00023"
"8.14400","-152.02065","0.00809"
"8.17300","-152.02065","0.00081"
"8.19300","-152.02065","-0.00505"
"8.23600","-152.02065","0.00929"
"8.26400","-152.02065","0.02833"
"8.30700","-152.02065","0.00273"
"8.34500","-152.02065","0.00605"
"8.37900","-152.02065","0.00013"
"8.39300","-152.02065","0.00191"
"8.42800","-152.02065","-0.00554"
"8.46800","-152.02065","0.00796"
"8.50900","-152.02065","0.01082"
"8.54200","-152.02065","0.01020"
"8.57400","-152.02065","-0.00936"
"8.60800","-152.02065","0.01048"
"8.63700","-152.02065","0.00351"
"8.67300","-152.02065","0.01110"
"8.70900","-152.02065","0.00807"
"8.73100","-152.02065","0.01151"
"8.76100","-152.02065","0.01097"
"8.79800","-152.02065","0.00571"
"8.82500","-152.02065","0.01807"
"8.86700","-152.02065","-0.00919"
"8.90000","-152.02065","-0.00646"
"8.94500","-152.02065","0.00994"
"8.98300","-152.02065","-0.00312"
"9.00900","-152.02065","-0.00719"
"9.03400","-152.02065","0.00855"
"9.07300","-152.02065","-0.05180"
"9.10500","-152.02065","-0.02627"
"9.13600","-152.02065","-0.02443"
"9.18200","-152.02065","-0.03032"
"9.21300","-152.02065","-0.01250"
"9.24800","-152.02065","-0.02563"
"9.26800","-152.02065","-0.02521"
"9.31000","-152.02065","-0.02116"
"9.33900","-152.02065","-0.00388"
"9.37800","-152.02065","-0.00980"
"9.40500","-152.02065","-0.01265"
"9.44500","-152.02065","-0.00862"
"9.46500","-152.02065","-0.01064"
"9.49600","-152.02065","-0.02030"
"9.51700","-152.02065","-0.01091"
"9.54000","-152.02065","0.00098"
"9.57800","-152.02065","-0.00031"
"9.60900","-152.02065","0.01227"
"9.64400","-152.02065","0.00701"
"9.66700","-152.02065","0.01215"
"9.71900","-152.02065","-0.00137"
"9.75600","-152.02065","-0.00901"
"9.79300","-152.02065","-0.01856"
"9.82500","-152.02065","0.01129"
"9.86300","-152.02065","0.00562"
"9.90400","-152.02065","-0.00632"
"9.94400","-152.02065","0.00056"
"9.97200","-152.02065","0.01182"
"10.01200","-152.02065","-0.00283"
"10.04200","-152.02065","0.00016"
"10.07700","-152.02065","0.01613"
"10.10700","-152.02065","-0.00811"
"10.13400","-152.02065","0.00009"
"10.17000","-152.02065","0.01209"
"10.19800","-152.02065","-0.00042"
"10.25000","-152.02065","0.01450"
"10.28400","-152.02065","0.00839"
"10.30900","-152.02065","-0.01521"
"10.33000","-152.02065","-0.00701"
"10.35200","-152.02065","0.01357"
"10.38600","-152.02065","0.01371"
"10.43600","-152.02065","-0.00185"
"10.46900","-152.02065","-0.01630"
"10.49800","-152.02065","0.00304"
"10.52700","-152.02065","-0.00475"
"10.55100","-152.02065","0.00258"
"10.59600","-152.02065","0.00600"
"10.64200","-152.02065","0.00212"
"10.67200","-152.02065","-0.01480"
"10.70000","-152.02065","-0.00125"
"10.72700","-152.02065","-0.00880"
"10.76300","-152.02065","-0.00080"
"10.79400","-152.02065","-0.01391"
"10.82600","-152.02065","0.01561"
"10.84900","-152.02065","0.00227"
"10.88000","-152.02065","0.00605"
"10.91600","-152.02065","0.00973"
"10.95800","-152.02065","0.01836"
"10.99000","-152.02065","0.00381"
"11.01200","-152.02065","0.00440"
"11.03500","-152.02065","0.00643"
"11.07000","-152.02065","-0.00283"
"11.10700","-152.02065","0.00297"
"11.15200","-152.02065","0.00378"
"11.19300","-152.02065","0.01051"
"11.23700","-152.02065","0.00792"
"11.27100","-152.02065","0.01021"
"11.30100","-152.02065","-0.01349"
"11.33300","-152.02065","-0.00229"
"11.35900","-152.02065","-0.00207"
"11.38600","-152.02065","0.02292"
"11.42200","-152.02065","0.00555"
"11.45000","-152.02065","-0.01052"
"11.48600","-152.02065","-0.00016"
"11.51300","-152.02065","-0.01524"
"11.54000","-152.02065","0.01352"
"11.56600","-152.02065","-0.00361"
"11.61100","-152.02065","0.00434"
"11.64900","-152.02065","0.00279"
"11.68000","-152.02065","0.00806"
"11.71700","-152.02065","0.02130"
"11.74700","-152.02065","-0.01279"
"11.76800","-152.02065","-0.00785"
"11.79700","-152.02065","0.01772"
"11.82000","-152.02065","0.01343"
"11.87000","-152.02065","0.00114"
"11.90800","-152.02065","0.00188"
"11.95000","-152.02065","-0.00054"
"11.99600","-152.02065","0.01312"
"12.02200","-152.02065","0.00732"
"12.05700","-152.02065","0.01824"
"12.09900","-152.02065","0.00194"
"12.13200","-152.02065","0.00833"
"12.16600","-152.02065","0.01586"
"12.18100","-152.02065","-0.00910"
"12.21300","-152.02065","0.00816"
"12.23500","-152.02065","-0.01199"
"12.26900","-152.02065","0.02352"
"12.30300","-152.02065","0.00806"
"12.33600","-152.02065","0.00098"
"12.35600","-152.02065","0.00689"
"12.38400","-152.02065","-0.00312"
"12.42100","-152.02065","0.00621"
"12.43400","-152.02065","0.01022"
"12.47400","-152.02065","0.01214"
"12.51000","-152.02065","0.01424"
"12.55700","-152.02065","-0.00276"
"12.58900","-152.02065","-0.00203"
"12.62700","-152.02065","0.00731"
"12.65700","-152.02065","-0.01026"
"12.68600","-152.02065","0.01549"
"12.71300","-152.02065","0.01010"
"12.74400","-152.02065","0.00075"
"12.76400","-152.02065","-0.00445"
"12.79000","-152.02065","0.01651"
"12.81200","-152.02065","-0.00254"
"12.84800","-152.02065","0.00536"
"12.88300","-152.02065","0.01256"
"12.92100","-152.02065","0.00291"
"12.94200","-152.02065","0.00980"
"12.96300","-152.02065","0.01095"
"13.00200","-152.02065","0.00275"
"13.01500","-152.02065","0.01019"
"13.05300","-152.02065","0.00525"
"13.08000","-152.02065","0.01459"
"13.11200","-152.02065","-0.00687"
"13.14400","-152.02065","-0.00725"
"13.17100","-152.02065","-0.01259"
"13.20700","-152.02065","-0.01241"
"13.23300","-152.02065","-0.00034"
"13.26900","-152.02065","-0.00289"
"13.30900","-152.02065","-0.00544"
"13.35300","-152.02065","0.01018"
"13.37400","-152.02065","-0.00005"
"13.42500","-152.02065","0.00487"
"13.44300","-152.02065","0.00614"
"13.47100","-152.02065","0.00603"
"13.49900","-152.02065","-0.00343"
"13.52200","-152.02065","-0.02670"
"13.55200","-152.02065","-0.10116"
"13.57500","-152.02065","-0.10245"
"13.62100","-152.02065","-0.06754"
"13.63700","-152.02065","-0.09239"
"13.65500","-152.02065","-0.06979"
"13.69300","-152.02065","-0.07676"
"13.71600","-152.02065","-0.07626"
"13.74100","-152.02065","-0.07931"
"13.77100","-152.02065","-0.05292"
"13.79600","-152.02065","-0.07344"
"13.82200","-152.02065","-0.06808"
"13.85500","-152.02065","-0.05770"
"13.87800","-152.02065","-0.04529"
"13.91700","-152.02065","-0.05127"
"13.93900","-152.02065","-0.05508"
"13.96600","-152.02065","-0.04818"
"14.00000","-152.02065","-0.04430"
"14.03500","-152.02065","-0.04442"
"14.07500","-152.02065","-0.03762"
"14.11100","-152.02065","-0.04586"
"14.13400","-152.02065","-0.04391"
"14.15900","-152.02065","-0.03015"
"14.20700","-152.02065","-0.03726"
"14.24100","-152.02065","-0.03801"
"14.25900","-152.02065","-0.03576"
"14.27900","-152.02065","-0.02936"
"14.31700","-152.02065","-0.01976"
"14.34700","-152.02065","-0.03318"
"14.37800","-152.02065","-0.03501"
"14.41000","-152.02065","-0.04026"
"14.43900","-152.02065","-0.02327"
"14.46000","-152.02065","-0.02556"
"14.48900","-152.02065","-0.03272"
"14.52200","-152.02065","-0.02023"
"14.54400","-152.02065","-0.02992"
"14.59000","-152.02065","-0.01128"
"14.61500","-152.02065","-0.02715"
"14.64700","-152.02065","-0.02532"
"14.66600","-152.02065","-0.02680"
"14.69800","-152.02065","-0.00027"
"14.73600","-152.02065","-0.02285"
"14.78200","-152.02065","-0.02358"
"14.81600","-152.02065","-0.01521"
"14.85100","-152.02065","0.00245"
"14.87300","-152.02065","-0.02698"
"14.90200","-152.02065","-0.01099"
"14.95300","-152.02065","-0.01439"
"14.98900","-152.02065","-0.02097"
"15.01500","-152.02065","-0.01381"
"15.03800","-152.02065","0.00578"
"15.07200","-152.02065","-0.00373"
"15.11600","-152.02065","0.00457"
"15.15100","-152.02065","0.00470"
"15.17200","-152.02065","-0.01335"
"15.19900","-152.02065","-0.01698"
"15.23400","-152.02065","0.00879"
"15.27500","-152.02065","0.01058"
"15.31400","-152.02065","0.00370"
"15.34000","-152.02065","0.00283"
"15.37000","-152.02065","-0.01261"
"15.40300","-152.02065","0.01204"
"15.43500","-152.02065","-0.00091"
"15.46500","-152.02065","0.00720"
"15.50700","-152.02065","0.00103"
"15.55200","-152.02065","-0.01026"
"15.56900","-152.02065","0.01077"
"15.60400","-152.02065","-0.00855"
"15.64400","-152.02065","-0.00329"
"15.68600","-152.02065","-0.00304"
"15.73300","-152.02065","0.01777"
"15.76900","-152.02065","0.01334"
"15.80200","-152.02065","0.01086"
"15.83500","-152.02065","0.01928"
"15.88100","-152.02065","-0.00485"
"15.92300","-152.02065","0.00779"
"15.95600","-152.02065","0.00749"
"16.00000","-152.02065","-0.00386"
"16.04000","-152.02065","0.00324"
"16.08000","-152.02065","0.01724"
"16.10500","-152.02065","0.01113"
"16.14400","-152.02065","0.00830"
"16.18500","-152.02065","0.00587"
"16.23200","-152.02065","0.01384"
"16.27300","-152.02065","-0.00275"
"16.30900","-152.02065","-0.00098"
"16.34800","-152.02065","0.01977"
"16.37900","-152.02065","-0.00077"
"16.41000","-152.02065","0.01255"
"16.45000","-152.02065","0.01546"
"16.48000","-152.02065","0.01859"
"16.51500","-152.02065","0.01251"
"16.54400","-152.02065","0.00353"
"16.56600","-152.02065","0.00856"
"16.60400","-152.02065","-0.00762"
"16.63500","-152.02065","0.00489"
"16.66400","-152.02065","0.02249"
"16.70300","-152.02065","-0.00093"
"16.74600","-152.02065","-0.00223"
"16.78300","-152.02065","0.00259"
"16.82800","-152.02065","-0.00731"
"16.87200","-152.02065","0.01534"
"16.90100","-152.02065","0.00664"
"16.93400","-152.02065","0.00865"
"16.96800","-152.02065","0.00266"
"17.00700","-152.02065","0.00368"
"17.04900","-152.02065","-0.00517"
"17.09600","-152.02065","0.01224"
"17.12100","-152.02065","0.01342"
"17.16200","-152.02065","0.00341"
"17.20000","-152.02065","0.00331"
"17.22600","-152.02065","0.01678"
"17.25800","-152.02065","-0.00665"
"17.28900","-152.02065","0.00998"
"17.30700","-152.02065","0.00786"
"17.33800","-152.02065","0.00452"
"17.39300","-152.02065","0.00598"
"17.43300","-152.02065","0.00661"
"17.45900","-152.02065","0.00052"
"17.48700","-152.02065","0.01935"
"17.51000","-152.02065","-0.01372"
"17.53400","-152.02065","0.00992"
"17.56900","-152.02065","0.00492"
"17.60100","-152.02065","-0.00240"
"17.63100","-152.02065","0.00582"
"17.67000","-152.02065","-0.00298"
"17.70800","-152.02065","0.00434"
"17.73600","-152.02065","0.00148"
"17.78900","-152.02065","0.01096"
"17.82800","-152.02065","-0.00005"
"17.86400","-152.02065","-0.00140"
"17.89800","-152.02065","-0.00385"
"17.92800","-152.02065","-0.01002"
"17.96500","-152.02065","-0.04539"
"17.99200","-152.02065","-0.09639"
"18.01800","-152.02065","-0.17311"
"18.05400","-152.02065","-0.15914"
"18.09300","-152.02065","-0.15025"
"18.12800","-152.02065","-0.15510"
"18.15600","-152.02065","-0.13567"
"18.19000","-152.02065","-0.15384"
"18.21000","-152.02065","-0.13717"
"18.24300","-152.02065","-0.13995"
"18.28300","-152.02065","-0.12615"
"18.31900","-152.02065","-0.11380"
"18.34700","-152.02065","-0.11628"
"18.36700","-152.02065","-0.09868"
"18.39800","-152.02065","-0.09341"
"18.42100","-152.02065","-0.09772"
"18.45700","-152.02065","-0.11491"
"18.48900","-152.02065","-0.09106"
"18.51300","-152.02065","-0.08819"
"18.53400","-152.02065","-0.08900"
"18.57400","-152.02065","-0.09540"
"18.60600","-152.02065","-0.08950"
"18.64200","-152.02065","-0.07690"
"18.67100","-152.02065","-0.07907"
"18.71500","-152.02065","-0.08587"
"18.75600","-152.02065","-0.08504"
"18.79400","-152.02065","-0.07701"
"18.82600","-152.02065","-0.07694"
"18.86400","-152.02065","-0.06601"
"18.89800","-152.02065","-0.06320"
"18.93200","-152.02065","-0.05983"
"18.95900","-152.02065","-0.05684"
"18.98100","-152.02065","-0.05389"
"19.00400","-152.02065","-0.05327"
"19.04700","-152.02065","-0.04011"
"19.08400","-152.02065","-0.05445"
"19.12700","-152.02065","-0.04992"
"19.15200","-152.02065","-0.02630"
"19.18300","-152.02065","-0.03779"
"19.21000","-152.02065","-0.03229"
"19.23900","-152.02065","-0.03415"
"19.27500","-152.02065","-0.04615"
"19.31600","-152.02065","-0.02635"
"19.34800","-152.02065","-0.04836"
"19.37300","-152.02065","-0.03769"
"19.41200","-152.02065","-0.04460"
"19.45100","-152.02065","-0.03900"
"19.48600","-152.02065","-0.01409"
"19.52100","-152.02065","-0.01534"
"19.56100","-152.02065","-0.02705"
"19.59600","-152.02065","-0.04197"
"19.64900","-152.02065","-0.03867"
"19.69300","-152.02065","-0.01775"
"19.71800","-152.02065","-0.02301"
"19.74800","-152.02065","-0.01373"
"19.79000","-152.02065","-0.00894"
"19.82000","-152.02065","-0.02620"
"19.86800","-152.02065","-0.00697"
"19.90300","-152.02065","-0.02496"
"19.93500","-152.02065","0.00435"
"19.95600","-152.02065","-0.02372"
"19.97900","-152.02065","-0.00453"
"20.01500","-152.02065","-0.02491"
"20.03300","-152.02065","0.00379"
"20.05900","-152.02065","-0.00530"
"20.09400","-152.02065","-0.01006"
"20.12800","-152.02065","-0.01002"
"20.15300","-152.02065","0.00927"
"20.17900","-152.02065","0.00100"
"20.21100","-152.02065","0.00270"
"20.25000","-152.02065","-0.00434"
"20.28700","-152.02065","-0.01273"
"20.32600","-152.02065","0.00693"
"20.36000","-152.02065","0.00442"
"20.38800","-152.02065","-0.02183"
"20.41500","-152.02065","-0.00967"
"20.44800","-152.02065","-0.00234"
"20.48400","-152.02065","0.00760"
"20.51500","-152.02065","-0.00266"
"20.54900","-152.02065","0.00058"
"20.58000","-152.02065","-0.01005"
"20.60200","-152.02065","0.01030"
"20.63300","-152.02065","-0.01492"
"20.66500","-152.02065","0.00107"
"20.69200","-152.02065","0.00039"
"20.71700","-152.02065","-0.00623"
"20.74700","-152.02065","-0.00844"
"20.79500","-152.02065","0.00153"
"20.83500","-152.02065","0.00530"
"20.88200","-152.02065","-0.00206"
"20.91400","-152.02065","0.01827"
"20.94800","-152.02065","-0.00846"
"20.98300","-152.02065","-0.00513"
"21.00900","-152.02065","0.00509"
"21.04300","-152.02065","0.00042"
"21.08600","-152.02065","0.00332"
"21.12300","-152.02065","0.00057"
"21.16300","-152.02065","0.01629"
"21.19700","-152.02065","-0.00164"
"21.23100","-152.02065","0.00677"
"21.26400","-152.02065","-0.01636"
"21.29600","-152.02065","0.01655"
"21.33600","-152.02065","0.01994"
"21.36400","-152.02065","0.00808"
"21.38800","-152.02065","0.00534"
"21.43200","-152.02065","-0.00508"
"21.47100","-152.02065","-0.00352"
"21.50800","-152.02065","0.00929"
"21.54300","-152.02065","-0.00266"
"21.56500","-152.02065","-0.00608"
"21.58900","-152.02065","0.00246"
"21.61000","-152.02065","-0.00202"
"21.63000","-152.02065","-0.00344"
"21.67000","-152.02065","-0.00403"
"21.70600","-152.02065","0.02289"
"21.73500","-152.02065","-0.00516"
"21.76100","-152.02065","0.01182"
"21.78900","-152.02065","0.00103"
"21.82500","-152.02065","0.01166"
"21.85800","-152.02065","0.00414"
"21.88400","-152.02065","-0.00094"
"21.92900","-152.02065","0.00151"
"21.95000","-152.02065","0.00382"
"21.97800","-152.02065","-0.00936"
"22.00700","-152.02065","0.01083"
"22.03900","-152.02065","-0.01519"
"22.08000","-152.02065","0.00808"
"22.12300","-152.02065","0.01382"
"22.16100","-152.02065","0.00730"
"22.19400","-152.02065","0.00758"
"22.21800","-152.02065","0.01050"
"22.24200","-152.02065","0.01204"
"22.27600","-152.02065","-0.00213"
"22.31700","-152.02065","0.00493"
"22.35000","-152.02065","0.01357"
"22.37100","-152.02065","0.00592"
"22.41400","-152.02065","0.00888"
"22.44500","-152.02065","-0.00108"
"22.48400","-152.02065","0.00460"
"22.50600","-152.02065","0.00907"
"22.53100","-152.02065","0.01993"
"22.56600","-152.02065","0.00719"
"22.59700","-152.02065","0.01187"
"22.62800","-152.02065","-0.00196"
"22.66700","-152.02065","0.00404"
"22.69600","-152.02065","0.00977"
"22.73400","-152.02065","-0.00867"
"22.77200","-152.02065","-0.00034"
"22.81400","-152.02065","-0.00929"
"22.85400","-152.02065","0.00289"
"22.87800","-152.02065","-0.00918"
"22.91100","-152.02065","0.00344"
"22.94800","-152.02065","0.01249"
"22.97800","-152.02065","0.00897"
"22.99400","-152.02065","-0.00034"
"23.03200","-152.02065","0.00533"
"23.05300","-152.02065","0.00518"
"23.09200","-152.02065","0.00816"
"23.12000","-152.02065","-0.00646"
"23.15400","-152.02065","-0.01068"
"23.19400","-152.02065","-0.00357"
"23.23500","-152.02065","0.00819"
"23.27000","-152.02065","-0.00124"
"23.30300","-152.02065","0.00199"
"23.34200","-152.02065","0.00086"
"23.37600","-152.02065","0.00077"
"23.40800","-152.02065","-0.00046"
"23.44700","-152.02065","0.01200"
"23.48200","-152.02065","-0.00406"
"23.51800","-152.02065","0.00591"
"23.54900","-152.02065","-0.00171"
"23.57300","-152.02065","-0.00495"
"23.60800","-152.02065","0.01847"
"23.63300","-152.02065","0.01235"
"23.67000","-152.02065","0.00733"
"23.70000","-152.02065","0.00852"
"23.73500","-152.02065","0.00201"
"23.77100","-152.02065","-0.00079"
"23.80700","-152.02065","0.01587"
"23.83600","-152.02065","0.00550"
"23.86600","-152.02065","0.01226"
"23.89800","-152.02065","0.01765"
"23.92300","-152.02065","0.00248"
"23.95300","-152.02065","-0.00010"
"23.97700","-152.02065","0.01871"
"24.01100","-152.02065","-0.00122"
"24.04500","-152.02065","0.00072"
"24.07100","-152.02065","-0.00057"
"24.11000","-152.02065","-0.00691"
"24.13500","-152.02065","0.01565"
"24.17700","-152.02065","-0.02661"
"24.20200","-152.02065","-0.05823"
"24.23100","-152.02065","-0.12454"
"24.25700","-152.02065","-0.17413"
"24.28900","-152.02065","-0.22521"
"24.30800","-152.02065","-0.24687"
"24.33700","-152.02065","-0.21806"
"24.37700","-152.02065","-0.23365"
"24.40400","-152.02065","-0.20118"
"24.43100","-152.02065","-0.20614"
"24.45400","-152.02065","-0.18153"
"24.47900","-152.02065","-0.18874"
"24.51600","-152.02065","-0.16891"
"24.55200","-152.02065","-0.16115"
"24.57600","-152.02065","-0.16355"
"24.60200","-152.02065","-0.16234"
"24.64200","-152.02065","-0.14740"
"24.67600","-152.02065","-0.14290"
"24.70500","-152.02065","-0.15234"
"24.73500","-152.02065","-0.13466"
"24.75700","-152.02065","-0.13350"
"24.78600","-152.02065","-0.13520"
"24.81800","-152.02065","-0.10860"
"24.83500","-152.02065","-0.13690"
"24.85700","-152.02065","-0.11480"
"24.89600","-152.02065","-0.11271"
"24.92100","-152.02065","-0.12269"
"24.94600","-152.02065","-0.12877"
"24.99000","-152.02065","-0.11123"
"25.02200","-152.02065","-0.09854"
"25.07000","-152.02065","-0.09977"
"25.10100","-152.02065","-0.11480"
"25.13300","-152.02065","-0.07508"
"25.16200","-152.02065","-0.10244"
"25.20100","-152.02065","-0.09276"
"25.24500","-152.02065","-0.07112"
"25.29000","-152.02065","-0.05785"
"25.32100","-152.02065","-0.07314"
"25.35000","-152.02065","-0.07987"
"25.37500","-152.02065","-0.06210"
"25.41400","-152.02065","-0.05902"
"25.45500","-152.02065","-0.05249"
"25.49400","-152.02065","-0.05115"
"25.53300","-152.02065","-0.04844"
"25.56100","-152.02065","-0.07801"
"25.57400","-152.02065","-0.05951"
"25.60300","-152.02065","-0.03032"
"25.63200","-152.02065","-0.03754"
"25.69000","-152.02065","-0.04850"
"25.72000","-152.02065","-0.04623"
"25.75400","-152.02065","-0.02738"
"25.79400","-152.02065","-0.03829"
"25.82700","-152.02065","-0.03697"
"25.86800","-152.02065","-0.01421"
"25.89800","-152.02065","-0.03572"
"25.92400","-152.02065","-0.03366"
"25.95100","-152.02065","-0.03447"
"25.98600","-152.02065","-0.02037"
"26.03000","-152.02065","-0.03182"
"26.05900","-152.02065","-0.01183"
"26.10200","-152.02065","-0.01664"
"26.13000","-152.02065","-0.00845"
"26.15500","-152.02065","-0.01524"
"26.18300","-152.02065","-0.02100"
"26.21900","-152.02065","-0.01219"
"26.25900","-152.02065","-0.01461"
"26.28600","-152.02065","-0.00979"
"26.32800","-152.02065","-0.00510"
"26.37300","-152.02065","0.00354"
"26.40000","-152.02065","-0.01183"
"26.44200","-152.02065","-0.00078"
"26.48100","-152.02065","-0.00670"
"26.52700","-152.02065","-0.00352"
"26.55200","-152.02065","-0.01577"
"26.59300","-152.02065","-0.01220"
"26.62400","-152.02065","0.00613"
"26.65700","-152.02065","0.00558"
"26.68000","-152.02065","0.00792"
"26.71100","-152.02065","-0.02198"
"26.74000","-152.02065","-0.00713"
"26.78200","-152.02065","0.00777"
"26.82400","-152.02065","-0.02196"
"26.86300","-152.02065","-0.02202"
"26.89400","-152.02065","-0.00828"
"26.92200","-152.02065","-0.01315"
"26.94700","-152.02065","-0.00103"
"26.98200","-152.02065","0.00699"
"27.01900","-152.02065","-0.00264"
"27.06000","-152.02065","0.00968"
"27.08600","-152.02065","-0.00403"
"27.12200","-152.02065","-0.01065"
"27.16400","-152.02065","0.00760"
"27.19100","-152.02065","0.01200"
"27.22200","-152.02065","-0.00531"
"27.25800","-152.02065","0.02440"
"27.28900","-152.02065","-0.01414"
"27.32500","-152.02065","0.01092"
"27.35300","-152.02065","-0.00858"
"27.37700","-152.02065","0.00016"
"27.41900","-152.02065","0.01311"
"27.45100","-152.02065","-0.00006"
"27.47400","-152.02065","-0.00350"
"27.50500","-152.02065","-0.00072"
"27.54100","-152.02065","0.01029"
"27.57300","-152.02065","0.02081"
"27.60400","-152.02065","-0.00792"
"27.64000","-152.02065","0.00768"
"27.67500","-152.02065","0.00485"
"27.70800","-152.02065","-0.00858"
"27.74400","-152.02065","0.01186"
"27.77100","-152.02065","0.00498"
"27.79000","-152.02065","0.00897"
"27.81300","-152.02065","-0.01071"
"27.85400","-152.02065","-0.00254"
"27.87800","-152.02065","0.02004"
"27.90500","-152.02065","0.00522"
"27.95100","-152.02065","0.00474"
"27.97400","-152.02065","-0.00060"
"28.00800","-152.02065","0.00485"
"28.03600","-152.02065","0.00617"
"28.06000","-152.02065","0.00978"
"28.09700","-152.02065","0.01195"
"28.12600","-152.02065","0.00020"
"28.15500","-152.02065","-0.00954"
"28.18600","-152.02065","0.01025"
"28.23000","-152.02065","-0.01065"
"28.26200","-152.02065","-0.00250"
"28.31000","-152.02065","0.02376"
"28.32700","-152.02065","0.00339"
"28.36600","-152.02065","0.00714"
"28.40000","-152.02065","0.02437"
"28.43400","-152.02065","-0.01382"
"28.46300","-152.02065","0.01215"
"28.49700","-152.02065","-0.00789"
"28.51800","-152.02065","0.01687"
"28.55300","-152.02065","0.00265"
"28.58700","-152.02065","-0.00346"
"28.61400","-152.02065","0.00447"
"28.63400","-152.02065","-0.00740"
"28.66400","-152.02065","0.01634"
"28.69900","-152.02065","0.00945"
"28.73200","-152.02065","-0.01293"
"28.76400","-152.02065","0.01291"
"28.79700","-152.02065","-0.00087"
"28.83600","-152.02065","0.00895"
"28.86800","-152.02065","-0.00271"
"28.90300","-152.02065","0.00520"
"28.93900","-152.02065","0.00308"
"28.97900","-152.02065","0.00419"
"29.01100","-152.02065","-0.00783"
"29.04100","-152.02065","0.01500"
"29.07800","-152.02065","0.00683"
"29.10600","-152.02065","0.00722"
"29.13100","-152.02065","-0.00557"
"29.15700","-152.02065","0.00211"
"29.20000","-152.02065","0.00315"
"29.21800","-152.02065","0.00695"
"29.26400","-152.02065","-0.00021"
"29.29800","-152.02065","-0.01439"
"29.32100","-152.02065","-0.01368"
"29.35500","-152.02065","-0.03203"
"29.38700","-152.02065","-0.11813"
"29.41600","-152.02065","-0.18557"
"29.44600","-152.02065","-0.23792"
"29.47500","-152.02065","-0.29681"
"29.50500","-152.02065","-0.35021"
"29.54800","-152.02065","-0.31836"
"29.58300","-152.02065","-0.29299"
"29.62600","-152.02065","-0.29578"
"29.65800","-152.02065","-0.27298"
"29.68700","-152.02065","-0.27268"
"29.70900","-152.02065","-0.27690"
"29.73700","-152.02065","-0.25425"
"29.76900","-152.02065","-0.24873"
"29.79000","-152.02065","-0.24896"
"29.81500","-152.02065","-0.24556"
"29.83900","-152.02065","-0.24503"
"29.88200","-152.02065","-0.23373"
"29.91800","-152.02065","-0.23680"
"29.95400","-152.02065","-0.21627"
"29.98900","-152.02065","-0.22423"
"30.02700","-152.02065","-0.22874"
"30.06900","-152.02065","-0.21639"
"30.10500","-152.02065","-0.20738"
"30.14000","-152.02065","-0.21632"
"30.17400","-152.02065","-0.18759"
"30.21800","-152.02065","-0.19152"
"30.24300","-152.02065","-0.20509"
"30.28400","-152.02065","-0.19828"
"30.31600","-152.02065","-0.17578"
"30.35800","-152.02065","-0.17447"
"30.39300","-152.02065","-0.17255"
"30.42800","-152.02065","-0.16275"
"30.45200","-152.02065","-0.16828"
"30.48400","-152.02065","-0.15091"
"30.50800","-152.02065","-0.15805"
"30.54300","-152.02065","-0.14053"
"30.57200","-152.02065","-0.14689"
"30.61900","-152.02065","-0.13139"
"30.65400","-152.02065","-0.15853"
"30.66800","-152.02065","-0.12493"
"30.69500","-152.02065","-0.12697"
"30.73600","-152.02065","-0.11951"
"30.77100","-152.02065","-0.10154"
"30.79900","-152.02065","-0.09334"
"30.83600","-152.02065","-0.09687"
"30.86200","-152.02065","-0.09941"
"30.89800","-152.02065","-0.08293"
"30.93100","-152.02065","-0.08450"
"30.95800","-152.02065","-0.08202"
"30.98700","-152.02065","-0.08712"
"31.00800","-152.02065","-0.09855"
"31.04500","-152.02065","-0.08187"
"31.09100","-152.02065","-0.06358"
"31.13200","-152.02065","-0.05850"
"31.15900","-152.02065","-0.06413"
"31.18100","-152.02065","-0.06722"
"31.22200","-152.02065","-0.07488"
"31.25500","-152.02065","-0.05909"
"31.28000","-152.02065","-0.04960"
"31.31700","-152.02065","-0.04865"
"31.35600","-152.02065","-0.04071"
"31.38600","-152.02065","-0.05291"
"31.41000","-152.02065","-0.02949"
"31.44100","-152.02065","-0.05577"
"31.48200","-152.02065","-0.06458"
"31.52300","-152.02065","-0.03956"
"31.55000","-152.02065","-0.05512"
"31.58300","-152.02065","-0.02954"
"31.61300","-152.02065","-0.06070"
"31.64600","-152.02065","-0.02367"
"31.69300","-152.02065","-0.04443"
"31.71700","-152.02065","-0.04580"
"31.74200","-152.02065","-0.04239"
"31.78200","-152.02065","-0.05186"
"31.81200","-152.02065","-0.01836"
"31.84100","-152.02065","-0.03298"
"31.86000","-152.02065","-0.04716"
"31.88900","-152.02065","-0.03906"
"31.92400","-152.02065","-0.02865"
"31.96400","-152.02065","-0.02495"
"31.99200","-152.02065","-0.04075"
"32.01600","-152.02065","-0.01712"
"32.06400","-152.02065","-0.01306"
"32.08200","-152.02065","-0.01768"
"32.10600","-152.02065","-0.01838"
"32.14800","-152.02065","-0.00660"
"32.17500","-152.02065","-0.02865"
"32.20400","-152.02065","-0.03369"
"32.23200","-152.02065","-0.02153"
"32.27100","-152.02065","-0.02844"
"32.30500","-152.02065","-0.01336"
"32.32500","-152.02065","-0.00293"
"32.36400","-152.02065","-0.01326"
"32.40000","-152.02065","-0.01798"
"32.43000","-152.02065","-0.01168"
"32.46500","-152.02065","-0.03228"
"32.50500","-152.02065","-0.01903"
"32.53700","-152.02065","-0.02134"
"32.55800","-152.02065","-0.02609"
"32.60400","-152.02065","-0.00106"
"32.63700","-152.02065","-0.01864"
"32.67600","-152.02065","-0.01536"
"32.71500","-152.02065","-0.02242"
"32.73400","-152.02065","0.00373"
"32.77200","-152.02065","-0.00821"
"32.79700","-152.02065","-0.01316"
"32.83800","-152.02065","-0.00238"
"32.86800","-152.02065","-0.00102"
"32.89300","-152.02065","-0.00365"
"32.92600","-152.02065","-0.03146"
"32.97800","-152.02065","-0.01831"
"33.01700","-152.02065","-0.01409"
"33.03200","-152.02065","-0.01820"
"33.04500","-152.02065","-0.02087"
"33.07400","-152.02065","-0.00804"
"33.10300","-152.02065","-0.00779"
"33.13700","-152.02065","-0.01995"
"33.16600","-152.02065","-0.00590"
"33.19300","-152.02065","-0.00045"
"33.22800","-152.02065","-0.02687"
"33.26000","-152.02065","0.01174"
"33.28700","-152.02065","-0.01485"
"33.31100","-152.02065","0.00270"
"33.34400","-152.02065","-0.01700"
"33.38500","-152.02065","-0.00424"
"33.41000","-152.02065","-0.00618"
"33.43800","-152.02065","-0.01986"
"33.45900","-152.02065","0.00253"
"33.49600","-152.02065","-0.01197"
"33.52900","-152.02065","0.01399"
"33.55800","-152.02065","-0.00793"
"33.60000","-152.02065","-0.00889"
"33.64700","-152.02065","-0.00826"
"33.68600","-152.02065","-0.00556"
"33.72000","-152.02065","0.00380"
"33.73300","-152.02065","0.00188"
"33.76800","-152.02065","0.00391"
"33.81400","-152.02065","-0.00499"
"33.84700","-152.02065","0.00039"
"33.89000","-152.02065","0.00941"
"33.93200","-152.02065","0.00974"
"33.96200","-152.02065","-0.01276"
"34.00600","-152.02065","-0.00927"
"34.03200","-152.02065","0.01014"
"34.07600","-152.02065","-0.00008"
"34.09200","-152.02065","-0.00062"
"34.14200","-152.02065","-0.00183"
"34.17000","-152.02065","-0.00178"
"34.20700","-152.02065","0.00967"
"34.23600","-152.02065","-0.00639"
"34.27700","-152.02065","-0.01343"
"34.29700","-152.02065","-0.00397"
"34.33800","-152.02065","0.00569"
"34.36900","-152.02065","-0.01367"
"34.39100","-152.02065","0.01153"
"34.43600","-152.02065","0.00408"
"34.46900","-152.02065","0.00339"
"34.50800","-152.02065","0.01439"
"34.53700","-152.02065","0.00615"
"34.57000","-152.02065","-0.00726"
"34.59500","-152.02065","-0.00951"
"34.63300","-152.02065","-0.00801"
"34.68400","-152.02065","-0.01092"
"34.71700","-152.02065","0.01552"
"34.75000","-152.02065","-0.01306"
"34.76800","-152.02065","0.00126"
"34.79700","-152.02065","-0.01236"
"34.83300","-152.02065","0.00052"
"34.85500","-152.02065","-0.01341"
"34.88900","-152.02065","-0.00575"
"34.91100","-152.02065","0.00205"
"34.94900","-152.02065","-0.00455"
"34.98200","-152.02065","0.01267"
"35.01400","-152.02065","-0.01727"
"35.05100","-152.02065","-0.01301"
"35.09300","-152.02065","-0.00244"
"35.11800","-152.02065","-0.00269"
"35.16200","-152.02065","0.00352"
"35.19600","-152.02065","0.00599"
"35.22600","-152.02065","0.00278"
"35.27100","-152.02065","0.00065"
"35.29600","-152.02065","0.01752"
"35.34100","-152.02065","-0.00446"
"35.36800","-152.02065","-0.01661"
"35.40400","-152.02065","0.00338"
"35.43800","-152.02065","0.00419"
"35.46800","-152.02065","0.00008"
"35.49000","-152.02065","0.01149"
"35.52800","-152.02065","0.00151"
"35.56500","-152.02065","-0.00271"
"35.59400","-152.02065","-0.00051"
"35.62100","-152.02065","-0.02050"
"35.65600","-152.02065","-0.07412"
"35.67900","-152.02065","-0.12268"
"35.70900","-152.02065","-0.19554"
"35.73300","-152.02065","-0.27364"
"35.76200","-152.02065","-0.30651"
"35.79200","-152.02065","-0.33504"
"35.81400","-152.02065","-0.38651"
"35.84200","-152.02065","-0.43750"
"35.88200","-152.02065","-0.44881"
"35.90900","-152.02065","-0.41396"
"35.95200","-152.02065","-0.38235"
"35.98700","-152.02065","-0.38065"
"36.01900","-152.02065","-0.34807"
"36.05300","-152.02065","-0.33727"
"36.08800","-152.02065","-0.30955"
"36.11400","-152.02065","-0.30088"
"36.15000","-152.02065","-0.27991"
"36.18900","-152.02065","-0.26492"
"36.23700","-152.02065","-0.25271"
"36.27100","-152.02065","-0.23007"
"36.28800","-152.02065","-0.25545"
"36.32200","-152.02065","-0.20647"
"36.36200","-152.02065","-0.21228"
"36.38100","-152.02065","-0.18797"
"36.40300","-152.02065","-0.20292"
"36.42500","-152.02065","-0.19831"
"36.44900","-152.02065","-0.16881"
"36.47300","-152.02065","-0.18274"
"36.50900","-152.02065","-0.16225"
"36.54500","-152.02065","-0.14990"
"36.56400","-152.02065","-0.14258"
"36.58300","-152.02065","-0.14697"
"36.62900","-152.02065","-0.15005"
"36.66600","-152.02065","-0.14672"
"36.69000","-152.02065","-0.12350"
"36.72400","-152.02065","-0.13164"
"36.75700","-152.02065","-0.13721"
"36.80200","-152.02065","-0.12286"
"36.84100","-152.02065","-0.13366"
"36.86100","-152.02065","-0.10994"
"36.88000","-152.02065","-0.11780"
"36.91300","-152.02065","-0.10197"
"36.94200","-152.02065","-0.13055"
"36.98200","-152.02065","-0.11160"
"37.02200","-152.02065","-0.11689"
"37.06400","-152.02065","-0.11538"
"37.09900","-152.02065","-0.11109"
"37.13100","-152.02065","-0.09904"
"37.17000","-152.02065","-0.10383"
"37.20100","-152.02065","-0.11547"
"37.24000","-152.02065","-0.08803"
"37.26300","-152.02065","-0.09507"
"37.30400","-152.02065","-0.11064"
"37.31700","-152.02065","-0.07768"
"37.34700","-152.02065","-0.08632"
"37.37900","-152.02065","-0.10332"
"37.41500","-152.02065","-0.11206"
"37.45200","-152.02065","-0.08665"
"37.49700","-152.02065","-0.08223"
"37.53400","-152.02065","-0.11054"
"37.56700","-152.02065","-0.09153"
"37.60200","-152.02065","-0.10025"
"37.63200","-152.02065","-0.07254"
"37.66500","-152.02065","-0.10017"
"37.70500","-152.02065","-0.10048"
"37.73800","-152.02065","-0.08352"
"37.76600","-152.02065","-0.07245"
"37.77900","-152.02065","-0.08196"
"37.80400","-152.02065","-0.08069"
"37.83100","-152.02065","-0.09454"
"37.85700","-152.02065","-0.09619"
"37.88500","-152.02065","-0.08026"
"37.92000","-152.02065","-0.07911"
"37.96100","-152.02065","-0.08541"
"38.00500","-152.02065","-0.08868"
"38.03900","-152.02065","-0.07056"
"38.07700","-152.02065","-0.07967"
"38.09900","-152.02065","-0.08898"
"38.12400","-152.02065","-0.09166"
"38.16400","-152.02065","-0.08958"
"38.19100","-152.02065","-0.07843"
"38.22300","-152.02065","-0.07763"
"38.25300","-152.02065","-0.07773"
"38.29500","-152.02065","-0.07063"
"38.34000","-152.02065","-0.07278"
"38.36800","-152.02065","-0.07363"
"38.39300","-152.02065","-0.07365"
"38.41600","-152.02065","-0.08877"
"38.44800","-152.02065","-0.05921"
"38.48100","-152.02065","-0.08448"
"38.51800","-152.02065","-0.08436"
"38.55700","-152.02065","-0.07894"
"38.59700","-152.02065","-0.07766"
"38.62600","-152.02065","-0.07925"
"38.66900","-152.02065","-0.06768"
"38.69700","-152.02065","-0.06768"
"38.72700","-152.02065","-0.08046"
"38.76800","-152.02065","-0.08205"
"38.80800","-152.02065","-0.07639"
"38.83600","-152.02065","-0.06972"
"38.87000","-152.02065","-0.04941"
"38.90000","-152.02065","-0.05977"
"38.92400","-152.02065","-0.07867"
"38.96400","-152.02065","-0.07377"
"39.01100","-152.02065","-0.05682"
"39.04100","-152.02065","-0.06557"
"39.07800","-152.02065","-0.06760"
"39.10800","-152.02065","-0.07025"
"39.13800","-152.02065","-0.07224"
"39.18500","-152.02065","-0.05707"
"39.22100","-152.02065","-0.05890"
"39.25300","-152.02065","-0.07022"
"39.27400","-152.02065","-0.04737"
"39.29800","-152.02065","-0.07125"
"39.32900","-152.02065","-0.05483"
"39.36900","-152.02065","-0.04822"
"39.39400","-152.02065","-0.06419"
"39.42400","-152.02065","-0.05674"
"39.45200","-152.02065","-0.04046"
"39.48500","-152.02065","-0.03833"
"39.51800","-152.02065","-0.02965"
"39.56000","-152.02065","-0.04212"
"39.57700","-152.02065","-0.00724"
"39.60300","-152.02065","-0.03320"
"39.63300","-152.02065","-0.03109"
"39.66400","-152.02065","-0.03618"
"39.69500","-152.02065","-0.02133"
"39.72200","-152.02065","-0.03819"
"39.76200","-152.02065","-0.03702"
"39.79900","-152.02065","-0.02880"
"39.82100","-152.02065","-0.03396"
"39.86600","-152.02065","-0.03402"
"39.89500","-152.02065","-0.03025"
"39.93100","-152.02065","-0.02686"
"39.95600","-152.02065","-0.02123"
"39.99700","-152.02065","-0.02812"
"40.02300","-152.02065","-0.04618"
"40.05200","-152.02065","-0.02837"
"40.09700","-152.02065","-0.02756"
"40.12900","-152.02065","-0.03548"
"40.15400","-152.02065","-0.02149"
"40.18300","-152.02065","-0.03231"
"40.21200","-152.02065","-0.04000"
"40.25300","-152.02065","-0.03105"
"40.27700","-152.02065","-0.04753"
"40.31400","-152.02065","-0.00993"
"40.34300","-152.02065","-0.04891"
"40.37900","-152.02065","-0.02988"
"40.42200","-152.02065","-0.03784"
"40.45500","-152.02065","-0.03819"
"40.48800","-152.02065","-0.03461"
"40.50800","-152.02065","-0.03964"
"40.53900","-152.02065","-0.03792"
"40.57500","-152.02065","-0.01884"
"40.59800","-152.02065","-0.04970"
"40.61100","-152.02065","-0.02429"
"40.64200","-152.02065","-0.03710"
"40.67000","-152.02065","-0.03980"
"40.70100","-152.02065","-0.02477"
"40.72900","-152.02065","-0.03778"
"40.77000","-152.02065","-0.04470"
"40.81400","-152.02065","-0.03486"
"40.85200","-152.02065","-0.02176"
"40.87900","-152.02065","-0.02483"
"40.91500","-152.02065","-0.02775"
"40.94600","-152.02065","-0.02745"
"40.97600","-152.02065","-0.03061"
"41.01300","-152.02065","-0.04926"
"41.03500","-152.02065","-0.01803"
"41.07500","-152.02065","-0.02294"
"41.12000","-152.02065","-0.03319"
"41.15500","-152.02065","-0.03694"
"41.19000","-152.02065","-0.02253"
"41.24100","-152.02065","-0.03102"
"41.27100","-152.02065","-0.02840"
"41.30800","-152.02065","-0.01780"
"41.33500","-152.02065","-0.01592"
"41.36500","-152.02065","-0.03173"
"41.40500","-152.02065","-0.03013"
"41.44100","-152.02065","-0.02182"
"41.48500","-152.02065","-0.03603"
"41.53100","-152.02065","-0.04593"
"41.56400","-152.02065","-0.02742"
"41.59400","-152.02065","-0.02692"
"41.63000","-152.02065","-0.03400"
"41.65500","-152.02065","-0.02821"
"41.69800","-152.02065","-0.03481"
"41.70800","-152.02065","-0.02823"