File: chapter 4/force/mini_patrick.is_tens_RawData/Specimen_RawData_2.csv
Time,Extension,Load
(s),(mm),(N)
"0.00000","-146.58836","-0.00459"
"0.07800","-146.58835","-0.00685"
"0.13900","-146.58835","-0.01035"
"0.20000","-146.58835","-0.01944"
"0.27500","-146.58835","0.00196"
"0.35200","-146.58835","0.00353"
"0.41800","-146.58835","0.00407"
"0.47700","-146.58835","0.00400"
"0.57400","-146.58835","0.00816"
"0.63100","-146.58835","-0.00310"
"0.69100","-146.58835","-0.00526"
"0.75300","-146.58835","0.00575"
"0.81800","-146.58835","-0.00195"
"0.89200","-146.58835","-0.01017"
"0.95500","-146.58835","0.00592"
"1.03200","-146.58835","0.00705"
"1.08500","-146.58835","-0.01175"
"1.14200","-146.58835","-0.01564"
"1.20100","-146.58835","-0.00960"
"1.27700","-146.58835","0.00929"
"1.33900","-146.58835","-0.01042"
"1.40800","-146.58835","-0.00027"
"1.45900","-146.58835","0.00288"
"1.49900","-146.58835","-0.01064"
"1.54300","-146.58835","-0.00834"
"1.62200","-146.58835","-0.00516"
"1.70100","-146.58835","0.00192"
"1.76800","-146.58835","-0.00178"
"1.83900","-146.58835","0.00377"
"1.91400","-146.58835","0.01731"
"1.96800","-146.58835","-0.00563"
"2.02300","-146.58835","0.00319"
"2.08000","-146.58835","0.00389"
"2.15100","-146.58835","0.00423"
"2.21300","-146.58835","0.00146"
"2.28500","-146.58835","0.00934"
"2.34900","-146.58835","-0.00816"
"2.42800","-146.58835","-0.01498"
"2.48900","-146.58835","-0.00324"
"2.56400","-146.58835","0.00153"
"2.63800","-146.58835","-0.01066"
"2.68500","-146.58835","-0.00419"
"2.75800","-146.58835","-0.00481"
"2.83000","-146.58835","-0.00989"
"2.88400","-146.58835","0.01732"
"2.93400","-146.58835","-0.00612"
"3.00600","-146.58835","-0.00865"
"3.07100","-146.58835","0.00391"
"3.12500","-146.58835","-0.00865"
"3.18900","-146.58835","-0.01351"
"3.26600","-146.58835","0.00032"
"3.33300","-146.58835","0.00639"
"3.40500","-146.58835","-0.01335"
"3.44900","-146.58835","-0.00728"
"3.51500","-146.58835","0.00237"
"3.58600","-146.58835","0.01897"
"3.64200","-146.58835","0.00042"
"3.69900","-146.58835","0.00579"
"3.77200","-146.58835","-0.00346"
"3.85700","-146.58835","-0.00153"
"3.91400","-146.58835","-0.01191"
"3.97800","-146.58835","0.00194"
"4.03700","-146.58835","0.01033"
"4.09000","-146.58835","0.00355"
"4.15800","-146.58835","0.01191"
"4.20600","-146.58835","0.00812"
"4.25500","-146.58835","-0.00282"
"4.32100","-146.58835","-0.00134"
"4.38000","-146.58835","-0.00462"
"4.44000","-146.58835","-0.00164"
"4.50500","-146.58835","0.00684"
"4.57500","-146.58835","-0.00881"
"4.64000","-146.58835","0.00046"
"4.72900","-146.58835","0.00198"
"4.79400","-146.58835","0.00421"
"4.86600","-146.58835","0.00443"
"4.91400","-146.58835","-0.00710"
"4.98300","-146.58835","0.00659"
"5.02700","-146.58835","-0.00536"
"5.11300","-146.58835","-0.00693"
"5.17700","-146.58835","-0.00316"
"5.24100","-146.58835","-0.00570"
"5.28900","-146.58835","-0.00277"
"5.34800","-146.58835","-0.00257"
"5.41200","-146.58835","-0.00679"
"5.47600","-146.58835","-0.01419"
"5.55400","-146.58835","-0.01701"
"5.63000","-146.58835","-0.01203"
"5.70700","-146.58835","-0.00184"
"5.76700","-146.58835","-0.00192"
"5.84600","-146.58835","0.00656"
"5.91900","-146.58835","0.00185"
"5.98400","-146.58835","-0.00941"
"6.06100","-146.58835","0.00451"
"6.10200","-146.58835","-0.00913"
"6.17600","-146.58835","0.00035"
"6.24400","-146.58835","-0.01175"
"6.31300","-146.58835","-0.01564"
"6.37300","-146.58835","-0.01647"
"6.42300","-146.58835","-0.02151"
"6.48000","-146.58835","-0.01386"
"6.53000","-146.58835","-0.01781"
"6.61300","-146.58835","-0.00533"
"6.67900","-146.58835","-0.01614"
"6.73900","-146.58835","0.00204"
"6.80600","-146.58835","-0.01083"
"6.86800","-146.58835","-0.00516"
"6.90100","-146.58835","-0.01491"
"6.98400","-146.58835","-0.00417"
"7.04700","-146.58835","-0.01957"
"7.09500","-146.58835","-0.02276"
"7.16300","-146.58835","0.01117"
"7.22100","-146.58835","0.00861"
"7.27300","-146.58835","-0.00865"
"7.34700","-146.58835","-0.00708"
"7.40400","-146.58835","-0.00556"
"7.47100","-146.58835","0.00370"
"7.51900","-146.58835","0.01005"
"7.59100","-146.58835","0.00317"
"7.64100","-146.58835","-0.00041"
"7.71300","-146.58835","0.00241"
"7.80200","-146.58835","-0.00798"
"7.89200","-146.58835","0.00668"
"7.97700","-146.58835","0.00799"
"8.03700","-146.58835","0.00517"
"8.10400","-146.58835","-0.00005"
"8.16000","-146.58835","-0.00107"
"8.21800","-146.58835","-0.00898"
"8.29700","-146.58835","0.00942"
"8.36900","-146.58835","0.00035"
"8.43300","-146.58835","-0.00253"
"8.49200","-146.58835","0.00217"
"8.54000","-146.58835","-0.01048"
"8.60900","-146.58835","0.01857"
"8.68100","-146.58835","0.00486"
"8.73800","-146.58835","-0.00048"
"8.81900","-146.58835","-0.00816"
"8.87300","-146.58835","-0.00444"
"8.95000","-146.58835","0.00847"
"9.02600","-146.58835","0.00577"
"9.11000","-146.58835","0.00740"
"9.19200","-146.58835","-0.00447"
"9.24500","-146.58835","-0.00815"
"9.29900","-146.58835","0.00401"
"9.34900","-146.58835","-0.00769"
"9.40200","-146.58835","0.00287"
"9.47400","-146.58835","-0.00155"
"9.55400","-146.58835","-0.00128"
"9.63800","-146.58835","-0.01248"
"9.72100","-146.58835","0.01733"
"9.78200","-146.58835","0.00599"
"9.83800","-146.58835","0.00932"
"9.91400","-146.58835","-0.00897"
"9.99700","-146.58835","-0.00407"
"10.08300","-146.58835","-0.00671"
"10.16400","-146.58835","-0.00587"
"10.23300","-146.58835","0.00098"
"10.29600","-146.58835","0.01036"
"10.34900","-146.58835","0.00295"
"10.42000","-146.58835","-0.00677"
"10.47700","-146.58835","-0.00694"
"10.55800","-146.58835","0.01533"
"10.61500","-146.58835","0.00801"
"10.68700","-146.58835","0.00786"
"10.76100","-146.58835","0.01761"
"10.81100","-146.58835","-0.00050"
"10.87000","-146.58835","0.00920"
"10.93200","-146.58835","-0.00120"
"10.99100","-146.58835","-0.07061"
"11.06400","-146.58835","-0.09632"
"11.13400","-146.58835","-0.07393"
"11.20200","-146.58835","-0.05686"
"11.26300","-146.58835","-0.05467"
"11.32400","-146.58835","-0.04456"
"11.37400","-146.58835","-0.04986"
"11.43100","-146.58835","-0.04094"
"11.48100","-146.58835","-0.04692"
"11.56200","-146.58835","-0.03627"
"11.62400","-146.58835","-0.04118"
"11.70800","-146.58835","-0.04179"
"11.78200","-146.58835","-0.02848"
"11.86300","-146.58835","-0.03410"
"11.92300","-146.58835","-0.04194"
"11.98300","-146.58835","-0.04157"
"12.03900","-146.58835","-0.03012"
"12.08500","-146.58835","-0.02584"
"12.14400","-146.58835","-0.02174"
"12.18700","-146.58835","-0.04166"
"12.26400","-146.58835","-0.02195"
"12.33800","-146.58835","-0.02771"
"12.42200","-146.58835","-0.01088"
"12.47600","-146.58835","-0.02652"
"12.53800","-146.58835","-0.01458"
"12.61700","-146.58835","-0.02570"
"12.67500","-146.58835","-0.01860"
"12.75400","-146.58835","-0.02640"
"12.82200","-146.58835","-0.01969"
"12.90900","-146.58835","-0.02151"
"12.97200","-146.58835","-0.02369"
"13.03600","-146.58835","-0.02108"
"13.10700","-146.58835","-0.02078"
"13.17200","-146.58835","-0.01875"
"13.25100","-146.58835","-0.01356"
"13.31800","-146.58835","-0.03129"
"13.37000","-146.58835","-0.02003"
"13.41900","-146.58835","-0.02174"
"13.48700","-146.58835","-0.00957"
"13.55000","-146.58835","-0.01402"
"13.62200","-146.58835","-0.03062"
"13.67100","-146.58835","-0.02830"
"13.74200","-146.58835","-0.03228"
"13.80500","-146.58835","-0.01630"
"13.87700","-146.58835","-0.02170"
"13.93000","-146.58835","-0.00003"
"13.99000","-146.58835","-0.01222"
"14.04600","-146.58835","-0.01768"
"14.10900","-146.58835","0.00492"
"14.17300","-146.58835","-0.01484"
"14.24700","-146.58835","-0.03562"
"14.31200","-146.58835","-0.02432"
"14.38100","-146.58835","-0.00954"
"14.44700","-146.58835","-0.01082"
"14.50600","-146.58835","-0.02134"
"14.57500","-146.58835","0.00446"
"14.64800","-146.58835","-0.00025"
"14.70500","-146.58835","-0.00852"
"14.77400","-146.58835","-0.00703"
"14.82000","-146.58835","-0.04594"
"14.88600","-146.58835","-0.01309"
"14.97000","-146.58835","-0.00802"
"15.01100","-146.58835","-0.01129"
"15.06900","-146.58835","-0.01429"
"15.10700","-146.58835","-0.03017"
"15.16300","-146.58835","-0.00234"
"15.24000","-146.58835","-0.01496"
"15.30500","-146.58835","-0.01543"
"15.37300","-146.58835","-0.01588"
"15.41700","-146.58835","-0.01477"
"15.49900","-146.58835","-0.02349"
"15.54800","-146.58835","-0.03404"
"15.59300","-146.58835","-0.00956"
"15.64600","-146.58835","-0.01986"
"15.70600","-146.58835","-0.01992"
"15.75500","-146.58835","-0.01175"
"15.81100","-146.58835","-0.00487"
"15.88200","-146.58835","-0.01144"
"15.94300","-146.58835","-0.02684"
"15.99400","-146.58835","-0.12831"
"16.04800","-146.58835","-0.17105"
"16.11500","-146.58835","-0.13753"
"16.16200","-146.58835","-0.12466"
"16.24200","-146.58835","-0.10826"
"16.30300","-146.58835","-0.11853"
"16.37400","-146.58835","-0.11283"
"16.44300","-146.58835","-0.10022"
"16.50200","-146.58835","-0.08959"
"16.56800","-146.58835","-0.08112"
"16.64700","-146.58835","-0.09054"
"16.71000","-146.58835","-0.08500"
"16.78300","-146.58835","-0.09233"
"16.84400","-146.58835","-0.07294"
"16.90200","-146.58835","-0.06401"
"16.97900","-146.58835","-0.05500"
"17.02900","-146.58835","-0.06568"
"17.09200","-146.58835","-0.06309"
"17.14200","-146.58835","-0.07708"
"17.22600","-146.58835","-0.05871"
"17.27300","-146.58835","-0.05732"
"17.33500","-146.58835","-0.06638"
"17.42100","-146.58835","-0.04390"
"17.46500","-146.58835","-0.05274"
"17.54000","-146.58835","-0.04897"
"17.60400","-146.58835","-0.05347"
"17.65900","-146.58835","-0.05477"
"17.73500","-146.58835","-0.05946"
"17.78100","-146.58835","-0.04091"
"17.84500","-146.58835","-0.04043"
"17.91000","-146.58835","-0.03828"
"17.97100","-146.58835","-0.04074"
"18.02900","-146.58835","-0.05074"
"18.07800","-146.58835","-0.03828"
"18.14000","-146.58835","-0.04294"
"18.20900","-146.58835","-0.04276"
"18.26800","-146.58835","-0.03055"
"18.34500","-146.58835","-0.03436"
"18.40500","-146.58835","-0.03713"
"18.48500","-146.58835","-0.04133"
"18.55300","-146.58835","-0.03171"
"18.61800","-146.58835","-0.02912"
"18.67500","-146.58835","-0.02926"
"18.73000","-146.58835","-0.07158"
"18.79200","-146.58835","-0.03211"
"18.89100","-146.58835","-0.02986"
"18.96600","-146.58835","-0.04088"
"19.01600","-146.58835","-0.04996"
"19.06900","-146.58835","-0.02593"
"19.12700","-146.58835","-0.02280"
"19.18700","-146.58835","-0.02534"
"19.24400","-146.58835","-0.03311"
"19.32200","-146.58835","-0.01219"
"19.39700","-146.58835","-0.03626"
"19.45500","-146.58835","-0.03354"
"19.54800","-146.58835","-0.00763"
"19.58800","-146.58835","-0.02706"
"19.65900","-146.58835","-0.03133"
"19.71800","-146.58835","-0.10965"
"19.77600","-146.58835","-0.14593"
"19.85100","-146.58835","-0.14025"
"19.92000","-146.58835","-0.12674"
"19.98400","-146.58835","-0.11539"
"20.03300","-146.58835","-0.12199"
"20.10800","-146.58835","-0.11421"
"20.15200","-146.58835","-0.10588"
"20.20300","-146.58835","-0.09404"
"20.27100","-146.58835","-0.10722"
"20.34100","-146.58835","-0.10166"
"20.40100","-146.58835","-0.09345"
"20.45700","-146.58835","-0.07637"
"20.54500","-146.58835","-0.09704"
"20.61700","-146.58835","-0.08867"
"20.68800","-146.58835","-0.07495"
"20.75600","-146.58835","-0.07204"
"20.82900","-146.58835","-0.07814"
"20.87300","-146.58835","-0.07416"
"20.93300","-146.58835","-0.07214"
"21.00600","-146.58835","-0.06881"
"21.07400","-146.58835","-0.06765"
"21.13300","-146.58835","-0.09067"
"21.18900","-146.58835","-0.04605"
"21.26200","-146.58835","-0.07337"
"21.33300","-146.58835","-0.05819"
"21.40800","-146.58835","-0.07093"
"21.48000","-146.58835","-0.05361"
"21.53400","-146.58835","-0.04721"
"21.59700","-146.58835","-0.05618"
"21.67800","-146.58835","-0.03615"
"21.73200","-146.58835","-0.06124"
"21.81300","-146.58835","-0.05328"
"21.87900","-146.58835","-0.04985"
"21.93700","-146.58835","-0.06190"
"21.99600","-146.58835","-0.04592"
"22.07000","-146.58835","-0.05583"
"22.12800","-146.58835","-0.04867"
"22.21200","-146.58835","-0.03564"
"22.27400","-146.58835","-0.04421"
"22.32800","-146.58835","-0.04243"
"22.38300","-146.58835","-0.03677"
"22.45100","-146.58835","-0.04772"
"22.53500","-146.58835","-0.03104"
"22.60100","-146.58835","-0.04406"
"22.66100","-146.58835","-0.04814"
"22.72600","-146.58835","-0.04793"
"22.80500","-146.58835","-0.04770"
"22.87200","-146.58835","-0.04453"
"22.93600","-146.58835","-0.03114"
"23.01100","-146.58835","-0.04604"
"23.07500","-146.58835","-0.03398"
"23.14300","-146.58835","-0.04635"
"23.20200","-146.58835","-0.04207"
"23.25800","-146.58835","-0.02918"
"23.32000","-146.58835","-0.04041"
"23.39100","-146.58835","-0.04477"
"23.46800","-146.58835","-0.05270"
"23.52400","-146.58835","-0.03475"
"23.58400","-146.58835","-0.03589"
"23.64300","-146.58835","-0.04075"
"23.71200","-146.58835","-0.03605"
"23.77500","-146.58835","-0.03855"
"23.84700","-146.58835","-0.05536"
"23.88600","-146.58835","-0.04047"
"23.96700","-146.58835","-0.03681"
"24.02700","-146.58835","-0.03645"
"24.10800","-146.58835","-0.03985"
"24.17500","-146.58835","-0.01973"
"24.22200","-146.58835","-0.03778"
"24.30900","-146.58835","-0.01873"
"24.37800","-146.58835","-0.03825"
"24.44500","-146.58835","-0.03249"
"24.51900","-146.58835","-0.04489"
"24.58100","-146.58835","-0.03131"
"24.63500","-146.58835","-0.03777"
"24.71400","-146.58835","-0.02003"
"24.77900","-146.58835","-0.03159"
"24.84400","-146.58835","-0.02922"
"24.93700","-146.58835","-0.04127"
"25.02100","-146.58835","-0.02973"
"25.08800","-146.58835","-0.02316"
"25.16600","-146.58835","-0.02378"
"25.22000","-146.58835","-0.02545"
"25.26600","-146.58835","-0.03146"
"25.32300","-146.58835","-0.02536"
"25.36200","-146.58835","-0.02775"
"25.42900","-146.58835","-0.03581"
"25.47600","-146.58835","-0.04941"
"25.54700","-146.58835","-0.03687"
"25.60400","-146.58835","-0.03395"
"25.68400","-146.58835","-0.01640"
"25.75200","-146.58835","-0.02532"
"25.82200","-146.58835","-0.03299"
"25.88400","-146.58835","-0.02854"
"25.95300","-146.58835","-0.03658"
"26.01400","-146.58835","-0.02893"
"26.08200","-146.58835","-0.04275"
"26.13800","-146.58835","-0.02500"
"26.20800","-146.58835","-0.02244"
"26.27400","-146.58835","-0.03101"
"26.32900","-146.58835","-0.03130"
"26.39800","-146.58835","-0.03250"
"26.45100","-146.58835","-0.02821"
"26.50900","-146.58835","-0.03585"
"26.56000","-146.58835","-0.02833"
"26.64200","-146.58835","-0.04414"
"26.69900","-146.58835","-0.03214"
"26.76400","-146.58835","-0.03545"
"26.83700","-146.58835","-0.04268"
"26.91800","-146.58835","-0.01669"
"26.96200","-146.58835","-0.02713"
"27.01200","-146.58835","-0.03041"
"27.08700","-146.58835","-0.02208"
"27.15100","-146.58835","-0.04319"
"27.20000","-146.58835","-0.03704"
"27.29100","-146.58835","-0.03585"
"27.35700","-146.58835","-0.02592"
"27.41800","-146.58835","-0.03646"
"27.48000","-146.58835","-0.02994"
"27.54900","-146.58835","-0.01984"
"27.60300","-146.58835","-0.03257"
"27.66100","-146.58835","-0.05100"
"27.73200","-146.58835","-0.13499"
"27.77700","-146.58835","-0.23111"
"27.83200","-146.58835","-0.20429"
"27.89400","-146.58835","-0.17375"
"27.94900","-146.58835","-0.17298"
"27.99500","-146.58835","-0.15574"
"28.05700","-146.58835","-0.16174"
"28.10800","-146.58835","-0.13071"
"28.16100","-146.58835","-0.11944"
"28.22500","-146.58835","-0.13220"
"28.29900","-146.58835","-0.11334"
"28.36700","-146.58835","-0.10647"
"28.43800","-146.58835","-0.11785"
"28.50700","-146.58835","-0.09665"
"28.58200","-146.58835","-0.10545"
"28.65200","-146.58835","-0.08299"
"28.70300","-146.58835","-0.11710"
"28.75200","-146.58835","-0.09505"
"28.81500","-146.58835","-0.08083"
"28.88100","-146.58835","-0.09644"
"28.97100","-146.58835","-0.07881"
"29.02900","-146.58835","-0.07582"
"29.13300","-146.58835","-0.08158"
"29.18300","-146.58835","-0.08473"
"29.25100","-146.58835","-0.07464"
"29.32200","-146.58835","-0.06504"
"29.38100","-146.58835","-0.05751"
"29.44800","-146.58835","-0.07659"
"29.48900","-146.58835","-0.05298"
"29.54000","-146.58835","-0.08330"
"29.61700","-146.58835","-0.06691"
"29.66900","-146.58835","-0.04250"
"29.73700","-146.58835","-0.07274"
"29.80100","-146.58835","-0.05431"
"29.87400","-146.58835","-0.05855"
"29.94400","-146.58835","-0.06493"
"30.01100","-146.58835","-0.06147"
"30.07600","-146.58835","-0.04955"
"30.13700","-146.58835","-0.06473"
"30.21600","-146.58835","-0.05304"
"30.27700","-146.58835","-0.04245"
"30.35600","-146.58835","-0.07246"
"30.41600","-146.58835","-0.07474"
"30.47400","-146.58835","-0.05999"
"30.53500","-146.58835","-0.06557"
"30.60800","-146.58835","-0.07866"
"30.66500","-146.58835","-0.07216"
"30.74300","-146.58835","-0.06029"
"30.79900","-146.58835","-0.06175"
"30.86400","-146.58835","-0.05056"
"30.93000","-146.58835","-0.07133"
"30.99800","-146.58835","-0.03068"
"31.08000","-146.58835","-0.05664"
"31.14400","-146.58835","-0.06316"
"31.20700","-146.58835","-0.05258"
"31.28800","-146.58835","-0.07838"
"31.35100","-146.58835","-0.04625"
"31.39800","-146.58835","-0.05247"
"31.44900","-146.58835","-0.05927"
"31.50100","-146.58835","-0.04839"
"31.55100","-146.58835","-0.05260"
"31.63900","-146.58835","-0.04639"
"31.71100","-146.58835","-0.05886"
"31.77900","-146.58835","-0.05544"
"31.85400","-146.58835","-0.05383"
"31.91300","-146.58835","-0.04796"
"31.97900","-146.58835","-0.05816"
"32.03700","-146.58835","-0.06484"
"32.08900","-146.58835","-0.06225"
"32.16600","-146.58835","-0.06509"
"32.23200","-146.58835","-0.06048"
"32.30200","-146.58835","-0.04564"
"32.32800","-146.58835","-0.04817"
"32.41200","-146.58835","-0.05434"
"32.48200","-146.58835","-0.05392"
"32.55400","-146.58835","-0.04062"
"32.62500","-146.58835","-0.04912"
"32.67300","-146.58835","-0.05554"
"32.74200","-146.58835","-0.03956"
"32.82600","-146.58835","-0.05208"
"32.88300","-146.58835","-0.05120"
"32.94300","-146.58835","-0.05344"
"32.99600","-146.58835","-0.04646"
"33.05800","-146.58835","-0.03712"
"33.14200","-146.58835","-0.04659"
"33.19800","-146.58835","-0.04564"
"33.26000","-146.58835","-0.04319"
"33.31800","-146.58835","-0.02782"
"33.38700","-146.58835","-0.04675"
"33.46300","-146.58835","-0.04003"
"33.52100","-146.58835","-0.03974"
"33.59600","-146.58835","-0.04717"
"33.65900","-146.58835","-0.06352"
"33.72000","-146.58835","-0.05535"
"33.78500","-146.58835","-0.04141"
"33.85500","-146.58835","-0.05380"
"33.92000","-146.58835","-0.05867"
"33.99600","-146.58835","-0.05121"
"34.05900","-146.58835","-0.04840"
"34.14700","-146.58835","-0.05588"
"34.20000","-146.58835","-0.03807"
"34.27900","-146.58835","-0.05564"
"34.36100","-146.58835","-0.04476"
"34.43600","-146.58835","-0.06195"
"34.52000","-146.58835","-0.06243"
"34.59700","-146.58835","-0.05335"
"34.68400","-146.58835","-0.04330"
"34.76000","-146.58835","-0.04815"
"34.84700","-146.58835","-0.06803"
"34.92700","-146.58835","-0.05260"
"35.00500","-146.58835","-0.05153"
"35.07000","-146.58835","-0.05004"
"35.12900","-146.58835","-0.05577"
"35.20500","-146.58835","-0.05579"
"35.26100","-146.58835","-0.05707"
"35.33800","-146.58835","-0.04585"
"35.41600","-146.58835","-0.05527"
"35.48200","-146.58835","-0.05190"
"35.54900","-146.58835","-0.05630"
"35.60900","-146.58835","-0.05481"
"35.67300","-146.58835","-0.04203"
"35.74900","-146.58835","-0.02976"
"35.84100","-146.58835","-0.04302"
"35.93000","-146.58835","-0.04484"
"35.99800","-146.58835","-0.04015"
"36.06800","-146.58835","-0.04804"
"36.14500","-146.58835","-0.05591"
"36.20300","-146.58835","-0.03737"
"36.25800","-146.58835","-0.04269"
"36.31900","-146.58835","-0.06675"
"36.37000","-146.58835","-0.04769"
"36.43100","-146.58835","-0.05745"
"36.48500","-146.58835","-0.06071"
"36.55000","-146.58835","-0.05441"
"36.63500","-146.58835","-0.03782"
"36.71700","-146.58835","-0.04733"
"36.78000","-146.58835","-0.04389"
"36.84200","-146.58835","-0.05671"
"36.90000","-146.58835","-0.05547"
"36.97200","-146.58835","-0.05342"
"37.03100","-146.58835","-0.05370"
"37.09300","-146.58835","-0.05697"
"37.14400","-146.58835","-0.07259"
"37.20200","-146.58835","-0.06610"
"37.26300","-146.58835","-0.05618"
"37.31400","-146.58835","-0.05034"
"37.37400","-146.58835","-0.05521"
"37.44500","-146.58835","-0.04285"
"37.52000","-146.58835","-0.04162"
"37.58300","-146.58835","-0.05579"
"37.64100","-146.58835","-0.03405"
"37.70400","-146.58835","-0.04198"
"37.76000","-146.58835","-0.03827"
"37.82600","-146.58835","-0.04693"
"37.88500","-146.58835","-0.04822"
"37.95700","-146.58835","-0.05135"
"38.02600","-146.58835","-0.03738"
"38.09100","-146.58835","-0.06862"
"38.15900","-146.58835","-0.05352"
"38.23600","-146.58835","-0.04927"
"38.31800","-146.58835","-0.04972"
"38.38400","-146.58835","-0.02968"
"38.44200","-146.58835","-0.04242"
"38.50800","-146.58835","-0.04780"
"38.57400","-146.58835","-0.04316"
"38.65000","-146.58835","-0.05931"
"38.70800","-146.58835","-0.04880"
"38.79800","-146.58835","-0.03476"
"38.84600","-146.58835","-0.05078"
"38.93000","-146.58835","-0.05793"
"38.98200","-146.58835","-0.03585"
"39.04100","-146.58835","-0.05593"
"39.09700","-146.58835","-0.04738"
"39.16900","-146.58835","-0.05932"
"39.24500","-146.58835","-0.04566"
"39.31000","-146.58835","-0.04840"
"39.39700","-146.58835","-0.04891"
"39.46200","-146.58835","-0.03195"
"39.54400","-146.58835","-0.03770"
"39.60800","-146.58835","-0.03683"
"39.68800","-146.58835","-0.06207"
"39.74300","-146.58835","-0.07077"
"39.80700","-146.58835","-0.05441"
"39.86900","-146.58835","-0.04190"
"39.93800","-146.58835","-0.04520"
"40.02200","-146.58835","-0.04114"
"40.07500","-146.58835","-0.04626"
"40.13100","-146.58835","-0.03495"
"40.18700","-146.58835","-0.05825"
"40.24700","-146.58835","-0.03334"
"40.31000","-146.58835","-0.05810"
"40.38500","-146.58835","-0.04616"
"40.42800","-146.58835","-0.05608"
"40.49500","-146.58835","-0.05361"
"40.55700","-146.58835","-0.06388"
"40.63100","-146.58835","-0.04914"
"40.71500","-146.58835","-0.06449"
"40.79700","-146.58835","-0.05221"
"40.85700","-146.58835","-0.05309"
"40.92800","-146.58835","-0.05794"
"40.99200","-146.58835","-0.04969"
"41.07000","-146.58835","-0.06471"
"41.12000","-146.58835","-0.04667"
"41.18300","-146.58835","-0.04398"
"41.26800","-146.58835","-0.05501"
"41.33000","-146.58835","-0.04723"
"41.39900","-146.58835","-0.04721"
"41.45000","-146.58835","-0.04667"
"41.52600","-146.58835","-0.05450"
"41.61200","-146.58835","-0.05011"
"41.69300","-146.58835","-0.05661"
"41.75100","-146.58835","-0.06737"
"41.80600","-146.58835","-0.19498"
"41.85900","-146.58835","-0.32800"
"41.91200","-146.58835","-0.31870"
"41.97200","-146.58835","-0.29875"
"42.02700","-146.58835","-0.27303"
"42.09500","-146.58835","-0.25649"
"42.15600","-146.58835","-0.24566"
"42.23200","-146.58835","-0.24686"
"42.31200","-146.58835","-0.22170"
"42.37300","-146.58835","-0.21406"
"42.43200","-146.58835","-0.21468"
"42.49400","-146.58835","-0.18553"
"42.54800","-146.58835","-0.18543"
"42.62800","-146.58835","-0.18105"
"42.71000","-146.58835","-0.14861"
"42.77400","-146.58835","-0.16188"
"42.84400","-146.58835","-0.15970"
"42.90300","-146.58835","-0.13233"
"42.95900","-146.58835","-0.11557"
"43.02900","-146.58835","-0.12621"
"43.07700","-146.58835","-0.11077"
"43.15600","-146.58835","-0.11119"
"43.19700","-146.58835","-0.10926"
"43.26700","-146.58835","-0.09289"
"43.33400","-146.58835","-0.06873"
"43.38800","-146.58835","-0.11747"
"43.44500","-146.58835","-0.11958"
"43.49900","-146.58835","-0.09289"
"43.55000","-146.58835","-0.09189"
"43.60000","-146.58835","-0.09260"
"43.65800","-146.58835","-0.08590"
"43.70000","-146.58835","-0.07420"
"43.76600","-146.58835","-0.09481"
"43.83800","-146.58835","-0.07336"
"43.89900","-146.58835","-0.08186"
"43.98300","-146.58835","-0.08483"
"44.02900","-146.58835","-0.06934"
"44.10100","-146.58835","-0.06937"
"44.15500","-146.58835","-0.08756"
"44.22100","-146.58835","-0.08157"
"44.30000","-146.58835","-0.05911"
"44.35600","-146.58835","-0.07491"
"44.41400","-146.58835","-0.06999"
"44.47700","-146.58835","-0.07094"
"44.54400","-146.58835","-0.07977"
"44.60600","-146.58835","-0.06382"
"44.67500","-146.58835","-0.05450"
"44.73900","-146.58835","-0.06226"
"44.80600","-146.58835","-0.05960"
"44.87200","-146.58835","-0.05055"
"44.92700","-146.58835","-0.05675"
"44.99900","-146.58835","-0.08393"
"45.05900","-146.58835","-0.06413"
"45.13000","-146.58835","-0.04540"
"45.19300","-146.58835","-0.06119"
"45.25800","-146.58835","-0.08169"
"45.32100","-146.58835","-0.05522"
"45.38100","-146.58835","-0.05705"
"45.44400","-146.58835","-0.07062"
"45.50600","-146.58835","-0.06766"
"45.57200","-146.58835","-0.05153"
"45.63600","-146.58835","-0.05856"
"45.68700","-146.58835","-0.07502"
"45.74400","-146.58835","-0.07135"
"45.80400","-146.58835","-0.07125"
"45.85800","-146.58835","-0.04244"
"45.92500","-146.58835","-0.07537"
"45.98400","-146.58835","-0.07722"
"46.05200","-146.58835","-0.06302"
"46.11500","-146.58835","-0.05493"
"46.18500","-146.58835","-0.05788"
"46.23500","-146.58835","-0.07863"
"46.28000","-146.58835","-0.05668"
"46.34100","-146.58835","-0.06210"
"46.39200","-146.58835","-0.05505"
"46.47600","-146.58835","-0.06748"
"46.53900","-146.58835","-0.05525"
"46.59400","-146.58835","-0.05780"
"46.63900","-146.58835","-0.05208"
"46.71600","-146.58835","-0.05502"
"46.76600","-146.58835","-0.05211"
"46.83100","-146.58835","-0.04252"
"46.90300","-146.58835","-0.05358"
"46.96900","-146.58835","-0.06346"
"47.03800","-146.58835","-0.05148"
"47.12400","-146.58835","-0.05759"
"47.19200","-146.58835","-0.04802"
"47.24700","-146.58835","-0.03666"
"47.31400","-146.58835","-0.05473"
"47.36900","-146.58835","-0.04719"
"47.43200","-146.58835","-0.08172"
"47.50100","-146.58835","-0.04139"
"47.54800","-146.58835","-0.04617"
"47.62500","-146.58835","-0.06010"
"47.70000","-146.58835","-0.04888"
"47.77200","-146.58835","-0.05644"
"47.80400","-146.58835","-0.05322"
"47.86400","-146.58835","-0.05830"
"47.91800","-146.58835","-0.04459"
"47.99300","-146.58835","-0.05174"
"48.06100","-146.58835","-0.06623"
"48.13000","-146.58835","-0.05517"
"48.20700","-146.58835","-0.03458"
"48.28400","-146.58835","-0.05539"
"48.35300","-146.58835","-0.06174"
"48.42900","-146.58835","-0.05291"
"48.51000","-146.58835","-0.05264"
"48.56300","-146.58835","-0.07334"
"48.62600","-146.58835","-0.05108"
"48.69700","-146.58835","-0.04237"
"48.76900","-146.58835","-0.05037"
"48.81000","-146.58835","-0.05581"
"48.87100","-146.58835","-0.06225"
"48.95000","-146.58835","-0.04003"
"49.00700","-146.58835","-0.04193"
"49.06800","-146.58835","-0.04893"
"49.15400","-146.58835","-0.04307"
"49.21700","-146.58835","-0.07021"
"49.26800","-146.58835","-0.05647"
"49.33900","-146.58835","-0.07348"
"49.41000","-146.58835","-0.05045"
"49.45700","-146.58835","-0.05407"
"49.51600","-146.58835","-0.05720"
"49.59100","-146.58835","-0.05369"
"49.66800","-146.58835","-0.05082"
"49.74000","-146.58835","-0.04903"
"49.81800","-146.58835","-0.06712"
"49.88000","-146.58835","-0.05030"
"49.94500","-146.58835","-0.04791"
"50.01000","-146.58835","-0.06653"
"50.05800","-146.58835","-0.06305"
"50.12400","-146.58835","-0.03956"
"50.18800","-146.58835","-0.06135"
"50.25500","-146.58835","-0.04610"
"50.31800","-146.58835","-0.04139"
"50.37600","-146.58835","-0.04068"
"50.44800","-146.58835","-0.05105"
"50.51400","-146.58835","-0.06690"
"50.57900","-146.58835","-0.04488"
"50.64100","-146.58835","-0.03552"
"50.68100","-146.58835","-0.05073"
"50.74500","-146.58835","-0.04692"
"50.81200","-146.58835","-0.05791"
"50.86800","-146.58835","-0.05414"
"50.92000","-146.58835","-0.05516"
"50.99100","-146.58835","-0.05589"
"51.05700","-146.58835","-0.04398"
"51.12200","-146.58835","-0.04728"
"51.17300","-146.58835","-0.15423"
"51.22600","-146.58835","-0.28478"
"51.27000","-146.58835","-0.45198"
"51.29900","-146.58835","-0.56327"
"51.35600","-146.58835","-0.57070"
"51.39800","-146.58835","-0.54100"
"51.46400","-146.58835","-0.53014"
"51.55000","-146.58835","-0.52678"
"51.61200","-146.58835","-0.50129"
"51.68000","-146.58835","-0.48806"
"51.73200","-146.58835","-0.46918"
"51.80900","-146.58835","-0.47995"
"51.86500","-146.58835","-0.44211"
"51.93900","-146.58835","-0.41972"
"51.99200","-146.58835","-0.41891"
"52.05500","-146.58835","-0.38915"
"52.09700","-146.58835","-0.40748"
"52.15900","-146.58835","-0.39667"
"52.21900","-146.58835","-0.37712"
"52.28300","-146.58835","-0.35873"
"52.35800","-146.58835","-0.34170"
"52.42500","-146.58835","-0.29539"
"52.49500","-146.58835","-0.27104"
"52.57000","-146.58835","-0.26067"
"52.64500","-146.58835","-0.26113"
"52.69700","-146.58835","-0.25791"
"52.75500","-146.58835","-0.24080"
"52.81800","-146.58835","-0.21337"
"52.88000","-146.58835","-0.19775"
"52.94700","-146.58835","-0.21750"
"53.00800","-146.58835","-0.20087"
"53.06500","-146.58835","-0.19785"
"53.12600","-146.58835","-0.17877"
"53.20300","-146.58835","-0.17631"
"53.25900","-146.58835","-0.18319"
"53.32300","-146.58835","-0.17023"
"53.39200","-146.58835","-0.17725"
"53.44800","-146.58835","-0.15485"
"53.50700","-146.58835","-0.14495"
"53.57700","-146.58835","-0.14888"
"53.64000","-146.58835","-0.14476"
"53.71100","-146.58835","-0.15813"
"53.79300","-146.58835","-0.12739"
"53.86200","-146.58835","-0.11423"
"53.93500","-146.58835","-0.12591"
"53.98200","-146.58835","-0.12736"
"54.05900","-146.58835","-0.10792"
"54.11000","-146.58835","-0.12656"
"54.17100","-146.58835","-0.13787"
"54.21900","-146.58835","-0.13708"
"54.27000","-146.58835","-0.10980"
"54.34500","-146.58835","-0.12064"
"54.39700","-146.58835","-0.12939"
"54.48100","-146.58835","-0.13255"
"54.53400","-146.58835","-0.11544"
"54.59500","-146.58835","-0.11545"
"54.65100","-146.58835","-0.10821"
"54.71600","-146.58835","-0.09090"
"54.79200","-146.58835","-0.08359"
"54.87000","-146.58835","-0.08425"
"54.93000","-146.58835","-0.08426"
"54.99500","-146.58835","-0.08148"
"55.03500","-146.58835","-0.08868"
"55.09700","-146.58835","-0.10549"
"55.16100","-146.58835","-0.09949"
"55.22900","-146.58835","-0.08930"
"55.28300","-146.58835","-0.07384"
"55.35800","-146.58835","-0.08807"
"55.44800","-146.58835","-0.07000"
"55.51900","-146.58835","-0.09043"
"55.56300","-146.58835","-0.08874"
"55.62100","-146.58835","-0.08427"
"55.70200","-146.58835","-0.07334"
"55.77800","-146.58835","-0.09495"
"55.84800","-146.58835","-0.07848"
"55.92500","-146.58835","-0.06807"
"55.98000","-146.58835","-0.06661"
"56.03600","-146.58835","-0.08234"
"56.10800","-146.58835","-0.08939"
"56.17300","-146.58835","-0.07431"
"56.23200","-146.58835","-0.08058"
"56.30300","-146.58835","-0.07400"
"56.38800","-146.58835","-0.06910"
"56.46500","-146.58835","-0.08304"
"56.54100","-146.58835","-0.06163"
"56.59000","-146.58835","-0.06039"
"56.65200","-146.58835","-0.08476"
"56.72100","-146.58835","-0.07369"
"56.78700","-146.58835","-0.08728"
"56.85600","-146.58835","-0.07835"
"56.93400","-146.58835","-0.06976"
"57.01500","-146.58835","-0.09205"
"57.09000","-146.58835","-0.06139"
"57.12600","-146.58835","-0.08408"
"57.19300","-146.58835","-0.08500"
"57.25200","-146.58835","-0.07164"
"57.32000","-146.58835","-0.07269"
"57.39100","-146.58835","-0.07276"
"57.45900","-146.58835","-0.07152"
"57.49800","-146.58835","-0.06185"
"57.55800","-146.58835","-0.06685"
"57.61300","-146.58835","-0.07134"
"57.67700","-146.58835","-0.07972"
"57.73200","-146.58835","-0.07682"
"57.79200","-146.58835","-0.07795"
"57.84700","-146.58835","-0.07041"
"57.88700","-146.58835","-0.05652"
"57.93500","-146.58835","-0.07159"
"58.00100","-146.58835","-0.06309"
"58.06800","-146.58835","-0.06990"
"58.13900","-146.58835","-0.07546"
"58.19900","-146.58835","-0.08438"
"58.25300","-146.58835","-0.05668"
"58.31700","-146.58835","-0.06854"
"58.39700","-146.58835","-0.06853"
"58.43300","-146.58835","-0.06874"
"58.50600","-146.58835","-0.06539"
"58.57100","-146.58835","-0.08157"
"58.64800","-146.58835","-0.05547"
"58.70500","-146.58835","-0.06002"
"58.78100","-146.58835","-0.06499"
"58.83700","-146.58835","-0.06411"
"58.90300","-146.58835","-0.05198"
"58.97500","-146.58835","-0.05364"
"59.04100","-146.58835","-0.07302"
"59.09300","-146.58835","-0.06507"
"59.15100","-146.58835","-0.06452"
"59.21500","-146.58835","-0.05537"
"59.27400","-146.58835","-0.04469"
"59.33300","-146.58835","-0.06000"
"59.39600","-146.58835","-0.07183"
"59.47000","-146.58835","-0.07761"
"59.51800","-146.58835","-0.06816"
"59.56600","-146.58835","-0.07153"
"59.64600","-146.58835","-0.05659"
"59.69500","-146.58835","-0.05726"
"59.74400","-146.58835","-0.05604"
"59.79100","-146.58835","-0.04232"
"59.84000","-146.58835","-0.05354"
"59.90300","-146.58835","-0.06290"
"59.95100","-146.58835","-0.07833"
"60.00600","-146.58835","-0.05399"
"60.04000","-146.58835","-0.03773"
"60.09200","-146.58835","-0.11525"
"60.15200","-146.58835","-0.27018"
"60.18700","-146.58835","-0.43094"
"60.23100","-146.58835","-0.60635"
"60.27800","-146.58835","-0.73840"
"60.32800","-146.58835","-0.84785"
"60.40000","-146.58835","-0.81955"
"60.46400","-146.58835","-0.83082"
"60.51300","-146.58835","-0.80763"
"60.59200","-146.58835","-0.78700"
"60.65800","-146.58835","-0.76742"
"60.71700","-146.58835","-0.75469"
"60.78300","-146.58835","-0.71963"
"60.83800","-146.58835","-0.71461"
"60.90100","-146.58835","-0.67248"
"60.96800","-146.58835","-0.66543"
"61.05000","-146.58835","-0.63540"
"61.12200","-146.58835","-0.62437"
"61.18600","-146.58835","-0.59281"
"61.24700","-146.58835","-0.60274"
"61.29500","-146.58835","-0.55990"
"61.37800","-146.58835","-0.55518"
"61.43500","-146.58835","-0.54091"
"61.51600","-146.58835","-0.52398"
"61.57900","-146.58835","-0.51283"
"61.62500","-146.58835","-0.49454"
"61.68800","-146.58835","-0.48156"
"61.76600","-146.58835","-0.46478"
"61.84000","-146.58835","-0.44719"
"61.91100","-146.58835","-0.42688"
"61.97700","-146.58835","-0.43885"
"62.03900","-146.58835","-0.42309"
"62.10900","-146.58835","-0.41380"
"62.19100","-146.58835","-0.41093"
"62.24300","-146.58835","-0.39756"
"62.31800","-146.58835","-0.38128"
"62.36000","-146.58835","-0.39718"
"62.42100","-146.58835","-0.38673"
"62.49000","-146.58835","-0.36558"
"62.55000","-146.58835","-0.37887"
"62.60500","-146.58835","-0.37564"
"62.67400","-146.58835","-0.35246"
"62.74400","-146.58835","-0.37857"
"62.80100","-146.58835","-0.36305"
"62.88700","-146.58835","-0.33861"
"62.96500","-146.58835","-0.34065"
"63.05000","-146.58835","-0.32842"
"63.11500","-146.58835","-0.34085"
"63.18600","-146.58835","-0.32820"
"63.25800","-146.58835","-0.33576"
"63.30500","-146.58835","-0.32073"
"63.37200","-146.58835","-0.31418"
"63.42900","-146.58835","-0.32906"
"63.48900","-146.58835","-0.31958"
"63.55400","-146.58835","-0.29033"
"63.61700","-146.58835","-0.30316"
"63.67900","-146.58835","-0.30566"
"63.73500","-146.58835","-0.28539"
"63.79100","-146.58835","-0.30036"
"63.85200","-146.58835","-0.29797"
"63.91400","-146.58835","-0.28266"
"63.98500","-146.58835","-0.27805"
"64.03800","-146.58835","-0.30304"
"64.09900","-146.58835","-0.29942"
"64.14600","-146.58835","-0.27972"
"64.20700","-146.58835","-0.28941"
"64.28700","-146.58835","-0.27424"
"64.36800","-146.58835","-0.27416"
"64.44400","-146.58835","-0.29125"
"64.50200","-146.58835","-0.28842"
"64.56100","-146.58835","-0.27202"
"64.63100","-146.58835","-0.27617"
"64.68600","-146.58835","-0.27657"
"64.74500","-146.58835","-0.28420"
"64.80700","-146.58835","-0.27888"
"64.86000","-146.58835","-0.27361"
"64.90200","-146.58835","-0.27856"
"64.94600","-146.58835","-0.26546"
"65.00400","-146.58835","-0.26066"
"65.05500","-146.58835","-0.26249"
"65.12300","-146.58835","-0.26453"
"65.17800","-146.58835","-0.27618"
"65.25200","-146.58835","-0.28602"
"65.30900","-146.58835","-0.26786"
"65.39600","-146.58835","-0.25363"
"65.46300","-146.58835","-0.24689"
"65.52600","-146.58835","-0.26732"
"65.58400","-146.58835","-0.26989"
"65.65600","-146.58835","-0.26026"
"65.73600","-146.58835","-0.26013"
"65.78000","-146.58835","-0.27151"
"65.86100","-146.58835","-0.25805"
"65.93200","-146.58835","-0.25546"
"65.98800","-146.58835","-0.25892"
"66.03200","-146.58835","-0.26112"
"66.10700","-146.58835","-0.25908"
"66.16600","-146.58835","-0.25953"
"66.21500","-146.58835","-0.25213"
"66.28900","-146.58835","-0.23713"
"66.34500","-146.58835","-0.24320"
"66.40400","-146.58835","-0.26522"
"66.47100","-146.58835","-0.23400"
"66.52800","-146.58835","-0.24943"
"66.58500","-146.58835","-0.23654"
"66.64800","-146.58835","-0.24069"
"66.69700","-146.58835","-0.23700"
"66.76200","-146.58835","-0.25600"
"66.84400","-146.58835","-0.26285"
"66.90400","-146.58835","-0.23745"
"66.97000","-146.58835","-0.22815"
"67.02100","-146.58835","-0.24166"
"67.08400","-146.58835","-0.25141"
"67.17200","-146.58835","-0.25695"
"67.23700","-146.58835","-0.23896"
"67.31300","-146.58835","-0.24005"
"67.39300","-146.58835","-0.24868"
"67.46100","-146.58835","-0.22283"
"67.54800","-146.58835","-0.24370"
"67.61800","-146.58835","-0.23828"
"67.68200","-146.58835","-0.22774"
"67.73300","-146.58835","-0.23561"
"67.81300","-146.58835","-0.23377"
"67.88900","-146.58835","-0.23830"
"67.94900","-146.58835","-0.24369"
"67.99500","-146.58835","-0.23243"
"68.06100","-146.58835","-0.24050"
"68.13200","-146.58835","-0.23281"
"68.20600","-146.58835","-0.23496"
"68.29000","-146.58835","-0.21451"
"68.36500","-146.58835","-0.23140"
"68.43600","-146.58835","-0.22914"
"68.49900","-146.58835","-0.24403"
"68.56100","-146.58835","-0.24645"
"68.61900","-146.58835","-0.23431"
"68.66700","-146.58835","-0.23916"
"68.74100","-146.58835","-0.22922"
"68.78900","-146.58835","-0.23928"
"68.84800","-146.58835","-0.22940"
"68.89900","-146.58835","-0.23641"
"68.95800","-146.58835","-0.22322"
"69.04500","-146.58835","-0.23151"
"69.10900","-146.58835","-0.22431"
"69.17100","-146.58835","-0.23038"
"69.25400","-146.58835","-0.23145"
"69.32900","-146.58835","-0.23210"
"69.37500","-146.58835","-0.23178"
"69.43900","-146.58835","-0.22665"
"69.50600","-146.58835","-0.21135"
"69.57800","-146.58835","-0.22877"
"69.65200","-146.58835","-0.22298"
"69.71700","-146.58835","-0.22250"
"69.78100","-146.58835","-0.21495"
"69.83700","-146.58835","-0.21178"
"69.89900","-146.58835","-0.20652"
"69.95900","-146.58835","-0.20481"
"70.02000","-146.58835","-0.21553"
"70.07700","-146.58835","-0.21057"
"70.14200","-146.58835","-0.21980"
"70.20800","-146.58835","-0.21710"
"70.28900","-146.58835","-0.23819"
"70.34700","-146.58835","-0.23221"
"70.40700","-146.58835","-0.22663"
"70.48700","-146.58835","-0.21982"
"70.54700","-146.58835","-0.22096"
"70.61200","-146.58835","-0.21191"
"70.69500","-146.58835","-0.21881"
"70.76000","-146.58835","-0.22061"
"70.81900","-146.58835","-0.22752"
"70.90000","-146.58835","-0.22144"
"70.97300","-146.58835","-0.21338"
"71.00800","-146.58835","-0.21448"
"71.06200","-146.58835","-0.22642"
"71.10400","-146.58835","-0.22188"
"71.16800","-146.58835","-0.21911"
"71.24800","-146.58835","-0.22621"
"71.30900","-146.58835","-0.22137"
"71.38000","-146.58835","-0.21841"
"71.44100","-146.58835","-0.20810"
"71.50400","-146.58835","-0.20704"
"71.56000","-146.58835","-0.22594"
"71.60700","-146.58835","-0.22475"
"71.70500","-146.58835","-0.20761"
"71.78000","-146.58835","-0.21355"
"71.85800","-146.58835","-0.20724"
"71.92400","-146.58835","-0.21336"
"71.99400","-146.58835","-0.21836"
"72.04700","-146.58835","-0.20835"
"72.10500","-146.58835","-0.20978"
"72.16900","-146.58835","-0.19786"
"72.23000","-146.58835","-0.20904"
"72.28900","-146.58835","-0.20749"
"72.35600","-146.58835","-0.21086"
"72.41600","-146.58835","-0.19811"
"72.49300","-146.58835","-0.20791"
"72.56900","-146.58835","-0.20175"
"72.65200","-146.58835","-0.21492"
"72.72100","-146.58835","-0.21775"
"72.78600","-146.58835","-0.20279"
"72.84400","-146.58835","-0.24613"
"72.90400","-146.58835","-0.35445"
"72.97100","-146.58835","-0.37474"
"73.01100","-146.58835","-0.50179"
"73.05000","-146.58835","-0.66254"
"73.11400","-146.58835","-0.61774"
"73.13600","-146.58835","-0.49659"
"73.14900","-146.58835","-0.75383"
"73.17700","-146.58835","-0.87501"
"73.19300","-146.58835","-0.71177"
"73.20500","-146.58835","-0.45234"
"73.21700","-146.58835","-0.19189"
"73.24400","-146.58835","-0.00646"
"73.30000","-146.58835","0.00612"
"73.35800","-146.58835","-0.10854"
"73.43800","-146.58835","0.00452"
"73.52100","-146.58835","0.02829"
"73.58700","-146.58835","-0.08455"
"73.63600","-146.58835","-0.10538"
"73.68900","-146.58835","-0.12876"
"73.75100","-146.58835","-0.11604"
"73.82700","-146.58835","-0.09975"
"73.89500","-146.58835","-0.06638"
"73.96800","-146.58835","-0.06484"
"74.02200","-146.58835","-0.09129"
"74.08600","-146.58835","-0.06597"
"74.15100","-146.58835","-0.09597"
"74.21500","-146.58835","-0.09342"
"74.28700","-146.58835","-0.10528"
"74.35900","-146.58835","-0.09398"
"74.38400","-146.58835","-0.15993"
"74.40800","-146.58835","-0.32423"
"74.45100","-146.58835","-0.22995"
"74.51700","-146.58835","-0.34078"
"74.58900","-146.58835","-0.35465"
"74.64500","-146.58835","-0.41419"
"74.68700","-146.58835","-0.58503"
"74.70800","-146.58835","-0.78432"
"74.72900","-146.58835","-0.98069"
"74.74300","-146.58835","-1.19538"
"74.75500","-146.58835","-1.41448"
"74.77000","-146.58835","-1.61142"
"74.78600","-146.58835","-1.84896"
"74.80400","-146.58835","-1.76066"
"74.81600","-146.58835","-1.32511"
"74.82800","-146.58835","-0.89761"
"74.84000","-146.58835","-0.53184"
"74.89500","-146.58835","-0.48240"
"74.95100","-146.58835","-0.53098"
"75.01300","-146.58835","-0.48190"
"75.07400","-146.58835","-0.47359"
"75.12500","-146.58835","-0.57602"
"75.16000","-146.58835","-0.43563"
"75.18900","-146.58835","-0.46534"
"75.24300","-146.58835","-0.56811"
"75.27200","-146.58835","-0.73957"
"75.29800","-146.58835","-0.91080"
"75.34100","-146.58835","-0.80628"
"75.38700","-146.58835","-0.77561"
"75.41400","-146.58835","-0.92516"
"75.43500","-146.58835","-1.10732"
"75.45200","-146.58835","-1.29703"
"75.47400","-146.58835","-1.04512"
"75.49000","-146.58835","-0.81220"
"75.52000","-146.58835","-0.86653"
"75.53400","-146.58835","-1.08196"
"75.57800","-146.58835","-1.02290"
"75.62700","-146.58835","-1.15036"
"75.68100","-146.58835","-1.11685"
"75.73400","-146.58835","-1.02816"
"75.76500","-146.58835","-0.94527"
"75.78800","-146.58835","-0.79834"
"75.80900","-146.58835","-0.62165"
"75.85400","-146.58835","-0.57949"
"75.88900","-146.58835","-0.42897"
"75.95800","-146.58835","-0.42077"
"76.00900","-146.58835","-0.36862"
"76.07400","-146.58835","-0.40477"
"76.14100","-146.58835","-0.39992"
"76.19500","-146.58835","-0.42005"
"76.21000","-146.58835","-0.60258"
"76.23000","-146.58835","-0.81887"
"76.27100","-146.58835","-0.70881"
"76.28600","-146.58835","-0.49978"
"76.31800","-146.58835","-0.34892"
"76.39100","-146.58835","-0.26755"
"76.47200","-146.58835","-0.26706"
"76.54400","-146.58835","-0.29226"
"76.60600","-146.58835","-0.33709"
"76.67400","-146.58835","-0.34717"
"76.74500","-146.58835","-0.42173"
"76.82400","-146.58835","-0.40912"
"76.87700","-146.58835","-0.52411"
"76.92300","-146.58835","-0.44842"
"76.97300","-146.58835","-0.53197"
"76.99800","-146.58835","-0.67877"
"77.02100","-146.58835","-0.84838"
"77.05600","-146.58835","-0.92939"
"77.07300","-146.58835","-0.85837"
"77.08700","-146.58835","-0.64818"
"77.13000","-146.58835","-0.73202"
"77.14600","-146.58835","-0.88443"
"77.16300","-146.58835","-1.09167"
"77.19200","-146.58835","-0.99686"
"77.22100","-146.58835","-0.82518"
"77.25600","-146.58835","-0.68865"
"77.30300","-146.58835","-0.64003"
"77.33900","-146.58835","-1.00379"
"77.35900","-146.58835","-0.76317"
"77.41000","-146.58835","-0.75283"
"77.46700","-146.58835","-0.73598"
"77.51400","-146.58835","-0.72983"
"77.56600","-146.58835","-0.71470"
"77.63400","-146.58835","-0.71542"
"77.71000","-146.58835","-0.70216"
"77.79100","-146.58835","-0.69034"
"77.86300","-146.58835","-0.68558"
"77.92300","-146.58835","-0.69988"
"77.98700","-146.58835","-0.67559"
"78.05800","-146.58835","-0.66817"
"78.10900","-146.58835","-0.67006"
"78.19000","-146.58835","-0.66954"
"78.24600","-146.58835","-0.66719"
"78.30500","-146.58835","-0.67387"
"78.37700","-146.58835","-0.68773"
"78.44300","-146.58835","-0.66558"
"78.52200","-146.58835","-0.66461"
"78.61000","-146.58835","-0.65239"
"78.67300","-146.58835","-0.66739"
"78.75100","-146.58835","-0.65852"
"78.81500","-146.58835","-0.64567"
"78.90600","-146.58835","-0.66123"
"78.97100","-146.58835","-0.64976"
"79.02600","-146.58835","-0.66556"
"79.08800","-146.58835","-0.64884"
"79.16600","-146.58835","-0.63800"
"79.23200","-146.58835","-0.64350"
"79.30800","-146.58835","-0.65039"
"79.37600","-146.58835","-0.65205"
"79.43700","-146.58835","-0.65057"
"79.50900","-146.58835","-0.65877"
"79.56800","-146.58835","-0.65097"
"79.64600","-146.58835","-0.63122"
"79.71000","-146.58835","-0.64878"
"79.77900","-146.58835","-0.62816"
"79.83400","-146.58835","-0.62894"
"79.90200","-146.58835","-0.64957"
"79.97400","-146.58835","-0.64721"
"80.04600","-146.58835","-0.64692"
"80.10300","-146.58835","-0.62479"
"80.16100","-146.58835","-0.63092"
"80.22800","-146.58835","-0.64489"
"80.28200","-146.58835","-0.63727"
"80.35000","-146.58835","-0.63258"
"80.42100","-146.58835","-0.64297"
"80.48500","-146.58835","-0.63053"
"80.53900","-146.58835","-0.65410"
"80.60500","-146.58835","-0.63279"
"80.66100","-146.58835","-0.65406"
"80.70600","-146.58835","-0.64856"
"80.76100","-146.58835","-0.62549"
"80.82700","-146.58835","-0.62979"
"80.89100","-146.58835","-0.63264"
"80.96500","-146.58835","-0.62982"
"81.01800","-146.58835","-0.64196"
"81.08900","-146.58835","-0.63546"
"81.15600","-146.58835","-0.61660"
"81.21600","-146.58835","-0.63430"
"81.28400","-146.58835","-0.64570"
"81.34800","-146.58835","-0.64087"
"81.41500","-146.58835","-0.63114"
"81.48700","-146.58835","-0.63572"
"81.55900","-146.58835","-0.63358"
"81.61800","-146.58835","-0.63527"
"81.69200","-146.58835","-0.63646"
"81.75700","-146.58835","-0.60849"
"81.82000","-146.58835","-0.61646"
"81.88500","-146.58835","-0.64702"
"81.92800","-146.58835","-0.62982"
"81.99600","-146.58835","-0.62722"
"82.05500","-146.58835","-0.61724"
"82.11100","-146.58835","-0.63021"
"82.17800","-146.58835","-0.62425"
"82.25000","-146.58835","-0.61950"
"82.32800","-146.58835","-0.63230"
"82.39400","-146.58835","-0.62163"
"82.45600","-146.58835","-0.61934"
"82.52500","-146.58835","-0.62568"
"82.60000","-146.58835","-0.62984"
"82.67900","-146.58835","-0.61911"
"82.74300","-146.58835","-0.60237"
"82.79600","-146.58835","-0.62584"
"82.86900","-146.58835","-0.64079"
"82.91200","-146.58835","-0.62961"
"82.96300","-146.58835","-0.62108"
"83.03400","-146.58835","-0.61796"
"83.10200","-146.58835","-0.61121"
"83.17300","-146.58835","-0.61947"
"83.18500","-146.58835","-0.62778"