File: chapter 4/force/mini_patrick.is_tens_RawData/Specimen_RawData_9.csv
Time,Extension,Load
(s),(mm),(N)
"0.00000","-155.25151","0.01159"
"0.04200","-155.25150","0.00262"
"0.09700","-155.25150","0.00850"
"0.14600","-155.25150","-0.00009"
"0.19200","-155.25150","-0.00232"
"0.24000","-155.25150","0.00406"
"0.28300","-155.25150","-0.01178"
"0.32600","-155.25150","-0.00865"
"0.37100","-155.25150","0.00155"
"0.43100","-155.25150","0.00540"
"0.47700","-155.25150","-0.00268"
"0.53700","-155.25150","-0.00250"
"0.58700","-155.25150","-0.00399"
"0.64300","-155.25150","-0.00412"
"0.67600","-155.25150","-0.01545"
"0.70500","-155.25150","-0.00652"
"0.75200","-155.25150","0.00478"
"0.81600","-155.25150","0.01224"
"0.87500","-155.25150","-0.00010"
"0.91100","-155.25150","0.01003"
"0.95500","-155.25150","-0.00139"
"0.98900","-155.25150","0.00034"
"1.03400","-155.25150","-0.00519"
"1.08200","-155.25150","0.00695"
"1.11200","-155.25150","-0.01193"
"1.14100","-155.25150","-0.01291"
"1.18600","-155.25150","0.01397"
"1.22700","-155.25150","0.00338"
"1.28100","-155.25150","-0.00180"
"1.32500","-155.25150","-0.00022"
"1.37100","-155.25150","0.00961"
"1.41700","-155.25150","-0.00231"
"1.47500","-155.25150","-0.00801"
"1.51900","-155.25150","-0.00293"
"1.55300","-155.25150","-0.00665"
"1.60200","-155.25150","-0.00097"
"1.64700","-155.25150","0.00102"
"1.68500","-155.25150","0.00097"
"1.72100","-155.25150","-0.01985"
"1.76600","-155.25150","0.00999"
"1.79900","-155.25150","0.01524"
"1.82600","-155.25150","-0.01100"
"1.88200","-155.25150","0.00047"
"1.94000","-155.25150","0.00435"
"1.98700","-155.25150","-0.01886"
"2.02900","-155.25150","-0.00914"
"2.08100","-155.25150","-0.01126"
"2.12300","-155.25150","0.00337"
"2.16600","-155.25150","-0.02216"
"2.21300","-155.25150","-0.03171"
"2.26100","-155.25150","-0.02736"
"2.31200","-155.25150","-0.02662"
"2.36900","-155.25150","-0.02678"
"2.41000","-155.25150","-0.04385"
"2.45600","-155.25150","-0.01660"
"2.48300","-155.25150","-0.01617"
"2.53200","-155.25150","-0.01975"
"2.55900","-155.25150","-0.01490"
"2.59000","-155.25150","-0.01385"
"2.62200","-155.25150","-0.00905"
"2.66900","-155.25150","-0.00725"
"2.71800","-155.25150","-0.01031"
"2.75700","-155.25150","-0.01144"
"2.79800","-155.25150","-0.03415"
"2.84000","-155.25150","-0.00681"
"2.86200","-155.25150","-0.01120"
"2.90100","-155.25150","-0.01517"
"2.93600","-155.25150","-0.01374"
"2.99200","-155.25150","-0.00939"
"3.03700","-155.25150","-0.00764"
"3.07600","-155.25150","-0.01544"
"3.12200","-155.25150","-0.02279"
"3.15700","-155.25150","0.00501"
"3.19900","-155.25150","0.00490"
"3.23100","-155.25150","-0.00816"
"3.28900","-155.25150","-0.01769"
"3.33300","-155.25150","-0.02267"
"3.37300","-155.25150","-0.00155"
"3.40200","-155.25150","-0.01306"
"3.44300","-155.25150","-0.00451"
"3.48400","-155.25150","-0.01864"
"3.52200","-155.25150","-0.00436"
"3.57100","-155.25150","-0.01908"
"3.62000","-155.25150","-0.00583"
"3.65500","-155.25150","-0.01112"
"3.71200","-155.25150","-0.00893"
"3.76100","-155.25150","-0.00140"
"3.80900","-155.25150","-0.02132"
"3.85200","-155.25150","-0.00105"
"3.90300","-155.25150","-0.01081"
"3.95100","-155.25150","0.00739"
"3.98900","-155.25150","-0.00276"
"4.04000","-155.25150","-0.00593"
"4.08700","-155.25150","-0.01121"
"4.12000","-155.25150","-0.00186"
"4.16900","-155.25150","0.00629"
"4.22600","-155.25150","-0.01867"
"4.27000","-155.25150","-0.01500"
"4.31300","-155.25150","-0.00650"
"4.36200","-155.25150","-0.01883"
"4.41300","-155.25150","-0.01016"
"4.46600","-155.25150","-0.01586"
"4.50500","-155.25150","-0.00963"
"4.55400","-155.25150","0.00435"
"4.60500","-155.25150","0.00015"
"4.64700","-155.25150","0.00625"
"4.69800","-155.25150","0.00789"
"4.75400","-155.25150","0.00286"
"4.80100","-155.25150","0.00160"
"4.85700","-155.25150","-0.00085"
"4.89800","-155.25150","0.00524"
"4.93300","-155.25150","-0.02711"
"4.98100","-155.25150","-0.00731"
"5.02600","-155.25150","-0.00332"
"5.06500","-155.25150","0.00218"
"5.10700","-155.25150","0.00658"
"5.13600","-155.25150","-0.00198"
"5.17900","-155.25150","0.00495"
"5.21100","-155.25150","-0.01169"
"5.26000","-155.25150","-0.01120"
"5.30000","-155.25150","-0.00662"
"5.35600","-155.25150","-0.00289"
"5.39400","-155.25150","0.00039"
"5.43700","-155.25150","0.00194"
"5.46900","-155.25150","0.00214"
"5.52800","-155.25150","-0.01006"
"5.55800","-155.25150","0.00565"
"5.59200","-155.25150","-0.00898"
"5.63800","-155.25150","-0.01432"
"5.67300","-155.25150","-0.02238"
"5.70700","-155.25150","0.01478"
"5.75800","-155.25150","-0.00083"
"5.80700","-155.25150","-0.00294"
"5.84600","-155.25150","-0.01398"
"5.88700","-155.25150","-0.01945"
"5.92200","-155.25150","-0.00057"
"5.96500","-155.25150","-0.00396"
"6.01900","-155.25150","0.00486"
"6.07500","-155.25150","0.00009"
"6.11700","-155.25150","0.00795"
"6.15800","-155.25150","-0.00246"
"6.19600","-155.25150","0.01155"
"6.23300","-155.25150","-0.01019"
"6.25200","-155.25150","-0.04377"
"6.30400","-155.25150","-0.10192"
"6.34000","-155.25150","-0.08816"
"6.38700","-155.25150","-0.08021"
"6.43600","-155.25150","-0.08147"
"6.48900","-155.25150","-0.08114"
"6.54700","-155.25150","-0.05642"
"6.60000","-155.25150","-0.06221"
"6.63400","-155.25150","-0.07329"
"6.68700","-155.25150","-0.07577"
"6.72200","-155.25150","-0.05316"
"6.75000","-155.25150","-0.05054"
"6.78600","-155.25150","-0.05297"
"6.84200","-155.25150","-0.04245"
"6.86900","-155.25150","-0.04428"
"6.92600","-155.25150","-0.04591"
"6.97800","-155.25150","-0.05705"
"7.02300","-155.25150","-0.04236"
"7.05100","-155.25150","-0.04608"
"7.09900","-155.25150","-0.05936"
"7.12500","-155.25150","-0.04116"
"7.17600","-155.25150","-0.04076"
"7.22300","-155.25150","-0.02304"
"7.26400","-155.25150","-0.03150"
"7.30700","-155.25150","-0.03932"
"7.35700","-155.25150","-0.03948"
"7.39800","-155.25150","-0.04101"
"7.45700","-155.25150","-0.05324"
"7.51100","-155.25150","-0.03841"
"7.54700","-155.25150","-0.01668"
"7.58200","-155.25150","-0.01434"
"7.61600","-155.25150","-0.03027"
"7.65500","-155.25150","-0.03500"
"7.71100","-155.25150","-0.02250"
"7.76200","-155.25150","-0.02843"
"7.79700","-155.25150","-0.03741"
"7.82200","-155.25150","-0.03376"
"7.85900","-155.25150","-0.02865"
"7.90900","-155.25150","-0.02662"
"7.96800","-155.25150","-0.03192"
"8.02100","-155.25150","-0.03846"
"8.05700","-155.25150","-0.01884"
"8.10700","-155.25150","-0.03345"
"8.14200","-155.25150","-0.02727"
"8.17400","-155.25150","-0.01678"
"8.20900","-155.25150","-0.03054"
"8.25700","-155.25150","-0.03257"
"8.31000","-155.25150","-0.02827"
"8.34700","-155.25150","-0.01966"
"8.39300","-155.25150","-0.02822"
"8.42900","-155.25150","-0.02508"
"8.48300","-155.25150","-0.03292"
"8.53700","-155.25150","-0.02946"
"8.59100","-155.25150","-0.02343"
"8.62500","-155.25150","-0.02465"
"8.67900","-155.25150","-0.02549"
"8.71100","-155.25150","-0.02535"
"8.74900","-155.25150","-0.02779"
"8.79300","-155.25150","-0.02501"
"8.83700","-155.25150","-0.02723"
"8.88100","-155.25150","-0.03707"
"8.94100","-155.25150","-0.01029"
"8.97200","-155.25150","-0.02826"
"9.00400","-155.25150","0.00221"
"9.04600","-155.25150","-0.01561"
"9.08500","-155.25150","-0.00300"
"9.12300","-155.25150","-0.00686"
"9.16300","-155.25150","-0.00779"
"9.19500","-155.25150","-0.03209"
"9.24500","-155.25150","-0.02384"
"9.28200","-155.25150","-0.01933"
"9.31100","-155.25150","-0.02046"
"9.36100","-155.25150","-0.02313"
"9.40700","-155.25150","-0.02538"
"9.44500","-155.25150","-0.02654"
"9.50000","-155.25150","-0.06623"
"9.53600","-155.25150","-0.16033"
"9.58300","-155.25150","-0.17706"
"9.61900","-155.25150","-0.20224"
"9.67100","-155.25150","-0.16745"
"9.71300","-155.25150","-0.15683"
"9.76400","-155.25150","-0.15650"
"9.79400","-155.25150","-0.14134"
"9.82700","-155.25150","-0.12928"
"9.85300","-155.25150","-0.12124"
"9.88400","-155.25150","-0.12624"
"9.92700","-155.25150","-0.12832"
"9.95700","-155.25150","-0.11332"
"10.01100","-155.25150","-0.10773"
"10.05500","-155.25150","-0.12214"
"10.11200","-155.25150","-0.09835"
"10.15300","-155.25150","-0.10659"
"10.21300","-155.25150","-0.09664"
"10.25300","-155.25150","-0.09348"
"10.29600","-155.25150","-0.09596"
"10.33200","-155.25150","-0.09885"
"10.36500","-155.25150","-0.08955"
"10.40500","-155.25150","-0.09036"
"10.45600","-155.25150","-0.07950"
"10.50400","-155.25150","-0.09054"
"10.56100","-155.25150","-0.08257"
"10.59700","-155.25150","-0.09744"
"10.64000","-155.25150","-0.10560"
"10.67200","-155.25150","-0.05796"
"10.71300","-155.25150","-0.08239"
"10.76400","-155.25150","-0.08690"
"10.81700","-155.25150","-0.06762"
"10.86600","-155.25150","-0.07449"
"10.92900","-155.25150","-0.06180"
"10.96800","-155.25150","-0.08205"
"11.00700","-155.25150","-0.07401"
"11.05700","-155.25150","-0.06171"
"11.09800","-155.25150","-0.06562"
"11.14000","-155.25150","-0.05085"
"11.18600","-155.25150","-0.05287"
"11.23700","-155.25150","-0.06103"
"11.27900","-155.25150","-0.06361"
"11.32500","-155.25150","-0.06808"
"11.35300","-155.25150","-0.07052"
"11.39100","-155.25150","-0.06256"
"11.43700","-155.25150","-0.06008"
"11.48700","-155.25150","-0.06125"
"11.54200","-155.25150","-0.06285"
"11.58900","-155.25150","-0.05789"
"11.63600","-155.25150","-0.07332"
"11.67100","-155.25150","-0.06876"
"11.71200","-155.25150","-0.05291"
"11.77100","-155.25150","-0.05228"
"11.80700","-155.25150","-0.06216"
"11.84500","-155.25150","-0.07282"
"11.88700","-155.25150","-0.05386"
"11.94400","-155.25150","-0.06047"
"12.00200","-155.25150","-0.05536"
"12.04600","-155.25150","-0.05065"
"12.11100","-155.25150","-0.04115"
"12.17100","-155.25150","-0.04023"
"12.20400","-155.25150","-0.05345"
"12.23700","-155.25150","-0.05467"
"12.27700","-155.25150","-0.05547"
"12.32000","-155.25150","-0.06675"
"12.34900","-155.25150","-0.03492"
"12.38400","-155.25150","-0.03782"
"12.43100","-155.25150","-0.04032"
"12.47500","-155.25150","-0.04650"
"12.52300","-155.25150","-0.04119"
"12.56800","-155.25150","-0.05146"
"12.62000","-155.25150","-0.03298"
"12.67200","-155.25150","-0.03187"
"12.71900","-155.25150","-0.03773"
"12.75300","-155.25150","-0.04404"
"12.80100","-155.25150","-0.02085"
"12.83700","-155.25150","-0.03023"
"12.88500","-155.25150","-0.03887"
"12.91800","-155.25150","-0.03900"
"12.97400","-155.25150","-0.03442"
"13.02200","-155.25150","-0.03170"
"13.05700","-155.25150","-0.06070"
"13.10300","-155.25150","-0.02496"
"13.13900","-155.25150","-0.03924"
"13.18900","-155.25150","-0.03911"
"13.22800","-155.25150","-0.05420"
"13.27700","-155.25150","-0.03791"
"13.32000","-155.25150","-0.04314"
"13.37100","-155.25150","-0.03670"
"13.42000","-155.25150","-0.03606"
"13.46700","-155.25150","-0.03340"
"13.51800","-155.25150","-0.04618"
"13.56700","-155.25150","-0.03573"
"13.63400","-155.25150","-0.03853"
"13.69000","-155.25150","-0.05527"
"13.74100","-155.25150","-0.04062"
"13.80000","-155.25150","-0.04054"
"13.84500","-155.25150","-0.02690"
"13.88600","-155.25150","-0.02013"
"13.91900","-155.25150","-0.03469"
"13.96100","-155.25150","-0.02795"
"13.99500","-155.25150","-0.03977"
"14.02800","-155.25150","-0.03458"
"14.05400","-155.25150","-0.02837"
"14.10000","-155.25150","-0.03501"
"14.13700","-155.25150","-0.02148"
"14.16700","-155.25150","-0.03951"
"14.22600","-155.25150","-0.02889"
"14.27900","-155.25150","-0.04189"
"14.33100","-155.25150","-0.03217"
"14.37400","-155.25150","-0.02546"
"14.42200","-155.25150","-0.03422"
"14.47700","-155.25150","-0.02799"
"14.50900","-155.25150","-0.03821"
"14.54900","-155.25150","-0.04422"
"14.58200","-155.25150","-0.03049"
"14.63100","-155.25150","-0.03825"
"14.67000","-155.25150","-0.02500"
"14.70700","-155.25150","-0.03333"
"14.75000","-155.25150","-0.03477"
"14.79500","-155.25150","-0.02570"
"14.85300","-155.25150","-0.04574"
"14.88700","-155.25150","-0.03331"
"14.91800","-155.25150","-0.04797"
"14.96400","-155.25150","-0.09002"
"14.99800","-155.25150","-0.18904"
"15.02600","-155.25150","-0.26785"
"15.05600","-155.25150","-0.25431"
"15.10000","-155.25150","-0.25093"
"15.14800","-155.25150","-0.24419"
"15.19900","-155.25150","-0.23111"
"15.24000","-155.25150","-0.21296"
"15.29300","-155.25150","-0.20426"
"15.33200","-155.25150","-0.17892"
"15.37900","-155.25150","-0.14361"
"15.42200","-155.25150","-0.15883"
"15.48400","-155.25150","-0.13321"
"15.53000","-155.25150","-0.13103"
"15.57400","-155.25150","-0.12819"
"15.61400","-155.25150","-0.13327"
"15.66000","-155.25150","-0.14699"
"15.69500","-155.25150","-0.12542"
"15.74700","-155.25150","-0.11699"
"15.79400","-155.25150","-0.11571"
"15.85800","-155.25150","-0.11628"
"15.90800","-155.25150","-0.11212"
"15.95600","-155.25150","-0.12449"
"15.98400","-155.25150","-0.09857"
"16.02400","-155.25150","-0.09201"
"16.05100","-155.25150","-0.08555"
"16.10400","-155.25150","-0.09642"
"16.14500","-155.25150","-0.07940"
"16.19300","-155.25150","-0.08973"
"16.24600","-155.25150","-0.10457"
"16.29300","-155.25150","-0.10329"
"16.34300","-155.25150","-0.08250"
"16.38900","-155.25150","-0.09962"
"16.42600","-155.25150","-0.10612"
"16.46800","-155.25150","-0.08510"
"16.51900","-155.25150","-0.09446"
"16.56900","-155.25150","-0.09434"
"16.61900","-155.25150","-0.07394"
"16.65800","-155.25150","-0.06954"
"16.70000","-155.25150","-0.07280"
"16.74400","-155.25150","-0.07397"
"16.77400","-155.25150","-0.08264"
"16.82000","-155.25150","-0.07983"
"16.86300","-155.25150","-0.08220"
"16.90600","-155.25150","-0.07284"
"16.97200","-155.25150","-0.06484"
"17.02300","-155.25150","-0.08190"
"17.07600","-155.25150","-0.07663"
"17.12400","-155.25150","-0.06290"
"17.18900","-155.25150","-0.06314"
"17.22000","-155.25150","-0.07261"
"17.25800","-155.25150","-0.08144"
"17.29700","-155.25150","-0.07819"
"17.33600","-155.25150","-0.08019"
"17.37400","-155.25150","-0.05908"
"17.40700","-155.25150","-0.08582"
"17.44800","-155.25150","-0.07052"
"17.48600","-155.25150","-0.07265"
"17.54000","-155.25150","-0.07285"
"17.57600","-155.25150","-0.06295"
"17.62100","-155.25150","-0.06742"
"17.67000","-155.25150","-0.07678"
"17.71900","-155.25150","-0.07571"
"17.77500","-155.25150","-0.07304"
"17.80400","-155.25150","-0.05318"
"17.83700","-155.25150","-0.07195"
"17.88000","-155.25150","-0.08395"
"17.93300","-155.25150","-0.05582"
"17.98500","-155.25150","-0.07474"
"18.03100","-155.25150","-0.05877"
"18.07300","-155.25150","-0.07739"
"18.13300","-155.25150","-0.06277"
"18.18700","-155.25150","-0.06284"
"18.23600","-155.25150","-0.07230"
"18.27800","-155.25150","-0.07402"
"18.32700","-155.25150","-0.06742"
"18.36500","-155.25150","-0.04475"
"18.38700","-155.25150","-0.06975"
"18.42700","-155.25150","-0.06273"
"18.47600","-155.25150","-0.07869"
"18.51600","-155.25150","-0.05188"
"18.57000","-155.25150","-0.05577"
"18.61200","-155.25150","-0.06607"
"18.66700","-155.25150","-0.05657"
"18.73200","-155.25150","-0.03977"
"18.77300","-155.25150","-0.05208"
"18.82000","-155.25150","-0.04883"
"18.86900","-155.25150","-0.07081"
"18.91600","-155.25150","-0.06596"
"18.96600","-155.25150","-0.05420"
"19.02400","-155.25150","-0.04922"
"19.08200","-155.25150","-0.05968"
"19.13300","-155.25150","-0.06206"
"19.19000","-155.25150","-0.04763"
"19.23900","-155.25150","-0.06648"
"19.27900","-155.25150","-0.06964"
"19.32000","-155.25150","-0.11427"
"19.34900","-155.25150","-0.19496"
"19.38400","-155.25150","-0.31261"
"19.41600","-155.25150","-0.39412"
"19.45500","-155.25150","-0.35543"
"19.50100","-155.25150","-0.32257"
"19.54300","-155.25150","-0.31957"
"19.58800","-155.25150","-0.30985"
"19.64100","-155.25150","-0.28154"
"19.68200","-155.25150","-0.25325"
"19.72400","-155.25150","-0.25064"
"19.77900","-155.25150","-0.23359"
"19.80500","-155.25150","-0.21604"
"19.85400","-155.25150","-0.19771"
"19.89100","-155.25150","-0.19776"
"19.93200","-155.25150","-0.21516"
"19.96600","-155.25150","-0.19315"
"20.02800","-155.25150","-0.17737"
"20.06200","-155.25150","-0.15752"
"20.11000","-155.25150","-0.16687"
"20.16100","-155.25150","-0.14741"
"20.19400","-155.25150","-0.16290"
"20.22800","-155.25150","-0.14804"
"20.26800","-155.25150","-0.14249"
"20.31800","-155.25150","-0.13386"
"20.37500","-155.25150","-0.15051"
"20.42000","-155.25150","-0.13250"
"20.47300","-155.25150","-0.12662"
"20.52200","-155.25150","-0.13242"
"20.56800","-155.25150","-0.12301"
"20.61000","-155.25150","-0.11485"
"20.65900","-155.25150","-0.12271"
"20.69900","-155.25150","-0.11906"
"20.74800","-155.25150","-0.13361"
"20.77500","-155.25150","-0.10553"
"20.81200","-155.25150","-0.13252"
"20.86400","-155.25150","-0.11461"
"20.90600","-155.25150","-0.11363"
"20.97000","-155.25150","-0.11145"
"21.00800","-155.25150","-0.11192"
"21.05200","-155.25150","-0.09749"
"21.10800","-155.25150","-0.10403"
"21.16100","-155.25150","-0.10115"
"21.19400","-155.25150","-0.11113"
"21.24700","-155.25150","-0.09502"
"21.28700","-155.25150","-0.11564"
"21.33100","-155.25150","-0.09545"
"21.38700","-155.25150","-0.08343"
"21.43300","-155.25150","-0.10491"
"21.47800","-155.25150","-0.11213"
"21.50700","-155.25150","-0.08849"
"21.55700","-155.25150","-0.08795"
"21.59300","-155.25150","-0.11078"
"21.63700","-155.25150","-0.08996"
"21.68200","-155.25150","-0.08953"
"21.73100","-155.25150","-0.09096"
"21.76500","-155.25150","-0.10751"
"21.79000","-155.25150","-0.09568"
"21.82600","-155.25150","-0.08439"
"21.87900","-155.25150","-0.07721"
"21.91700","-155.25150","-0.07648"
"21.96000","-155.25150","-0.10329"
"22.01400","-155.25150","-0.09583"
"22.04000","-155.25150","-0.10221"
"22.09500","-155.25150","-0.09018"
"22.14500","-155.25150","-0.08875"
"22.18300","-155.25150","-0.07550"
"22.23900","-155.25150","-0.09317"
"22.27800","-155.25150","-0.08753"
"22.32200","-155.25150","-0.09015"
"22.35900","-155.25150","-0.10587"
"22.39700","-155.25150","-0.10050"
"22.43400","-155.25150","-0.08649"
"22.47800","-155.25150","-0.09888"
"22.52000","-155.25150","-0.09003"
"22.56800","-155.25150","-0.10379"
"22.60500","-155.25150","-0.08744"
"22.63400","-155.25150","-0.08359"
"22.67000","-155.25150","-0.09119"
"22.70800","-155.25150","-0.07776"
"22.74700","-155.25150","-0.08405"
"22.78100","-155.25150","-0.09301"
"22.81900","-155.25150","-0.09382"
"22.85800","-155.25150","-0.07745"
"22.90000","-155.25150","-0.09568"
"22.96000","-155.25150","-0.07671"
"23.02800","-155.25150","-0.10133"
"23.06200","-155.25150","-0.08795"
"23.10400","-155.25150","-0.07757"
"23.15700","-155.25150","-0.07348"
"23.18800","-155.25150","-0.06877"
"23.22700","-155.25150","-0.07535"
"23.27100","-155.25150","-0.08797"
"23.32200","-155.25150","-0.08303"
"23.36000","-155.25150","-0.07078"
"23.40600","-155.25150","-0.08563"
"23.44800","-155.25150","-0.07574"
"23.49800","-155.25150","-0.09041"
"23.55300","-155.25150","-0.07224"
"23.60000","-155.25150","-0.08441"
"23.64000","-155.25150","-0.08706"
"23.68600","-155.25150","-0.07788"
"23.72700","-155.25150","-0.06918"
"23.77200","-155.25150","-0.08533"
"23.82200","-155.25150","-0.06916"
"23.86300","-155.25150","-0.08946"
"23.91800","-155.25150","-0.09235"
"23.97000","-155.25150","-0.07994"
"24.01800","-155.25150","-0.08490"
"24.06100","-155.25150","-0.09250"
"24.10300","-155.25150","-0.08446"
"24.13500","-155.25150","-0.07278"
"24.17000","-155.25150","-0.09462"
"24.20100","-155.25150","-0.08689"
"24.24300","-155.25150","-0.06854"
"24.28000","-155.25150","-0.08037"
"24.33300","-155.25150","-0.07619"
"24.37500","-155.25150","-0.07617"
"24.41900","-155.25150","-0.07747"
"24.46700","-155.25150","-0.07881"
"24.50100","-155.25150","-0.08124"
"24.54300","-155.25150","-0.08030"
"24.57200","-155.25150","-0.06563"
"24.60700","-155.25150","-0.08446"
"24.64400","-155.25150","-0.06427"
"24.68900","-155.25150","-0.09130"
"24.73100","-155.25150","-0.08039"
"24.76600","-155.25150","-0.07681"
"24.80500","-155.25150","-0.07536"
"24.85700","-155.25150","-0.07283"
"24.90300","-155.25150","-0.07182"
"24.95600","-155.25150","-0.07636"
"25.01700","-155.25150","-0.08747"
"25.05100","-155.25150","-0.07980"
"25.09900","-155.25150","-0.07532"
"25.14000","-155.25150","-0.08085"
"25.18200","-155.25150","-0.07472"
"25.21000","-155.25150","-0.07452"
"25.25900","-155.25150","-0.07834"
"25.30400","-155.25150","-0.06789"
"25.33400","-155.25150","-0.07933"
"25.38700","-155.25150","-0.08581"
"25.41700","-155.25150","-0.07888"
"25.45200","-155.25150","-0.08088"
"25.51600","-155.25150","-0.07556"
"25.53700","-155.25150","-0.06914"
"25.57900","-155.25150","-0.07750"
"25.62800","-155.25150","-0.09775"
"25.66500","-155.25150","-0.09045"
"25.70600","-155.25150","-0.08548"
"25.74300","-155.25150","-0.07801"
"25.79900","-155.25150","-0.07723"
"25.83100","-155.25150","-0.08085"
"25.87900","-155.25150","-0.07786"
"25.91700","-155.25150","-0.08591"
"25.96500","-155.25150","-0.06728"
"25.99500","-155.25150","-0.08370"
"26.04600","-155.25150","-0.07916"
"26.07100","-155.25150","-0.07119"
"26.10600","-155.25150","-0.07199"
"26.14600","-155.25150","-0.07008"
"26.17500","-155.25150","-0.09527"
"26.22300","-155.25150","-0.08315"
"26.26600","-155.25150","-0.08600"
"26.31000","-155.25150","-0.07462"
"26.34800","-155.25150","-0.07629"
"26.39300","-155.25150","-0.10009"
"26.43100","-155.25150","-0.08273"
"26.46200","-155.25150","-0.07921"
"26.50800","-155.25150","-0.06035"
"26.56700","-155.25150","-0.08640"
"26.62600","-155.25150","-0.07806"
"26.66700","-155.25150","-0.07418"
"26.71000","-155.25150","-0.09132"
"26.76100","-155.25150","-0.07301"
"26.82200","-155.25150","-0.06769"
"26.86200","-155.25150","-0.07243"
"26.91800","-155.25150","-0.07488"
"26.95100","-155.25150","-0.08173"
"26.99200","-155.25150","-0.07989"
"27.02100","-155.25150","-0.05721"
"27.07600","-155.25150","-0.06317"
"27.13200","-155.25150","-0.08310"
"27.17100","-155.25150","-0.07022"
"27.22000","-155.25150","-0.05411"
"27.26500","-155.25150","-0.07698"
"27.32200","-155.25150","-0.07267"
"27.38400","-155.25150","-0.06964"
"27.42300","-155.25150","-0.07621"
"27.46000","-155.25150","-0.08253"
"27.50600","-155.25150","-0.08191"
"27.54700","-155.25150","-0.07040"
"27.58900","-155.25150","-0.07148"
"27.64800","-155.25150","-0.08287"
"27.70200","-155.25150","-0.07702"
"27.76400","-155.25150","-0.07326"
"27.80900","-155.25150","-0.08586"
"27.87100","-155.25150","-0.07874"
"27.90200","-155.25150","-0.08855"
"27.94400","-155.25150","-0.07653"
"27.97300","-155.25150","-0.09913"
"28.01700","-155.25150","-0.18783"
"28.04500","-155.25150","-0.29562"
"28.07600","-155.25150","-0.39253"
"28.10200","-155.25150","-0.46639"
"28.14200","-155.25150","-0.52556"
"28.17000","-155.25150","-0.48694"
"28.22800","-155.25150","-0.44064"
"28.27000","-155.25150","-0.44149"
"28.31000","-155.25150","-0.45488"
"28.34500","-155.25150","-0.42794"
"28.38100","-155.25150","-0.40070"
"28.42000","-155.25150","-0.36408"
"28.47300","-155.25150","-0.33018"
"28.51800","-155.25150","-0.31476"
"28.55300","-155.25150","-0.30484"
"28.59600","-155.25150","-0.28150"
"28.65000","-155.25150","-0.26365"
"28.68500","-155.25150","-0.25038"
"28.72700","-155.25150","-0.23561"
"28.76800","-155.25150","-0.23978"
"28.82600","-155.25150","-0.21757"
"28.87900","-155.25150","-0.20931"
"28.92200","-155.25150","-0.20637"
"28.97000","-155.25150","-0.18106"
"28.99700","-155.25150","-0.20943"
"29.03500","-155.25150","-0.17279"
"29.07900","-155.25150","-0.18393"
"29.11600","-155.25150","-0.18996"
"29.16000","-155.25150","-0.17546"
"29.20800","-155.25150","-0.16313"
"29.24900","-155.25150","-0.16155"
"29.30300","-155.25150","-0.15650"
"29.36500","-155.25150","-0.15005"
"29.39100","-155.25150","-0.14061"
"29.42900","-155.25150","-0.13633"
"29.49000","-155.25150","-0.13277"
"29.52300","-155.25150","-0.13566"
"29.57500","-155.25150","-0.11660"
"29.62900","-155.25150","-0.11402"
"29.66400","-155.25150","-0.10175"
"29.70400","-155.25150","-0.11354"
"29.74900","-155.25150","-0.12310"
"29.79700","-155.25150","-0.10971"
"29.83000","-155.25150","-0.11340"
"29.88500","-155.25150","-0.11396"
"29.93500","-155.25150","-0.10047"
"29.97400","-155.25150","-0.09389"
"30.00300","-155.25150","-0.11189"
"30.05200","-155.25150","-0.09535"
"30.09300","-155.25150","-0.10593"
"30.15200","-155.25150","-0.08406"
"30.18800","-155.25150","-0.10813"
"30.24000","-155.25150","-0.09183"
"30.29900","-155.25150","-0.08292"
"30.33400","-155.25150","-0.10209"
"30.36700","-155.25150","-0.07643"
"30.41700","-155.25150","-0.08503"
"30.45500","-155.25150","-0.09450"
"30.50300","-155.25150","-0.08015"
"30.53500","-155.25150","-0.07379"
"30.58600","-155.25150","-0.08643"
"30.61900","-155.25150","-0.07372"
"30.67000","-155.25150","-0.07146"
"30.72400","-155.25150","-0.08573"
"30.79300","-155.25150","-0.08228"
"30.82400","-155.25150","-0.07772"
"30.88300","-155.25150","-0.08658"
"30.94100","-155.25150","-0.08306"
"31.00100","-155.25150","-0.07494"
"31.04700","-155.25150","-0.08422"
"31.09900","-155.25150","-0.08706"
"31.12600","-155.25150","-0.08369"
"31.18800","-155.25150","-0.06880"
"31.22200","-155.25150","-0.07088"
"31.25900","-155.25150","-0.07013"
"31.29900","-155.25150","-0.09057"
"31.34700","-155.25150","-0.07908"
"31.39000","-155.25150","-0.08412"
"31.44600","-155.25150","-0.07478"
"31.49700","-155.25150","-0.08924"
"31.53800","-155.25150","-0.08533"
"31.57400","-155.25150","-0.07894"
"31.61200","-155.25150","-0.06675"
"31.64500","-155.25150","-0.08194"
"31.69800","-155.25150","-0.08920"
"31.75200","-155.25150","-0.07246"
"31.79800","-155.25150","-0.07879"
"31.83400","-155.25150","-0.06252"
"31.87800","-155.25150","-0.08315"
"31.91200","-155.25150","-0.06444"
"31.95300","-155.25150","-0.08293"
"32.00400","-155.25150","-0.06395"
"32.04100","-155.25150","-0.07322"
"32.08300","-155.25150","-0.06521"
"32.11300","-155.25150","-0.06185"
"32.14700","-155.25150","-0.07745"
"32.18900","-155.25150","-0.05932"
"32.22600","-155.25150","-0.05705"
"32.26400","-155.25150","-0.07956"
"32.29700","-155.25150","-0.06276"
"32.33100","-155.25150","-0.07144"
"32.36800","-155.25150","-0.07893"
"32.41200","-155.25150","-0.06423"
"32.46100","-155.25150","-0.07664"
"32.50800","-155.25150","-0.06163"
"32.54600","-155.25150","-0.06124"
"32.58700","-155.25150","-0.05635"
"32.62200","-155.25150","-0.08134"
"32.66000","-155.25150","-0.07521"
"32.70300","-155.25150","-0.06525"
"32.75600","-155.25150","-0.05786"
"32.79600","-155.25150","-0.07026"
"32.83800","-155.25150","-0.06701"
"32.88000","-155.25150","-0.07655"
"32.93600","-155.25150","-0.08267"
"32.98000","-155.25150","-0.07794"
"33.03600","-155.25150","-0.06736"
"33.08800","-155.25150","-0.05879"
"33.13700","-155.25150","-0.05276"
"33.19800","-155.25150","-0.07225"
"33.23800","-155.25150","-0.05866"
"33.29400","-155.25150","-0.06251"
"33.33600","-155.25150","-0.07159"
"33.38400","-155.25150","-0.06778"
"33.44100","-155.25150","-0.07387"
"33.48200","-155.25150","-0.07029"
"33.52000","-155.25150","-0.07218"
"33.56900","-155.25150","-0.05182"
"33.59600","-155.25150","-0.07464"
"33.63000","-155.25150","-0.05999"
"33.67900","-155.25150","-0.06459"
"33.71500","-155.25150","-0.06068"
"33.73300","-155.25150","-0.07822"
"33.76900","-155.25150","-0.05113"
"33.80900","-155.25150","-0.07021"
"33.86300","-155.25150","-0.07819"
"33.92100","-155.25150","-0.07634"
"33.97300","-155.25150","-0.07012"
"34.01000","-155.25150","-0.07046"
"34.05900","-155.25150","-0.06283"
"34.09900","-155.25150","-0.05325"
"34.13300","-155.25150","-0.06132"
"34.18500","-155.25150","-0.06372"
"34.23900","-155.25150","-0.05789"
"34.28800","-155.25150","-0.07874"
"34.33800","-155.25150","-0.05742"
"34.38000","-155.25150","-0.08154"
"34.41500","-155.25150","-0.05094"
"34.45400","-155.25150","-0.06166"
"34.51400","-155.25150","-0.06556"
"34.54700","-155.25150","-0.07770"
"34.58600","-155.25150","-0.12462"
"34.61600","-155.25150","-0.22409"
"34.63700","-155.25150","-0.28779"
"34.66400","-155.25150","-0.37135"
"34.69700","-155.25150","-0.47110"
"34.73400","-155.25150","-0.51257"
"34.78000","-155.25150","-0.54943"
"34.81500","-155.25150","-0.55834"
"34.84600","-155.25150","-0.55162"
"34.89100","-155.25150","-0.53740"
"34.93100","-155.25150","-0.52091"
"34.96700","-155.25150","-0.50907"
"35.03200","-155.25150","-0.50671"
"35.08700","-155.25150","-0.48665"
"35.13100","-155.25150","-0.46374"
"35.15600","-155.25150","-0.46696"
"35.20400","-155.25150","-0.46351"
"35.24600","-155.25150","-0.45293"
"35.27800","-155.25150","-0.44240"
"35.33400","-155.25150","-0.44194"
"35.36800","-155.25150","-0.42027"
"35.42500","-155.25150","-0.41579"
"35.47100","-155.25150","-0.37885"
"35.50200","-155.25150","-0.37915"
"35.55500","-155.25150","-0.35433"
"35.59400","-155.25150","-0.32753"
"35.64000","-155.25150","-0.31956"
"35.69900","-155.25150","-0.30090"
"35.74000","-155.25150","-0.28579"
"35.77800","-155.25150","-0.28456"
"35.82500","-155.25150","-0.29013"
"35.87800","-155.25150","-0.26022"
"35.91300","-155.25150","-0.26285"
"35.95000","-155.25150","-0.23385"
"36.00200","-155.25150","-0.24028"
"36.05400","-155.25150","-0.23378"
"36.08600","-155.25150","-0.23811"
"36.11400","-155.25150","-0.22349"
"36.16900","-155.25150","-0.22193"
"36.20700","-155.25150","-0.20591"
"36.25300","-155.25150","-0.20357"
"36.31100","-155.25150","-0.20238"
"36.34600","-155.25150","-0.18193"
"36.39000","-155.25150","-0.20013"
"36.43000","-155.25150","-0.18299"
"36.48700","-155.25150","-0.19285"
"36.53300","-155.25150","-0.18559"
"36.58000","-155.25150","-0.16964"
"36.64100","-155.25150","-0.16704"
"36.67300","-155.25150","-0.16750"
"36.71600","-155.25150","-0.15285"
"36.76100","-155.25150","-0.17321"
"36.81500","-155.25150","-0.15960"
"36.86100","-155.25150","-0.15274"
"36.90200","-155.25150","-0.14449"
"36.93700","-155.25150","-0.14939"
"36.99100","-155.25150","-0.13133"
"37.02000","-155.25150","-0.13087"
"37.06100","-155.25150","-0.13155"
"37.10700","-155.25150","-0.14144"
"37.15900","-155.25150","-0.12827"
"37.20300","-155.25150","-0.12445"
"37.25500","-155.25150","-0.12350"
"37.29900","-155.25150","-0.10135"
"37.34000","-155.25150","-0.13002"
"37.38100","-155.25150","-0.12346"
"37.41800","-155.25150","-0.12777"
"37.46300","-155.25150","-0.12703"
"37.51500","-155.25150","-0.11577"
"37.56100","-155.25150","-0.09594"
"37.60600","-155.25150","-0.10368"
"37.63400","-155.25150","-0.13328"
"37.67600","-155.25150","-0.10957"
"37.71700","-155.25150","-0.09738"
"37.75600","-155.25150","-0.08686"
"37.81100","-155.25150","-0.10892"
"37.86100","-155.25150","-0.10295"
"37.90500","-155.25150","-0.10039"
"37.95800","-155.25150","-0.10842"
"38.01900","-155.25150","-0.09960"
"38.07000","-155.25150","-0.11250"
"38.10700","-155.25150","-0.10314"
"38.14500","-155.25150","-0.07396"
"38.17500","-155.25150","-0.09566"
"38.20300","-155.25150","-0.11961"
"38.25200","-155.25150","-0.09152"
"38.29100","-155.25150","-0.08868"
"38.34100","-155.25150","-0.08096"
"38.39800","-155.25150","-0.07230"
"38.43900","-155.25150","-0.07138"
"38.48500","-155.25150","-0.08449"
"38.52400","-155.25150","-0.08872"
"38.56200","-155.25150","-0.08023"
"38.60800","-155.25150","-0.08115"
"38.63500","-155.25150","-0.09685"
"38.68600","-155.25150","-0.09218"
"38.72400","-155.25150","-0.09637"
"38.75100","-155.25150","-0.07565"
"38.80400","-155.25150","-0.07105"
"38.85200","-155.25150","-0.08925"
"38.91100","-155.25150","-0.08888"
"38.95900","-155.25150","-0.07346"
"39.00500","-155.25150","-0.07942"
"39.06600","-155.25150","-0.09274"
"39.10200","-155.25150","-0.07652"
"39.13800","-155.25150","-0.08397"
"39.17600","-155.25150","-0.07687"
"39.21800","-155.25150","-0.06819"
"39.24700","-155.25150","-0.09109"
"39.27800","-155.25150","-0.08574"
"39.31600","-155.25150","-0.08355"
"39.37100","-155.25150","-0.06186"
"39.40900","-155.25150","-0.07160"
"39.45500","-155.25150","-0.06588"
"39.50300","-155.25150","-0.07841"
"39.54000","-155.25150","-0.08578"
"39.60200","-155.25150","-0.06054"
"39.65600","-155.25150","-0.08395"
"39.69300","-155.25150","-0.07641"
"39.72800","-155.25150","-0.06484"
"39.77100","-155.25150","-0.06453"
"39.80300","-155.25150","-0.08395"
"39.85600","-155.25150","-0.07510"
"39.90100","-155.25150","-0.07142"
"39.95500","-155.25150","-0.07473"
"39.99700","-155.25150","-0.06950"
"40.04100","-155.25150","-0.07371"
"40.08700","-155.25150","-0.06903"
"40.13300","-155.25150","-0.07705"
"40.18200","-155.25150","-0.06442"
"40.22000","-155.25150","-0.06386"
"40.25300","-155.25150","-0.08197"
"40.28800","-155.25150","-0.06239"
"40.33200","-155.25150","-0.07263"
"40.37600","-155.25150","-0.06500"
"40.42300","-155.25150","-0.06718"
"40.46400","-155.25150","-0.06997"
"40.50500","-155.25150","-0.05720"
"40.55600","-155.25150","-0.06026"
"40.59200","-155.25150","-0.05686"
"40.63600","-155.25150","-0.06600"
"40.68400","-155.25150","-0.06983"
"40.72800","-155.25150","-0.06814"
"40.77400","-155.25150","-0.05325"
"40.80900","-155.25150","-0.04367"
"40.85000","-155.25150","-0.05550"
"40.88500","-155.25150","-0.06276"
"40.92800","-155.25150","-0.06452"
"40.97200","-155.25150","-0.04965"
"41.01300","-155.25150","-0.06074"
"41.05800","-155.25150","-0.07033"
"41.10200","-155.25150","-0.06891"
"41.14000","-155.25150","-0.08247"
"41.18700","-155.25150","-0.05882"
"41.23000","-155.25150","-0.05540"
"41.27600","-155.25150","-0.05483"
"41.31700","-155.25150","-0.05924"
"41.36800","-155.25150","-0.06089"
"41.41100","-155.25150","-0.05330"
"41.43800","-155.25150","-0.04779"
"41.47700","-155.25150","-0.05174"
"41.52800","-155.25150","-0.05069"
"41.57400","-155.25150","-0.06435"
"41.62000","-155.25150","-0.07599"
"41.66300","-155.25150","-0.06459"
"41.70000","-155.25150","-0.06482"
"41.73300","-155.25150","-0.06470"
"41.77800","-155.25150","-0.05934"
"41.82000","-155.25150","-0.05923"
"41.86700","-155.25150","-0.05894"
"41.92700","-155.25150","-0.05707"
"41.97000","-155.25150","-0.05737"
"42.00100","-155.25150","-0.05826"
"42.04200","-155.25150","-0.05692"
"42.08600","-155.25150","-0.06344"
"42.12600","-155.25150","-0.04562"
"42.17500","-155.25150","-0.05491"
"42.21600","-155.25150","-0.04195"
"42.25500","-155.25150","-0.04794"
"42.29600","-155.25150","-0.04069"
"42.33700","-155.25150","-0.06703"
"42.38500","-155.25150","-0.06832"
"42.43000","-155.25150","-0.04930"
"42.48100","-155.25150","-0.04298"
"42.52100","-155.25150","-0.04691"
"42.57500","-155.25150","-0.04759"
"42.62300","-155.25150","-0.04130"
"42.66900","-155.25150","-0.04662"
"42.72900","-155.25150","-0.05058"
"42.75800","-155.25150","-0.04962"
"42.80400","-155.25150","-0.06313"
"42.84600","-155.25150","-0.05946"
"42.88400","-155.25150","-0.05761"
"42.91800","-155.25150","-0.05263"
"42.96500","-155.25150","-0.07020"
"43.00500","-155.25150","-0.05244"
"43.04100","-155.25150","-0.05723"
"43.07900","-155.25150","-0.06096"
"43.11900","-155.25150","-0.05273"
"43.15300","-155.25150","-0.04258"
"43.18800","-155.25150","-0.04379"
"43.25500","-155.25150","-0.03450"
"43.29700","-155.25150","-0.04563"
"43.34400","-155.25150","-0.06133"
"43.40100","-155.25150","-0.05561"
"43.42600","-155.25150","-0.06078"
"43.44700","-155.25150","-0.04214"
"43.48800","-155.25150","-0.05197"
"43.53900","-155.25150","-0.05736"
"43.59400","-155.25150","-0.06626"
"43.65100","-155.25150","-0.05095"
"43.70000","-155.25150","-0.06158"
"43.74100","-155.25150","-0.07467"
"43.77000","-155.25150","-0.05310"
"43.81400","-155.25150","-0.04518"
"43.85200","-155.25150","-0.04811"
"43.88500","-155.25150","-0.04364"
"43.91800","-155.25150","-0.04259"
"43.97300","-155.25150","-0.04360"
"44.03300","-155.25150","-0.03214"
"44.06500","-155.25150","-0.05236"
"44.11500","-155.25150","-0.04556"
"44.16000","-155.25150","-0.05557"
"44.22200","-155.25150","-0.04614"
"44.26500","-155.25150","-0.04162"
"44.29800","-155.25150","-0.05131"
"44.36100","-155.25150","-0.05521"
"44.39700","-155.25150","-0.02752"
"44.44000","-155.25150","-0.05006"
"44.48900","-155.25150","-0.04788"
"44.53700","-155.25150","-0.03742"
"44.58500","-155.25150","-0.05330"
"44.64200","-155.25150","-0.04237"
"44.68700","-155.25150","-0.03821"
"44.73800","-155.25150","-0.04656"
"44.76400","-155.25150","-0.04689"
"44.79000","-155.25150","-0.04375"
"44.83900","-155.25150","-0.06066"
"44.87500","-155.25150","-0.05969"
"44.92900","-155.25150","-0.04991"
"44.96900","-155.25150","-0.04783"
"45.01300","-155.25150","-0.05106"
"45.06000","-155.25150","-0.05174"
"45.11300","-155.25150","-0.04544"
"45.15100","-155.25150","-0.04365"
"45.18600","-155.25150","-0.04397"
"45.22100","-155.25150","-0.05802"
"45.26900","-155.25150","-0.04264"
"45.32100","-155.25150","-0.03886"
"45.35600","-155.25150","-0.06469"
"45.41000","-155.25150","-0.03855"
"45.44700","-155.25150","-0.03403"
"45.48800","-155.25150","-0.04821"
"45.54100","-155.25150","-0.04606"
"45.57800","-155.25150","-0.03470"
"45.60700","-155.25150","-0.05702"
"45.65400","-155.25150","-0.04512"
"45.68900","-155.25150","-0.03848"
"45.73100","-155.25150","-0.03165"
"45.78000","-155.25150","-0.03722"
"45.83500","-155.25150","-0.03693"
"45.89200","-155.25150","-0.03210"
"45.93700","-155.25150","-0.05170"
"45.98600","-155.25150","-0.04914"
"46.03700","-155.25150","-0.02780"
"46.08400","-155.25150","-0.03689"
"46.13800","-155.25150","-0.03031"
"46.18700","-155.25150","-0.05488"
"46.24500","-155.25150","-0.04187"
"46.27800","-155.25150","-0.04710"
"46.33500","-155.25150","-0.05170"
"46.37100","-155.25150","-0.03673"
"46.40400","-155.25150","-0.03406"
"46.44800","-155.25150","-0.03150"
"46.50400","-155.25150","-0.03800"
"46.56100","-155.25150","-0.04329"
"46.59400","-155.25150","-0.04704"
"46.64600","-155.25150","-0.03259"
"46.69100","-155.25150","-0.05190"
"46.74300","-155.25150","-0.04616"
"46.78100","-155.25150","-0.04480"
"46.83500","-155.25150","-0.04381"
"46.89100","-155.25150","-0.04963"
"46.92100","-155.25150","-0.04086"
"46.96100","-155.25150","-0.04226"
"47.00900","-155.25150","-0.04957"
"47.04700","-155.25150","-0.06215"
"47.09400","-155.25150","-0.04484"
"47.13200","-155.25150","-0.03017"
"47.17800","-155.25150","-0.05340"
"47.21700","-155.25150","-0.05101"
"47.26100","-155.25150","-0.05411"
"47.29400","-155.25150","-0.01514"
"47.33500","-155.25150","-0.04372"
"47.38700","-155.25150","-0.02669"
"47.42300","-155.25150","-0.05399"
"47.47400","-155.25150","-0.04882"
"47.52100","-155.25150","-0.05796"
"47.56400","-155.25150","-0.05070"
"47.60700","-155.25150","-0.04201"
"47.65000","-155.25150","-0.02655"
"47.68000","-155.25150","-0.05532"
"47.71400","-155.25150","-0.05441"
"47.75900","-155.25150","-0.04246"
"47.79200","-155.25150","-0.04636"
"47.84600","-155.25150","-0.03922"
"47.90600","-155.25150","-0.05426"
"47.93800","-155.25150","-0.04315"
"47.99100","-155.25150","-0.04144"
"48.02000","-155.25150","-0.03889"
"48.06800","-155.25150","-0.02974"
"48.11800","-155.25150","-0.03972"
"48.15400","-155.25150","-0.04011"
"48.19000","-155.25150","-0.03138"
"48.22800","-155.25150","-0.04210"
"48.26200","-155.25150","-0.04710"
"48.32500","-155.25150","-0.03447"
"48.37200","-155.25150","-0.03982"
"48.42100","-155.25150","-0.03224"
"48.46400","-155.25150","-0.04549"
"48.49900","-155.25150","-0.03383"
"48.54100","-155.25150","-0.04636"
"48.57900","-155.25150","-0.04485"
"48.60800","-155.25150","-0.06570"
"48.64600","-155.25150","-0.04687"
"48.69800","-155.25150","-0.03876"
"48.73000","-155.25150","-0.03766"
"48.77400","-155.25150","-0.02209"
"48.82400","-155.25150","-0.03792"
"48.87900","-155.25150","-0.04385"
"48.92700","-155.25150","-0.04799"
"48.97600","-155.25150","-0.05699"
"49.03800","-155.25150","-0.04824"
"49.08900","-155.25150","-0.03829"
"49.14500","-155.25150","-0.03793"
"49.18300","-155.25150","-0.04925"
"49.22900","-155.25150","-0.04756"
"49.28500","-155.25150","-0.05448"
"49.33100","-155.25150","-0.04693"
"49.37300","-155.25150","-0.03100"
"49.40800","-155.25150","-0.03300"
"49.46800","-155.25150","-0.04375"
"49.52000","-155.25150","-0.04018"
"49.57100","-155.25150","-0.03077"
"49.62300","-155.25150","-0.02638"
"49.67900","-155.25150","-0.04809"
"49.70500","-155.25150","-0.05218"
"49.74700","-155.25150","-0.05321"
"49.80000","-155.25150","-0.05704"
"49.82600","-155.25150","-0.04437"
"49.86500","-155.25150","-0.03960"
"49.91300","-155.25150","-0.05181"
"49.96700","-155.25150","-0.02379"
"50.00700","-155.25150","-0.04344"
"50.05400","-155.25150","-0.05106"
"50.11000","-155.25150","-0.04294"
"50.14800","-155.25150","-0.04719"
"50.20400","-155.25150","-0.04320"
"50.24000","-155.25150","-0.03603"
"50.28100","-155.25150","-0.03904"
"50.32800","-155.25150","-0.05493"
"50.37500","-155.25150","-0.04184"
"50.42000","-155.25150","-0.04342"
"50.47600","-155.25150","-0.05114"
"50.53500","-155.25150","-0.04200"
"50.58100","-155.25150","-0.04922"
"50.63700","-155.25150","-0.04113"
"50.68500","-155.25150","-0.05202"
"50.73500","-155.25150","-0.03664"
"50.78400","-155.25150","-0.03843"
"50.83000","-155.25150","-0.04627"
"50.88100","-155.25150","-0.04338"
"50.93100","-155.25150","-0.03430"
"50.97700","-155.25150","-0.05204"
"51.01500","-155.25150","-0.02605"
"51.05700","-155.25150","-0.05105"
"51.08900","-155.25150","-0.04308"
"51.12200","-155.25150","-0.04651"
"51.17700","-155.25150","-0.04498"
"51.21700","-155.25150","-0.05459"
"51.25000","-155.25150","-0.05165"
"51.28300","-155.25150","-0.05051"
"51.33000","-155.25150","-0.03044"
"51.37900","-155.25150","-0.03098"
"51.42300","-155.25150","-0.04726"
"51.45300","-155.25150","-0.04822"
"51.50900","-155.25150","-0.05333"
"51.54400","-155.25150","-0.02684"
"51.58500","-155.25150","-0.04632"
"51.60700","-155.25150","-0.04156"
"51.64300","-155.25150","-0.05547"
"51.67300","-155.25150","-0.03469"
"51.71200","-155.25150","-0.03495"
"51.74600","-155.25150","-0.03837"
"51.78200","-155.25150","-0.02918"
"51.83200","-155.25150","-0.02173"
"51.86800","-155.25150","-0.03489"
"51.92100","-155.25150","-0.04771"
"51.98300","-155.25150","-0.04497"
"52.02600","-155.25150","-0.03472"
"52.08600","-155.25150","-0.02947"
"52.14400","-155.25150","-0.04111"
"52.18700","-155.25150","-0.04360"
"52.24100","-155.25150","-0.03867"
"52.29400","-155.25150","-0.03579"
"52.32200","-155.25150","-0.03302"
"52.35200","-155.25150","-0.03708"
"52.40300","-155.25150","-0.03197"
"52.44500","-155.25150","-0.04401"
"52.47400","-155.25150","-0.05949"
"52.51300","-155.25150","-0.04572"
"52.55400","-155.25150","-0.03986"
"52.60000","-155.25150","-0.02993"
"52.64200","-155.25150","-0.04658"
"52.70300","-155.25150","-0.04923"
"52.74300","-155.25150","-0.04682"
"52.78900","-155.25150","-0.04855"
"52.82700","-155.25150","-0.04321"
"52.88100","-155.25150","-0.04599"
"52.94400","-155.25150","-0.03498"
"52.96000","-155.25150","-0.03794"
"53.03000","-155.25150","-0.03923"
"53.07500","-155.25150","-0.03591"
"53.11900","-155.25150","-0.04441"
"53.16600","-155.25150","-0.04366"
"53.20900","-155.25150","-0.03209"
"53.25800","-155.25150","-0.04748"
"53.29700","-155.25150","-0.05146"
"53.34000","-155.25150","-0.03126"
"53.38900","-155.25150","-0.03983"
"53.44600","-155.25150","-0.02450"
"53.48200","-155.25150","-0.03758"
"53.52200","-155.25150","-0.03794"
"53.57000","-155.25150","-0.05604"
"53.60300","-155.25150","-0.03459"
"53.65000","-155.25150","-0.03770"
"53.68500","-155.25150","-0.03545"
"53.73500","-155.25150","-0.03175"
"53.77600","-155.25150","-0.05422"
"53.81800","-155.25150","-0.02808"
"53.87200","-155.25150","-0.04507"
"53.92200","-155.25150","-0.03949"
"53.96400","-155.25150","-0.01028"
"53.99500","-155.25150","-0.04840"
"54.04000","-155.25150","-0.03988"
"54.07700","-155.25150","-0.04230"
"54.12000","-155.25150","-0.02436"
"54.17600","-155.25150","-0.04857"
"54.23400","-155.25150","-0.04330"
"54.29100","-155.25150","-0.03982"
"54.33800","-155.25150","-0.04668"
"54.38900","-155.25150","-0.04722"
"54.43800","-155.25150","-0.03664"
"54.47500","-155.25150","-0.04720"
"54.50400","-155.25150","-0.04939"
"54.54500","-155.25150","-0.04105"
"54.57900","-155.25150","-0.04544"
"54.62800","-155.25150","-0.04848"
"54.66700","-155.25150","-0.05177"
"54.72100","-155.25150","-0.03880"
"54.78200","-155.25150","-0.03010"
"54.82300","-155.25150","-0.03334"
"54.87100","-155.25150","-0.04321"
"54.90600","-155.25150","-0.05979"
"54.96400","-155.25150","-0.03297"
"55.00000","-155.25150","-0.04775"
"55.06200","-155.25150","-0.03854"
"55.10400","-155.25150","-0.04475"
"55.14800","-155.25150","-0.03953"
"55.19700","-155.25150","-0.04428"
"55.22900","-155.25150","-0.04270"
"55.27000","-155.25150","-0.04638"
"55.31200","-155.25150","-0.03680"
"55.36600","-155.25150","-0.04682"
"55.40500","-155.25150","-0.03150"
"55.44800","-155.25150","-0.03580"
"55.50300","-155.25150","-0.04622"
"55.53700","-155.25150","-0.03099"
"55.57100","-155.25150","-0.03969"
"55.60900","-155.25150","-0.04726"
"55.64000","-155.25150","-0.04796"
"55.67300","-155.25150","-0.04398"
"55.72200","-155.25150","-0.03306"
"55.77500","-155.25150","-0.03820"
"55.81900","-155.25150","-0.03573"
"55.85600","-155.25150","-0.04392"
"55.89600","-155.25150","-0.04865"
"55.93000","-155.25150","-0.02944"
"55.98200","-155.25150","-0.03425"
"56.02100","-155.25150","-0.03261"
"56.07000","-155.25150","-0.04046"
"56.11000","-155.25150","-0.05006"
"56.16200","-155.25150","-0.03969"
"56.19800","-155.25150","-0.03692"
"56.24100","-155.25150","-0.05044"
"56.29300","-155.25150","-0.04826"
"56.34200","-155.25150","-0.02100"
"56.38000","-155.25150","-0.03000"
"56.41000","-155.25150","-0.03460"