File: chapter 4/force/mini_patrick.is_tens_RawData/Specimen_RawData_4.csv
Time,Extension,Load
(s),(mm),(N)
"0.00000","-152.35843","0.00348"
"0.03000","-152.35838","0.01133"
"0.08400","-152.35838","0.00555"
"0.11200","-152.35838","-0.01241"
"0.15500","-152.35838","0.00767"
"0.18600","-152.35838","-0.01146"
"0.23500","-152.35838","-0.01032"
"0.26500","-152.35838","0.00122"
"0.30800","-152.35838","0.00629"
"0.34100","-152.35838","0.00186"
"0.38700","-152.35838","-0.00020"
"0.43900","-152.35838","-0.00729"
"0.46700","-152.35838","0.00841"
"0.49700","-152.35838","0.00476"
"0.52400","-152.35838","-0.01436"
"0.56000","-152.35838","-0.00278"
"0.60500","-152.35838","-0.00335"
"0.64500","-152.35838","0.00819"
"0.66800","-152.35838","-0.00656"
"0.70200","-152.35838","-0.01416"
"0.75900","-152.35838","-0.00554"
"0.80300","-152.35838","-0.01163"
"0.83500","-152.35838","0.00201"
"0.87100","-152.35838","0.00751"
"0.91500","-152.35838","-0.01843"
"0.95300","-152.35838","-0.00777"
"0.98600","-152.35838","0.01467"
"1.02200","-152.35838","0.00371"
"1.04900","-152.35838","-0.00041"
"1.09000","-152.35838","-0.00834"
"1.12100","-152.35838","-0.01091"
"1.16100","-152.35838","-0.00008"
"1.20400","-152.35838","-0.00612"
"1.23900","-152.35838","-0.00844"
"1.27900","-152.35838","0.00300"
"1.30700","-152.35838","-0.00556"
"1.34800","-152.35838","0.00366"
"1.40000","-152.35838","0.00559"
"1.41800","-152.35838","0.00127"
"1.44300","-152.35838","-0.00074"
"1.47000","-152.35838","0.00538"
"1.50400","-152.35838","-0.01582"
"1.53900","-152.35838","0.01229"
"1.57200","-152.35838","0.00309"
"1.60300","-152.35838","-0.01892"
"1.64600","-152.35838","-0.02340"
"1.69200","-152.35838","0.00300"
"1.72500","-152.35838","0.00466"
"1.76000","-152.35838","-0.00640"
"1.80300","-152.35838","-0.01142"
"1.84900","-152.35838","-0.00362"
"1.88100","-152.35838","-0.01634"
"1.91600","-152.35838","-0.01795"
"1.95100","-152.35838","0.01681"
"1.98800","-152.35838","0.00521"
"2.01700","-152.35838","-0.01808"
"2.05500","-152.35838","0.00046"
"2.10300","-152.35838","0.00518"
"2.13300","-152.35838","0.00362"
"2.17300","-152.35838","-0.00902"
"2.20500","-152.35838","-0.00080"
"2.24300","-152.35838","-0.00450"
"2.28800","-152.35838","0.00071"
"2.32200","-152.35838","-0.01122"
"2.35600","-152.35838","-0.00338"
"2.39400","-152.35838","-0.00392"
"2.43500","-152.35838","-0.00349"
"2.48700","-152.35838","0.00086"
"2.51900","-152.35838","-0.00057"
"2.56000","-152.35838","0.00667"
"2.59300","-152.35838","-0.00282"
"2.63100","-152.35838","-0.00435"
"2.67500","-152.35838","0.00148"
"2.71600","-152.35838","0.00081"
"2.75600","-152.35838","-0.00329"
"2.77900","-152.35838","0.01053"
"2.82900","-152.35838","0.00468"
"2.88000","-152.35838","0.01235"
"2.91500","-152.35838","0.00165"
"2.94800","-152.35838","-0.01243"
"2.98800","-152.35838","-0.00894"
"3.01900","-152.35838","0.00945"
"3.05900","-152.35838","-0.01032"
"3.10000","-152.35838","-0.00964"
"3.13500","-152.35838","-0.01016"
"3.18700","-152.35838","-0.00939"
"3.22400","-152.35838","-0.00885"
"3.26000","-152.35838","-0.01016"
"3.30800","-152.35838","0.00336"
"3.35500","-152.35838","0.00331"
"3.37800","-152.35838","-0.00572"
"3.41100","-152.35838","-0.02034"
"3.45700","-152.35838","0.00908"
"3.48100","-152.35838","-0.00056"
"3.51900","-152.35838","0.00208"
"3.57800","-152.35838","-0.00829"
"3.60800","-152.35838","0.00547"
"3.62800","-152.35838","-0.01730"
"3.65400","-152.35838","0.00585"
"3.70500","-152.35838","0.00921"
"3.73900","-152.35838","-0.00559"
"3.77600","-152.35838","-0.01662"
"3.80700","-152.35838","-0.01084"
"3.84300","-152.35838","-0.00371"
"3.88500","-152.35838","-0.00365"
"3.92900","-152.35838","-0.00657"
"3.96300","-152.35838","0.00946"
"3.99300","-152.35838","-0.00096"
"4.02200","-152.35838","0.00326"
"4.05400","-152.35838","-0.00928"
"4.09100","-152.35838","-0.02045"
"4.13300","-152.35838","0.00212"
"4.17900","-152.35838","-0.00900"
"4.22500","-152.35838","0.00448"
"4.25900","-152.35838","-0.01210"
"4.28600","-152.35838","-0.00129"
"4.32000","-152.35838","-0.00990"
"4.35800","-152.35838","0.00231"
"4.40000","-152.35838","0.01644"
"4.44400","-152.35838","-0.00650"
"4.48000","-152.35838","-0.01134"
"4.52900","-152.35838","-0.01040"
"4.55800","-152.35838","-0.00859"
"4.59000","-152.35838","-0.01280"
"4.61500","-152.35838","-0.00328"
"4.64700","-152.35838","-0.00722"
"4.67600","-152.35838","0.01136"
"4.70000","-152.35838","0.00506"
"4.73900","-152.35838","0.00997"
"4.77800","-152.35838","-0.00725"
"4.82500","-152.35838","-0.00814"
"4.86100","-152.35838","-0.00597"
"4.90700","-152.35838","-0.01157"
"4.95100","-152.35838","-0.01016"
"4.99900","-152.35838","-0.00358"
"5.04000","-152.35838","-0.00161"
"5.07300","-152.35838","-0.01216"
"5.10600","-152.35838","-0.00201"
"5.13700","-152.35838","-0.00275"
"5.16400","-152.35838","-0.01592"
"5.19300","-152.35838","-0.00686"
"5.24100","-152.35838","0.01187"
"5.26900","-152.35838","-0.00753"
"5.30600","-152.35838","-0.01677"
"5.35600","-152.35838","-0.00633"
"5.39300","-152.35838","-0.00075"
"5.43900","-152.35838","0.00588"
"5.47000","-152.35838","-0.02094"
"5.50700","-152.35838","-0.01573"
"5.52900","-152.35838","-0.01674"
"5.55800","-152.35838","0.00095"
"5.58700","-152.35838","-0.01913"
"5.61900","-152.35838","-0.00487"
"5.65700","-152.35838","-0.00206"
"5.69400","-152.35838","-0.00183"
"5.72500","-152.35838","-0.00938"
"5.74900","-152.35838","-0.00048"
"5.78100","-152.35838","0.01020"
"5.82100","-152.35838","-0.04344"
"5.85600","-152.35838","-0.02734"
"5.88900","-152.35838","-0.01978"
"5.93700","-152.35838","-0.03958"
"5.98100","-152.35838","-0.01640"
"6.03000","-152.35838","-0.01549"
"6.07200","-152.35838","-0.03253"
"6.10800","-152.35838","-0.03054"
"6.14200","-152.35838","-0.02323"
"6.19000","-152.35838","-0.01127"
"6.23100","-152.35838","-0.01256"
"6.27900","-152.35838","-0.01007"
"6.30700","-152.35838","-0.02340"
"6.34900","-152.35838","-0.01936"
"6.39500","-152.35838","-0.01505"
"6.42400","-152.35838","-0.02257"
"6.46000","-152.35838","-0.01517"
"6.50400","-152.35838","-0.01716"
"6.52900","-152.35838","-0.00264"
"6.56300","-152.35838","-0.03526"
"6.59300","-152.35838","0.00145"
"6.63900","-152.35838","-0.01805"
"6.68500","-152.35838","-0.02329"
"6.74200","-152.35838","-0.01741"
"6.77600","-152.35838","-0.02624"
"6.81600","-152.35838","-0.01627"
"6.85800","-152.35838","-0.01824"
"6.88700","-152.35838","-0.01227"
"6.93100","-152.35838","-0.01709"
"6.96200","-152.35838","-0.02231"
"6.99400","-152.35838","-0.01471"
"7.03100","-152.35838","-0.00118"
"7.07800","-152.35838","-0.01645"
"7.12900","-152.35838","-0.01322"
"7.17500","-152.35838","-0.01732"
"7.21100","-152.35838","-0.01721"
"7.23900","-152.35838","-0.00675"
"7.28200","-152.35838","-0.00525"
"7.32200","-152.35838","-0.00301"
"7.35600","-152.35838","0.00909"
"7.40500","-152.35838","-0.01113"
"7.44000","-152.35838","-0.00259"
"7.48500","-152.35838","-0.00641"
"7.51000","-152.35838","-0.00066"
"7.54400","-152.35838","-0.00862"
"7.56200","-152.35838","-0.00376"
"7.58700","-152.35838","0.00266"
"7.61000","-152.35838","0.00357"
"7.63900","-152.35838","-0.02077"
"7.67800","-152.35838","-0.01154"
"7.71900","-152.35838","-0.00291"
"7.76400","-152.35838","-0.01108"
"7.80600","-152.35838","-0.01655"
"7.84400","-152.35838","-0.00471"
"7.87400","-152.35838","-0.00270"
"7.90900","-152.35838","-0.00207"
"7.92700","-152.35838","-0.01362"
"7.97100","-152.35838","-0.00604"
"8.00200","-152.35838","-0.01114"
"8.04300","-152.35838","-0.00735"
"8.08900","-152.35838","-0.01034"
"8.14000","-152.35838","-0.00765"
"8.19500","-152.35838","-0.00091"
"8.24800","-152.35838","0.00076"
"8.30300","-152.35838","-0.00687"
"8.34400","-152.35838","-0.00700"
"8.36900","-152.35838","-0.00936"
"8.39800","-152.35838","-0.00305"
"8.42300","-152.35838","0.00543"
"8.46200","-152.35838","0.00164"
"8.50500","-152.35838","-0.02495"
"8.55100","-152.35838","-0.00082"
"8.58800","-152.35838","-0.00046"
"8.60500","-152.35838","-0.01240"
"8.64400","-152.35838","-0.01194"
"8.68200","-152.35838","-0.01127"
"8.73300","-152.35838","-0.00849"
"8.77600","-152.35838","0.00217"
"8.81500","-152.35838","-0.00893"
"8.86900","-152.35838","-0.01650"
"8.89700","-152.35838","-0.00537"
"8.93600","-152.35838","-0.00628"
"8.98500","-152.35838","-0.01358"
"9.02600","-152.35838","-0.01196"
"9.05500","-152.35838","-0.01691"
"9.08200","-152.35838","-0.01142"
"9.11800","-152.35838","-0.00731"
"9.15900","-152.35838","-0.00945"
"9.21100","-152.35838","-0.00023"
"9.25800","-152.35838","-0.00716"
"9.29600","-152.35838","-0.02060"
"9.33300","-152.35838","-0.01293"
"9.35800","-152.35838","-0.01938"
"9.39600","-152.35838","-0.02611"
"9.43300","-152.35838","-0.00820"
"9.47000","-152.35838","-0.00994"
"9.51300","-152.35838","-0.00652"
"9.55300","-152.35838","0.00401"
"9.58400","-152.35838","0.00438"
"9.61800","-152.35838","0.00365"
"9.65300","-152.35838","-0.01573"
"9.70300","-152.35838","-0.00095"
"9.73400","-152.35838","-0.00987"
"9.76700","-152.35838","0.00069"
"9.79000","-152.35838","-0.00212"
"9.82100","-152.35838","-0.00980"
"9.86200","-152.35838","-0.02203"
"9.89800","-152.35838","-0.00872"
"9.94200","-152.35838","0.00342"
"9.98200","-152.35838","0.00874"
"10.02000","-152.35838","-0.00116"
"10.05900","-152.35838","-0.01735"
"10.09900","-152.35838","-0.00601"
"10.14300","-152.35838","-0.00181"
"10.18800","-152.35838","-0.00698"
"10.22900","-152.35838","-0.00913"
"10.26400","-152.35838","-0.01333"
"10.30900","-152.35838","-0.01117"
"10.33100","-152.35838","-0.01924"
"10.38200","-152.35838","-0.00697"
"10.42300","-152.35838","-0.00727"
"10.45100","-152.35838","-0.02152"
"10.48200","-152.35838","-0.00828"
"10.51400","-152.35838","-0.00207"
"10.55000","-152.35838","-0.01720"
"10.59300","-152.35838","0.00891"
"10.62400","-152.35838","-0.00712"
"10.67300","-152.35838","-0.00311"
"10.69800","-152.35838","0.00588"
"10.73200","-152.35838","-0.01376"
"10.77000","-152.35838","-0.00671"
"10.81500","-152.35838","-0.01287"
"10.83500","-152.35838","0.00404"
"10.87300","-152.35838","-0.01136"
"10.89400","-152.35838","0.00521"
"10.92400","-152.35838","-0.00502"
"10.95900","-152.35838","0.01130"
"10.98500","-152.35838","-0.00535"
"11.02600","-152.35838","-0.00300"
"11.06100","-152.35838","-0.00003"
"11.09900","-152.35838","-0.01273"
"11.13400","-152.35838","-0.00565"
"11.15900","-152.35838","0.00188"
"11.19400","-152.35838","0.00011"
"11.23300","-152.35838","-0.00170"
"11.27400","-152.35838","0.00163"
"11.31200","-152.35838","-0.00312"
"11.35200","-152.35838","-0.00085"
"11.40000","-152.35838","-0.01138"
"11.42800","-152.35838","-0.00671"
"11.46800","-152.35838","-0.03264"
"11.49700","-152.35838","-0.09002"
"11.54400","-152.35838","-0.09583"
"11.57400","-152.35838","-0.06926"
"11.59900","-152.35838","-0.06918"
"11.63100","-152.35838","-0.08316"
"11.65700","-152.35838","-0.07437"
"11.67900","-152.35838","-0.06319"
"11.73200","-152.35838","-0.03707"
"11.76900","-152.35838","-0.06582"
"11.79300","-152.35838","-0.04434"
"11.82800","-152.35838","-0.03977"
"11.86000","-152.35838","-0.05514"
"11.90100","-152.35838","-0.02500"
"11.94800","-152.35838","-0.03639"
"11.99300","-152.35838","-0.04887"
"12.04100","-152.35838","-0.03740"
"12.09200","-152.35838","-0.04262"
"12.14600","-152.35838","-0.04081"
"12.17800","-152.35838","-0.02280"
"12.21800","-152.35838","-0.02933"
"12.25600","-152.35838","-0.03937"
"12.28100","-152.35838","-0.02340"
"12.30700","-152.35838","-0.02923"
"12.34700","-152.35838","-0.03594"
"12.37000","-152.35838","-0.05139"
"12.41000","-152.35838","-0.03448"
"12.44300","-152.35838","-0.03031"
"12.48500","-152.35838","-0.02443"
"12.52700","-152.35838","-0.03645"
"12.57600","-152.35838","-0.03178"
"12.62500","-152.35838","-0.03506"
"12.67600","-152.35838","-0.02401"
"12.73500","-152.35838","-0.04068"
"12.77600","-152.35838","-0.03064"
"12.83200","-152.35838","-0.02580"
"12.87300","-152.35838","-0.01957"
"12.90800","-152.35838","-0.04241"
"12.94300","-152.35838","-0.02534"
"12.98200","-152.35838","-0.01362"
"13.02100","-152.35838","-0.00830"
"13.07000","-152.35838","-0.01768"
"13.11200","-152.35838","-0.02735"
"13.14300","-152.35838","-0.02023"
"13.18100","-152.35838","-0.02032"
"13.22500","-152.35838","-0.03358"
"13.25100","-152.35838","-0.03915"
"13.29200","-152.35838","-0.02042"
"13.33000","-152.35838","-0.01461"
"13.37000","-152.35838","-0.03331"
"13.40700","-152.35838","-0.00821"
"13.44000","-152.35838","-0.01456"
"13.47500","-152.35838","-0.03223"
"13.52300","-152.35838","-0.02955"
"13.56900","-152.35838","-0.02627"
"13.59600","-152.35838","-0.01394"
"13.64000","-152.35838","-0.03175"
"13.67700","-152.35838","-0.04011"
"13.72100","-152.35838","-0.02124"
"13.77600","-152.35838","-0.02422"
"13.81600","-152.35838","-0.02817"
"13.85200","-152.35838","-0.01541"
"13.89700","-152.35838","-0.01491"
"13.93800","-152.35838","-0.02963"
"13.98400","-152.35838","-0.02109"
"14.02500","-152.35838","-0.01719"
"14.05000","-152.35838","-0.03024"
"14.10500","-152.35838","-0.02759"
"14.12400","-152.35838","-0.01353"
"14.16700","-152.35838","-0.01733"
"14.19300","-152.35838","-0.03110"
"14.22400","-152.35838","-0.01998"
"14.26000","-152.35838","-0.02282"
"14.29900","-152.35838","-0.01284"
"14.34000","-152.35838","-0.02730"
"14.37300","-152.35838","-0.00514"
"14.41300","-152.35838","-0.01065"
"14.45300","-152.35838","-0.02677"
"14.49000","-152.35838","-0.02743"
"14.53700","-152.35838","-0.01599"
"14.57900","-152.35838","-0.01912"
"14.62300","-152.35838","-0.00780"
"14.66400","-152.35838","-0.00817"
"14.70500","-152.35838","-0.01654"
"14.75900","-152.35838","-0.02039"
"14.79200","-152.35838","-0.01803"
"14.82800","-152.35838","0.00267"
"14.86200","-152.35838","-0.01371"
"14.90700","-152.35838","-0.02578"
"14.95400","-152.35838","-0.00681"
"14.99600","-152.35838","-0.01696"
"15.03100","-152.35838","-0.02079"
"15.07100","-152.35838","-0.01354"
"15.10600","-152.35838","-0.03388"
"15.14000","-152.35838","-0.01788"
"15.17300","-152.35838","-0.01644"
"15.20800","-152.35838","-0.03037"
"15.25700","-152.35838","-0.01837"
"15.29700","-152.35838","-0.03571"
"15.32800","-152.35838","-0.01072"
"15.35300","-152.35838","-0.00333"
"15.39900","-152.35838","-0.00973"
"15.43000","-152.35838","-0.01947"
"15.46200","-152.35838","-0.02171"
"15.50400","-152.35838","0.00035"
"15.53000","-152.35838","0.00469"
"15.55400","-152.35838","-0.00768"
"15.58000","-152.35838","-0.00450"
"15.60700","-152.35838","-0.00646"
"15.64400","-152.35838","-0.01530"
"15.68400","-152.35838","-0.02906"
"15.72200","-152.35838","-0.02530"
"15.76500","-152.35838","-0.01791"
"15.80600","-152.35838","-0.00690"
"15.85300","-152.35838","-0.01716"
"15.89800","-152.35838","-0.02973"
"15.93100","-152.35838","-0.01513"
"15.96800","-152.35838","-0.00686"
"16.00500","-152.35838","-0.01788"
"16.05300","-152.35838","-0.01826"
"16.09200","-152.35838","-0.01502"
"16.11900","-152.35838","-0.02210"
"16.14800","-152.35838","-0.12136"
"16.17300","-152.35838","-0.19305"
"16.22700","-152.35838","-0.16914"
"16.27100","-152.35838","-0.16170"
"16.31200","-152.35838","-0.15774"
"16.35800","-152.35838","-0.13169"
"16.38500","-152.35838","-0.12720"
"16.42200","-152.35838","-0.13003"
"16.47000","-152.35838","-0.12797"
"16.51400","-152.35838","-0.13437"
"16.56100","-152.35838","-0.12330"
"16.60000","-152.35838","-0.11810"
"16.63200","-152.35838","-0.10459"
"16.67700","-152.35838","-0.12853"
"16.73400","-152.35838","-0.10380"
"16.77300","-152.35838","-0.10192"
"16.81500","-152.35838","-0.12280"
"16.85200","-152.35838","-0.11286"
"16.89100","-152.35838","-0.11040"
"16.92600","-152.35838","-0.11046"
"16.96900","-152.35838","-0.09481"
"17.01000","-152.35838","-0.09440"
"17.04200","-152.35838","-0.10015"
"17.08000","-152.35838","-0.09855"
"17.10800","-152.35838","-0.07899"
"17.14500","-152.35838","-0.07755"
"17.19100","-152.35838","-0.08853"
"17.21900","-152.35838","-0.07100"
"17.26000","-152.35838","-0.07430"
"17.31200","-152.35838","-0.07258"
"17.34900","-152.35838","-0.07841"
"17.37700","-152.35838","-0.05746"
"17.41600","-152.35838","-0.07312"
"17.45800","-152.35838","-0.07683"
"17.49700","-152.35838","-0.08732"
"17.53100","-152.35838","-0.07982"
"17.55900","-152.35838","-0.06160"
"17.59900","-152.35838","-0.08120"
"17.64200","-152.35838","-0.08686"
"17.66700","-152.35838","-0.06893"
"17.70200","-152.35838","-0.06760"
"17.74300","-152.35838","-0.07397"
"17.79900","-152.35838","-0.06912"
"17.84600","-152.35838","-0.08463"
"17.87500","-152.35838","-0.06249"
"17.90500","-152.35838","-0.06776"
"17.93900","-152.35838","-0.06031"
"17.97400","-152.35838","-0.07280"
"18.00300","-152.35838","-0.07455"
"18.03800","-152.35838","-0.06187"
"18.07600","-152.35838","-0.06248"
"18.10500","-152.35838","-0.05299"
"18.14600","-152.35838","-0.06247"
"18.17400","-152.35838","-0.07483"
"18.19800","-152.35838","-0.06623"
"18.24900","-152.35838","-0.07846"
"18.27600","-152.35838","-0.06175"
"18.31600","-152.35838","-0.06739"
"18.35700","-152.35838","-0.06975"
"18.39800","-152.35838","-0.06837"
"18.45600","-152.35838","-0.04857"
"18.49100","-152.35838","-0.05352"
"18.53800","-152.35838","-0.05046"
"18.56600","-152.35838","-0.05182"
"18.59700","-152.35838","-0.05753"
"18.63200","-152.35838","-0.04750"
"18.67100","-152.35838","-0.05762"
"18.71100","-152.35838","-0.07012"
"18.76200","-152.35838","-0.05658"
"18.79600","-152.35838","-0.03382"
"18.82400","-152.35838","-0.06656"
"18.86100","-152.35838","-0.06126"
"18.91100","-152.35838","-0.05634"
"18.95400","-152.35838","-0.05386"
"18.98200","-152.35838","-0.05357"
"19.02100","-152.35838","-0.04643"
"19.07300","-152.35838","-0.04440"
"19.11200","-152.35838","-0.05479"
"19.13700","-152.35838","-0.05006"
"19.17200","-152.35838","-0.04864"
"19.20700","-152.35838","-0.03115"
"19.23400","-152.35838","-0.04717"
"19.27000","-152.35838","-0.05194"
"19.30400","-152.35838","-0.05740"
"19.35000","-152.35838","-0.04663"
"19.36900","-152.35838","-0.04472"
"19.40400","-152.35838","-0.04684"
"19.44700","-152.35838","-0.04157"
"19.49000","-152.35838","-0.05764"
"19.52300","-152.35838","-0.02735"
"19.56300","-152.35838","-0.04211"
"19.59600","-152.35838","-0.05556"
"19.63900","-152.35838","-0.04509"
"19.67700","-152.35838","-0.05636"
"19.72400","-152.35838","-0.03844"
"19.75500","-152.35838","-0.06403"
"19.77800","-152.35838","-0.04182"
"19.80500","-152.35838","-0.06349"
"19.84900","-152.35838","-0.03876"
"19.89600","-152.35838","-0.05062"
"19.93700","-152.35838","-0.05177"
"19.96000","-152.35838","-0.04333"
"20.00300","-152.35838","-0.04919"
"20.02600","-152.35838","-0.03850"
"20.07100","-152.35838","-0.05575"
"20.10500","-152.35838","-0.03633"
"20.12000","-152.35838","-0.05111"
"20.16400","-152.35838","-0.04817"
"20.21000","-152.35838","-0.05403"
"20.25000","-152.35838","-0.04393"
"20.28400","-152.35838","-0.05407"
"20.32900","-152.35838","-0.03642"
"20.36700","-152.35838","-0.04721"
"20.40700","-152.35838","-0.03810"
"20.45000","-152.35838","-0.04023"
"20.48200","-152.35838","-0.05907"
"20.51200","-152.35838","-0.02391"
"20.54400","-152.35838","-0.06162"
"20.57500","-152.35838","-0.03062"
"20.61800","-152.35838","-0.04025"
"20.66000","-152.35838","-0.03074"
"20.69100","-152.35838","-0.04611"
"20.73000","-152.35838","-0.03892"
"20.75800","-152.35838","-0.03064"
"20.79200","-152.35838","-0.04065"
"20.83300","-152.35838","-0.04700"
"20.86700","-152.35838","-0.03420"
"20.91000","-152.35838","-0.05214"
"20.94400","-152.35838","-0.03383"
"20.97100","-152.35838","-0.03983"
"21.01300","-152.35838","-0.04096"
"21.05100","-152.35838","-0.04787"
"21.08600","-152.35838","-0.04170"
"21.13400","-152.35838","-0.05159"
"21.18700","-152.35838","-0.04944"
"21.23300","-152.35838","-0.03051"
"21.26900","-152.35838","-0.03872"
"21.29900","-152.35838","-0.03995"
"21.33300","-152.35838","-0.03127"
"21.36500","-152.35838","-0.05266"
"21.40800","-152.35838","-0.02722"
"21.45000","-152.35838","-0.04561"
"21.48200","-152.35838","-0.04314"
"21.51600","-152.35838","-0.05375"
"21.55700","-152.35838","-0.03898"
"21.61100","-152.35838","-0.05416"
"21.65400","-152.35838","-0.02563"
"21.68800","-152.35838","-0.04068"
"21.72100","-152.35838","-0.03863"
"21.77200","-152.35838","-0.04040"
"21.79900","-152.35838","-0.04923"
"21.83800","-152.35838","-0.04955"
"21.90200","-152.35838","-0.04222"
"21.95400","-152.35838","-0.04042"
"22.00100","-152.35838","-0.02857"
"22.03500","-152.35838","-0.04194"
"22.07400","-152.35838","-0.03815"
"22.10200","-152.35838","-0.02598"
"22.14900","-152.35838","-0.03201"
"22.19800","-152.35838","-0.02924"
"22.22900","-152.35838","-0.03907"
"22.27500","-152.35838","-0.03414"
"22.32000","-152.35838","-0.02948"
"22.37200","-152.35838","-0.03563"
"22.41600","-152.35838","-0.05272"
"22.45200","-152.35838","-0.07916"
"22.47900","-152.35838","-0.15856"
"22.51000","-152.35838","-0.20461"
"22.53200","-152.35838","-0.25965"
"22.58300","-152.35838","-0.24735"
"22.62700","-152.35838","-0.20765"
"22.66300","-152.35838","-0.20014"
"22.71500","-152.35838","-0.19137"
"22.74900","-152.35838","-0.20110"
"22.77900","-152.35838","-0.18852"
"22.80500","-152.35838","-0.18538"
"22.82900","-152.35838","-0.17517"
"22.85500","-152.35838","-0.19189"
"22.89300","-152.35838","-0.18202"
"22.91500","-152.35838","-0.16490"
"22.94600","-152.35838","-0.15422"
"22.97500","-152.35838","-0.15115"
"23.02300","-152.35838","-0.13358"
"23.04500","-152.35838","-0.14538"
"23.09500","-152.35838","-0.11634"
"23.13100","-152.35838","-0.12022"
"23.16900","-152.35838","-0.11721"
"23.20800","-152.35838","-0.11660"
"23.26100","-152.35838","-0.09904"
"23.31100","-152.35838","-0.08789"
"23.35700","-152.35838","-0.08353"
"23.37800","-152.35838","-0.09570"
"23.41300","-152.35838","-0.07738"
"23.44400","-152.35838","-0.07681"
"23.48700","-152.35838","-0.07210"
"23.52400","-152.35838","-0.07417"
"23.55200","-152.35838","-0.05920"
"23.58900","-152.35838","-0.06084"
"23.63200","-152.35838","-0.06698"
"23.67100","-152.35838","-0.07696"
"23.71100","-152.35838","-0.08369"
"23.75800","-152.35838","-0.06551"
"23.78300","-152.35838","-0.08213"
"23.83000","-152.35838","-0.08678"
"23.85200","-152.35838","-0.06375"
"23.88400","-152.35838","-0.09876"
"23.91100","-152.35838","-0.08515"
"23.93800","-152.35838","-0.07948"
"23.97700","-152.35838","-0.06953"
"24.02000","-152.35838","-0.05744"
"24.05200","-152.35838","-0.07296"
"24.08700","-152.35838","-0.07284"
"24.10700","-152.35838","-0.06086"
"24.14800","-152.35838","-0.08220"
"24.18800","-152.35838","-0.08726"
"24.22600","-152.35838","-0.07072"
"24.26700","-152.35838","-0.06068"
"24.31200","-152.35838","-0.06965"
"24.34600","-152.35838","-0.06671"
"24.37900","-152.35838","-0.05919"
"24.42800","-152.35838","-0.06552"
"24.46300","-152.35838","-0.08093"
"24.49200","-152.35838","-0.06426"
"24.54000","-152.35838","-0.05497"
"24.56300","-152.35838","-0.05966"
"24.59700","-152.35838","-0.06269"
"24.63500","-152.35838","-0.04794"
"24.66900","-152.35838","-0.05617"
"24.70100","-152.35838","-0.07079"
"24.73700","-152.35838","-0.04660"
"24.77400","-152.35838","-0.05587"
"24.80400","-152.35838","-0.05746"
"24.84600","-152.35838","-0.03531"
"24.88600","-152.35838","-0.05968"
"24.92500","-152.35838","-0.07131"
"24.97500","-152.35838","-0.05452"
"25.02500","-152.35838","-0.05673"
"25.06500","-152.35838","-0.05879"
"25.09800","-152.35838","-0.04914"
"25.13200","-152.35838","-0.07217"
"25.16700","-152.35838","-0.05856"
"25.20100","-152.35838","-0.05178"
"25.23800","-152.35838","-0.05641"
"25.26700","-152.35838","-0.05780"
"25.31400","-152.35838","-0.04193"
"25.33600","-152.35838","-0.05400"
"25.38000","-152.35838","-0.06496"
"25.41100","-152.35838","-0.04789"
"25.46300","-152.35838","-0.04641"
"25.49700","-152.35838","-0.04985"
"25.52800","-152.35838","-0.03315"
"25.56000","-152.35838","-0.04512"
"25.60400","-152.35838","-0.04051"
"25.65000","-152.35838","-0.04023"
"25.68300","-152.35838","-0.06965"
"25.72000","-152.35838","-0.05981"
"25.75800","-152.35838","-0.05118"
"25.79900","-152.35838","-0.06608"
"25.83400","-152.35838","-0.05839"
"25.89200","-152.35838","-0.05428"
"25.91800","-152.35838","-0.04592"
"25.95300","-152.35838","-0.05789"
"25.99600","-152.35838","-0.06116"
"26.03500","-152.35838","-0.04490"
"26.06700","-152.35838","-0.04458"
"26.09300","-152.35838","-0.04317"
"26.14700","-152.35838","-0.05635"
"26.20100","-152.35838","-0.06017"
"26.23500","-152.35838","-0.04618"
"26.28400","-152.35838","-0.03352"
"26.33900","-152.35838","-0.04925"
"26.37800","-152.35838","-0.04016"
"26.39900","-152.35838","-0.05668"
"26.43300","-152.35838","-0.02671"
"26.47000","-152.35838","-0.04683"
"26.49900","-152.35838","-0.03045"
"26.54900","-152.35838","-0.04478"
"26.59100","-152.35838","-0.02180"
"26.64100","-152.35838","-0.03158"
"26.69200","-152.35838","-0.04656"
"26.72400","-152.35838","-0.04800"
"26.76900","-152.35838","-0.02600"
"26.80400","-152.35838","-0.03424"
"26.84600","-152.35838","-0.01268"
"26.87200","-152.35838","-0.02840"
"26.90700","-152.35838","-0.02664"
"26.94100","-152.35838","-0.04387"
"26.98500","-152.35838","-0.03426"
"27.03100","-152.35838","-0.03533"
"27.06900","-152.35838","-0.03687"
"27.10200","-152.35838","-0.04307"
"27.15100","-152.35838","-0.03402"
"27.17900","-152.35838","-0.04665"
"27.22000","-152.35838","-0.01481"
"27.25100","-152.35838","-0.02768"
"27.29200","-152.35838","-0.04622"
"27.34500","-152.35838","-0.03925"
"27.39300","-152.35838","-0.04416"
"27.43000","-152.35838","-0.05202"
"27.46200","-152.35838","-0.02942"
"27.50700","-152.35838","-0.03967"
"27.54700","-152.35838","-0.02814"
"27.58400","-152.35838","-0.04307"
"27.62200","-152.35838","-0.03226"
"27.65700","-152.35838","-0.03530"
"27.69700","-152.35838","-0.03909"
"27.73000","-152.35838","-0.03580"
"27.78100","-152.35838","-0.03396"
"27.82000","-152.35838","-0.03260"
"27.85000","-152.35838","-0.02542"
"27.88900","-152.35838","-0.01544"
"27.92600","-152.35838","-0.02994"
"27.97300","-152.35838","-0.02915"
"28.01500","-152.35838","-0.03113"
"28.05600","-152.35838","-0.03155"
"28.08200","-152.35838","-0.03597"
"28.11900","-152.35838","-0.06362"
"28.15000","-152.35838","-0.02600"
"28.20300","-152.35838","-0.04550"
"28.24600","-152.35838","-0.03545"
"28.29000","-152.35838","-0.01327"
"28.32400","-152.35838","-0.02764"
"28.36800","-152.35838","-0.04520"
"28.40200","-152.35838","-0.02739"
"28.45700","-152.35838","-0.04806"
"28.49100","-152.35838","-0.02003"
"28.52600","-152.35838","-0.02410"
"28.55700","-152.35838","-0.04044"
"28.60200","-152.35838","-0.02260"
"28.65300","-152.35838","-0.02554"
"28.68000","-152.35838","-0.02531"
"28.70700","-152.35838","-0.04749"
"28.73700","-152.35838","-0.03067"
"28.78100","-152.35838","-0.02702"
"28.82100","-152.35838","-0.03209"
"28.85600","-152.35838","-0.03607"
"28.89900","-152.35838","-0.03203"
"28.92200","-152.35838","-0.04434"
"28.95900","-152.35838","-0.04929"
"28.99400","-152.35838","-0.03741"
"29.02600","-152.35838","-0.02327"
"29.06200","-152.35838","-0.04213"
"29.09700","-152.35838","-0.03119"
"29.13800","-152.35838","-0.04590"
"29.17100","-152.35838","-0.01880"
"29.20700","-152.35838","-0.03618"
"29.23300","-152.35838","-0.03004"
"29.28600","-152.35838","-0.04013"
"29.31800","-152.35838","-0.02839"
"29.36100","-152.35838","-0.04015"
"29.40100","-152.35838","-0.03801"
"29.42600","-152.35838","-0.03207"
"29.46800","-152.35838","-0.02502"
"29.50100","-152.35838","-0.05473"
"29.54000","-152.35838","-0.03059"
"29.57700","-152.35838","-0.04442"
"29.61100","-152.35838","-0.04754"
"29.65000","-152.35838","-0.04132"
"29.69000","-152.35838","-0.03469"
"29.72500","-152.35838","-0.04690"
"29.75700","-152.35838","-0.03977"
"29.79400","-152.35838","-0.04551"
"29.82500","-152.35838","-0.07342"
"29.85400","-152.35838","-0.13406"
"29.89000","-152.35838","-0.23611"
"29.92000","-152.35838","-0.32613"
"29.94900","-152.35838","-0.31845"
"29.98900","-152.35838","-0.33536"
"30.02800","-152.35838","-0.31125"
"30.05000","-152.35838","-0.29044"
"30.08100","-152.35838","-0.29041"
"30.11600","-152.35838","-0.29556"
"30.16500","-152.35838","-0.28344"
"30.20200","-152.35838","-0.25569"
"30.24000","-152.35838","-0.23528"
"30.26200","-152.35838","-0.19763"
"30.29900","-152.35838","-0.19808"
"30.34100","-152.35838","-0.19436"
"30.38400","-152.35838","-0.18710"
"30.40700","-152.35838","-0.16304"
"30.44700","-152.35838","-0.17142"
"30.47200","-152.35838","-0.16377"
"30.50400","-152.35838","-0.16013"
"30.54600","-152.35838","-0.14875"
"30.58800","-152.35838","-0.13849"
"30.63600","-152.35838","-0.13635"
"30.67500","-152.35838","-0.11954"
"30.71800","-152.35838","-0.12639"
"30.76700","-152.35838","-0.12579"
"30.80500","-152.35838","-0.11730"
"30.84500","-152.35838","-0.10900"
"30.87100","-152.35838","-0.08723"
"30.89900","-152.35838","-0.10208"
"30.92300","-152.35838","-0.08763"
"30.96100","-152.35838","-0.08635"
"30.99300","-152.35838","-0.07793"
"31.03000","-152.35838","-0.08801"
"31.07400","-152.35838","-0.07826"
"31.10500","-152.35838","-0.09160"
"31.12900","-152.35838","-0.06394"
"31.16900","-152.35838","-0.08522"
"31.20900","-152.35838","-0.09341"
"31.25300","-152.35838","-0.06348"
"31.28000","-152.35838","-0.08290"
"31.31700","-152.35838","-0.07120"
"31.34800","-152.35838","-0.05537"
"31.38200","-152.35838","-0.06976"
"31.42100","-152.35838","-0.06956"
"31.45100","-152.35838","-0.05878"
"31.49100","-152.35838","-0.05317"
"31.53900","-152.35838","-0.05782"
"31.58400","-152.35838","-0.05809"
"31.62100","-152.35838","-0.05793"
"31.64300","-152.35838","-0.03639"
"31.68200","-152.35838","-0.05877"
"31.72600","-152.35838","-0.05319"
"31.75800","-152.35838","-0.04137"
"31.78500","-152.35838","-0.04315"
"31.83400","-152.35838","-0.07105"
"31.85900","-152.35838","-0.03674"
"31.88900","-152.35838","-0.04942"
"31.91700","-152.35838","-0.03317"
"31.95600","-152.35838","-0.01550"
"32.00000","-152.35838","-0.03998"
"32.03900","-152.35838","-0.05877"
"32.07000","-152.35838","-0.03144"
"32.10000","-152.35838","-0.02973"
"32.14400","-152.35838","-0.05085"
"32.18800","-152.35838","-0.04966"
"32.21300","-152.35838","-0.01832"
"32.24400","-152.35838","-0.03316"
"32.26700","-152.35838","-0.01796"
"32.31500","-152.35838","-0.03026"
"32.36900","-152.35838","-0.02820"
"32.42400","-152.35838","-0.04233"
"32.46200","-152.35838","-0.03668"
"32.50300","-152.35838","-0.04200"
"32.54300","-152.35838","-0.04474"
"32.57400","-152.35838","-0.03538"
"32.61400","-152.35838","-0.05618"
"32.64500","-152.35838","-0.03977"
"32.68900","-152.35838","-0.02651"
"32.73100","-152.35838","-0.04101"
"32.75900","-152.35838","-0.03722"
"32.78300","-152.35838","-0.02714"
"32.81900","-152.35838","-0.02953"
"32.85900","-152.35838","-0.03583"
"32.90300","-152.35838","-0.04567"
"32.93300","-152.35838","-0.03636"
"32.97400","-152.35838","-0.03097"
"33.00400","-152.35838","-0.03884"
"33.02700","-152.35838","-0.04374"
"33.06200","-152.35838","-0.02223"
"33.10300","-152.35838","-0.03135"
"33.14300","-152.35838","-0.04039"
"33.17500","-152.35838","-0.03642"
"33.20500","-152.35838","-0.03596"
"33.24800","-152.35838","-0.03416"
"33.28700","-152.35838","-0.03460"
"33.31900","-152.35838","-0.04198"
"33.35900","-152.35838","-0.02579"
"33.39600","-152.35838","-0.03384"
"33.43100","-152.35838","-0.03548"
"33.47900","-152.35838","-0.03273"
"33.53100","-152.35838","-0.04790"
"33.59200","-152.35838","-0.03129"
"33.62000","-152.35838","-0.03845"
"33.64900","-152.35838","-0.02162"
"33.67900","-152.35838","-0.03106"
"33.71300","-152.35838","-0.03112"
"33.75100","-152.35838","-0.02805"
"33.78500","-152.35838","-0.04429"
"33.80000","-152.35838","-0.02572"
"33.85500","-152.35838","-0.02708"
"33.90400","-152.35838","-0.03400"
"33.93500","-152.35838","-0.03940"
"33.98300","-152.35838","-0.02938"
"34.02600","-152.35838","-0.03706"
"34.07600","-152.35838","-0.03384"
"34.12400","-152.35838","-0.04020"
"34.16300","-152.35838","-0.02636"
"34.20100","-152.35838","-0.04587"
"34.22300","-152.35838","-0.03537"
"34.26300","-152.35838","-0.04168"
"34.29700","-152.35838","-0.04659"
"34.33400","-152.35838","-0.03848"
"34.36700","-152.35838","-0.02201"
"34.40200","-152.35838","-0.03834"
"34.43300","-152.35838","-0.02235"
"34.47800","-152.35838","-0.03382"
"34.50000","-152.35838","-0.03959"
"34.53900","-152.35838","-0.03218"
"34.59500","-152.35838","-0.01031"
"34.63600","-152.35838","-0.03661"
"34.66200","-152.35838","-0.04916"
"34.68500","-152.35838","-0.03513"
"34.72900","-152.35838","-0.03664"
"34.76200","-152.35838","-0.02634"
"34.79900","-152.35838","-0.02048"
"34.84000","-152.35838","-0.04487"
"34.87500","-152.35838","-0.03150"
"34.91000","-152.35838","-0.02487"
"34.93900","-152.35838","-0.03324"
"34.98100","-152.35838","-0.02820"
"35.00100","-152.35838","-0.04278"
"35.03400","-152.35838","-0.02361"
"35.09000","-152.35838","-0.04322"
"35.13100","-152.35838","-0.04323"
"35.15900","-152.35838","-0.01155"
"35.19300","-152.35838","-0.03672"
"35.22400","-152.35838","-0.02041"
"35.25600","-152.35838","-0.04389"
"35.28600","-152.35838","-0.02650"
"35.33700","-152.35838","-0.03146"
"35.36500","-152.35838","-0.02991"
"35.41200","-152.35838","-0.03012"
"35.44200","-152.35838","-0.03168"
"35.46900","-152.35838","-0.02063"
"35.52100","-152.35838","-0.03777"
"35.55000","-152.35838","-0.02781"
"35.59900","-152.35838","-0.03563"
"35.63700","-152.35838","-0.01971"
"35.66600","-152.35838","-0.03253"
"35.71700","-152.35838","-0.03187"
"35.76200","-152.35838","-0.04074"
"35.78300","-152.35838","-0.02341"
"35.83300","-152.35838","-0.02553"
"35.86800","-152.35838","-0.02984"
"35.91200","-152.35838","-0.02395"
"35.94300","-152.35838","-0.04025"
"35.97600","-152.35838","-0.02874"
"36.00800","-152.35838","-0.03701"
"36.05500","-152.35838","-0.04174"
"36.08600","-152.35838","-0.01895"
"36.13100","-152.35838","-0.04467"
"36.16600","-152.35838","-0.03879"
"36.21200","-152.35838","-0.02304"
"36.26300","-152.35838","-0.02711"
"36.29800","-152.35838","-0.03046"
"36.34100","-152.35838","-0.02105"
"36.37600","-152.35838","-0.05104"
"36.41100","-152.35838","-0.02823"
"36.43900","-152.35838","-0.04016"
"36.48500","-152.35838","-0.04173"
"36.52400","-152.35838","-0.02596"
"36.57100","-152.35838","-0.03535"
"36.62100","-152.35838","-0.03483"
"36.66200","-152.35838","-0.02760"
"36.70900","-152.35838","-0.03220"
"36.74800","-152.35838","-0.04845"
"36.78800","-152.35838","-0.03527"
"36.82200","-152.35838","-0.08179"
"36.85000","-152.35838","-0.17074"
"36.88200","-152.35838","-0.25371"
"36.92100","-152.35838","-0.28613"
"36.93400","-152.35838","-0.35975"
"36.96200","-152.35838","-0.44959"
"37.00600","-152.35838","-0.46381"
"37.04300","-152.35838","-0.44201"
"37.09500","-152.35838","-0.41196"
"37.13200","-152.35838","-0.39636"
"37.17500","-152.35838","-0.39821"
"37.22100","-152.35838","-0.37985"
"37.25700","-152.35838","-0.36280"
"37.30600","-152.35838","-0.35899"
"37.36200","-152.35838","-0.35426"
"37.40200","-152.35838","-0.33992"
"37.43200","-152.35838","-0.31932"
"37.47600","-152.35838","-0.32057"
"37.51700","-152.35838","-0.30484"
"37.55400","-152.35838","-0.30588"
"37.59800","-152.35838","-0.28410"
"37.63300","-152.35838","-0.27892"
"37.68400","-152.35838","-0.24671"
"37.71500","-152.35838","-0.25236"
"37.74200","-152.35838","-0.23263"
"37.77600","-152.35838","-0.19738"
"37.80400","-152.35838","-0.18899"
"37.84500","-152.35838","-0.16949"
"37.88700","-152.35838","-0.17309"
"37.91500","-152.35838","-0.18835"
"37.95100","-152.35838","-0.15211"
"37.98200","-152.35838","-0.14630"
"38.02500","-152.35838","-0.14752"
"38.08600","-152.35838","-0.12895"
"38.11700","-152.35838","-0.12429"
"38.15700","-152.35838","-0.12373"
"38.19300","-152.35838","-0.11853"
"38.23500","-152.35838","-0.11937"
"38.26500","-152.35838","-0.10710"
"38.29400","-152.35838","-0.10376"
"38.33800","-152.35838","-0.09825"
"38.37200","-152.35838","-0.08957"
"38.40600","-152.35838","-0.08929"
"38.43900","-152.35838","-0.09430"
"38.46500","-152.35838","-0.07632"
"38.50900","-152.35838","-0.06904"
"38.55100","-152.35838","-0.07722"
"38.58800","-152.35838","-0.08167"
"38.62600","-152.35838","-0.08007"
"38.64700","-152.35838","-0.08846"
"38.68100","-152.35838","-0.08842"
"38.71000","-152.35838","-0.07070"
"38.75500","-152.35838","-0.08354"
"38.78400","-152.35838","-0.06518"
"38.81100","-152.35838","-0.07366"
"38.85200","-152.35838","-0.08358"
"38.88600","-152.35838","-0.07466"
"38.91400","-152.35838","-0.06588"
"38.94700","-152.35838","-0.06823"
"38.99400","-152.35838","-0.07761"
"39.03800","-152.35838","-0.07399"
"39.09500","-152.35838","-0.07051"
"39.14000","-152.35838","-0.05594"
"39.17200","-152.35838","-0.07012"
"39.22000","-152.35838","-0.07770"
"39.25200","-152.35838","-0.05915"
"39.28500","-152.35838","-0.06692"
"39.32200","-152.35838","-0.06856"
"39.34900","-152.35838","-0.06264"
"39.40200","-152.35838","-0.05763"
"39.44800","-152.35838","-0.06320"
"39.49300","-152.35838","-0.05107"
"39.52400","-152.35838","-0.07449"
"39.56100","-152.35838","-0.05211"
"39.60300","-152.35838","-0.04415"
"39.65900","-152.35838","-0.04640"
"39.69900","-152.35838","-0.07821"
"39.73500","-152.35838","-0.06433"
"39.76200","-152.35838","-0.05794"
"39.79600","-152.35838","-0.03803"
"39.84000","-152.35838","-0.05154"
"39.86900","-152.35838","-0.05118"
"39.89500","-152.35838","-0.06139"
"39.92800","-152.35838","-0.06225"
"39.96300","-152.35838","-0.05526"
"39.98700","-152.35838","-0.06608"
"40.02500","-152.35838","-0.05902"
"40.06400","-152.35838","-0.05096"
"40.10500","-152.35838","-0.05329"
"40.14200","-152.35838","-0.06262"
"40.16300","-152.35838","-0.05448"
"40.20500","-152.35838","-0.05180"
"40.25900","-152.35838","-0.04023"
"40.28500","-152.35838","-0.04896"
"40.33000","-152.35838","-0.05382"
"40.38600","-152.35838","-0.04006"
"40.42600","-152.35838","-0.03989"
"40.45600","-152.35838","-0.04431"
"40.50000","-152.35838","-0.05996"
"40.53500","-152.35838","-0.04489"
"40.58400","-152.35838","-0.04684"
"40.62200","-152.35838","-0.03646"
"40.65500","-152.35838","-0.04093"
"40.69500","-152.35838","-0.03981"
"40.72000","-152.35838","-0.04824"
"40.77200","-152.35838","-0.02979"
"40.81100","-152.35838","-0.04546"
"40.84700","-152.35838","-0.03519"
"40.88000","-152.35838","-0.04597"
"40.90000","-152.35838","-0.03857"
"40.94800","-152.35838","-0.03140"
"40.99100","-152.35838","-0.03905"
"41.02800","-152.35838","-0.03463"
"41.06300","-152.35838","-0.04242"
"41.10900","-152.35838","-0.04052"
"41.15700","-152.35838","-0.03995"
"41.19600","-152.35838","-0.03085"
"41.24700","-152.35838","-0.03674"
"41.29300","-152.35838","-0.03431"
"41.33400","-152.35838","-0.04436"
"41.36400","-152.35838","-0.02568"
"41.39800","-152.35838","-0.03533"
"41.44900","-152.35838","-0.02221"
"41.48400","-152.35838","-0.04347"
"41.52900","-152.35838","-0.03351"
"41.57500","-152.35838","-0.04525"
"41.63400","-152.35838","-0.04284"
"41.67700","-152.35838","-0.03141"
"41.71600","-152.35838","-0.02332"
"41.75300","-152.35838","-0.03247"
"41.81400","-152.35838","-0.02643"
"41.84100","-152.35838","-0.02464"
"41.87800","-152.35838","-0.02525"
"41.92100","-152.35838","-0.02911"
"41.95900","-152.35838","-0.02815"
"42.01200","-152.35838","-0.04408"
"42.04600","-152.35838","-0.03552"
"42.08500","-152.35838","-0.01638"
"42.11600","-152.35838","-0.02467"
"42.15000","-152.35838","-0.03617"
"42.18700","-152.35838","-0.03141"
"42.22900","-152.35838","-0.03512"
"42.25500","-152.35838","-0.03022"
"42.29900","-152.35838","-0.03414"
"42.33200","-152.35838","-0.02218"
"42.36400","-152.35838","-0.03875"
"42.40300","-152.35838","-0.03133"
"42.43400","-152.35838","-0.02176"
"42.46900","-152.35838","-0.03354"
"42.50500","-152.35838","-0.05482"
"42.53900","-152.35838","-0.02761"
"42.57400","-152.35838","-0.02028"
"42.61200","-152.35838","-0.02819"
"42.65300","-152.35838","-0.03042"
"42.68700","-152.35838","-0.02669"
"42.70800","-152.35838","-0.02276"
"42.75300","-152.35838","-0.02817"
"42.79600","-152.35838","-0.02335"
"42.83300","-152.35838","-0.02246"
"42.87900","-152.35838","-0.03420"
"42.93000","-152.35838","-0.03185"
"42.97800","-152.35838","-0.03904"
"43.01300","-152.35838","-0.01538"
"43.06400","-152.35838","-0.02512"
"43.09300","-152.35838","-0.04642"
"43.13900","-152.35838","-0.02599"
"43.18500","-152.35838","-0.01717"
"43.23000","-152.35838","-0.03658"
"43.26300","-152.35838","-0.01102"
"43.31600","-152.35838","-0.02551"
"43.34900","-152.35838","-0.03064"
"43.39400","-152.35838","-0.03208"
"43.43100","-152.35838","-0.04145"
"43.45700","-152.35838","-0.03188"
"43.48100","-152.35838","-0.03800"
"43.52300","-152.35838","-0.01796"
"43.55200","-152.35838","-0.00995"
"43.59500","-152.35838","-0.04648"
"43.63200","-152.35838","-0.03117"
"43.67000","-152.35838","-0.02694"
"43.69700","-152.35838","-0.03836"
"43.73600","-152.35838","-0.03554"
"43.77000","-152.35838","-0.04017"
"43.80700","-152.35838","-0.02304"
"43.83700","-152.35838","-0.03014"
"43.88100","-152.35838","-0.02619"
"43.91700","-152.35838","-0.02369"
"43.95600","-152.35838","-0.02357"
"43.98300","-152.35838","-0.02672"
"44.02400","-152.35838","-0.03439"
"44.05100","-152.35838","-0.01751"
"44.08800","-152.35838","-0.02073"
"44.13500","-152.35838","-0.04469"
"44.16700","-152.35838","-0.02822"
"44.20500","-152.35838","-0.03374"
"44.23200","-152.35838","-0.01714"
"44.25600","-152.35838","-0.02540"
"44.29800","-152.35838","-0.03384"
"44.34100","-152.35838","-0.01554"
"44.38200","-152.35838","-0.01365"
"44.41700","-152.35838","-0.04781"
"44.45800","-152.35838","-0.03221"
"44.48200","-152.35838","-0.01050"
"44.52000","-152.35838","-0.02835"
"44.55300","-152.35838","-0.01130"
"44.58600","-152.35838","-0.02462"
"44.60600","-152.35838","-0.02049"
"44.65000","-152.35838","-0.02182"
"44.68800","-152.35838","-0.04112"
"44.72000","-152.35838","-0.02169"
"44.75700","-152.35838","-0.02668"
"44.78100","-152.35838","-0.01898"
"44.81800","-152.35838","-0.02635"
"44.86400","-152.35838","-0.03151"
"44.89000","-152.35838","-0.04494"
"44.92900","-152.35838","-0.03033"
"44.96600","-152.35838","-0.02589"
"45.01400","-152.35838","-0.03316"
"45.05800","-152.35838","-0.02524"
"45.10400","-152.35838","-0.04419"
"45.13700","-152.35838","-0.02798"
"45.17700","-152.35838","-0.03528"
"45.20300","-152.35838","-0.03061"
"45.24100","-152.35838","-0.03162"
"45.28100","-152.35838","-0.04462"
"45.31000","-152.35838","-0.02333"
"45.34200","-152.35838","-0.03299"
"45.38100","-152.35838","-0.03115"
"45.41400","-152.35838","-0.02756"
"45.45100","-152.35838","-0.02475"
"45.49300","-152.35838","-0.03353"
"45.52800","-152.35838","-0.01870"
"45.56600","-152.35838","-0.02602"
"45.61400","-152.35838","-0.03541"
"45.65000","-152.35838","-0.01717"
"45.68400","-152.35838","-0.02300"
"45.74200","-152.35838","-0.03261"
"45.79200","-152.35838","-0.03705"
"45.82900","-152.35838","-0.03555"
"45.87700","-152.35838","-0.01682"
"45.90400","-152.35838","-0.02074"
"45.94700","-152.35838","-0.01983"
"45.99900","-152.35838","-0.02708"
"46.02400","-152.35838","-0.02674"
"46.06800","-152.35838","-0.04208"
"46.11000","-152.35838","-0.01970"
"46.15000","-152.35838","-0.02400"
"46.19100","-152.35838","-0.01770"
"46.23300","-152.35838","-0.03391"
"46.26400","-152.35838","-0.02296"
"46.30500","-152.35838","-0.03423"
"46.33400","-152.35838","-0.11156"
"46.36500","-152.35838","-0.19669"
"46.40500","-152.35838","-0.27170"
"46.43200","-152.35838","-0.35765"
"46.46800","-152.35838","-0.42543"
"46.49800","-152.35838","-0.50898"
"46.53700","-152.35838","-0.55427"
"46.58000","-152.35838","-0.58413"
"46.60900","-152.35838","-0.57170"
"46.64400","-152.35838","-0.52919"
"46.67300","-152.35838","-0.53831"
"46.71900","-152.35838","-0.52579"
"46.75600","-152.35838","-0.52408"
"46.79700","-152.35838","-0.54286"
"46.83600","-152.35838","-0.53492"
"46.86800","-152.35838","-0.52383"
"46.90700","-152.35838","-0.51214"
"46.95000","-152.35838","-0.54310"
"46.97700","-152.35838","-0.51869"
"47.01300","-152.35838","-0.52690"
"47.05000","-152.35838","-0.52289"
"47.08300","-152.35838","-0.50673"
"47.12000","-152.35838","-0.49532"
"47.16600","-152.35838","-0.49939"
"47.21300","-152.35838","-0.48989"
"47.25700","-152.35838","-0.46232"
"47.32100","-152.35838","-0.43578"
"47.37500","-152.35838","-0.42478"
"47.40400","-152.35838","-0.42090"
"47.45300","-152.35838","-0.40332"
"47.48600","-152.35838","-0.37486"
"47.54400","-152.35838","-0.34615"
"47.58700","-152.35838","-0.32294"
"47.62000","-152.35838","-0.33031"
"47.66000","-152.35838","-0.30882"
"47.70300","-152.35838","-0.31578"
"47.74100","-152.35838","-0.29531"
"47.79500","-152.35838","-0.29777"
"47.83300","-152.35838","-0.28804"
"47.87200","-152.35838","-0.29764"
"47.90200","-152.35838","-0.26626"
"47.93600","-152.35838","-0.27656"
"47.98400","-152.35838","-0.27283"
"48.01200","-152.35838","-0.25964"
"48.05400","-152.35838","-0.25313"
"48.10000","-152.35838","-0.24268"
"48.13900","-152.35838","-0.24123"
"48.18200","-152.35838","-0.25486"
"48.22100","-152.35838","-0.24832"
"48.26100","-152.35838","-0.24754"
"48.29300","-152.35838","-0.24416"
"48.33500","-152.35838","-0.24942"
"48.34700","-152.35838","-0.25691"
"48.39500","-152.35838","-0.24132"
"48.44900","-152.35838","-0.23301"
"48.49200","-152.35838","-0.23675"
"48.53600","-152.35838","-0.24177"
"48.57200","-152.35838","-0.22927"
"48.60000","-152.35838","-0.23495"
"48.64300","-152.35838","-0.21761"
"48.67600","-152.35838","-0.22344"
"48.71600","-152.35838","-0.20633"
"48.77000","-152.35838","-0.20516"
"48.80300","-152.35838","-0.21640"
"48.85300","-152.35838","-0.21368"
"48.89100","-152.35838","-0.20907"
"48.93100","-152.35838","-0.20705"
"48.96900","-152.35838","-0.20896"
"49.00300","-152.35838","-0.20967"
"49.05100","-152.35838","-0.21607"
"49.09200","-152.35838","-0.20388"
"49.11600","-152.35838","-0.19260"
"49.15800","-152.35838","-0.20397"
"49.20000","-152.35838","-0.20044"
"49.25900","-152.35838","-0.19352"
"49.28400","-152.35838","-0.20295"
"49.32300","-152.35838","-0.18617"
"49.36400","-152.35838","-0.19860"
"49.39300","-152.35838","-0.18473"
"49.43600","-152.35838","-0.16682"
"49.47200","-152.35838","-0.19713"
"49.51300","-152.35838","-0.19541"
"49.55700","-152.35838","-0.17379"
"49.60900","-152.35838","-0.18132"
"49.64900","-152.35838","-0.17282"
"49.69400","-152.35838","-0.16673"
"49.72900","-152.35838","-0.20179"
"49.77700","-152.35838","-0.18476"
"49.80300","-152.35838","-0.17402"
"49.84800","-152.35838","-0.17445"
"49.87000","-152.35838","-0.15987"
"49.89700","-152.35838","-0.16642"
"49.93300","-152.35838","-0.17800"
"49.96000","-152.35838","-0.16234"
"49.98300","-152.35838","-0.09858"
"50.03000","-152.35838","-0.08419"
"50.06300","-152.35838","-0.05118"
"50.10100","-152.35838","-0.05834"
"50.13800","-152.35838","-0.06800"
"50.18900","-152.35838","-0.07053"
"50.22900","-152.35838","-0.07440"
"50.27400","-152.35838","-0.06139"
"50.31800","-152.35838","-0.07193"
"50.36100","-152.35838","-0.05101"
"50.38900","-152.35838","-0.06284"
"50.44100","-152.35838","-0.04907"
"50.47800","-152.35838","-0.04745"
"50.51000","-152.35838","-0.06091"
"50.54400","-152.35838","-0.05871"
"50.58100","-152.35838","-0.06351"
"50.61300","-152.35838","-0.05926"
"50.64900","-152.35838","-0.04967"
"50.69200","-152.35838","-0.04954"
"50.74200","-152.35838","-0.06076"
"50.79100","-152.35838","-0.04076"
"50.81700","-152.35838","-0.05598"
"50.86100","-152.35838","-0.07129"
"50.88900","-152.35838","-0.05627"
"50.93300","-152.35838","-0.04875"
"50.96600","-152.35838","-0.04646"
"50.99100","-152.35838","-0.04493"
"51.01900","-152.35838","-0.04563"
"51.05100","-152.35838","-0.05889"
"51.09200","-152.35838","-0.04153"
"51.13900","-152.35838","-0.04981"
"51.17000","-152.35838","-0.04669"
"51.19600","-152.35838","-0.03318"
"51.24000","-152.35838","-0.04302"
"51.27200","-152.35838","-0.05916"
"51.30000","-152.35838","-0.04724"
"51.33200","-152.35838","-0.03487"
"51.36400","-152.35838","-0.06021"
"51.39800","-152.35838","-0.04467"
"51.43800","-152.35838","-0.05970"
"51.46900","-152.35838","-0.04635"
"51.50600","-152.35838","-0.03570"
"51.54900","-152.35838","-0.05970"
"51.58900","-152.35838","-0.06026"
"51.62900","-152.35838","-0.04176"
"51.67200","-152.35838","-0.05311"
"51.71300","-152.35838","-0.05951"
"51.75800","-152.35838","-0.03686"
"51.79400","-152.35838","-0.04203"
"51.82400","-152.35838","-0.05285"
"51.86000","-152.35838","-0.03804"
"51.89200","-152.35838","-0.05953"
"51.93500","-152.35838","-0.05769"
"51.98500","-152.35838","-0.05918"
"52.04000","-152.35838","-0.05864"
"52.08700","-152.35838","-0.05137"
"52.13600","-152.35838","-0.05553"
"52.15100","-152.35838","-0.04060"