File: chapter 4/force/mini_patrick.is_tens_RawData/Specimen_RawData_7.csv
Time,Extension,Load
(s),(mm),(N)
"0.00000","-152.52029","-0.00632"
"0.06500","-152.52045","0.00115"
"0.11600","-152.52045","-0.00399"
"0.16900","-152.52045","0.00360"
"0.22000","-152.52042","0.00685"
"0.27800","-152.52042","0.02015"
"0.33000","-152.52039","0.00593"
"0.37400","-152.52039","-0.00367"
"0.40600","-152.52039","-0.00796"
"0.45700","-152.52036","0.00252"
"0.50600","-152.52036","-0.00661"
"0.53800","-152.52036","0.00805"
"0.58300","-152.52036","0.00678"
"0.62100","-152.52036","0.00316"
"0.66800","-152.52032","0.00677"
"0.71600","-152.52032","-0.01438"
"0.76900","-152.52032","0.00018"
"0.80100","-152.52032","0.00900"
"0.85600","-152.52032","-0.00916"
"0.89900","-152.52032","0.02117"
"0.93100","-152.52032","0.01261"
"0.97700","-152.52032","0.01095"
"1.01200","-152.52032","-0.00797"
"1.05800","-152.52029","0.00833"
"1.11700","-152.52029","0.00239"
"1.16700","-152.52029","-0.01229"
"1.20800","-152.52029","0.00770"
"1.25300","-152.52029","0.01521"
"1.30100","-152.52029","-0.00548"
"1.34900","-152.52029","-0.00803"
"1.38700","-152.52029","0.00863"
"1.42800","-152.52029","-0.00560"
"1.45800","-152.52029","0.01454"
"1.50400","-152.52029","-0.00782"
"1.54700","-152.52029","0.00608"
"1.60500","-152.52029","-0.00337"
"1.65500","-152.52029","0.01712"
"1.69600","-152.52029","-0.00261"
"1.74700","-152.52029","0.01015"
"1.79700","-152.52029","0.00538"
"1.85000","-152.52029","0.00746"
"1.89800","-152.52029","0.00439"
"1.93800","-152.52029","0.00173"
"1.98300","-152.52029","0.00151"
"2.02100","-152.52029","-0.00430"
"2.08700","-152.52029","0.00121"
"2.12600","-152.52029","0.00033"
"2.18200","-152.52029","0.00766"
"2.23700","-152.52029","0.00452"
"2.30300","-152.52029","-0.00099"
"2.35800","-152.52029","0.00556"
"2.40900","-152.52029","-0.00825"
"2.46800","-152.52029","0.01237"
"2.52100","-152.52029","0.01502"
"2.57600","-152.52029","0.00015"
"2.63800","-152.52029","0.01421"
"2.68600","-152.52029","0.00338"
"2.72700","-152.52029","0.00834"
"2.78200","-152.52029","0.01419"
"2.82200","-152.52029","-0.01532"
"2.86000","-152.52029","-0.00775"
"2.91100","-152.52029","-0.01811"
"2.96100","-152.52029","-0.02001"
"2.99700","-152.52029","-0.01921"
"3.04900","-152.52029","-0.00173"
"3.09000","-152.52029","-0.02265"
"3.14700","-152.52029","-0.02391"
"3.19100","-152.52029","-0.00261"
"3.23800","-152.52029","-0.02544"
"3.29200","-152.52029","-0.01056"
"3.36500","-152.52029","-0.00747"
"3.42500","-152.52029","-0.00269"
"3.47100","-152.52029","0.00128"
"3.52100","-152.52029","-0.01241"
"3.56300","-152.52029","0.00196"
"3.62400","-152.52029","-0.00568"
"3.68100","-152.52029","-0.00394"
"3.73500","-152.52029","0.00550"
"3.76700","-152.52029","-0.00428"
"3.82700","-152.52029","0.00506"
"3.88400","-152.52029","-0.00157"
"3.92800","-152.52029","0.01625"
"3.98500","-152.52029","-0.00634"
"4.03800","-152.52029","0.00260"
"4.08600","-152.52029","0.00274"
"4.14000","-152.52029","0.02179"
"4.19800","-152.52029","0.00695"
"4.25200","-152.52029","0.02445"
"4.28200","-152.52029","0.00877"
"4.31400","-152.52029","-0.00327"
"4.36900","-152.52029","-0.00314"
"4.41200","-152.52029","0.00429"
"4.45600","-152.52029","0.01747"
"4.51900","-152.52029","-0.00444"
"4.55500","-152.52029","0.00620"
"4.59700","-152.52029","-0.00291"
"4.64900","-152.52029","0.00789"
"4.68500","-152.52029","-0.00791"
"4.73900","-152.52029","0.00508"
"4.80000","-152.52029","0.01214"
"4.84200","-152.52029","-0.01145"
"4.88600","-152.52029","-0.00240"
"4.93200","-152.52029","-0.01085"
"4.96400","-152.52029","0.01656"
"5.01700","-152.52029","0.01556"
"5.08100","-152.52029","0.00968"
"5.12800","-152.52029","0.01414"
"5.17100","-152.52029","0.01930"
"5.20900","-152.52029","0.00232"
"5.26200","-152.52029","0.00610"
"5.30200","-152.52029","0.00308"
"5.36200","-152.52029","-0.00662"
"5.42100","-152.52029","0.01943"
"5.48000","-152.52029","0.00751"
"5.54100","-152.52029","0.01153"
"5.57200","-152.52029","-0.00118"
"5.60600","-152.52029","0.00727"
"5.64000","-152.52029","0.01019"
"5.70600","-152.52029","0.01551"
"5.75600","-152.52029","0.00716"
"5.81900","-152.52029","-0.00099"
"5.87900","-152.52029","-0.00874"
"5.93200","-152.52029","0.00387"
"5.97400","-152.52029","0.00150"
"6.02000","-152.52029","-0.00928"
"6.06700","-152.52029","0.01026"
"6.12400","-152.52029","-0.00152"
"6.16700","-152.52029","0.00542"
"6.23500","-152.52029","0.00597"
"6.27800","-152.52029","-0.00807"
"6.32000","-152.52029","0.00133"
"6.35800","-152.52029","0.00460"
"6.38500","-152.52029","-0.00765"
"6.42700","-152.52029","0.00640"
"6.49600","-152.52029","0.00765"
"6.53800","-152.52029","-0.00350"
"6.58100","-152.52029","0.00552"
"6.62200","-152.52029","0.01926"
"6.66400","-152.52029","0.02016"
"6.71700","-152.52029","0.01271"
"6.78300","-152.52029","-0.00088"
"6.83800","-152.52029","-0.00016"
"6.88700","-152.52029","-0.00441"
"6.94200","-152.52029","0.01060"
"6.98400","-152.52029","0.00406"
"7.02800","-152.52029","0.00913"
"7.08600","-152.52029","0.00317"
"7.11600","-152.52029","0.00788"
"7.15600","-152.52029","0.01152"
"7.20700","-152.52029","0.01591"
"7.25500","-152.52029","0.01340"
"7.30500","-152.52029","0.00688"
"7.35400","-152.52029","-0.00335"
"7.40500","-152.52029","-0.00079"
"7.43800","-152.52029","0.00289"
"7.47200","-152.52029","0.00424"
"7.52200","-152.52029","-0.00561"
"7.57700","-152.52029","0.00465"
"7.63400","-152.52029","-0.00373"
"7.69200","-152.52029","0.00936"
"7.72500","-152.52029","0.01442"
"7.77200","-152.52029","0.00429"
"7.81300","-152.52029","0.00963"
"7.86900","-152.52029","0.00631"
"7.92400","-152.52029","-0.00640"
"7.96600","-152.52029","0.00563"
"8.01400","-152.52029","0.00073"
"8.05400","-152.52029","-0.00890"
"8.10100","-152.52029","0.02024"
"8.16400","-152.52029","0.00694"
"8.22300","-152.52029","0.00109"
"8.27100","-152.52029","0.00086"
"8.33500","-152.52029","0.00806"
"8.39100","-152.52029","0.00257"
"8.44600","-152.52029","-0.00200"
"8.49200","-152.52029","-0.01296"
"8.54100","-152.52029","-0.00376"
"8.57800","-152.52029","0.01457"
"8.62200","-152.52029","0.00024"
"8.68300","-152.52029","0.01109"
"8.73500","-152.52029","0.02233"
"8.79600","-152.52029","-0.01325"
"8.84400","-152.52029","-0.07612"
"8.89000","-152.52029","-0.06187"
"8.93100","-152.52029","-0.06646"
"8.97900","-152.52029","-0.05602"
"9.02400","-152.52029","-0.05738"
"9.06200","-152.52029","-0.05633"
"9.12500","-152.52029","-0.04895"
"9.18100","-152.52029","-0.03645"
"9.21500","-152.52029","-0.04309"
"9.25400","-152.52029","-0.03587"
"9.30000","-152.52029","-0.02891"
"9.35600","-152.52029","-0.02692"
"9.38600","-152.52029","-0.04454"
"9.44100","-152.52029","-0.03781"
"9.49500","-152.52029","-0.04144"
"9.53500","-152.52029","-0.03757"
"9.56700","-152.52029","-0.03839"
"9.60600","-152.52029","-0.02173"
"9.65100","-152.52029","-0.02707"
"9.70300","-152.52029","-0.02981"
"9.73700","-152.52029","-0.02832"
"9.79200","-152.52029","-0.02521"
"9.85000","-152.52029","-0.01723"
"9.90900","-152.52029","-0.01765"
"9.96600","-152.52029","-0.00830"
"10.01700","-152.52029","-0.02222"
"10.07100","-152.52029","-0.01800"
"10.12600","-152.52029","-0.01932"
"10.16700","-152.52029","-0.01312"
"10.22200","-152.52029","-0.01388"
"10.26500","-152.52029","-0.01172"
"10.30900","-152.52029","-0.01917"
"10.34700","-152.52029","-0.03209"
"10.39700","-152.52029","-0.02573"
"10.45300","-152.52029","-0.02698"
"10.49500","-152.52029","-0.01088"
"10.53700","-152.52029","-0.01124"
"10.57700","-152.52029","-0.01805"
"10.62200","-152.52029","-0.00951"
"10.68000","-152.52029","-0.00500"
"10.72000","-152.52029","-0.02614"
"10.79500","-152.52029","-0.00120"
"10.83200","-152.52029","0.00364"
"10.86500","-152.52029","-0.01774"
"10.91400","-152.52029","-0.02472"
"10.95600","-152.52029","-0.00959"
"11.00200","-152.52029","0.00384"
"11.04900","-152.52029","-0.01495"
"11.09300","-152.52029","-0.00668"
"11.15400","-152.52029","-0.01231"
"11.18300","-152.52029","-0.01961"
"11.23300","-152.52029","-0.01930"
"11.27600","-152.52029","-0.01164"
"11.31700","-152.52029","-0.01469"
"11.36300","-152.52029","-0.00358"
"11.39800","-152.52029","-0.01360"
"11.44200","-152.52029","0.00124"
"11.49600","-152.52029","-0.01489"
"11.53200","-152.52029","-0.01717"
"11.58700","-152.52029","-0.02279"
"11.62800","-152.52029","-0.00893"
"11.69200","-152.52029","-0.01709"
"11.73700","-152.52029","-0.00295"
"11.79100","-152.52029","-0.01281"
"11.84500","-152.52029","-0.01024"
"11.90600","-152.52029","-0.01234"
"11.94900","-152.52029","0.00151"
"12.00600","-152.52029","-0.02824"
"12.04600","-152.52029","-0.02659"
"12.09300","-152.52029","-0.01504"
"12.13100","-152.52029","-0.00946"
"12.19400","-152.52029","-0.00063"
"12.25100","-152.52029","-0.01247"
"12.30100","-152.52029","-0.01504"
"12.35200","-152.52029","-0.00688"
"12.39600","-152.52029","-0.00586"
"12.43200","-152.52029","-0.02018"
"12.46700","-152.52029","-0.01840"
"12.51200","-152.52029","-0.00165"
"12.55700","-152.52029","-0.00605"
"12.60400","-152.52029","0.00240"
"12.66300","-152.52029","-0.01250"
"12.69900","-152.52029","0.00004"
"12.74700","-152.52029","-0.00436"
"12.78800","-152.52029","-0.01050"
"12.82800","-152.52029","-0.00306"
"12.87300","-152.52029","-0.00138"
"12.90900","-152.52029","-0.01100"
"12.97500","-152.52029","-0.01063"
"13.00900","-152.52029","0.00358"
"13.06900","-152.52029","0.00112"
"13.12300","-152.52029","0.01014"
"13.17700","-152.52029","-0.00562"
"13.22900","-152.52029","-0.00074"
"13.27400","-152.52029","-0.00335"
"13.31400","-152.52029","-0.00807"
"13.36200","-152.52029","-0.00483"
"13.41100","-152.52029","-0.00934"
"13.47200","-152.52029","0.00996"
"13.51800","-152.52029","-0.01221"
"13.57900","-152.52029","-0.00100"
"13.64500","-152.52029","-0.00067"
"13.69700","-152.52029","-0.02264"
"13.74400","-152.52029","-0.02570"
"13.77100","-152.52029","-0.01057"
"13.81000","-152.52029","-0.00375"
"13.86900","-152.52029","-0.04439"
"13.92500","-152.52029","-0.15682"
"13.96500","-152.52029","-0.12267"
"14.01800","-152.52029","-0.13064"
"14.05400","-152.52029","-0.12161"
"14.09700","-152.52029","-0.09758"
"14.15300","-152.52029","-0.09191"
"14.21200","-152.52029","-0.08841"
"14.25500","-152.52029","-0.08894"
"14.29900","-152.52029","-0.08418"
"14.35700","-152.52029","-0.06648"
"14.39000","-152.52029","-0.08023"
"14.43500","-152.52029","-0.07320"
"14.48500","-152.52029","-0.07461"
"14.51700","-152.52029","-0.08330"
"14.56500","-152.52029","-0.04990"
"14.59900","-152.52029","-0.07718"
"14.63300","-152.52029","-0.09043"
"14.67200","-152.52029","-0.07231"
"14.72500","-152.52029","-0.06991"
"14.78000","-152.52029","-0.06506"
"14.83700","-152.52029","-0.05424"
"14.87300","-152.52029","-0.05551"
"14.93100","-152.52029","-0.06158"
"14.96500","-152.52029","-0.04105"
"15.02100","-152.52029","-0.05351"
"15.08500","-152.52029","-0.05736"
"15.13500","-152.52029","-0.02899"
"15.18200","-152.52029","-0.03551"
"15.22100","-152.52029","-0.04025"
"15.26800","-152.52029","-0.04667"
"15.34000","-152.52029","-0.02859"
"15.38400","-152.52029","-0.04457"
"15.42200","-152.52029","-0.05037"
"15.47500","-152.52029","-0.02946"
"15.52300","-152.52029","-0.03015"
"15.56400","-152.52029","-0.04368"
"15.60400","-152.52029","-0.05796"
"15.65100","-152.52029","-0.02588"
"15.70700","-152.52029","-0.04224"
"15.74500","-152.52029","-0.02640"
"15.80500","-152.52029","-0.01418"
"15.86300","-152.52029","-0.03358"
"15.92100","-152.52029","-0.03159"
"15.98400","-152.52029","-0.03821"
"16.04600","-152.52029","-0.03464"
"16.08900","-152.52029","-0.03999"
"16.14200","-152.52029","-0.02175"
"16.18300","-152.52029","-0.02943"
"16.23400","-152.52029","-0.01675"
"16.29200","-152.52029","-0.03400"
"16.34000","-152.52029","-0.01460"
"16.37600","-152.52029","-0.01685"
"16.42800","-152.52029","-0.03130"
"16.50100","-152.52029","-0.02872"
"16.55600","-152.52029","-0.02850"
"16.61900","-152.52029","-0.02112"
"16.68000","-152.52029","-0.01556"
"16.71000","-152.52029","-0.02975"
"16.74700","-152.52029","-0.02558"
"16.79500","-152.52029","-0.02379"
"16.84000","-152.52029","-0.01298"
"16.90800","-152.52029","-0.03441"
"16.93600","-152.52029","-0.02421"
"16.99000","-152.52029","-0.01636"
"17.03600","-152.52029","-0.01996"
"17.09800","-152.52029","-0.03500"
"17.13800","-152.52029","-0.01635"
"17.18500","-152.52029","-0.02745"
"17.22400","-152.52029","-0.01050"
"17.27100","-152.52029","-0.01529"
"17.30800","-152.52029","-0.00558"
"17.33300","-152.52029","-0.01182"
"17.40000","-152.52029","-0.02013"
"17.46300","-152.52029","-0.01023"
"17.51900","-152.52029","-0.01207"
"17.56900","-152.52029","-0.01823"
"17.62700","-152.52029","-0.02149"
"17.69000","-152.52029","-0.02221"
"17.72900","-152.52029","-0.02257"
"17.78000","-152.52029","-0.03495"
"17.80700","-152.52029","-0.03151"
"17.84000","-152.52029","-0.01808"
"17.88700","-152.52029","-0.00712"
"17.92200","-152.52029","-0.01777"
"17.96500","-152.52029","-0.01154"
"18.00400","-152.52029","-0.01501"
"18.03800","-152.52029","-0.02812"
"18.08500","-152.52029","-0.00359"
"18.13700","-152.52029","-0.01040"
"18.19100","-152.52029","-0.00500"
"18.21900","-152.52029","-0.01206"
"18.27100","-152.52029","-0.02051"
"18.33300","-152.52029","-0.00956"
"18.37600","-152.52029","-0.01498"
"18.43000","-152.52029","-0.01670"
"18.49400","-152.52029","-0.01399"
"18.54300","-152.52029","-0.03004"
"18.58300","-152.52029","-0.06726"
"18.63700","-152.52029","-0.17678"
"18.69400","-152.52029","-0.16789"
"18.75700","-152.52029","-0.16069"
"18.80400","-152.52029","-0.15488"
"18.86600","-152.52029","-0.14693"
"18.91600","-152.52029","-0.12305"
"18.97300","-152.52029","-0.13484"
"19.01100","-152.52029","-0.11293"
"19.05000","-152.52029","-0.10413"
"19.09000","-152.52029","-0.10277"
"19.13900","-152.52029","-0.09083"
"19.19000","-152.52029","-0.08556"
"19.23800","-152.52029","-0.07571"
"19.28300","-152.52029","-0.08941"
"19.33500","-152.52029","-0.07424"
"19.40400","-152.52029","-0.05949"
"19.45100","-152.52029","-0.07507"
"19.51000","-152.52029","-0.07178"
"19.55800","-152.52029","-0.06516"
"19.61100","-152.52029","-0.05949"
"19.66500","-152.52029","-0.06371"
"19.71500","-152.52029","-0.05831"
"19.77000","-152.52029","-0.05719"
"19.82300","-152.52029","-0.05729"
"19.87600","-152.52029","-0.06294"
"19.91900","-152.52029","-0.06085"
"19.95800","-152.52029","-0.07158"
"20.00500","-152.52029","-0.05780"
"20.05800","-152.52029","-0.05998"
"20.10100","-152.52029","-0.07450"
"20.14700","-152.52029","-0.06919"
"20.20200","-152.52029","-0.05714"
"20.25700","-152.52029","-0.07759"
"20.31300","-152.52029","-0.07546"
"20.36700","-152.52029","-0.05148"
"20.41100","-152.52029","-0.07120"
"20.45200","-152.52029","-0.07102"
"20.50100","-152.52029","-0.06349"
"20.55300","-152.52029","-0.05500"
"20.60100","-152.52029","-0.04570"
"20.65200","-152.52029","-0.04110"
"20.71100","-152.52029","-0.06586"
"20.76200","-152.52029","-0.06091"
"20.81900","-152.52029","-0.05168"
"20.87500","-152.52029","-0.05191"
"20.92800","-152.52029","-0.06150"
"20.98300","-152.52029","-0.06533"
"21.03000","-152.52029","-0.04657"
"21.08600","-152.52029","-0.06520"
"21.13700","-152.52029","-0.07577"
"21.20100","-152.52029","-0.07054"
"21.25400","-152.52029","-0.06593"
"21.30100","-152.52029","-0.05390"
"21.35800","-152.52029","-0.05930"
"21.40900","-152.52029","-0.06242"
"21.46200","-152.52029","-0.06905"
"21.51400","-152.52029","-0.06288"
"21.54700","-152.52029","-0.05294"
"21.59000","-152.52029","-0.05551"
"21.63300","-152.52029","-0.05583"
"21.68100","-152.52029","-0.05996"
"21.75200","-152.52029","-0.05888"
"21.78900","-152.52029","-0.05361"
"21.83000","-152.52029","-0.06537"
"21.88200","-152.52029","-0.04648"
"21.93700","-152.52029","-0.04731"
"21.98000","-152.52029","-0.05965"
"22.02300","-152.52029","-0.05777"
"22.06300","-152.52029","-0.04309"
"22.11900","-152.52029","-0.05232"
"22.17500","-152.52029","-0.06013"
"22.22600","-152.52029","-0.05996"
"22.27700","-152.52029","-0.06081"
"22.33700","-152.52029","-0.04898"
"22.37900","-152.52029","-0.04681"
"22.43000","-152.52029","-0.03713"
"22.48000","-152.52029","-0.04407"
"22.52700","-152.52029","-0.06063"
"22.58900","-152.52029","-0.06358"
"22.65700","-152.52029","-0.04182"
"22.69500","-152.52029","-0.05958"
"22.74600","-152.52029","-0.08245"
"22.78400","-152.52029","-0.06025"
"22.83000","-152.52029","-0.01667"
"22.87600","-152.52029","-0.03372"
"22.92600","-152.52029","-0.04217"
"22.97400","-152.52029","-0.02781"
"23.01100","-152.52029","-0.02959"
"23.05300","-152.52029","-0.02641"
"23.09700","-152.52029","-0.04631"
"23.15000","-152.52029","-0.03460"
"23.19500","-152.52029","-0.03933"
"23.23200","-152.52029","-0.01770"
"23.27700","-152.52029","-0.03944"
"23.32800","-152.52029","-0.03617"
"23.38100","-152.52029","-0.03480"
"23.45600","-152.52029","-0.02279"
"23.51100","-152.52029","-0.03975"
"23.55400","-152.52029","-0.03117"
"23.61400","-152.52029","-0.04295"
"23.66700","-152.52029","-0.03578"
"23.73000","-152.52029","-0.03578"
"23.78200","-152.52029","-0.03490"
"23.83100","-152.52029","-0.02009"
"23.86300","-152.52029","-0.03560"
"23.91100","-152.52029","-0.04285"
"23.95700","-152.52029","-0.01689"
"24.01900","-152.52029","-0.03187"
"24.06700","-152.52029","-0.02696"
"24.12200","-152.52029","-0.03367"
"24.18800","-152.52029","-0.02622"
"24.24600","-152.52029","-0.02637"
"24.31500","-152.52029","-0.02981"
"24.35500","-152.52029","-0.04488"
"24.41300","-152.52029","-0.03337"
"24.47300","-152.52029","-0.02760"
"24.52800","-152.52029","-0.02559"
"24.58100","-152.52029","-0.03244"
"24.62500","-152.52029","-0.03494"
"24.66400","-152.52029","-0.04234"
"24.71500","-152.52029","-0.04367"
"24.76400","-152.52029","-0.04078"
"24.81000","-152.52029","-0.03132"
"24.87200","-152.52029","-0.03898"
"24.93500","-152.52029","-0.02903"
"24.99400","-152.52029","-0.02946"
"25.03800","-152.52029","-0.03505"
"25.09700","-152.52029","-0.01134"
"25.14300","-152.52029","-0.03052"
"25.18000","-152.52029","-0.02888"
"25.23400","-152.52029","-0.06486"
"25.28500","-152.52029","-0.14592"
"25.32400","-152.52029","-0.27628"
"25.36600","-152.52029","-0.26633"
"25.41800","-152.52029","-0.23061"
"25.47600","-152.52029","-0.22706"
"25.52100","-152.52029","-0.22528"
"25.56900","-152.52029","-0.20013"
"25.59600","-152.52029","-0.20817"
"25.65100","-152.52029","-0.18748"
"25.69900","-152.52029","-0.17638"
"25.74700","-152.52029","-0.17750"
"25.78800","-152.52029","-0.17557"
"25.83700","-152.52029","-0.15111"
"25.88800","-152.52029","-0.12670"
"25.93000","-152.52029","-0.13575"
"25.98000","-152.52029","-0.13180"
"26.03600","-152.52029","-0.12849"
"26.07900","-152.52029","-0.11003"
"26.12000","-152.52029","-0.10778"
"26.16700","-152.52029","-0.10594"
"26.23100","-152.52029","-0.09571"
"26.28200","-152.52029","-0.07621"
"26.30700","-152.52029","-0.06808"
"26.35500","-152.52029","-0.06509"
"26.40000","-152.52029","-0.07871"
"26.43800","-152.52029","-0.06405"
"26.50400","-152.52029","-0.06485"
"26.55600","-152.52029","-0.06841"
"26.59400","-152.52029","-0.05805"
"26.64800","-152.52029","-0.05079"
"26.69700","-152.52029","-0.05936"
"26.75100","-152.52029","-0.04245"
"26.81100","-152.52029","-0.05770"
"26.86400","-152.52029","-0.03803"
"26.90100","-152.52029","-0.04586"
"26.95600","-152.52029","-0.05564"
"27.00800","-152.52029","-0.04394"
"27.06000","-152.52029","-0.05756"
"27.11100","-152.52029","-0.04179"
"27.16600","-152.52029","-0.04710"
"27.21100","-152.52029","-0.05180"
"27.25100","-152.52029","-0.03957"
"27.30800","-152.52029","-0.03293"
"27.36300","-152.52029","-0.03805"
"27.41200","-152.52029","-0.04879"
"27.46100","-152.52029","-0.04951"
"27.51900","-152.52029","-0.04681"
"27.57300","-152.52029","-0.03975"
"27.62300","-152.52029","-0.03625"
"27.68600","-152.52029","-0.04872"
"27.74500","-152.52029","-0.04571"
"27.79900","-152.52029","-0.05147"
"27.86700","-152.52029","-0.04420"
"27.90500","-152.52029","-0.06556"
"27.95000","-152.52029","-0.04054"
"27.99900","-152.52029","-0.04085"
"28.05400","-152.52029","-0.03047"
"28.10900","-152.52029","-0.05774"
"28.15100","-152.52029","-0.04803"
"28.19700","-152.52029","-0.04629"
"28.26900","-152.52029","-0.04418"
"28.32200","-152.52029","-0.03700"
"28.37300","-152.52029","-0.04115"
"28.40400","-152.52029","-0.02245"
"28.44000","-152.52029","-0.02888"
"28.47800","-152.52029","-0.03183"
"28.53700","-152.52029","-0.03929"
"28.58900","-152.52029","-0.04440"
"28.64700","-152.52029","-0.03421"
"28.68500","-152.52029","-0.04089"
"28.73100","-152.52029","-0.04688"
"28.77800","-152.52029","-0.03544"
"28.83300","-152.52029","-0.04490"
"28.88000","-152.52029","-0.04098"
"28.92700","-152.52029","-0.05372"
"28.96500","-152.52029","-0.04243"
"28.99900","-152.52029","-0.02922"
"29.06800","-152.52029","-0.04482"
"29.12400","-152.52029","-0.05129"
"29.17600","-152.52029","-0.04303"
"29.22200","-152.52029","-0.03170"
"29.28300","-152.52029","-0.03347"
"29.32400","-152.52029","-0.04108"
"29.36400","-152.52029","-0.02623"
"29.40100","-152.52029","-0.03683"
"29.44500","-152.52029","-0.04552"
"29.47600","-152.52029","-0.04682"
"29.52600","-152.52029","-0.04474"
"29.58700","-152.52029","-0.04710"
"29.64500","-152.52029","-0.05045"
"29.69100","-152.52029","-0.04588"
"29.73600","-152.52029","-0.03396"
"29.79800","-152.52029","-0.03147"
"29.85800","-152.52029","-0.04172"
"29.90400","-152.52029","-0.03972"
"29.94300","-152.52029","-0.03490"
"30.00400","-152.52029","-0.04707"
"30.05400","-152.52029","-0.04677"
"30.09500","-152.52029","-0.05973"
"30.14600","-152.52029","-0.04612"
"30.18800","-152.52029","-0.05640"
"30.22700","-152.52029","-0.03595"
"30.27100","-152.52029","-0.03925"
"30.30800","-152.52029","-0.05288"
"30.35100","-152.52029","-0.04137"
"30.40500","-152.52029","-0.06103"
"30.44400","-152.52029","-0.03519"
"30.49900","-152.52029","-0.04453"
"30.56000","-152.52029","-0.05239"
"30.60600","-152.52029","-0.04030"
"30.65300","-152.52029","-0.06186"
"30.68200","-152.52029","-0.04353"
"30.75500","-152.52029","-0.03647"
"30.79900","-152.52029","-0.03487"
"30.84800","-152.52029","-0.04818"
"30.90300","-152.52029","-0.03702"
"30.95200","-152.52029","-0.04052"
"31.01200","-152.52029","-0.04443"
"31.05100","-152.52029","-0.04441"
"31.12000","-152.52029","-0.02922"
"31.17000","-152.52029","-0.05279"
"31.21700","-152.52029","-0.02329"
"31.26300","-152.52029","-0.05140"
"31.30900","-152.52029","-0.03855"
"31.35900","-152.52029","-0.03730"
"31.41700","-152.52029","-0.04355"
"31.45800","-152.52029","-0.03954"
"31.51600","-152.52029","-0.03404"
"31.55800","-152.52029","-0.04264"
"31.59700","-152.52029","-0.05484"
"31.63400","-152.52029","-0.04822"
"31.68900","-152.52029","-0.03566"
"31.73100","-152.52029","-0.05383"
"31.76400","-152.52029","-0.04988"
"31.80800","-152.52029","-0.04778"
"31.85600","-152.52029","-0.04655"
"31.91200","-152.52029","-0.04461"
"31.96500","-152.52029","-0.06819"
"32.02600","-152.52029","-0.05027"
"32.06600","-152.52029","-0.04738"
"32.11600","-152.52029","-0.06772"
"32.16900","-152.52029","-0.05468"
"32.20900","-152.52029","-0.04362"
"32.24400","-152.52029","-0.03086"
"32.28000","-152.52029","-0.05602"
"32.31100","-152.52029","-0.04568"
"32.35600","-152.52029","-0.04958"
"32.38900","-152.52029","-0.06626"
"32.43900","-152.52029","-0.03799"
"32.47700","-152.52029","-0.02628"
"32.51500","-152.52029","-0.04318"
"32.56800","-152.52029","-0.03445"
"32.61400","-152.52029","-0.06141"
"32.65800","-152.52029","-0.03630"
"32.70300","-152.52029","-0.04320"
"32.76100","-152.52029","-0.03044"
"32.79500","-152.52029","-0.05126"
"32.84900","-152.52029","-0.10287"
"32.89600","-152.52029","-0.23377"
"32.92700","-152.52029","-0.30290"
"32.96400","-152.52029","-0.35973"
"32.99400","-152.52029","-0.36358"
"33.04600","-152.52029","-0.32973"
"33.10600","-152.52029","-0.33711"
"33.15600","-152.52029","-0.31913"
"33.20000","-152.52029","-0.30436"
"33.23900","-152.52029","-0.28534"
"33.28600","-152.52029","-0.28121"
"33.34100","-152.52029","-0.27535"
"33.38700","-152.52029","-0.25866"
"33.42600","-152.52029","-0.26162"
"33.46900","-152.52029","-0.26186"
"33.51600","-152.52029","-0.25300"
"33.56700","-152.52029","-0.25066"
"33.62600","-152.52029","-0.24318"
"33.67700","-152.52029","-0.23439"
"33.70900","-152.52029","-0.22127"
"33.75800","-152.52029","-0.20808"
"33.79900","-152.52029","-0.19545"
"33.86000","-152.52029","-0.20254"
"33.90800","-152.52029","-0.19862"
"33.96100","-152.52029","-0.18160"
"34.01900","-152.52029","-0.17165"
"34.07800","-152.52029","-0.17898"
"34.13300","-152.52029","-0.16676"
"34.18400","-152.52029","-0.17484"
"34.22100","-152.52029","-0.16674"
"34.25200","-152.52029","-0.14298"
"34.29200","-152.52029","-0.15711"
"34.32700","-152.52029","-0.07961"
"34.36200","-152.52029","-0.08168"
"34.41300","-152.52029","-0.08052"
"34.46000","-152.52029","-0.07472"
"34.51500","-152.52029","-0.06896"
"34.57600","-152.52029","-0.05793"
"34.62000","-152.52029","-0.06640"
"34.68300","-152.52029","-0.05963"
"34.72300","-152.52029","-0.04685"
"34.76400","-152.52029","-0.06198"
"34.83500","-152.52029","-0.04675"
"34.87800","-152.52029","-0.05024"
"34.93900","-152.52029","-0.04602"
"34.98900","-152.52029","-0.05344"
"35.04200","-152.52029","-0.04866"
"35.09900","-152.52029","-0.05098"
"35.15900","-152.52029","-0.05845"
"35.21700","-152.52029","-0.06147"
"35.26000","-152.52029","-0.04474"
"35.30000","-152.52029","-0.04411"
"35.35600","-152.52029","-0.03582"
"35.41100","-152.52029","-0.04850"
"35.45400","-152.52029","-0.04729"
"35.50400","-152.52029","-0.05447"
"35.54200","-152.52029","-0.04571"
"35.60400","-152.52029","-0.04028"
"35.66400","-152.52029","-0.03345"
"35.71800","-152.52029","-0.03922"
"35.76800","-152.52029","-0.03405"
"35.81100","-152.52029","-0.02226"
"35.85300","-152.52029","-0.05390"
"35.89800","-152.52029","-0.04049"
"35.94500","-152.52029","-0.04897"
"35.97200","-152.52029","-0.04558"
"36.00900","-152.52029","-0.03277"
"36.07600","-152.52029","-0.04467"
"36.13800","-152.52029","-0.04761"
"36.18600","-152.52029","-0.02292"
"36.23200","-152.52029","-0.04141"
"36.29600","-152.52029","-0.04039"
"36.34800","-152.52029","-0.04702"
"36.40400","-152.52029","-0.04715"
"36.45900","-152.52029","-0.03150"
"36.51300","-152.52029","-0.03136"
"36.55900","-152.52029","-0.02742"
"36.60800","-152.52029","-0.03923"
"36.66300","-152.52029","-0.02813"
"36.71700","-152.52029","-0.03630"
"36.76000","-152.52029","-0.04310"
"36.80400","-152.52029","-0.03836"
"36.85300","-152.52029","-0.03878"
"36.88900","-152.52029","-0.02783"
"36.94100","-152.52029","-0.02240"
"36.98200","-152.52029","-0.04725"
"37.03900","-152.52029","-0.02830"
"37.09800","-152.52029","-0.04027"
"37.15500","-152.52029","-0.02497"
"37.19800","-152.52029","-0.02987"
"37.23700","-152.52029","-0.02644"
"37.27400","-152.52029","-0.03759"
"37.33600","-152.52029","-0.04853"
"37.37600","-152.52029","-0.04324"
"37.43800","-152.52029","-0.04253"
"37.48000","-152.52029","-0.03548"
"37.52700","-152.52029","-0.03549"
"37.58700","-152.52029","-0.03348"
"37.63900","-152.52029","-0.01433"
"37.68300","-152.52029","-0.03194"
"37.73400","-152.52029","-0.02501"
"37.77000","-152.52029","-0.01156"
"37.79700","-152.52029","-0.02632"
"37.83100","-152.52029","-0.01277"
"37.86700","-152.52029","-0.03224"
"37.91900","-152.52029","-0.02935"
"37.96600","-152.52029","-0.01838"
"38.01300","-152.52029","-0.03189"
"38.06200","-152.52029","-0.03579"
"38.11400","-152.52029","-0.03162"
"38.15700","-152.52029","-0.02050"
"38.22100","-152.52029","-0.02947"
"38.26600","-152.52029","-0.03509"
"38.30700","-152.52029","-0.03126"
"38.35500","-152.52029","-0.01566"
"38.39700","-152.52029","-0.02733"
"38.43900","-152.52029","-0.02416"
"38.48600","-152.52029","-0.03962"
"38.54600","-152.52029","-0.02661"
"38.60500","-152.52029","-0.02230"
"38.66800","-152.52029","-0.02629"
"38.71500","-152.52029","-0.03869"
"38.76700","-152.52029","-0.01443"
"38.82500","-152.52029","-0.03773"
"38.87800","-152.52029","-0.03710"
"38.93500","-152.52029","-0.01582"
"38.99700","-152.52029","-0.02740"
"39.03900","-152.52029","-0.02256"
"39.08900","-152.52029","-0.03907"
"39.14300","-152.52029","-0.02284"
"39.18800","-152.52029","-0.03560"
"39.23300","-152.52029","-0.02522"
"39.30000","-152.52029","-0.02453"
"39.36300","-152.52029","-0.02352"
"39.41500","-152.52029","-0.03686"
"39.46100","-152.52029","-0.03315"
"39.49900","-152.52029","-0.04445"
"39.55100","-152.52029","-0.02040"
"39.58300","-152.52029","-0.01898"
"39.62900","-152.52029","-0.03144"
"39.70600","-152.52029","-0.02941"
"39.74000","-152.52029","-0.02647"
"39.78400","-152.52029","-0.03084"
"39.83400","-152.52029","-0.01247"
"39.88000","-152.52029","-0.01851"
"39.93000","-152.52029","-0.02371"
"39.96900","-152.52029","-0.03690"
"39.99700","-152.52029","-0.02600"
"40.04300","-152.52029","-0.02325"
"40.10100","-152.52029","-0.01872"
"40.16200","-152.52029","-0.03669"
"40.22400","-152.52029","-0.01095"
"40.27500","-152.52029","-0.02120"
"40.33100","-152.52029","-0.03926"
"40.37000","-152.52029","-0.03252"
"40.41400","-152.52029","-0.01471"
"40.44900","-152.52029","-0.03422"
"40.50100","-152.52029","-0.02380"
"40.55100","-152.52029","-0.02947"
"40.60800","-152.52029","-0.01420"
"40.66500","-152.52029","-0.00975"
"40.70900","-152.52029","-0.01699"
"40.75500","-152.52029","-0.02694"
"40.81900","-152.52029","-0.02800"
"40.86700","-152.52029","-0.02456"
"40.92400","-152.52029","-0.01401"
"40.98300","-152.52029","-0.03061"
"41.04000","-152.52029","-0.01654"
"41.08500","-152.52029","-0.02783"
"41.14300","-152.52029","-0.01753"
"41.18700","-152.52029","-0.01701"
"41.22700","-152.52029","-0.02581"
"41.28100","-152.52029","-0.03341"
"41.31900","-152.52029","-0.04175"
"41.35800","-152.52029","-0.04145"
"41.40800","-152.52029","-0.03591"
"41.45900","-152.52029","-0.03256"
"41.50200","-152.52029","-0.01746"
"41.53000","-152.52029","-0.02367"
"41.58200","-152.52029","-0.02050"
"41.63200","-152.52029","-0.04091"
"41.68200","-152.52029","-0.04479"
"41.72900","-152.52029","-0.03373"
"41.78200","-152.52029","-0.02376"
"41.83400","-152.52029","-0.02613"
"41.88500","-152.52029","-0.02184"
"41.92600","-152.52029","-0.02433"
"41.98100","-152.52029","-0.04324"
"42.02700","-152.52029","-0.02888"
"42.06900","-152.52029","-0.01724"
"42.11900","-152.52029","-0.02731"
"42.15400","-152.52029","-0.03599"
"42.19800","-152.52029","-0.02997"
"42.23700","-152.52029","-0.02887"
"42.29200","-152.52029","-0.03953"
"42.34500","-152.52029","-0.03737"
"42.40400","-152.52029","-0.03119"
"42.45400","-152.52029","-0.02973"
"42.52000","-152.52029","-0.02527"
"42.58100","-152.52029","-0.03570"
"42.64500","-152.52029","-0.03065"
"42.69500","-152.52029","-0.04259"
"42.75300","-152.52029","-0.03288"
"42.81200","-152.52029","-0.04007"
"42.85000","-152.52029","-0.05182"
"42.89800","-152.52029","-0.02870"
"42.93500","-152.52029","-0.02749"
"42.97200","-152.52029","-0.02591"
"43.01800","-152.52029","-0.01300"
"43.06100","-152.52029","-0.02327"
"43.12200","-152.52029","-0.03151"
"43.17500","-152.52029","-0.02943"
"43.23600","-152.52029","-0.02843"
"43.28000","-152.52029","-0.03597"
"43.33600","-152.52029","-0.03972"
"43.38600","-152.52029","-0.03403"
"43.42500","-152.52029","-0.03682"
"43.49300","-152.52029","-0.02065"
"43.53200","-152.52029","-0.03492"
"43.57900","-152.52029","-0.03812"
"43.63900","-152.52029","-0.03163"
"43.71200","-152.52029","-0.03874"
"43.77600","-152.52029","-0.03878"
"43.83200","-152.52029","-0.01980"
"43.89200","-152.52029","-0.04020"
"43.92800","-152.52029","-0.01954"
"43.96100","-152.52029","-0.03226"
"44.01600","-152.52029","-0.02637"
"44.07700","-152.52029","-0.03003"
"44.12200","-152.52029","-0.01449"
"44.16500","-152.52029","-0.04646"
"44.23800","-152.52029","-0.02389"
"44.29800","-152.52029","-0.04483"
"44.35100","-152.52029","-0.03804"
"44.39000","-152.52029","-0.01815"
"44.43600","-152.52029","-0.03073"
"44.50600","-152.52029","-0.03393"
"44.55000","-152.52029","-0.03632"
"44.61300","-152.52029","-0.04315"
"44.66900","-152.52029","-0.03600"
"44.72500","-152.52029","-0.04955"
"44.77700","-152.52029","-0.02972"
"44.82700","-152.52029","-0.03515"
"44.87800","-152.52029","-0.04646"
"44.91700","-152.52029","-0.03255"
"44.94300","-152.52029","-0.03581"
"44.98500","-152.52029","-0.10597"
"45.02600","-152.52029","-0.20856"
"45.06200","-152.52029","-0.29883"
"45.11100","-152.52029","-0.37151"
"45.16600","-152.52029","-0.41579"
"45.22600","-152.52029","-0.43679"
"45.28800","-152.52029","-0.40595"
"45.34800","-152.52029","-0.39753"
"45.38800","-152.52029","-0.38942"
"45.43100","-152.52029","-0.37781"
"45.48100","-152.52029","-0.36040"
"45.53600","-152.52029","-0.33872"
"45.57300","-152.52029","-0.33923"
"45.62400","-152.52029","-0.33736"
"45.66300","-152.52029","-0.32287"
"45.72400","-152.52029","-0.31909"
"45.77800","-152.52029","-0.30530"
"45.84100","-152.52029","-0.31104"
"45.89900","-152.52029","-0.30548"
"45.96300","-152.52029","-0.29167"
"46.02000","-152.52029","-0.28926"
"46.07700","-152.52029","-0.28168"
"46.12800","-152.52029","-0.26865"
"46.17600","-152.52029","-0.27917"
"46.23300","-152.52029","-0.24750"
"46.29000","-152.52029","-0.25369"
"46.33800","-152.52029","-0.24306"
"46.37800","-152.52029","-0.24507"
"46.42200","-152.52029","-0.25117"
"46.46800","-152.52029","-0.22705"
"46.53200","-152.52029","-0.22155"
"46.57700","-152.52029","-0.22724"
"46.61500","-152.52029","-0.21475"
"46.65000","-152.52029","-0.19954"
"46.69400","-152.52029","-0.21521"
"46.75000","-152.52029","-0.19177"
"46.80200","-152.52029","-0.19655"
"46.84900","-152.52029","-0.18345"
"46.88100","-152.52029","-0.18742"
"46.93900","-152.52029","-0.19261"
"46.97600","-152.52029","-0.17847"
"47.02700","-152.52029","-0.16568"
"47.08500","-152.52029","-0.18148"
"47.14100","-152.52029","-0.16408"
"47.18200","-152.52029","-0.15592"
"47.23700","-152.52029","-0.14159"
"47.27300","-152.52029","-0.14904"
"47.33200","-152.52029","-0.15931"
"47.37900","-152.52029","-0.12307"
"47.43700","-152.52029","-0.15960"
"47.49200","-152.52029","-0.15157"
"47.54700","-152.52029","-0.12272"
"47.59100","-152.52029","-0.07830"
"47.63900","-152.52029","-0.05692"
"47.70700","-152.52029","-0.07527"
"47.75100","-152.52029","-0.06051"
"47.78700","-152.52029","-0.06927"
"47.81800","-152.52029","-0.06908"
"47.86200","-152.52029","-0.07498"
"47.89700","-152.52029","-0.04871"
"47.93800","-152.52029","-0.06985"
"47.98600","-152.52029","-0.05788"
"48.03600","-152.52029","-0.06460"
"48.08200","-152.52029","-0.05821"
"48.12200","-152.52029","-0.07113"
"48.17300","-152.52029","-0.06508"
"48.22300","-152.52029","-0.07099"
"48.27400","-152.52029","-0.06716"
"48.33800","-152.52029","-0.05020"
"48.39000","-152.52029","-0.06323"
"48.42500","-152.52029","-0.05287"
"48.46600","-152.52029","-0.04519"
"48.52800","-152.52029","-0.06836"
"48.56500","-152.52029","-0.06064"
"48.62700","-152.52029","-0.05747"
"48.68100","-152.52029","-0.06988"
"48.73300","-152.52029","-0.06520"
"48.80700","-152.52029","-0.04008"
"48.86600","-152.52029","-0.06082"
"48.90000","-152.52029","-0.05805"
"48.94900","-152.52029","-0.05629"
"49.00000","-152.52029","-0.06421"
"49.05500","-152.52029","-0.05592"
"49.12600","-152.52029","-0.04527"
"49.17800","-152.52029","-0.06504"
"49.22700","-152.52029","-0.04044"
"49.29600","-152.52029","-0.05260"
"49.33500","-152.52029","-0.04238"
"49.38200","-152.52029","-0.06323"
"49.42900","-152.52029","-0.06824"
"49.48400","-152.52029","-0.04383"
"49.54900","-152.52029","-0.04842"
"49.59400","-152.52029","-0.04819"
"49.62700","-152.52029","-0.04806"
"49.67600","-152.52029","-0.04015"
"49.73400","-152.52029","-0.04660"
"49.78400","-152.52029","-0.05956"
"49.83000","-152.52029","-0.04738"
"49.89000","-152.52029","-0.05327"
"49.92500","-152.52029","-0.03520"
"49.98100","-152.52029","-0.05245"
"50.04400","-152.52029","-0.04876"
"50.10300","-152.52029","-0.04269"
"50.15700","-152.52029","-0.03018"
"50.20100","-152.52029","-0.04188"
"50.24600","-152.52029","-0.03923"
"50.30100","-152.52029","-0.03582"
"50.36000","-152.52029","-0.04628"
"50.41300","-152.52029","-0.02918"
"50.47100","-152.52029","-0.03719"
"50.52800","-152.52029","-0.04175"
"50.57300","-152.52029","-0.02339"
"50.61600","-152.52029","-0.04585"
"50.68200","-152.52029","-0.03937"
"50.74600","-152.52029","-0.03824"
"50.79700","-152.52029","-0.03586"
"50.84600","-152.52029","-0.02507"
"50.90600","-152.52029","-0.03908"
"50.96600","-152.52029","-0.04544"
"51.02500","-152.52029","-0.02974"
"51.06200","-152.52029","-0.05511"
"51.12100","-152.52029","-0.02904"
"51.17500","-152.52029","-0.04930"
"51.21600","-152.52029","-0.05352"
"51.26200","-152.52029","-0.04931"
"51.32400","-152.52029","-0.03191"
"51.37900","-152.52029","-0.02160"
"51.43100","-152.52029","-0.03076"
"51.49500","-152.52029","-0.02326"
"51.53900","-152.52029","-0.03563"
"51.60100","-152.52029","-0.01769"
"51.65100","-152.52029","-0.04144"
"51.69900","-152.52029","-0.03648"
"51.73700","-152.52029","-0.03964"
"51.78400","-152.52029","-0.04504"
"51.83100","-152.52029","-0.02911"
"51.89200","-152.52029","-0.04303"
"51.95100","-152.52029","-0.03994"
"51.98600","-152.52029","-0.04220"
"52.02800","-152.52029","-0.02824"
"52.06800","-152.52029","-0.01609"
"52.10700","-152.52029","-0.02992"
"52.14300","-152.52029","-0.04466"
"52.19300","-152.52029","-0.03747"
"52.22600","-152.52029","-0.02467"
"52.26700","-152.52029","-0.04405"
"52.31400","-152.52029","-0.02546"
"52.37800","-152.52029","-0.01710"
"52.42100","-152.52029","-0.03110"
"52.46700","-152.52029","-0.02573"
"52.49900","-152.52029","-0.04150"
"52.55100","-152.52029","-0.03600"
"52.60700","-152.52029","-0.03721"
"52.65600","-152.52029","-0.03950"
"52.71600","-152.52029","-0.02751"
"52.74700","-152.52029","-0.21107"
"52.75900","-152.52029","-0.39981"
"52.78500","-152.52029","-0.33531"
"52.79900","-152.52029","-0.20443"
"52.82200","-152.52029","-0.08918"
"52.85500","-152.52029","-0.02701"
"52.91000","-152.52029","0.01346"
"52.96400","-152.52029","-0.04563"
"53.00400","-152.52029","-0.10545"
"53.04600","-152.52029","-0.18618"
"53.08300","-152.52029","-0.16699"
"53.10500","-152.52029","-0.03832"
"53.15800","-152.52029","0.00602"
"53.19000","-152.52029","-0.03047"
"53.23100","-152.52029","0.00862"
"53.27400","-152.52029","-0.00480"
"53.33700","-152.52029","-0.00941"
"53.38300","-152.52029","0.00186"
"53.43700","-152.52029","-0.00173"
"53.48100","-152.52029","0.00898"
"53.53100","-152.52029","-0.00172"
"53.59200","-152.52029","-0.01278"
"53.63000","-152.52029","-0.00451"
"53.68200","-152.52029","0.00514"
"53.73100","-152.52029","0.01214"
"53.78000","-152.52029","0.01777"
"53.81000","-152.52029","0.02047"
"53.85100","-152.52029","-0.00360"
"53.89300","-152.52029","-0.01064"
"53.92100","-152.52029","0.00679"
"53.99200","-152.52029","0.01763"
"54.03400","-152.52029","0.00401"
"54.07800","-152.52029","0.01381"
"54.12400","-152.52029","0.00549"
"54.18100","-152.52029","-0.00751"
"54.23300","-152.52029","0.01693"
"54.27500","-152.52029","0.00376"
"54.30600","-152.52029","0.00495"
"54.35500","-152.52029","0.02180"
"54.41000","-152.52029","-0.00502"
"54.47500","-152.52029","-0.00771"
"54.53400","-152.52029","0.00884"
"54.56800","-152.52029","0.00476"
"54.62600","-152.52029","0.00949"
"54.69000","-152.52029","0.03086"
"54.72900","-152.52029","-0.01917"
"54.76900","-152.52029","-0.01856"
"54.82700","-152.52029","-0.02793"
"54.89000","-152.52029","-0.03127"
"54.94300","-152.52029","-0.01616"
"54.99200","-152.52029","-0.01715"
"55.03500","-152.52029","-0.02659"
"55.09100","-152.52029","-0.01932"
"55.14000","-152.52029","-0.01695"
"55.17600","-152.52029","-0.02115"
"55.21500","-152.52029","-0.01376"
"55.27300","-152.52029","-0.01071"
"55.32700","-152.52029","-0.01123"
"55.37200","-152.52029","-0.02484"
"55.42400","-152.52029","-0.01841"
"55.47300","-152.52029","-0.00713"
"55.53500","-152.52029","-0.00577"
"55.58300","-152.52029","-0.01469"
"55.63300","-152.52029","0.00179"
"55.66500","-152.52029","-0.00446"
"55.72900","-152.52029","-0.00282"
"55.76400","-152.52029","-0.02490"
"55.81700","-152.52029","-0.00682"
"55.87900","-152.52029","-0.02261"
"55.93100","-152.52029","-0.02554"
"55.97600","-152.52029","-0.00398"
"56.02300","-152.52029","-0.01175"
"56.07900","-152.52029","-0.01774"
"56.13200","-152.52029","-0.02118"
"56.19200","-152.52029","-0.01832"
"56.25600","-152.52029","-0.02243"
"56.29400","-152.52029","-0.02410"
"56.36200","-152.52029","-0.01198"
"56.42200","-152.52029","-0.01344"
"56.47500","-152.52029","-0.02487"
"56.51500","-152.52029","-0.02303"
"56.55900","-152.52029","-0.00995"
"56.60400","-152.52029","-0.00888"
"56.64800","-152.52029","-0.01588"
"56.70100","-152.52029","-0.00984"
"56.73700","-152.52029","-0.02190"
"56.79500","-152.52029","-0.01435"
"56.84200","-152.52029","-0.02042"
"56.88400","-152.52029","-0.02794"
"56.93000","-152.52029","-0.01823"
"56.98300","-152.52029","-0.01514"
"57.03000","-152.52029","-0.00790"
"57.07500","-152.52029","-0.00128"
"57.11400","-152.52029","-0.00673"
"57.15700","-152.52029","-0.02505"
"57.20200","-152.52029","-0.02454"
"57.23500","-152.52029","-0.01771"
"57.29200","-152.52029","-0.01607"
"57.34700","-152.52029","-0.02941"
"57.39300","-152.52029","-0.02132"
"57.42900","-152.52029","-0.00683"
"57.48900","-152.52029","-0.01076"
"57.52800","-152.52029","-0.01040"
"57.57100","-152.52029","-0.01339"
"57.62400","-152.52029","-0.02100"
"57.67800","-152.52029","-0.01590"
"57.73900","-152.52029","-0.01924"
"57.77800","-152.52029","-0.01353"
"57.84900","-152.52029","-0.00597"
"57.90600","-152.52029","-0.01955"
"57.96000","-152.52029","-0.02343"
"58.02300","-152.52029","-0.02122"
"58.08100","-152.52029","-0.02451"
"58.13900","-152.52029","-0.01992"
"58.20000","-152.52029","-0.00554"
"58.25000","-152.52029","-0.01722"
"58.29800","-152.52029","-0.02515"
"58.35700","-152.52029","0.00366"
"58.41300","-152.52029","-0.01206"
"58.46600","-152.52029","-0.01410"
"58.51000","-152.52029","-0.01327"
"58.56300","-152.52029","-0.00169"
"58.59500","-152.52029","-0.02391"
"58.64400","-152.52029","-0.00889"
"58.69100","-152.52029","-0.01726"
"58.74200","-152.52029","-0.03560"
"58.78900","-152.52029","-0.00747"
"58.83900","-152.52029","-0.01197"
"58.89200","-152.52029","-0.02055"
"58.92500","-152.52029","-0.00814"
"58.97700","-152.52029","-0.01514"
"59.03900","-152.52029","-0.02180"
"59.09900","-152.52029","-0.01295"
"59.16600","-152.52029","-0.03166"
"59.20400","-152.52029","-0.01145"
"59.26600","-152.52029","-0.01295"
"59.30700","-152.52029","-0.05712"
"59.34800","-152.52029","-0.16799"
"59.38800","-152.52029","-0.25593"
"59.42400","-152.52029","-0.33087"
"59.47700","-152.52029","-0.40249"
"59.51800","-152.52029","-0.44245"
"59.56400","-152.52029","-0.45427"
"59.60400","-152.52029","-0.41246"
"59.63900","-152.52029","-0.41401"
"59.69000","-152.52029","-0.39804"
"59.73000","-152.52029","-0.38212"
"59.77000","-152.52029","-0.38111"
"59.80600","-152.52029","-0.35978"
"59.85200","-152.52029","-0.34463"
"59.89900","-152.52029","-0.34919"
"59.96500","-152.52029","-0.34251"
"60.01700","-152.52029","-0.32555"
"60.07300","-152.52029","-0.31209"
"60.12700","-152.52029","-0.31690"
"60.17300","-152.52029","-0.31042"
"60.23100","-152.52029","-0.31184"
"60.29700","-152.52029","-0.29897"
"60.34600","-152.52029","-0.27382"
"60.39500","-152.52029","-0.27844"
"60.45200","-152.52029","-0.29895"
"60.51000","-152.52029","-0.26823"
"60.55000","-152.52029","-0.27777"
"60.60100","-152.52029","-0.25286"
"60.65400","-152.52029","-0.24926"
"60.69700","-152.52029","-0.24625"
"60.74300","-152.52029","-0.23414"
"60.81300","-152.52029","-0.23332"
"60.85200","-152.52029","-0.23875"
"60.89800","-152.52029","-0.21446"
"60.97000","-152.52029","-0.22537"
"61.00600","-152.52029","-0.20387"
"61.05500","-152.52029","-0.12759"
"61.11000","-152.52029","-0.11729"
"61.16300","-152.52029","-0.11415"
"61.19900","-152.52029","-0.11016"
"61.24800","-152.52029","-0.10530"
"61.28800","-152.52029","-0.10172"
"61.32800","-152.52029","-0.08142"
"61.37900","-152.52029","-0.08592"
"61.42100","-152.52029","-0.06992"
"61.46500","-152.52029","-0.08922"
"61.51100","-152.52029","-0.07124"
"61.56200","-152.52029","-0.07653"
"61.61500","-152.52029","-0.07313"
"61.67300","-152.52029","-0.07853"
"61.73300","-152.52029","-0.07226"
"61.77100","-152.52029","-0.06744"
"61.82900","-152.52029","-0.08311"
"61.89000","-152.52029","-0.07572"
"61.93900","-152.52029","-0.05699"
"62.00400","-152.52029","-0.07043"
"62.04300","-152.52029","-0.07037"
"62.11000","-152.52029","-0.06238"
"62.16300","-152.52029","-0.07316"
"62.21300","-152.52029","-0.06416"
"62.25600","-152.52029","-0.05471"
"62.30700","-152.52029","-0.05680"
"62.34500","-152.52029","-0.05877"
"62.39300","-152.52029","-0.06272"
"62.43700","-152.52029","-0.06303"
"62.49200","-152.52029","-0.05493"
"62.54200","-152.52029","-0.05640"
"62.57600","-152.52029","-0.04971"
"62.63200","-152.52029","-0.06077"
"62.66200","-152.52029","-0.06201"
"62.73300","-152.52029","-0.06250"
"62.79300","-152.52029","-0.05734"
"62.83900","-152.52029","-0.06376"
"62.86600","-152.52029","-0.05978"
"62.93000","-152.52029","-0.07249"
"62.98200","-152.52029","-0.06628"
"63.03400","-152.52029","-0.05953"
"63.08400","-152.52029","-0.05076"
"63.12300","-152.52029","-0.05192"
"63.18300","-152.52029","-0.06258"
"63.23200","-152.52029","-0.05826"
"63.29000","-152.52029","-0.04903"
"63.34500","-152.52029","-0.04516"
"63.39000","-152.52029","-0.04108"
"63.43700","-152.52029","-0.05684"
"63.50200","-152.52029","-0.05615"
"63.55500","-152.52029","-0.06823"
"63.59900","-152.52029","-0.04493"
"63.64400","-152.52029","-0.05036"
"63.68200","-152.52029","-0.03468"
"63.73300","-152.52029","-0.02788"
"63.77400","-152.52029","-0.05147"
"63.83500","-152.52029","-0.04493"
"63.92500","-152.52029","-0.04732"
"63.96400","-152.52029","-0.04789"
"64.02800","-152.52029","-0.04599"
"64.08600","-152.52029","-0.06262"
"64.12500","-152.52029","-0.05621"
"64.17900","-152.52029","-0.06648"
"64.22900","-152.52029","-0.04707"
"64.27100","-152.52029","-0.05684"
"64.32100","-152.52029","-0.05822"
"64.38100","-152.52029","-0.03603"
"64.42600","-152.52029","-0.04859"
"64.48600","-152.52029","-0.05022"
"64.53700","-152.52029","-0.02733"
"64.56700","-152.52029","-0.03783"
"64.62000","-152.52029","-0.05178"
"64.67200","-152.52029","-0.04750"
"64.73500","-152.52029","-0.04672"
"64.78500","-152.52029","-0.04224"
"64.83700","-152.52029","-0.03883"
"64.87600","-152.52029","-0.03605"
"64.91900","-152.52029","-0.04931"
"64.97100","-152.52029","-0.04067"
"65.02200","-152.52029","-0.03620"
"65.07300","-152.52029","-0.04052"
"65.11700","-152.52029","-0.04957"
"65.16500","-152.52029","-0.04648"
"65.19900","-152.52029","-0.02759"
"65.25400","-152.52029","-0.03569"
"65.29600","-152.52029","-0.05695"
"65.34300","-152.52029","-0.02886"
"65.38200","-152.52029","-0.03131"
"65.45100","-152.52029","-0.04231"
"65.49000","-152.52029","-0.03686"
"65.54500","-152.52029","-0.02727"
"65.59300","-152.52029","-0.02854"
"65.63600","-152.52029","-0.04543"
"65.68600","-152.52029","-0.06067"
"65.74600","-152.52029","-0.02567"
"65.78500","-152.52029","-0.02978"
"65.83600","-152.52029","-0.03247"
"65.89600","-152.52029","-0.02562"
"65.93600","-152.52029","-0.04534"
"65.99900","-152.52029","-0.04424"
"66.03800","-152.52029","-0.04378"
"66.08400","-152.52029","-0.02925"
"66.12700","-152.52029","-0.04948"
"66.16700","-152.52029","-0.04553"
"66.19800","-152.52029","-0.02871"
"66.23800","-152.52029","-0.03534"
"66.28400","-152.52029","-0.04967"
"66.34700","-152.52029","-0.03823"
"66.39800","-152.52029","-0.04302"
"66.43800","-152.52029","-0.03872"
"66.48200","-152.52029","-0.03692"
"66.53000","-152.52029","-0.05443"
"66.56700","-152.52029","-0.02290"
"66.60800","-152.52029","-0.04362"
"66.66600","-152.52029","-0.03867"
"66.71800","-152.52029","-0.02803"
"66.77100","-152.52029","-0.02521"
"66.81500","-152.52029","-0.03075"
"66.86300","-152.52029","-0.04340"
"66.92500","-152.52029","-0.03215"
"66.96900","-152.52029","-0.03516"
"67.03800","-152.52029","-0.04469"
"67.10100","-152.52029","-0.03977"
"67.13800","-152.52029","-0.03394"
"67.18100","-152.52029","-0.03918"