File: chapter 4/force/mini_patrick.is_tens_RawData/Specimen_RawData_3.csv
Time,Extension,Load
(s),(mm),(N)
"0.00000","-151.67305","0.00565"
"0.10600","-151.67305","-0.00027"
"0.16900","-151.67305","-0.00311"
"0.24800","-151.67305","0.01056"
"0.30800","-151.67305","0.00326"
"0.38800","-151.67305","-0.01908"
"0.47500","-151.67305","-0.00715"
"0.56300","-151.67305","0.00267"
"0.65000","-151.67305","-0.00962"
"0.71600","-151.67305","0.02078"
"0.80200","-151.67305","0.00496"
"0.88300","-151.67305","-0.00757"
"0.98000","-151.67305","-0.00159"
"1.05900","-151.67305","0.00773"
"1.16000","-151.67305","0.00545"
"1.22900","-151.67305","0.00835"
"1.30900","-151.67305","-0.00294"
"1.40300","-151.67305","0.00245"
"1.47800","-151.67305","0.00374"
"1.55600","-151.67305","-0.00638"
"1.63400","-151.67305","-0.01000"
"1.71200","-151.67305","0.01006"
"1.80800","-151.67305","0.00324"
"1.89500","-151.67305","0.00706"
"1.94300","-151.67305","0.00756"
"2.03700","-151.67305","-0.01224"
"2.11000","-151.67305","-0.00652"
"2.16600","-151.67305","0.02231"
"2.23100","-151.67305","-0.00173"
"2.30900","-151.67305","-0.01038"
"2.41200","-151.67305","0.00969"
"2.49200","-151.67305","-0.01387"
"2.58700","-151.67305","-0.00790"
"2.66200","-151.67305","-0.00948"
"2.75600","-151.67305","0.01089"
"2.83400","-151.67305","-0.00386"
"2.93900","-151.67305","-0.00095"
"3.00500","-151.67305","-0.01084"
"3.08000","-151.67305","-0.00673"
"3.16800","-151.67305","-0.01385"
"3.25500","-151.67305","0.00217"
"3.34800","-151.67305","0.01301"
"3.43000","-151.67305","0.00127"
"3.51400","-151.67305","0.00624"
"3.60100","-151.67305","0.00062"
"3.67100","-151.67305","-0.00611"
"3.75900","-151.67305","-0.00660"
"3.82700","-151.67305","-0.03759"
"3.90500","-151.67305","-0.04351"
"3.99400","-151.67305","-0.04365"
"4.07000","-151.67305","-0.02625"
"4.14200","-151.67305","-0.03683"
"4.24900","-151.67305","-0.03839"
"4.32900","-151.67305","-0.00925"
"4.41700","-151.67305","-0.01653"
"4.50400","-151.67305","-0.01744"
"4.59400","-151.67305","-0.03765"
"4.67500","-151.67305","-0.01904"
"4.78100","-151.67305","-0.01785"
"4.86400","-151.67305","-0.02502"
"4.95600","-151.67305","-0.00304"
"5.03800","-151.67305","-0.02472"
"5.11800","-151.67305","-0.01374"
"5.22500","-151.67305","-0.01032"
"5.30600","-151.67305","-0.00654"
"5.39400","-151.67305","-0.00732"
"5.47900","-151.67305","-0.02041"
"5.55500","-151.67305","-0.00617"
"5.62300","-151.67305","-0.00218"
"5.71900","-151.67305","-0.00473"
"5.79100","-151.67305","-0.01018"
"5.87000","-151.67305","-0.01269"
"5.93800","-151.67305","0.00543"
"6.01500","-151.67305","-0.00972"
"6.10300","-151.67305","-0.02077"
"6.18500","-151.67305","0.00115"
"6.28300","-151.67305","-0.00342"
"6.36600","-151.67305","-0.00871"
"6.43500","-151.67305","-0.00279"
"6.51600","-151.67305","-0.00098"
"6.56500","-151.67305","0.01349"
"6.64900","-151.67305","0.00744"
"6.76000","-151.67305","-0.01168"
"6.83100","-151.67305","-0.02741"
"6.92600","-151.67305","-0.01013"
"6.98300","-151.67305","-0.00058"
"7.06300","-151.67305","-0.01055"
"7.14700","-151.67305","-0.00499"
"7.23300","-151.67305","0.00230"
"7.30900","-151.67305","-0.01138"
"7.39500","-151.67305","-0.02823"
"7.49800","-151.67305","-0.00944"
"7.57300","-151.67305","0.00741"
"7.62700","-151.67305","-0.00955"
"7.71300","-151.67305","-0.02442"
"7.78200","-151.67305","0.00604"
"7.86900","-151.67305","0.00496"
"7.96400","-151.67305","-0.00547"
"8.04500","-151.67305","-0.00336"
"8.12500","-151.67305","-0.01124"
"8.19300","-151.67305","-0.00859"
"8.27500","-151.67305","-0.00546"
"8.35900","-151.67305","0.00815"
"8.42100","-151.67305","0.00794"
"8.49500","-151.67305","-0.00874"
"8.58100","-151.67305","-0.00451"
"8.65200","-151.67305","-0.01165"
"8.73300","-151.67305","-0.00592"
"8.79400","-151.67305","-0.01046"
"8.87900","-151.67305","0.01612"
"8.96000","-151.67305","-0.01880"
"9.04200","-151.67305","-0.00886"
"9.10400","-151.67305","-0.02261"
"9.18400","-151.67305","0.00361"
"9.26500","-151.67305","0.00232"
"9.36100","-151.67305","-0.00673"
"9.45900","-151.67305","-0.08201"
"9.55000","-151.67305","-0.09850"
"9.64100","-151.67305","-0.08455"
"9.73100","-151.67305","-0.09196"
"9.81700","-151.67305","-0.08095"
"9.89900","-151.67305","-0.05868"
"9.98000","-151.67305","-0.08179"
"10.06700","-151.67305","-0.06402"
"10.13800","-151.67305","-0.06023"
"10.20500","-151.67305","-0.05102"
"10.28700","-151.67305","-0.05711"
"10.37400","-151.67305","-0.05893"
"10.47600","-151.67305","-0.03686"
"10.55300","-151.67305","-0.05991"
"10.65000","-151.67305","-0.02890"
"10.70300","-151.67305","-0.05326"
"10.79900","-151.67305","-0.04682"
"10.89000","-151.67305","-0.03538"
"10.98900","-151.67305","-0.03615"
"11.08400","-151.67305","-0.04755"
"11.19500","-151.67305","-0.04207"
"11.27400","-151.67305","-0.03115"
"11.34200","-151.67305","-0.04993"
"11.42600","-151.67305","-0.03148"
"11.50400","-151.67305","-0.03057"
"11.59700","-151.67305","-0.02955"
"11.68600","-151.67305","-0.04015"
"11.75800","-151.67305","-0.04200"
"11.85700","-151.67305","-0.03172"
"11.91900","-151.67305","-0.02869"
"11.99000","-151.67305","-0.03439"
"12.07600","-151.67305","-0.02859"
"12.16300","-151.67305","-0.04157"
"12.23100","-151.67305","-0.02864"
"12.29300","-151.67305","-0.02084"
"12.36200","-151.67305","-0.02258"
"12.44100","-151.67305","-0.03675"
"12.52100","-151.67305","-0.03966"
"12.59700","-151.67305","-0.04103"
"12.68100","-151.67305","-0.03611"
"12.75600","-151.67305","-0.02993"
"12.83000","-151.67305","-0.04118"
"12.91500","-151.67305","-0.03823"
"13.00300","-151.67305","-0.03162"
"13.08700","-151.67305","-0.04532"
"13.16500","-151.67305","-0.01703"
"13.24700","-151.67305","-0.03213"
"13.33000","-151.67305","-0.02534"
"13.41500","-151.67305","-0.01917"
"13.49700","-151.67305","-0.02807"
"13.57700","-151.67305","-0.01852"
"13.66500","-151.67305","-0.04444"
"13.74500","-151.67305","-0.02381"
"13.83300","-151.67305","-0.01214"
"13.89900","-151.67305","-0.04193"
"13.97400","-151.67305","-0.02106"
"14.06600","-151.67305","-0.02200"
"14.15800","-151.67305","-0.03223"
"14.22400","-151.67305","-0.02922"
"14.29500","-151.67305","-0.02384"
"14.36700","-151.67305","-0.14263"
"14.45400","-151.67305","-0.20549"
"14.51200","-151.67305","-0.17538"
"14.57800","-151.67305","-0.16333"
"14.63900","-151.67305","-0.17446"
"14.74700","-151.67305","-0.14723"
"14.83700","-151.67305","-0.13048"
"14.92400","-151.67305","-0.13130"
"15.00700","-151.67305","-0.12105"
"15.08300","-151.67305","-0.11284"
"15.17100","-151.67305","-0.10392"
"15.22900","-151.67305","-0.10155"
"15.31000","-151.67305","-0.09191"
"15.40500","-151.67305","-0.08593"
"15.50600","-151.67305","-0.06830"
"15.58200","-151.67305","-0.07566"
"15.65500","-151.67305","-0.05962"
"15.75100","-151.67305","-0.05680"
"15.83600","-151.67305","-0.06755"
"15.91600","-151.67305","-0.06768"
"15.99700","-151.67305","-0.05122"
"16.09700","-151.67305","-0.06666"
"16.17300","-151.67305","-0.03699"
"16.28300","-151.67305","-0.05861"
"16.38900","-151.67305","-0.06221"
"16.47000","-151.67305","-0.05325"
"16.55800","-151.67305","-0.06219"
"16.65700","-151.67305","-0.05561"
"16.72500","-151.67305","-0.04788"
"16.82700","-151.67305","-0.04717"
"16.89400","-151.67305","-0.05394"
"16.96900","-151.67305","-0.05045"
"17.04800","-151.67305","-0.04394"
"17.11300","-151.67305","-0.05986"
"17.20000","-151.67305","-0.04875"
"17.28800","-151.67305","-0.03902"
"17.34900","-151.67305","-0.02894"
"17.42300","-151.67305","-0.04546"
"17.51100","-151.67305","-0.02811"
"17.59100","-151.67305","-0.05527"
"17.66400","-151.67305","-0.04225"
"17.77500","-151.67305","-0.03847"
"17.86700","-151.67305","-0.03267"
"17.96700","-151.67305","-0.02542"
"18.04500","-151.67305","-0.04936"
"18.10800","-151.67305","-0.05245"
"18.18500","-151.67305","-0.03126"
"18.25100","-151.67305","-0.03947"
"18.32800","-151.67305","-0.03622"
"18.39500","-151.67305","-0.04007"
"18.47300","-151.67305","-0.03104"
"18.54900","-151.67305","-0.04198"
"18.65400","-151.67305","-0.03601"
"18.73800","-151.67305","-0.03824"
"18.81300","-151.67305","-0.04325"
"18.88500","-151.67305","-0.03512"
"18.96500","-151.67305","-0.04826"
"19.05300","-151.67305","-0.04068"
"19.12900","-151.67305","-0.04719"
"19.21400","-151.67305","-0.04911"
"19.27300","-151.67305","-0.03498"
"19.33800","-151.67305","-0.04943"
"19.42200","-151.67305","-0.04486"
"19.49900","-151.67305","-0.05357"
"19.57700","-151.67305","-0.02432"
"19.65900","-151.67305","-0.03035"
"19.72600","-151.67305","-0.02771"
"19.82200","-151.67305","-0.03460"
"19.88000","-151.67305","-0.04686"
"19.97100","-151.67305","-0.03757"
"20.04500","-151.67305","-0.02567"
"20.12600","-151.67305","-0.04879"
"20.22400","-151.67305","-0.05265"
"20.29800","-151.67305","-0.03969"
"20.38300","-151.67305","-0.02359"
"20.46500","-151.67305","-0.02884"
"20.54200","-151.67305","-0.03189"
"20.63700","-151.67305","-0.03227"
"20.70800","-151.67305","-0.02627"
"20.78000","-151.67305","-0.05226"
"20.86400","-151.67305","-0.22171"
"20.90800","-151.67305","-0.32260"
"20.98700","-151.67305","-0.27900"
"21.07000","-151.67305","-0.24390"
"21.15800","-151.67305","-0.23880"
"21.24500","-151.67305","-0.23356"
"21.34800","-151.67305","-0.22264"
"21.41000","-151.67305","-0.20996"
"21.50100","-151.67305","-0.20826"
"21.60300","-151.67305","-0.19578"
"21.68200","-151.67305","-0.17434"
"21.75700","-151.67305","-0.16934"
"21.82400","-151.67305","-0.18169"
"21.91100","-151.67305","-0.19603"
"21.98700","-151.67305","-0.17592"
"22.07500","-151.67305","-0.18935"
"22.16100","-151.67305","-0.16980"
"22.23300","-151.67305","-0.18603"
"22.30300","-151.67305","-0.16675"
"22.36100","-151.67305","-0.15559"
"22.44400","-151.67305","-0.16265"
"22.53300","-151.67305","-0.15337"
"22.60500","-151.67305","-0.15297"
"22.67300","-151.67305","-0.15741"
"22.75600","-151.67305","-0.14667"
"22.83000","-151.67305","-0.13143"
"22.91100","-151.67305","-0.15593"
"22.98100","-151.67305","-0.15475"
"23.05200","-151.67305","-0.07782"
"23.14100","-151.67305","-0.08346"
"23.21300","-151.67305","-0.08352"
"23.30800","-151.67305","-0.07290"
"23.40300","-151.67305","-0.09753"
"23.47900","-151.67305","-0.06985"
"23.53700","-151.67305","-0.06879"
"23.60800","-151.67305","-0.08780"
"23.67900","-151.67305","-0.06694"
"23.77100","-151.67305","-0.09848"
"23.83900","-151.67305","-0.08179"
"23.96200","-151.67305","-0.06959"
"24.05900","-151.67305","-0.06782"
"24.13500","-151.67305","-0.08040"
"24.20900","-151.67305","-0.07367"
"24.28600","-151.67305","-0.08517"
"24.37600","-151.67305","-0.08217"
"24.45100","-151.67305","-0.09382"
"24.53700","-151.67305","-0.07145"
"24.60400","-151.67305","-0.08228"
"24.69100","-151.67305","-0.08882"
"24.76100","-151.67305","-0.08788"
"24.84900","-151.67305","-0.07907"
"24.93800","-151.67305","-0.08343"
"25.01000","-151.67305","-0.09950"
"25.09300","-151.67305","-0.07017"
"25.19000","-151.67305","-0.07566"
"25.27000","-151.67305","-0.08107"
"25.34100","-151.67305","-0.06902"
"25.42400","-151.67305","-0.08339"
"25.48700","-151.67305","-0.09109"
"25.56100","-151.67305","-0.07560"
"25.64300","-151.67305","-0.08108"
"25.72900","-151.67305","-0.07760"
"25.78700","-151.67305","-0.10498"
"25.86100","-151.67305","-0.08125"
"25.94100","-151.67305","-0.06878"
"25.99500","-151.67305","-0.07845"
"26.07300","-151.67305","-0.08995"
"26.14500","-151.67305","-0.08054"
"26.26700","-151.67305","-0.08563"
"26.34100","-151.67305","-0.09357"
"26.43300","-151.67305","-0.07160"
"26.54300","-151.67305","-0.07271"
"26.62700","-151.67305","-0.07536"
"26.71100","-151.67305","-0.08312"
"26.79900","-151.67305","-0.08915"
"26.88100","-151.67305","-0.07226"
"26.96900","-151.67305","-0.08992"
"27.03100","-151.67305","-0.08982"
"27.12000","-151.67305","-0.07806"
"27.21900","-151.67305","-0.08356"
"27.31200","-151.67305","-0.07023"
"27.38600","-151.67305","-0.07719"
"27.47700","-151.67305","-0.07650"
"27.54900","-151.67305","-0.07855"
"27.63100","-151.67305","-0.07720"
"27.72400","-151.67305","-0.09549"
"27.82100","-151.67305","-0.08274"
"27.90300","-151.67305","-0.07852"
"27.99000","-151.67305","-0.06431"
"28.07200","-151.67305","-0.07652"
"28.15800","-151.67305","-0.07705"
"28.24500","-151.67305","-0.07185"
"28.31800","-151.67305","-0.08759"
"28.40900","-151.67305","-0.07301"
"28.49600","-151.67305","-0.08173"
"28.58300","-151.67305","-0.07573"
"28.65900","-151.67305","-0.07699"
"28.75100","-151.67305","-0.07006"
"28.83100","-151.67305","-0.08104"
"28.91900","-151.67305","-0.07296"
"28.97700","-151.67305","-0.08192"
"29.07100","-151.67305","-0.07261"
"29.16100","-151.67305","-0.07946"
"29.23900","-151.67305","-0.06254"
"29.33900","-151.67305","-0.06559"
"29.42100","-151.67305","-0.07543"
"29.51300","-151.67305","-0.06575"
"29.61800","-151.67305","-0.06893"
"29.69600","-151.67305","-0.06589"
"29.79800","-151.67305","-0.05173"
"29.88100","-151.67305","-0.05785"
"30.01000","-151.67305","-0.07690"
"30.08300","-151.67305","-0.07537"
"30.16100","-151.67305","-0.07775"
"30.24400","-151.67305","-0.06529"
"30.31100","-151.67305","-0.05930"
"30.40000","-151.67305","-0.06896"
"30.49800","-151.67305","-0.06688"
"30.57600","-151.67305","-0.07861"
"30.67000","-151.67305","-0.05714"
"30.76300","-151.67305","-0.06207"
"30.83600","-151.67305","-0.07398"
"30.94400","-151.67305","-0.05747"
"31.02300","-151.67305","-0.06763"
"31.08800","-151.67305","-0.06178"
"31.18800","-151.67305","-0.06579"
"31.26800","-151.67305","-0.06570"
"31.34100","-151.67305","-0.06628"
"31.41800","-151.67305","-0.06934"
"31.51200","-151.67305","-0.07698"
"31.60800","-151.67305","-0.07766"
"31.67300","-151.67305","-0.07208"
"31.75500","-151.67305","-0.07573"
"31.84100","-151.67305","-0.06319"
"31.94500","-151.67305","-0.06324"
"32.03600","-151.67305","-0.06973"
"32.12100","-151.67305","-0.19998"
"32.19200","-151.67305","-0.27157"
"32.26400","-151.67305","-0.25169"
"32.33700","-151.67305","-0.24890"
"32.41300","-151.67305","-0.23285"
"32.49500","-151.67305","-0.24121"
"32.57200","-151.67305","-0.23872"
"32.62700","-151.67305","-0.22306"
"32.70500","-151.67305","-0.23264"
"32.78800","-151.67305","-0.21100"
"32.87100","-151.67305","-0.21721"
"32.94300","-151.67305","-0.21630"
"33.00900","-151.67305","-0.22573"
"33.08600","-151.67305","-0.20213"
"33.16000","-151.67305","-0.21310"
"33.22900","-151.67305","-0.16969"
"33.28600","-151.67305","-0.17395"
"33.36800","-151.67305","-0.17120"
"33.45200","-151.67305","-0.16219"
"33.54900","-151.67305","-0.15714"
"33.63500","-151.67305","-0.17088"
"33.70400","-151.67305","-0.17732"
"33.77300","-151.67305","-0.16654"
"33.84800","-151.67305","-0.15950"
"33.95100","-151.67305","-0.16508"
"34.01700","-151.67305","-0.12322"
"34.08200","-151.67305","-0.11642"
"34.15400","-151.67305","-0.12353"
"34.24000","-151.67305","-0.11733"
"34.32100","-151.67305","-0.11553"
"34.41700","-151.67305","-0.13232"
"34.52300","-151.67305","-0.12137"
"34.60200","-151.67305","-0.14653"
"34.66400","-151.67305","-0.14466"
"34.76400","-151.67305","-0.14486"
"34.87500","-151.67305","-0.12927"
"34.94500","-151.67305","-0.11397"
"35.02300","-151.67305","-0.13820"
"35.09400","-151.67305","-0.10502"
"35.17800","-151.67305","-0.12869"
"35.25500","-151.67305","-0.12029"
"35.31700","-151.67305","-0.11765"
"35.41500","-151.67305","-0.11520"
"35.47700","-151.67305","-0.13057"
"35.56500","-151.67305","-0.12657"
"35.65300","-151.67305","-0.12464"
"35.71600","-151.67305","-0.10610"
"35.80000","-151.67305","-0.13699"
"35.87900","-151.67305","-0.10882"
"35.94800","-151.67305","-0.13151"
"36.04000","-151.67305","-0.10778"
"36.11500","-151.67305","-0.12127"
"36.14800","-151.67305","-0.32391"
"36.20900","-151.67305","-0.23243"
"36.28000","-151.67305","-0.31527"
"36.31800","-151.67305","-0.52927"
"36.39100","-151.67305","-0.57442"
"36.44300","-151.67305","-0.37121"
"36.50400","-151.67305","-0.33572"
"36.59100","-151.67305","-0.42361"
"36.65400","-151.67305","-0.43888"
"36.72800","-151.67305","-0.31208"
"36.76400","-151.67305","-0.11392"
"36.79600","-151.67305","-0.04216"
"36.86800","-151.67305","-0.17187"
"36.95200","-151.67305","-0.19734"
"37.01800","-151.67305","-0.03846"
"37.05300","-151.67305","-0.27969"
"37.06800","-151.67305","-0.52005"
"37.11000","-151.67305","-0.37351"
"37.14000","-151.67305","-0.12359"
"37.21100","-151.67305","-0.07107"
"37.24400","-151.67305","-0.37011"
"37.28900","-151.67305","-0.29861"
"37.32300","-151.67305","-0.10081"
"37.38200","-151.67305","0.01588"
"37.46600","-151.67305","0.00729"
"37.58000","-151.67305","0.01951"
"37.66600","-151.67305","-0.08354"
"37.70700","-151.67305","-0.04810"
"37.77600","-151.67305","0.01620"
"37.86800","-151.67305","0.00181"
"37.95200","-151.67305","0.02549"
"38.03400","-151.67305","0.01447"
"38.13100","-151.67305","-0.00157"
"38.22300","-151.67305","0.02146"
"38.28900","-151.67305","-0.01884"
"38.35100","-151.67305","0.01597"
"38.43300","-151.67305","0.01054"
"38.51800","-151.67305","0.01652"
"38.58700","-151.67305","-0.06578"
"38.65300","-151.67305","-0.03398"
"38.74400","-151.67305","-0.05458"
"38.82800","-151.67305","-0.05584"
"38.90100","-151.67305","-0.07290"
"38.96700","-151.67305","-0.19410"
"39.03000","-151.67305","-0.05562"
"39.09900","-151.67305","-0.06119"
"39.17600","-151.67305","-0.03530"
"39.24200","-151.67305","-0.15361"
"39.29400","-151.67305","0.02221"
"39.38100","-151.67305","0.02013"
"39.49100","-151.67305","0.01072"
"39.57300","-151.67305","-0.01047"
"39.66300","-151.67305","0.01214"
"39.74600","-151.67305","0.00717"
"39.83500","-151.67305","0.00230"
"39.89200","-151.67305","-0.01368"
"39.99300","-151.67305","0.02050"
"40.07300","-151.67305","0.00778"
"40.15600","-151.67305","0.01750"
"40.25600","-151.67305","-0.00018"
"40.32600","-151.67305","-0.00012"
"40.41100","-151.67305","-0.00234"
"40.45900","-151.67305","-0.09078"
"40.51300","-151.67305","-0.05691"
"40.57000","-151.67305","-0.05259"
"40.63400","-151.67305","-0.04379"
"40.70900","-151.67305","-0.04617"
"40.77600","-151.67305","-0.02861"
"40.84900","-151.67305","-0.04494"
"40.92700","-151.67305","-0.04925"
"41.03900","-151.67305","-0.05144"
"41.10800","-151.67305","-0.04088"
"41.20700","-151.67305","-0.03272"
"41.27500","-151.67305","-0.04753"
"41.37100","-151.67305","-0.05015"
"41.45700","-151.67305","-0.04663"
"41.53800","-151.67305","-0.05696"
"41.63700","-151.67305","-0.03415"
"41.72600","-151.67305","-0.04855"
"41.80500","-151.67305","-0.03904"
"41.88800","-151.67305","-0.04224"
"41.96200","-151.67305","-0.04704"
"42.03500","-151.67305","-0.04318"
"42.13300","-151.67305","-0.03855"
"42.19200","-151.67305","-0.03820"
"42.28100","-151.67305","-0.03978"
"42.37200","-151.67305","-0.04080"
"42.44300","-151.67305","-0.05124"
"42.54000","-151.67305","-0.04392"
"42.62700","-151.67305","-0.04770"
"42.69600","-151.67305","-0.02470"
"42.76600","-151.67305","-0.04480"
"42.89100","-151.67305","-0.02239"
"42.98600","-151.67305","-0.03945"
"43.04500","-151.67305","-0.02550"
"43.13900","-151.67305","-0.03457"
"43.24500","-151.67305","-0.02836"
"43.32800","-151.67305","-0.04953"
"43.39200","-151.67305","-0.03748"
"43.48600","-151.67305","-0.03692"
"43.59400","-151.67305","-0.01876"
"43.67400","-151.67305","-0.04225"
"43.75800","-151.67305","-0.02469"
"43.83900","-151.67305","-0.04708"
"43.91600","-151.67305","-0.02622"
"43.99400","-151.67305","-0.01614"
"44.06800","-151.67305","-0.03918"
"44.16500","-151.67305","-0.01574"
"44.24200","-151.67305","-0.04512"
"44.32200","-151.67305","-0.03824"
"44.43200","-151.67305","-0.01657"
"44.49900","-151.67305","-0.03666"
"44.57600","-151.67305","-0.03957"
"44.67300","-151.67305","-0.03802"
"44.75200","-151.67305","-0.02868"
"44.83400","-151.67305","-0.05041"
"44.92300","-151.67305","-0.05096"
"45.00900","-151.67305","-0.03007"
"45.09800","-151.67305","-0.02329"
"45.20100","-151.67305","-0.03894"
"45.29500","-151.67305","-0.02471"
"45.37500","-151.67305","-0.04122"
"45.44900","-151.67305","-0.04476"
"45.51700","-151.67305","-0.01711"
"45.59600","-151.67305","-0.04049"
"45.66300","-151.67305","-0.02435"
"45.74800","-151.67305","-0.04833"
"45.83300","-151.67305","-0.03079"
"45.89400","-151.67305","-0.02280"
"45.96000","-151.67305","-0.02251"
"46.06100","-151.67305","-0.02534"
"46.14300","-151.67305","-0.02837"
"46.22100","-151.67305","-0.03359"
"46.30300","-151.67305","-0.03312"
"46.39600","-151.67305","-0.01422"
"46.46400","-151.67305","-0.04096"
"46.53900","-151.67305","-0.02239"
"46.64600","-151.67305","-0.03928"
"46.74200","-151.67305","-0.03182"
"46.83000","-151.67305","-0.03657"
"46.89600","-151.67305","-0.03007"
"46.98000","-151.67305","-0.04545"
"47.06400","-151.67305","-0.03241"
"47.11500","-151.67305","-0.03793"
"47.18700","-151.67305","-0.03999"
"47.25000","-151.67305","-0.03446"
"47.33400","-151.67305","-0.02722"
"47.42800","-151.67305","-0.02961"
"47.53200","-151.67305","-0.03929"
"47.64400","-151.67305","-0.05133"
"47.71400","-151.67305","-0.25127"
"47.77100","-151.67305","-0.39879"
"47.86200","-151.67305","-0.30694"
"47.94800","-151.67305","-0.27661"
"48.04500","-151.67305","-0.25821"
"48.12600","-151.67305","-0.27486"
"48.23800","-151.67305","-0.25406"
"48.29200","-151.67305","-0.25527"
"48.37500","-151.67305","-0.24357"
"48.45100","-151.67305","-0.23176"
"48.53500","-151.67305","-0.22215"
"48.62600","-151.67305","-0.22114"
"48.71700","-151.67305","-0.23649"
"48.83600","-151.67305","-0.20170"
"48.90700","-151.67305","-0.20957"
"49.00200","-151.67305","-0.17952"
"49.08700","-151.67305","-0.17494"
"49.14500","-151.67305","-0.16155"
"49.22600","-151.67305","-0.16808"
"49.32100","-151.67305","-0.16781"
"49.38500","-151.67305","-0.16012"
"49.44100","-151.67305","-0.14884"
"49.53500","-151.67305","-0.14268"
"49.61700","-151.67305","-0.14577"
"49.70400","-151.67305","-0.14748"
"49.77900","-151.67305","-0.13022"
"49.87200","-151.67305","-0.12298"
"49.97200","-151.67305","-0.11833"
"50.05500","-151.67305","-0.11509"
"50.13700","-151.67305","-0.13315"
"50.21600","-151.67305","-0.11380"
"50.28100","-151.67305","-0.10760"
"50.37600","-151.67305","-0.11475"
"50.44400","-151.67305","-0.12742"
"50.52400","-151.67305","-0.10712"
"50.59500","-151.67305","-0.10239"
"50.66200","-151.67305","-0.11253"
"50.72400","-151.67305","-0.10149"
"50.79700","-151.67305","-0.09644"
"50.90500","-151.67305","-0.11414"
"50.98900","-151.67305","-0.09980"
"51.07300","-151.67305","-0.10967"
"51.17200","-151.67305","-0.10330"
"51.24800","-151.67305","-0.09870"
"51.33300","-151.67305","-0.09889"
"51.42500","-151.67305","-0.08666"
"51.52000","-151.67305","-0.08204"
"51.59800","-151.67305","-0.08500"
"51.67500","-151.67305","-0.07881"
"51.76600","-151.67305","-0.08133"
"51.83600","-151.67305","-0.05671"
"51.92000","-151.67305","-0.06738"
"52.00000","-151.67305","-0.08162"
"52.10600","-151.67305","-0.06452"
"52.19700","-151.67305","-0.07320"
"52.28400","-151.67305","-0.06847"
"52.36100","-151.67305","-0.07771"
"52.44700","-151.67305","-0.06927"
"52.51400","-151.67305","-0.05173"
"52.58700","-151.67305","-0.06230"
"52.64800","-151.67305","-0.07630"
"52.73200","-151.67305","-0.05474"
"52.79100","-151.67305","-0.07734"
"52.88400","-151.67305","-0.07732"
"52.95400","-151.67305","-0.07091"
"53.04200","-151.67305","-0.06018"
"53.13900","-151.67305","-0.07104"
"53.22900","-151.67305","-0.06555"
"53.29400","-151.67305","-0.07656"
"53.38200","-151.67305","-0.06285"
"53.45000","-151.67305","-0.06109"
"53.55300","-151.67305","-0.06193"
"53.62900","-151.67305","-0.08621"
"53.71300","-151.67305","-0.07046"
"53.78800","-151.67305","-0.07668"
"53.86000","-151.67305","-0.07177"
"53.93400","-151.67305","-0.06601"
"54.01400","-151.67305","-0.08350"
"54.10100","-151.67305","-0.07179"
"54.19600","-151.67305","-0.09125"
"54.27000","-151.67305","-0.08813"
"54.34600","-151.67305","-0.06254"
"54.41600","-151.67305","-0.08440"
"54.52300","-151.67305","-0.07419"
"54.62000","-151.67305","-0.07754"
"54.70600","-151.67305","-0.06650"
"54.78300","-151.67305","-0.07015"
"54.88600","-151.67305","-0.08548"
"54.95800","-151.67305","-0.05917"
"55.03100","-151.67305","-0.07061"
"55.11200","-151.67305","-0.07933"
"55.17800","-151.67305","-0.06733"
"55.25100","-151.67305","-0.06888"
"55.34300","-151.67305","-0.08970"
"55.41300","-151.67305","-0.06353"
"55.47900","-151.67305","-0.07704"
"55.57500","-151.67305","-0.05843"
"55.66500","-151.67305","-0.07519"
"55.75000","-151.67305","-0.07737"
"55.84900","-151.67305","-0.08190"
"55.91000","-151.67305","-0.08575"
"55.98700","-151.67305","-0.08199"
"56.07700","-151.67305","-0.07463"
"56.14600","-151.67305","-0.08108"
"56.23400","-151.67305","-0.08163"
"56.31500","-151.67305","-0.06554"
"56.39000","-151.67305","-0.06532"
"56.48300","-151.67305","-0.09339"
"56.54900","-151.67305","-0.07648"
"56.63000","-151.67305","-0.08377"
"56.70400","-151.67305","-0.07846"
"56.76000","-151.67305","-0.06358"
"56.82800","-151.67305","-0.08245"
"56.90500","-151.67305","-0.06411"
"56.98800","-151.67305","-0.06855"
"57.05900","-151.67305","-0.07929"
"57.14100","-151.67305","-0.06774"
"57.23100","-151.67305","-0.07593"
"57.33700","-151.67305","-0.07163"
"57.39900","-151.67305","-0.07586"
"57.43600","-151.67305","-0.06574"
"57.52600","-151.67305","-0.06429"
"57.61000","-151.67305","-0.07160"
"57.69600","-151.67305","-0.07304"
"57.79500","-151.67305","-0.07652"
"57.88700","-151.67305","-0.08396"
"57.95300","-151.67305","-0.07412"
"58.03600","-151.67305","-0.08923"
"58.10300","-151.67305","-0.05887"
"58.20300","-151.67305","-0.07187"
"58.29200","-151.67305","-0.08291"
"58.37800","-151.67305","-0.07248"
"58.43700","-151.67305","-0.07634"
"58.52300","-151.67305","-0.06411"
"58.62300","-151.67305","-0.05875"
"58.71300","-151.67305","-0.07506"
"58.80100","-151.67305","-0.06839"
"58.88300","-151.67305","-0.07944"
"58.96000","-151.67305","-0.08194"
"59.03900","-151.67305","-0.06293"
"59.14300","-151.67305","-0.07425"
"59.21800","-151.67305","-0.08390"
"59.29100","-151.67305","-0.05926"
"59.37700","-151.67305","-0.06036"
"59.45000","-151.67305","-0.05579"
"59.52900","-151.67305","-0.07580"
"59.62600","-151.67305","-0.07852"
"59.70000","-151.67305","-0.06620"
"59.77600","-151.67305","-0.08009"
"59.87600","-151.67305","-0.05719"
"59.95800","-151.67305","-0.05988"
"60.03000","-151.67305","-0.06153"
"60.08400","-151.67305","-0.06929"
"60.15700","-151.67305","-0.07280"
"60.21800","-151.67305","-0.07801"
"60.29200","-151.67305","-0.06419"
"60.36700","-151.67305","-0.06762"
"60.46400","-151.67305","-0.07009"
"60.52700","-151.67305","-0.07136"
"60.59800","-151.67305","-0.06348"
"60.69500","-151.67305","-0.07070"
"60.79800","-151.67305","-0.07096"
"60.87300","-151.67305","-0.08273"
"60.94500","-151.67305","-0.06601"
"61.03300","-151.67305","-0.06535"
"61.11800","-151.67305","-0.06978"
"61.21300","-151.67305","-0.07937"
"61.29100","-151.67305","-0.26316"
"61.37200","-151.67305","-0.35652"
"61.45000","-151.67305","-0.33440"
"61.53000","-151.67305","-0.33056"
"61.59800","-151.67305","-0.32249"
"61.69200","-151.67305","-0.31590"
"61.79100","-151.67305","-0.29193"
"61.88500","-151.67305","-0.29379"
"61.98600","-151.67305","-0.27191"
"62.07100","-151.67305","-0.28893"
"62.15500","-151.67305","-0.27338"
"62.24200","-151.67305","-0.25706"
"62.32200","-151.67305","-0.25762"
"62.36600","-151.67305","-0.24995"
"62.44900","-151.67305","-0.22867"
"62.51100","-151.67305","-0.20093"
"62.60100","-151.67305","-0.20509"
"62.68700","-151.67305","-0.19239"
"62.77100","-151.67305","-0.21680"
"62.85900","-151.67305","-0.20725"
"62.94200","-151.67305","-0.18181"
"63.02700","-151.67305","-0.12970"
"63.10800","-151.67305","-0.16315"
"63.18300","-151.67305","-0.16912"
"63.26700","-151.67305","-0.15340"
"63.34100","-151.67305","-0.16011"
"63.40000","-151.67305","-0.15916"
"63.49000","-151.67305","-0.16696"
"63.54900","-151.67305","-0.16610"
"63.61900","-151.67305","-0.17100"
"63.70400","-151.67305","-0.15217"
"63.80500","-151.67305","-0.16060"
"63.90200","-151.67305","-0.14535"
"64.00000","-151.67305","-0.14414"
"64.07300","-151.67305","-0.16179"
"64.15600","-151.67305","-0.13565"
"64.22700","-151.67305","-0.10596"
"64.29100","-151.67305","-0.11752"
"64.39600","-151.67305","-0.10452"
"64.48000","-151.67305","-0.12681"
"64.54300","-151.67305","-0.11716"
"64.60600","-151.67305","-0.11161"
"64.69300","-151.67305","-0.11669"
"64.79400","-151.67305","-0.11886"
"64.89600","-151.67305","-0.12846"
"64.97300","-151.67305","-0.13096"
"65.04400","-151.67305","-0.12545"
"65.13800","-151.67305","-0.11170"
"65.22900","-151.67305","-0.10373"
"65.29000","-151.67305","-0.12505"
"65.36400","-151.67305","-0.13163"
"65.45500","-151.67305","-0.11576"
"65.53400","-151.67305","-0.10854"
"65.63000","-151.67305","-0.12935"
"65.70400","-151.67305","-0.12342"
"65.77400","-151.67305","-0.13517"
"65.83300","-151.67305","-0.12841"
"65.90100","-151.67305","-0.11246"
"65.97200","-151.67305","-0.12387"
"66.05700","-151.67305","-0.12031"
"66.12400","-151.67305","-0.12177"
"66.19300","-151.67305","-0.13591"
"66.27700","-151.67305","-0.11361"
"66.35700","-151.67305","-0.12253"
"66.42200","-151.67305","-0.10863"
"66.51900","-151.67305","-0.09686"
"66.61500","-151.67305","-0.10700"
"66.70000","-151.67305","-0.13529"
"66.78500","-151.67305","-0.13954"
"66.86800","-151.67305","-0.10728"
"66.94600","-151.67305","-0.13272"
"67.06500","-151.67305","-0.11173"
"67.15000","-151.67305","-0.11773"
"67.21600","-151.67305","-0.11303"
"67.29300","-151.67305","-0.12822"
"67.36900","-151.67305","-0.11357"
"67.44000","-151.67305","-0.12657"
"67.52700","-151.67305","-0.12168"
"67.61500","-151.67305","-0.11607"
"67.70000","-151.67305","-0.20110"
"67.75300","-151.67305","-0.22744"
"67.80800","-151.67305","-0.03220"
"67.87900","-151.67305","-0.11464"
"67.92700","-151.67305","-0.33648"
"67.99400","-151.67305","-0.37843"
"68.05100","-151.67305","-0.17261"
"68.10200","-151.67305","-0.29464"
"68.12600","-151.67305","-0.52370"
"68.16000","-151.67305","-0.47873"
"68.18100","-151.67305","-0.23856"
"68.20500","-151.67305","-0.00147"
"68.29100","-151.67305","0.00226"
"68.37500","-151.67305","0.02656"
"68.44500","-151.67305","0.00732"
"68.54200","-151.67305","0.01129"
"68.63600","-151.67305","0.00218"
"68.72000","-151.67305","0.01468"
"68.78600","-151.67305","0.00445"
"68.84900","-151.67305","0.00775"
"68.92200","-151.67305","-0.00374"
"68.99700","-151.67305","0.01783"
"69.07900","-151.67305","0.00665"
"69.16400","-151.67305","0.01019"
"69.24000","-151.67305","-0.00214"
"69.30900","-151.67305","0.00754"
"69.40700","-151.67305","0.00625"
"69.47500","-151.67305","-0.00233"
"69.55800","-151.67305","0.01440"
"69.66600","-151.67305","0.00614"
"69.75400","-151.67305","0.01499"
"69.83900","-151.67305","0.01770"
"69.91000","-151.67305","-0.01350"
"69.97400","-151.67305","0.00700"
"70.04700","-151.67305","-0.01548"
"70.12300","-151.67305","0.00732"
"70.20700","-151.67305","-0.00213"
"70.27300","-151.67305","0.01176"
"70.35500","-151.67305","0.00770"
"70.44300","-151.67305","0.00388"
"70.52700","-151.67305","0.00105"
"70.61000","-151.67305","0.01834"
"70.69300","-151.67305","0.01162"
"70.79300","-151.67305","0.00402"
"70.85700","-151.67305","0.00512"
"70.94500","-151.67305","0.01043"
"71.03900","-151.67305","0.00862"
"71.12200","-151.67305","-0.00693"
"71.16500","-151.67305","-0.00065"
"71.25900","-151.67305","-0.02630"
"71.34800","-151.67305","-0.08399"
"71.43600","-151.67305","-0.03706"
"71.48500","-151.67305","-0.19194"
"71.53600","-151.67305","-0.21157"
"71.57400","-151.67305","0.02244"
"71.68600","-151.67305","0.01410"
"71.77500","-151.67305","-0.00444"
"71.85700","-151.67305","-0.00033"
"71.92700","-151.67305","0.00587"
"72.00200","-151.67305","0.01527"
"72.08300","-151.67305","0.00633"
"72.16800","-151.67305","-0.00570"
"72.24400","-151.67305","-0.00009"
"72.31400","-151.67305","0.02160"
"72.39900","-151.67305","0.00079"
"72.49100","-151.67305","-0.00680"
"72.57100","-151.67305","-0.00861"
"72.64200","-151.67305","0.00464"
"72.73700","-151.67305","-0.00272"
"72.82300","-151.67305","0.00495"
"72.90400","-151.67305","0.00813"
"72.97700","-151.67305","-0.10331"
"73.02800","-151.67305","-0.01350"
"73.11200","-151.67305","-0.01233"
"73.18300","-151.67305","-0.01440"
"73.26600","-151.67305","-0.01320"
"73.34300","-151.67305","-0.02908"
"73.41600","-151.67305","-0.02865"
"73.47100","-151.67305","-0.01424"
"73.53600","-151.67305","-0.00287"
"73.62900","-151.67305","-0.02528"
"73.72000","-151.67305","-0.01166"
"73.81500","-151.67305","-0.03243"
"73.86500","-151.67305","-0.01222"
"73.92200","-151.67305","-0.01776"
"74.00300","-151.67305","-0.01970"
"74.05700","-151.67305","-0.00882"
"74.13700","-151.67305","-0.03093"
"74.22900","-151.67305","-0.01590"
"74.31400","-151.67305","0.00042"
"74.38200","-151.67305","-0.03073"
"74.46900","-151.67305","-0.01191"
"74.58000","-151.67305","-0.02996"
"74.67100","-151.67305","-0.00430"
"74.73300","-151.67305","-0.02057"
"74.84800","-151.67305","-0.02488"
"74.92900","-151.67305","-0.01335"
"75.00100","-151.67305","-0.03166"
"75.07100","-151.67305","-0.00325"
"75.15500","-151.67305","-0.01475"
"75.23200","-151.67305","-0.02021"
"75.32200","-151.67305","-0.02117"
"75.40900","-151.67305","-0.02967"
"75.48800","-151.67305","-0.01073"
"75.59800","-151.67305","-0.01071"
"75.70100","-151.67305","-0.01653"
"75.80400","-151.67305","-0.01591"
"75.91900","-151.67305","-0.02272"
"75.98100","-151.67305","-0.00439"
"76.05800","-151.67305","0.00099"
"76.14600","-151.67305","-0.03528"
"76.23400","-151.67305","0.00112"
"76.29000","-151.67305","-0.00719"
"76.36800","-151.67305","0.01021"
"76.43600","-151.67305","-0.02472"
"76.52300","-151.67305","-0.02020"
"76.59000","-151.67305","-0.01326"
"76.66800","-151.67305","-0.00849"
"76.78000","-151.67305","-0.02746"
"76.86100","-151.67305","0.00569"
"76.95500","-151.67305","-0.01740"
"77.04800","-151.67305","0.00174"
"77.10400","-151.67305","-0.00462"
"77.16600","-151.67305","-0.01392"
"77.26100","-151.67305","-0.02331"
"77.34300","-151.67305","-0.00537"
"77.43900","-151.67305","-0.01266"
"77.53700","-151.67305","-0.01202"
"77.61600","-151.67305","-0.01072"
"77.70600","-151.67305","-0.02086"
"77.78600","-151.67305","-0.00590"
"77.87400","-151.67305","0.00447"
"77.97400","-151.67305","-0.00252"
"78.06100","-151.67305","0.00957"
"78.13700","-151.67305","-0.02127"
"78.21000","-151.67305","-0.00291"
"78.29900","-151.67305","-0.02815"
"78.38200","-151.67305","-0.00482"
"78.46900","-151.67305","-0.00501"
"78.54600","-151.67305","-0.01763"
"78.62000","-151.67305","-0.02755"
"78.70300","-151.67305","-0.00699"
"78.78200","-151.67305","-0.01500"
"78.85500","-151.67305","-0.02423"
"78.93600","-151.67305","-0.01071"
"79.01000","-151.67305","-0.01742"
"79.08000","-151.67305","-0.02128"
"79.15100","-151.67305","-0.12553"
"79.19200","-151.67305","-0.30799"
"79.25000","-151.67305","-0.40134"
"79.31200","-151.67305","-0.38218"
"79.40500","-151.67305","-0.34877"
"79.49200","-151.67305","-0.34349"
"79.57300","-151.67305","-0.31330"
"79.69000","-151.67305","-0.29624"
"79.76600","-151.67305","-0.28558"
"79.83100","-151.67305","-0.29049"
"79.91400","-151.67305","-0.29340"
"79.99900","-151.67305","-0.28821"
"80.08600","-151.67305","-0.28194"
"80.16300","-151.67305","-0.26457"
"80.25200","-151.67305","-0.28967"
"80.33400","-151.67305","-0.27595"
"80.42200","-151.67305","-0.25331"
"80.51900","-151.67305","-0.24712"
"80.59000","-151.67305","-0.22417"
"80.68200","-151.67305","-0.21892"
"80.76700","-151.67305","-0.20206"
"80.86100","-151.67305","-0.21368"
"80.92900","-151.67305","-0.20687"
"80.99200","-151.67305","-0.20436"
"81.07800","-151.67305","-0.21299"
"81.16700","-151.67305","-0.20932"
"81.22600","-151.67305","-0.18773"
"81.27200","-151.67305","-0.18766"
"81.35600","-151.67305","-0.20104"
"81.44200","-151.67305","-0.20244"
"81.52300","-151.67305","-0.17558"
"81.61100","-151.67305","-0.19813"
"81.67700","-151.67305","-0.18684"
"81.76400","-151.67305","-0.18853"
"81.84400","-151.67305","-0.17835"
"81.92600","-151.67305","-0.19015"
"82.00100","-151.67305","-0.17803"
"82.06200","-151.67305","-0.19817"
"82.13400","-151.67305","-0.17780"
"82.20500","-151.67305","-0.17302"
"82.27500","-151.67305","-0.17396"
"82.33800","-151.67305","-0.15435"
"82.40300","-151.67305","-0.17896"
"82.46400","-151.67305","-0.17451"
"82.52500","-151.67305","-0.17093"
"82.61200","-151.67305","-0.17094"
"82.69300","-151.67305","-0.18608"
"82.75800","-151.67305","-0.17130"
"82.85100","-151.67305","-0.19177"
"82.93400","-151.67305","-0.17463"
"83.01900","-151.67305","-0.15761"
"83.09200","-151.67305","-0.15082"
"83.15000","-151.67305","-0.17253"
"83.22300","-151.67305","-0.15921"
"83.30300","-151.67305","-0.16757"
"83.37500","-151.67305","-0.15764"
"83.45100","-151.67305","-0.15717"
"83.54900","-151.67305","-0.15687"
"83.64200","-151.67305","-0.16329"
"83.72700","-151.67305","-0.16988"
"83.80500","-151.67305","-0.14857"
"83.88200","-151.67305","-0.15067"
"83.94900","-151.67305","-0.15983"
"84.03000","-151.67305","-0.15782"
"84.10600","-151.67305","-0.14294"
"84.18400","-151.67305","-0.16965"
"84.28100","-151.67305","-0.15220"
"84.37500","-151.67305","-0.14146"
"84.46500","-151.67305","-0.13947"
"84.54500","-151.67305","-0.15692"
"84.63100","-151.67305","-0.14356"
"84.71800","-151.67305","-0.14829"
"84.80000","-151.67305","-0.13916"
"84.91500","-151.67305","-0.15327"
"85.00100","-151.67305","-0.14448"
"85.09600","-151.67305","-0.12673"
"85.18400","-151.67305","-0.14669"
"85.25300","-151.67305","-0.13000"
"85.34200","-151.67305","-0.13729"
"85.41600","-151.67305","-0.12665"
"85.50200","-151.67305","-0.12526"
"85.60300","-151.67305","-0.13101"
"85.69000","-151.67305","-0.14273"
"85.77800","-151.67305","-0.14865"
"85.86200","-151.67305","-0.12735"
"85.91400","-151.67305","-0.33868"
"85.95500","-151.67305","-0.36822"
"85.98600","-151.67305","-0.21218"
"86.03200","-151.67305","-0.22605"
"86.10300","-151.67305","-0.29852"
"86.15800","-151.67305","-0.15682"
"86.21000","-151.67305","-0.07719"
"86.29800","-151.67305","-0.03901"
"86.37800","-151.67305","-0.01184"
"86.45100","-151.67305","-0.04515"
"86.53800","-151.67305","0.00049"
"86.62900","-151.67305","0.00021"
"86.72400","-151.67305","0.00550"
"86.80500","-151.67305","-0.00877"
"86.88500","-151.67305","0.01102"
"86.96800","-151.67305","-0.00157"
"87.08000","-151.67305","-0.00630"
"87.17300","-151.67305","0.00299"
"87.27300","-151.67305","0.00839"
"87.34000","-151.67305","0.00697"
"87.42300","-151.67305","0.00366"
"87.51900","-151.67305","0.01703"
"87.60100","-151.67305","0.01890"
"87.66400","-151.67305","0.00307"
"87.72400","-151.67305","0.00722"
"87.81200","-151.67305","0.01413"
"87.88200","-151.67305","0.00734"
"87.97300","-151.67305","0.01723"
"88.07000","-151.67305","0.02001"
"88.17500","-151.67305","0.01207"
"88.26200","-151.67305","0.01235"
"88.32600","-151.67305","0.00597"
"88.41200","-151.67305","-0.00118"
"88.49100","-151.67305","0.01431"
"88.56100","-151.67305","-0.00094"
"88.63500","-151.67305","-0.01004"
"88.71800","-151.67305","0.00698"
"88.80000","-151.67305","0.01292"
"88.86000","-151.67305","-0.09072"
"88.94500","-151.67305","-0.03705"
"89.01100","-151.67305","-0.02133"
"89.09000","-151.67305","-0.01175"
"89.18200","-151.67305","-0.02935"
"89.24100","-151.67305","-0.02170"
"89.31900","-151.67305","-0.02116"
"89.39900","-151.67305","0.00087"
"89.47100","-151.67305","-0.00816"
"89.56900","-151.67305","-0.01659"
"89.64700","-151.67305","-0.00779"
"89.72700","-151.67305","-0.01424"
"89.82200","-151.67305","0.00112"
"89.89900","-151.67305","-0.01850"
"89.96200","-151.67305","-0.02595"
"90.04700","-151.67305","-0.02645"
"90.14500","-151.67305","-0.01941"
"90.23600","-151.67305","-0.01983"
"90.32700","-151.67305","-0.00800"
"90.42800","-151.67305","-0.02060"
"90.49800","-151.67305","-0.00545"
"90.56600","-151.67305","-0.00309"
"90.64200","-151.67305","-0.02894"
"90.70100","-151.67305","-0.03308"
"90.76300","-151.67305","-0.02837"
"90.84200","-151.67305","-0.01562"
"90.92100","-151.67305","-0.01356"
"91.01000","-151.67305","-0.01688"
"91.07100","-151.67305","-0.02753"
"91.13400","-151.67305","-0.01092"
"91.21000","-151.67305","-0.02688"
"91.27300","-151.67305","-0.01492"
"91.35500","-151.67305","-0.00814"
"91.44400","-151.67305","-0.01129"
"91.55400","-151.67305","-0.00623"
"91.62400","-151.67305","-0.00334"
"91.69800","-151.67305","-0.01233"
"91.76400","-151.67305","-0.01833"
"91.82400","-151.67305","-0.00050"
"91.90800","-151.67305","-0.01360"
"91.98000","-151.67305","-0.00498"
"92.05600","-151.67305","0.00783"
"92.13500","-151.67305","-0.02020"
"92.21500","-151.67305","-0.02568"
"92.28800","-151.67305","-0.01793"
"92.36300","-151.67305","0.00015"
"92.43100","-151.67305","-0.02367"
"92.49800","-151.67305","-0.01300"
"92.57300","-151.67305","-0.00945"
"92.66700","-151.67305","-0.02054"
"92.75200","-151.67305","-0.00399"
"92.82100","-151.67305","-0.01640"
"92.91700","-151.67305","-0.01484"
"93.00200","-151.67305","-0.01867"
"93.07800","-151.67305","-0.01300"
"93.15400","-151.67305","-0.00729"
"93.23100","-151.67305","-0.01139"
"93.29700","-151.67305","0.00909"
"93.37000","-151.67305","-0.00865"
"93.45200","-151.67305","-0.00612"
"93.54500","-151.67305","-0.01665"
"93.64000","-151.67305","-0.00477"
"93.71800","-151.67305","-0.01935"
"93.80700","-151.67305","-0.01776"
"93.87500","-151.67305","0.00574"
"93.95400","-151.67305","-0.01011"
"94.03500","-151.67305","-0.01632"
"94.11700","-151.67305","-0.01407"
"94.20800","-151.67305","-0.01212"
"94.28900","-151.67305","-0.00550"
"94.37100","-151.67305","-0.00573"
"94.43100","-151.67305","-0.00418"
"94.50500","-151.67305","-0.00844"
"94.59400","-151.67305","-0.00344"
"94.68400","-151.67305","-0.00824"
"94.76300","-151.67305","-0.00910"
"94.84900","-151.67305","-0.00122"
"94.91900","-151.67305","-0.01749"
"95.00700","-151.67305","-0.01145"
"95.08500","-151.67305","-0.00588"
"95.15700","-151.67305","-0.02188"
"95.23700","-151.67305","-0.00818"
"95.31500","-151.67305","-0.01337"
"95.41500","-151.67305","-0.02135"
"95.49600","-151.67305","-0.01143"
"95.59400","-151.67305","-0.01403"
"95.67000","-151.67305","-0.00584"
"95.78000","-151.67305","-0.01300"
"95.85600","-151.67305","-0.00600"
"95.93700","-151.67305","-0.01218"
"96.01200","-151.67305","-0.02102"
"96.10100","-151.67305","-0.05480"
"96.16200","-151.67305","-0.26948"
"96.22000","-151.67305","-0.42907"
"96.31700","-151.67305","-0.43296"
"96.38300","-151.67305","-0.47671"
"96.45500","-151.67305","-0.46542"
"96.52700","-151.67305","-0.43985"
"96.60900","-151.67305","-0.41144"
"96.70700","-151.67305","-0.38634"
"96.79000","-151.67305","-0.38543"
"96.86700","-151.67305","-0.35074"
"96.93700","-151.67305","-0.36012"
"97.01300","-151.67305","-0.34440"
"97.09900","-151.67305","-0.33426"
"97.19400","-151.67305","-0.31236"
"97.28000","-151.67305","-0.31783"
"97.37100","-151.67305","-0.31760"
"97.44700","-151.67305","-0.31084"
"97.53000","-151.67305","-0.30573"
"97.59400","-151.67305","-0.31366"
"97.66400","-151.67305","-0.29444"
"97.75900","-151.67305","-0.30675"
"97.85100","-151.67305","-0.28065"
"97.93200","-151.67305","-0.27338"
"98.02700","-151.67305","-0.28298"
"98.11100","-151.67305","-0.21752"
"98.17800","-151.67305","-0.24708"
"98.26600","-151.67305","-0.24973"
"98.37300","-151.67305","-0.24274"
"98.45900","-151.67305","-0.23867"
"98.55300","-151.67305","-0.23326"
"98.63900","-151.67305","-0.22685"
"98.72200","-151.67305","-0.22500"
"98.81100","-151.67305","-0.22152"
"98.89000","-151.67305","-0.21854"
"98.96100","-151.67305","-0.20439"
"99.02500","-151.67305","-0.21576"
"99.13100","-151.67305","-0.22000"
"99.21900","-151.67305","-0.21370"
"99.28100","-151.67305","-0.22256"
"99.36600","-151.67305","-0.19818"
"99.45300","-151.67305","-0.20579"
"99.54400","-151.67305","-0.19353"
"99.63300","-151.67305","-0.20376"
"99.71000","-151.67305","-0.21982"
"99.81900","-151.67305","-0.20041"
"99.92400","-151.67305","-0.20477"
"99.99200","-151.67305","-0.20243"
"100.06800","-151.67305","-0.18186"
"100.14300","-151.67305","-0.19531"
"100.23100","-151.67305","-0.20646"
"100.33900","-151.67305","-0.20458"
"100.43000","-151.67305","-0.20015"
"100.50400","-151.67305","-0.18922"
"100.58500","-151.67305","-0.19128"
"100.67400","-151.67305","-0.18515"
"100.74100","-151.67305","-0.18548"
"100.82800","-151.67305","-0.19553"
"100.92100","-151.67305","-0.16552"
"101.02100","-151.67305","-0.19873"
"101.09500","-151.67305","-0.18183"
"101.16300","-151.67305","-0.18537"
"101.24500","-151.67305","-0.17577"
"101.34900","-151.67305","-0.17013"
"101.44000","-151.67305","-0.17333"
"101.49400","-151.67305","-0.17059"
"101.58300","-151.67305","-0.16920"
"101.66900","-151.67305","-0.17841"
"101.76800","-151.67305","-0.17611"
"101.85200","-151.67305","-0.16994"
"101.91600","-151.67305","-0.16852"
"102.00700","-151.67305","-0.15770"
"102.09000","-151.67305","-0.15796"
"102.17100","-151.67305","-0.17894"
"102.23200","-151.67305","-0.16485"
"102.32400","-151.67305","-0.15281"
"102.41000","-151.67305","-0.14827"
"102.48500","-151.67305","-0.16579"
"102.55700","-151.67305","-0.16362"
"102.63300","-151.67305","-0.15754"
"102.71000","-151.67305","-0.15742"
"102.78900","-151.67305","-0.16103"
"102.88900","-151.67305","-0.15697"
"102.97500","-151.67305","-0.15525"
"103.06400","-151.67305","-0.16526"
"103.15400","-151.67305","-0.14002"
"103.22500","-151.67305","-0.16391"
"103.29600","-151.67305","-0.14872"
"103.37000","-151.67305","-0.14792"
"103.45800","-151.67305","-0.15379"
"103.54100","-151.67305","-0.14804"
"103.61800","-151.67305","-0.14396"
"103.69800","-151.67305","-0.14217"
"103.79200","-151.67305","-0.14845"
"103.87200","-151.67305","-0.13152"
"103.96600","-151.67305","-0.14722"
"104.04700","-151.67305","-0.14195"
"104.13400","-151.67305","-0.12608"
"104.20100","-151.67305","-0.15694"
"104.26200","-151.67305","-0.16063"
"104.33200","-151.67305","-0.13057"
"104.41100","-151.67305","-0.15747"
"104.49000","-151.67305","-0.13053"
"104.56100","-151.67305","-0.15282"
"104.64400","-151.67305","-0.13638"
"104.72000","-151.67305","-0.14678"
"104.81100","-151.67305","-0.12811"
"104.89700","-151.67305","-0.12700"
"104.95900","-151.67305","-0.13242"
"105.05400","-151.67305","-0.13566"
"105.13400","-151.67305","-0.12706"
"105.19800","-151.67305","-0.13047"
"105.28900","-151.67305","-0.14462"
"105.37400","-151.67305","-0.13422"
"105.43800","-151.67305","-0.13727"
"105.52700","-151.67305","-0.14150"
"105.60100","-151.67305","-0.14051"
"105.68100","-151.67305","-0.12643"
"105.77000","-151.67305","-0.11524"
"105.82700","-151.67305","-0.11051"
"105.91300","-151.67305","-0.12749"
"106.01000","-151.67305","-0.14593"
"106.07400","-151.67305","-0.10911"
"106.17600","-151.67305","-0.12320"
"106.26100","-151.67305","-0.11418"
"106.33400","-151.67305","-0.12097"
"106.41400","-151.67305","-0.11549"
"106.47300","-151.67305","-0.12291"
"106.55800","-151.67305","-0.11108"
"106.63500","-151.67305","-0.10231"
"106.71700","-151.67305","-0.12103"
"106.80400","-151.67305","-0.13011"
"106.89300","-151.67305","-0.11895"
"106.97200","-151.67305","-0.12115"
"107.05100","-151.67305","-0.13670"
"107.11800","-151.67305","-0.12123"
"107.22200","-151.67305","-0.11621"
"107.29900","-151.67305","-0.12162"
"107.39300","-151.67305","-0.11758"
"107.47000","-151.67305","-0.11814"
"107.54600","-151.67305","-0.10912"
"107.61400","-151.67305","-0.11132"
"107.69500","-151.67305","-0.11735"
"107.75300","-151.67305","-0.12423"
"107.84700","-151.67305","-0.11092"
"107.91800","-151.67305","-0.10621"
"108.00600","-151.67305","-0.10816"
"108.10500","-151.67305","-0.10550"
"108.19800","-151.67305","-0.12174"
"108.26200","-151.67305","-0.11303"
"108.33500","-151.67305","-0.10870"
"108.42400","-151.67305","-0.10070"
"108.50100","-151.67305","-0.11749"
"108.58100","-151.67305","-0.09999"
"108.66400","-151.67305","-0.08763"
"108.76300","-151.67305","-0.09700"
"108.83900","-151.67305","-0.09937"
"108.92200","-151.67305","-0.10065"
"109.01800","-151.67305","-0.12499"
"109.09100","-151.67305","-0.11737"
"109.15400","-151.67305","-0.12115"
"109.24100","-151.67305","-0.11045"
"109.30900","-151.67305","-0.10449"
"109.40800","-151.67305","-0.10898"
"109.49100","-151.67305","-0.11015"
"109.56000","-151.67305","-0.10359"
"109.64600","-151.67305","-0.10837"