File: chapter 4/force/mini_patrick.is_tens_RawData/Specimen_RawData_1.csv
Time,Extension,Load
(s),(mm),(N)
"0.00000","-147.73099","0.00459"
"0.08300","-147.73099","-0.01151"
"0.17300","-147.73099","0.00761"
"0.24100","-147.73099","-0.00586"
"0.31500","-147.73099","-0.00599"
"0.40000","-147.73099","-0.00073"
"0.48300","-147.73099","-0.00537"
"0.57100","-147.73099","-0.00589"
"0.65200","-147.73099","0.01147"
"0.71800","-147.73099","0.00311"
"0.81100","-147.73099","-0.01055"
"0.89100","-147.73099","-0.00155"
"0.98100","-147.73099","-0.01238"
"1.04900","-147.73099","0.02039"
"1.11200","-147.73099","0.01114"
"1.19200","-147.73099","-0.00491"
"1.25800","-147.73099","0.01560"
"1.32300","-147.73099","-0.00448"
"1.41000","-147.73099","-0.00651"
"1.49000","-147.73099","0.00387"
"1.55000","-147.73099","-0.01326"
"1.64000","-147.73099","-0.00237"
"1.72200","-147.73099","0.01612"
"1.78700","-147.73099","0.00696"
"1.87600","-147.73099","0.00231"
"1.96500","-147.73099","-0.01765"
"2.04500","-147.73099","-0.01911"
"2.14900","-147.73099","0.00433"
"2.22100","-147.73099","-0.01685"
"2.29900","-147.73099","-0.00350"
"2.37000","-147.73099","-0.00981"
"2.45700","-147.73099","-0.00457"
"2.52700","-147.73099","-0.01309"
"2.62900","-147.73099","-0.00914"
"2.71300","-147.73099","0.00664"
"2.79700","-147.73099","-0.00212"
"2.86800","-147.73099","-0.01214"
"2.95200","-147.73099","-0.02084"
"3.01600","-147.73099","-0.01718"
"3.09300","-147.73099","-0.01195"
"3.18600","-147.73099","0.01083"
"3.27800","-147.73099","0.00496"
"3.37100","-147.73099","-0.01288"
"3.44400","-147.73099","-0.00719"
"3.51500","-147.73099","-0.00836"
"3.57700","-147.73099","-0.01103"
"3.64900","-147.73099","0.00593"
"3.73200","-147.73099","-0.01385"
"3.79400","-147.73099","-0.01664"
"3.88500","-147.73099","-0.01790"
"3.98100","-147.73099","-0.02019"
"4.08300","-147.73099","-0.00675"
"4.17700","-147.73099","-0.00702"
"4.25600","-147.73099","-0.00535"
"4.34000","-147.73099","-0.01422"
"4.40200","-147.73099","0.00578"
"4.48600","-147.73099","-0.00197"
"4.56500","-147.73099","0.00347"
"4.65700","-147.73099","0.00781"
"4.74300","-147.73099","0.01418"
"4.81600","-147.73099","-0.01922"
"4.89900","-147.73099","0.01713"
"4.97700","-147.73099","-0.00344"
"5.08100","-147.73099","-0.00087"
"5.17300","-147.73099","0.01034"
"5.24600","-147.73099","-0.01173"
"5.32500","-147.73099","-0.00796"
"5.39100","-147.73099","-0.00420"
"5.47900","-147.73099","0.01330"
"5.55700","-147.73099","-0.01601"
"5.64100","-147.73099","-0.00222"
"5.74200","-147.73099","-0.00288"
"5.82500","-147.73099","-0.00099"
"5.94100","-147.73099","-0.00749"
"6.01300","-147.73099","0.01388"
"6.10600","-147.73099","-0.00790"
"6.18200","-147.73099","-0.00430"
"6.25900","-147.73099","0.00181"
"6.35800","-147.73099","-0.00867"
"6.45700","-147.73099","0.00590"
"6.52000","-147.73099","0.01903"
"6.59600","-147.73099","-0.02054"
"6.67000","-147.73099","0.01117"
"6.76100","-147.73099","0.01008"
"6.83500","-147.73099","-0.01807"
"6.90800","-147.73099","-0.00736"
"7.01900","-147.73099","-0.00402"
"7.11500","-147.73099","-0.01376"
"7.18700","-147.73099","-0.01344"
"7.27200","-147.73099","-0.00614"
"7.34100","-147.73099","-0.01437"
"7.42200","-147.73099","0.00792"
"7.50100","-147.73099","0.01124"
"7.58000","-147.73099","0.00339"
"7.66700","-147.73099","-0.00171"
"7.72700","-147.73099","-0.00639"
"7.81200","-147.73099","0.00268"
"7.89200","-147.73099","-0.00806"
"7.97400","-147.73099","0.00899"
"8.06200","-147.73099","0.00830"
"8.13800","-147.73099","0.00019"
"8.23600","-147.73099","-0.00424"
"8.30500","-147.73099","0.00101"
"8.38800","-147.73099","-0.00120"
"8.46700","-147.73099","-0.00405"
"8.56300","-147.73099","0.01074"
"8.63200","-147.73099","-0.01315"
"8.69800","-147.73099","-0.00309"
"8.76200","-147.73099","0.00996"
"8.83800","-147.73099","-0.01447"
"8.90700","-147.73099","-0.00452"
"8.99200","-147.73099","-0.00120"
"9.07500","-147.73099","-0.00919"
"9.15000","-147.73099","-0.00373"
"9.23100","-147.73099","0.00054"
"9.32100","-147.73099","0.00035"
"9.43100","-147.73099","0.00580"
"9.51600","-147.73099","-0.00691"
"9.60400","-147.73099","-0.01551"
"9.68500","-147.73099","-0.00576"
"9.78800","-147.73099","-0.00415"
"9.85700","-147.73099","-0.01031"
"9.95200","-147.73099","0.00263"
"10.00600","-147.73099","-0.02016"
"10.07900","-147.73099","-0.10141"
"10.16400","-147.73099","-0.06872"
"10.24200","-147.73099","-0.07712"
"10.31700","-147.73099","-0.05834"
"10.41400","-147.73099","-0.06655"
"10.50800","-147.73099","-0.06252"
"10.59900","-147.73099","-0.05060"
"10.70700","-147.73099","-0.04953"
"10.77600","-147.73099","-0.04305"
"10.84100","-147.73099","-0.04340"
"10.94200","-147.73099","-0.03873"
"11.03000","-147.73099","-0.04533"
"11.12100","-147.73099","-0.03474"
"11.21900","-147.73099","-0.03160"
"11.28700","-147.73099","-0.03431"
"11.36900","-147.73099","-0.01866"
"11.44800","-147.73099","-0.02864"
"11.52400","-147.73099","-0.02766"
"11.60100","-147.73099","-0.02539"
"11.70200","-147.73099","-0.02734"
"11.78200","-147.73099","-0.00898"
"11.88300","-147.73099","-0.00546"
"11.98400","-147.73099","-0.00272"
"12.06100","-147.73099","-0.01059"
"12.13600","-147.73099","-0.02197"
"12.21700","-147.73099","-0.01806"
"12.28700","-147.73099","-0.02303"
"12.39200","-147.73099","-0.00793"
"12.46900","-147.73099","0.00124"
"12.54600","-147.73099","0.00295"
"12.63500","-147.73099","-0.00546"
"12.72600","-147.73099","-0.01512"
"12.81200","-147.73099","0.00232"
"12.87000","-147.73099","-0.01783"
"12.96500","-147.73099","0.00241"
"13.04000","-147.73099","0.00137"
"13.11300","-147.73099","-0.01917"
"13.18200","-147.73099","-0.01202"
"13.27500","-147.73099","-0.00184"
"13.35700","-147.73099","-0.02023"
"13.43800","-147.73099","-0.01890"
"13.54100","-147.73099","-0.00338"
"13.62700","-147.73099","-0.01169"
"13.69800","-147.73099","-0.01418"
"13.79100","-147.73099","-0.00355"
"13.86800","-147.73099","-0.00773"
"13.95100","-147.73099","-0.01352"
"14.04500","-147.73099","-0.01906"
"14.14300","-147.73099","-0.00278"
"14.21500","-147.73099","-0.00026"
"14.29000","-147.73099","-0.00259"
"14.39700","-147.73099","-0.01482"
"14.46700","-147.73099","-0.00026"
"14.55000","-147.73099","-0.01219"
"14.63100","-147.73099","0.00122"
"14.72500","-147.73099","0.00196"
"14.81400","-147.73099","-0.00027"
"14.89600","-147.73099","0.00065"
"14.99100","-147.73099","-0.01303"
"15.07300","-147.73099","0.00473"
"15.15500","-147.73099","-0.00840"
"15.24300","-147.73099","0.01299"
"15.31900","-147.73099","0.00813"
"15.41500","-147.73099","0.00000"
"15.48100","-147.73099","0.00228"
"15.55500","-147.73099","-0.00781"
"15.62500","-147.73099","-0.00320"
"15.72200","-147.73099","-0.00899"
"15.78400","-147.73099","0.01137"
"15.83900","-147.73099","0.00141"
"15.93000","-147.73099","-0.00499"
"15.98600","-147.73099","-0.01397"
"16.06800","-147.73099","-0.00736"
"16.16200","-147.73099","0.00858"
"16.22700","-147.73099","0.00182"
"16.30200","-147.73099","-0.00095"
"16.40200","-147.73099","-0.00280"
"16.49800","-147.73099","-0.00996"
"16.60500","-147.73099","-0.01651"
"16.68900","-147.73099","-0.01849"
"16.77200","-147.73099","-0.00506"
"16.85400","-147.73099","-0.02854"
"16.90900","-147.73099","-0.00511"
"16.98100","-147.73099","-0.00400"
"17.06600","-147.73099","-0.00978"
"17.15600","-147.73099","-0.00733"
"17.21800","-147.73099","-0.00443"
"17.32000","-147.73099","0.00329"
"17.42700","-147.73099","-0.01163"
"17.50300","-147.73099","-0.01145"
"17.56800","-147.73099","-0.01552"
"17.64200","-147.73099","0.00190"
"17.71500","-147.73099","0.01332"
"17.80100","-147.73099","-0.01913"
"17.87800","-147.73099","-0.01130"
"17.96200","-147.73099","0.00961"
"18.05000","-147.73099","-0.01014"
"18.15400","-147.73099","-0.01208"
"18.23200","-147.73099","0.00218"
"18.33200","-147.73099","-0.00193"
"18.42300","-147.73099","-0.00281"
"18.50600","-147.73099","-0.00367"
"18.59500","-147.73099","-0.00889"
"18.67300","-147.73099","-0.01312"
"18.77300","-147.73099","-0.00392"
"18.85600","-147.73099","0.00265"
"18.94400","-147.73099","-0.00164"
"19.00700","-147.73099","0.00211"
"19.08800","-147.73099","0.00904"
"19.17900","-147.73099","-0.00225"
"19.24900","-147.73099","0.00056"
"19.31900","-147.73099","0.00129"
"19.40900","-147.73099","-0.00298"
"19.48000","-147.73099","-0.01117"
"19.55500","-147.73099","-0.01507"
"19.64300","-147.73099","0.01465"
"19.70700","-147.73099","-0.00748"
"19.78900","-147.73099","-0.18169"
"19.84800","-147.73099","-0.24989"
"19.94100","-147.73099","-0.20377"
"20.02800","-147.73099","-0.17869"
"20.09700","-147.73099","-0.18657"
"20.17300","-147.73099","-0.16129"
"20.26000","-147.73099","-0.15707"
"20.35000","-147.73099","-0.14562"
"20.43200","-147.73099","-0.12431"
"20.51700","-147.73099","-0.11552"
"20.61300","-147.73099","-0.13805"
"20.70700","-147.73099","-0.11828"
"20.79600","-147.73099","-0.11884"
"20.88000","-147.73099","-0.10971"
"20.94600","-147.73099","-0.10146"
"21.02000","-147.73099","-0.10400"
"21.08400","-147.73099","-0.10701"
"21.16600","-147.73099","-0.09518"
"21.26000","-147.73099","-0.10432"
"21.33700","-147.73099","-0.10989"
"21.41500","-147.73099","-0.09711"
"21.49200","-147.73099","-0.09174"
"21.57400","-147.73099","-0.02718"
"21.65800","-147.73099","-0.03494"
"21.74500","-147.73099","-0.02894"
"21.84200","-147.73099","-0.02448"
"21.90700","-147.73099","-0.02138"
"21.98500","-147.73099","-0.02926"
"22.06600","-147.73099","-0.01211"
"22.13400","-147.73099","-0.02239"
"22.21800","-147.73099","-0.02219"
"22.32900","-147.73099","-0.01315"
"22.43600","-147.73099","-0.01972"
"22.52500","-147.73099","-0.02142"
"22.61200","-147.73099","-0.02603"
"22.70000","-147.73099","-0.02851"
"22.78800","-147.73099","-0.01763"
"22.88400","-147.73099","0.00310"
"22.95300","-147.73099","-0.02474"
"23.03700","-147.73099","-0.00631"
"23.10200","-147.73099","-0.02175"
"23.18100","-147.73099","-0.02152"
"23.23700","-147.73099","-0.01040"
"23.30800","-147.73099","-0.01239"
"23.37200","-147.73099","-0.01728"
"23.44800","-147.73099","-0.01721"
"23.52200","-147.73099","-0.00500"
"23.60200","-147.73099","-0.01795"
"23.64600","-147.73099","-0.00389"
"23.69400","-147.73099","-0.01393"
"23.76900","-147.73099","0.00273"
"23.86100","-147.73099","-0.01025"
"23.93300","-147.73099","-0.00685"
"24.00000","-147.73099","-0.00680"
"24.07800","-147.73099","0.00554"
"24.15500","-147.73099","-0.01244"
"24.23200","-147.73099","-0.00267"
"24.31200","-147.73099","-0.00732"
"24.40100","-147.73099","0.00998"
"24.45600","-147.73099","0.01027"
"24.51000","-147.73099","-0.00275"
"24.59600","-147.73099","-0.00361"
"24.68700","-147.73099","-0.01159"
"24.75100","-147.73099","-0.01150"
"24.83300","-147.73099","0.00359"
"24.91700","-147.73099","-0.00211"
"25.00000","-147.73099","-0.01471"
"25.08000","-147.73099","-0.00160"
"25.17100","-147.73099","-0.00219"
"25.25000","-147.73099","0.00925"
"25.33000","-147.73099","-0.00088"
"25.40900","-147.73099","-0.01562"
"25.48900","-147.73099","-0.01048"
"25.55400","-147.73099","-0.01127"
"25.62000","-147.73099","-0.01668"
"25.70700","-147.73099","-0.00297"
"25.78200","-147.73099","0.00132"
"25.87000","-147.73099","0.00174"
"25.96600","-147.73099","0.00037"
"26.05100","-147.73099","-0.00691"
"26.14000","-147.73099","-0.02306"
"26.20600","-147.73099","0.00037"
"26.28800","-147.73099","0.00368"
"26.35400","-147.73099","-0.00398"
"26.44900","-147.73099","-0.01464"
"26.53900","-147.73099","-0.02114"
"26.63900","-147.73099","-0.00529"
"26.71800","-147.73099","-0.02249"
"26.81200","-147.73099","0.00356"
"26.88400","-147.73099","0.00056"
"26.95600","-147.73099","-0.00082"
"27.00800","-147.73099","0.00300"
"27.08700","-147.73099","-0.00788"
"27.17100","-147.73099","-0.00946"
"27.26100","-147.73099","0.00304"
"27.33700","-147.73099","0.00368"
"27.41600","-147.73099","-0.01267"
"27.47800","-147.73099","-0.00455"
"27.55900","-147.73099","-0.00579"
"27.61200","-147.73099","-0.01037"
"27.67900","-147.73099","-0.00090"
"27.76700","-147.73099","-0.00821"
"27.84400","-147.73099","0.00936"
"27.90700","-147.73099","0.00875"
"28.00500","-147.73099","0.00251"
"28.08400","-147.73099","0.00937"
"28.16200","-147.73099","0.01036"
"28.23200","-147.73099","-0.01356"
"28.29200","-147.73099","0.00424"
"28.34500","-147.73099","-0.01537"
"28.43800","-147.73099","-0.00596"
"28.49500","-147.73099","-0.00779"
"28.57200","-147.73099","-0.00001"
"28.66300","-147.73099","-0.00239"
"28.74100","-147.73099","-0.01194"
"28.82100","-147.73099","0.00591"
"28.88100","-147.73099","0.00749"
"28.96700","-147.73099","-0.01533"
"29.02700","-147.73099","0.00593"
"29.08400","-147.73099","-0.00350"
"29.14800","-147.73099","0.00622"
"29.23200","-147.73099","-0.01640"
"29.30000","-147.73099","-0.01834"
"29.37200","-147.73099","-0.00632"
"29.43800","-147.73099","-0.00920"
"29.50000","-147.73099","-0.00895"
"29.59200","-147.73099","-0.00282"
"29.66700","-147.73099","-0.00370"
"29.75100","-147.73099","-0.00533"
"29.83800","-147.73099","-0.01051"
"29.91600","-147.73099","-0.01058"
"30.00100","-147.73099","0.00389"
"30.08400","-147.73099","0.00194"
"30.16900","-147.73099","-0.01237"
"30.25100","-147.73099","-0.00547"
"30.33800","-147.73099","-0.00723"
"30.42400","-147.73099","-0.00463"
"30.52900","-147.73099","0.00389"
"30.60300","-147.73099","-0.00383"
"30.68600","-147.73099","-0.00910"
"30.79600","-147.73099","-0.00490"
"30.86900","-147.73099","-0.01382"
"30.95900","-147.73099","-0.00740"
"31.04500","-147.73099","-0.01528"
"31.12900","-147.73099","0.00343"
"31.20700","-147.73099","-0.00219"
"31.29300","-147.73099","-0.01615"
"31.37500","-147.73099","0.01835"
"31.45600","-147.73099","-0.01162"
"31.55400","-147.73099","-0.01863"
"31.60800","-147.73099","-0.00459"
"31.67700","-147.73099","-0.01009"
"31.74600","-147.73099","-0.00383"
"31.84400","-147.73099","-0.00515"
"31.92900","-147.73099","-0.00792"
"32.01200","-147.73099","-0.00479"
"32.08600","-147.73099","-0.00142"
"32.19100","-147.73099","0.00303"
"32.29000","-147.73099","-0.00088"
"32.38300","-147.73099","-0.00006"
"32.46100","-147.73099","-0.00504"
"32.54400","-147.73099","-0.01178"
"32.61400","-147.73099","-0.00775"
"32.70700","-147.73099","-0.01132"
"32.79300","-147.73099","0.01038"
"32.87200","-147.73099","-0.01214"
"32.93500","-147.73099","0.00577"
"33.03200","-147.73099","0.00219"
"33.11900","-147.73099","-0.01245"
"33.17000","-147.73099","-0.00105"
"33.24700","-147.73099","0.00169"
"33.31900","-147.73099","-0.00569"
"33.40500","-147.73099","-0.01540"
"33.45500","-147.73099","0.00626"
"33.54600","-147.73099","0.00133"
"33.62300","-147.73099","0.01409"
"33.69900","-147.73099","0.00463"
"33.78600","-147.73099","0.01308"
"33.88500","-147.73099","0.00053"
"33.98500","-147.73099","0.00848"
"34.09900","-147.73099","0.00584"
"34.16700","-147.73099","-0.01338"
"34.26600","-147.73099","0.00078"
"34.34400","-147.73099","0.00250"
"34.42400","-147.73099","-0.00846"
"34.50100","-147.73099","-0.00940"
"34.58100","-147.73099","-0.00862"
"34.66000","-147.73099","-0.01633"
"34.73000","-147.73099","0.00806"
"34.81700","-147.73099","0.01481"
"34.88500","-147.73099","0.00853"
"34.95400","-147.73099","-0.00160"
"35.03600","-147.73099","-0.00119"
"35.12300","-147.73099","0.00741"
"35.20500","-147.73099","-0.00492"
"35.28700","-147.73099","-0.00041"
"35.37500","-147.73099","-0.01254"
"35.45200","-147.73099","0.00857"
"35.53600","-147.73099","-0.00992"
"35.62800","-147.73099","0.00227"
"35.71000","-147.73099","-0.00961"
"35.79800","-147.73099","0.00514"
"35.87600","-147.73099","-0.01762"
"35.97900","-147.73099","-0.00084"
"36.05900","-147.73099","-0.00023"
"36.14500","-147.73099","-0.00281"
"36.23200","-147.73099","-0.00169"
"36.31500","-147.73099","-0.00219"
"36.39800","-147.73099","-0.01103"
"36.47500","-147.73099","-0.01205"
"36.54900","-147.73099","0.00139"
"36.64100","-147.73099","0.00714"
"36.72700","-147.73099","-0.00732"
"36.78100","-147.73099","-0.00119"
"36.89000","-147.73099","0.00158"
"36.97100","-147.73099","-0.01113"
"37.04400","-147.73099","0.01338"
"37.12200","-147.73099","-0.00797"
"37.20200","-147.73099","0.00571"
"37.27900","-147.73099","0.01131"
"37.34000","-147.73099","-0.02169"
"37.43100","-147.73099","-0.00380"
"37.49500","-147.73099","-0.00245"
"37.56700","-147.73099","-0.00201"
"37.63800","-147.73099","-0.00430"
"37.72100","-147.73099","-0.01153"
"37.80700","-147.73099","-0.00944"
"37.88800","-147.73099","-0.00472"
"37.98800","-147.73099","-0.00685"
"38.07100","-147.73099","0.00120"
"38.14100","-147.73099","0.00687"
"38.22400","-147.73099","-0.01240"
"38.30900","-147.73099","0.01443"
"38.40400","-147.73099","-0.00096"
"38.49800","-147.73099","-0.00470"
"38.58000","-147.73099","-0.01789"
"38.67300","-147.73099","-0.00647"
"38.76200","-147.73099","-0.00002"
"38.84500","-147.73099","-0.00976"
"38.93400","-147.73099","0.00428"
"39.01100","-147.73099","-0.00554"
"39.09200","-147.73099","-0.00657"
"39.16600","-147.73099","-0.00839"
"39.24300","-147.73099","-0.00156"
"39.35000","-147.73099","0.01093"
"39.43600","-147.73099","-0.01271"
"39.53100","-147.73099","-0.00227"
"39.60400","-147.73099","-0.00704"
"39.67600","-147.73099","-0.00789"
"39.74300","-147.73099","-0.00378"
"39.82500","-147.73099","0.00438"
"39.89100","-147.73099","-0.01365"
"39.96400","-147.73099","-0.10084"
"40.05800","-147.73099","-0.06689"
"40.11400","-147.73099","-0.06784"
"40.17900","-147.73099","-0.05106"
"40.26800","-147.73099","-0.04928"
"40.36600","-147.73099","-0.04623"
"40.44500","-147.73099","-0.04649"
"40.53700","-147.73099","-0.05212"
"40.62700","-147.73099","-0.03948"
"40.70900","-147.73099","-0.03231"
"40.79500","-147.73099","-0.04469"
"40.87900","-147.73099","-0.01420"
"40.95400","-147.73099","-0.04163"
"41.04600","-147.73099","-0.02984"
"41.12200","-147.73099","-0.01445"
"41.20000","-147.73099","-0.01458"
"41.27100","-147.73099","-0.02504"
"41.34000","-147.73099","-0.01622"
"41.41500","-147.73099","-0.01404"
"41.48800","-147.73099","0.00622"
"41.57000","-147.73099","-0.00248"
"41.67200","-147.73099","-0.01742"
"41.75100","-147.73099","-0.01341"
"41.84400","-147.73099","-0.00176"
"41.91200","-147.73099","-0.00669"
"41.98700","-147.73099","-0.01542"
"42.05400","-147.73099","-0.01627"
"42.10800","-147.73099","-0.00585"
"42.18500","-147.73099","-0.02035"
"42.26700","-147.73099","-0.00383"
"42.34400","-147.73099","0.00230"
"42.41700","-147.73099","0.00349"
"42.50900","-147.73099","-0.01849"
"42.60200","-147.73099","-0.00567"
"42.68500","-147.73099","-0.00120"
"42.78500","-147.73099","0.00101"
"42.86800","-147.73099","-0.01228"
"42.94700","-147.73099","-0.00483"
"43.03700","-147.73099","-0.01239"
"43.10800","-147.73099","-0.00327"
"43.20300","-147.73099","-0.00835"
"43.28200","-147.73099","-0.01988"
"43.37900","-147.73099","-0.00726"
"43.45100","-147.73099","0.00283"
"43.53500","-147.73099","-0.01449"
"43.60500","-147.73099","-0.00993"
"43.67800","-147.73099","0.00285"
"43.74200","-147.73099","0.00444"
"43.82400","-147.73099","-0.00449"
"43.91200","-147.73099","-0.00701"
"43.98000","-147.73099","-0.00887"
"44.05200","-147.73099","0.00266"
"44.14400","-147.73099","0.00536"
"44.22100","-147.73099","-0.00421"
"44.30800","-147.73099","0.00304"
"44.38600","-147.73099","0.01332"
"44.44500","-147.73099","0.00126"
"44.52300","-147.73099","-0.00842"
"44.61500","-147.73099","0.00375"
"44.68800","-147.73099","0.00189"
"44.76800","-147.73099","-0.00398"
"44.85000","-147.73099","-0.00040"
"44.95100","-147.73099","-0.00308"
"45.05500","-147.73099","-0.01182"
"45.14100","-147.73099","0.00346"
"45.20600","-147.73099","-0.00510"
"45.28800","-147.73099","-0.00225"
"45.37600","-147.73099","-0.00376"
"45.47200","-147.73099","-0.00922"
"45.57600","-147.73099","-0.00922"
"45.64800","-147.73099","0.00372"
"45.73400","-147.73099","-0.02230"
"45.79600","-147.73099","0.01168"
"45.85700","-147.73099","0.00334"
"45.93700","-147.73099","0.00196"
"46.02700","-147.73099","0.00542"
"46.12200","-147.73099","0.00442"
"46.20400","-147.73099","0.00212"
"46.29600","-147.73099","0.00187"
"46.38700","-147.73099","-0.00343"
"46.46400","-147.73099","-0.00724"
"46.54200","-147.73099","-0.01272"
"46.61300","-147.73099","-0.00511"
"46.69600","-147.73099","0.00750"
"46.77400","-147.73099","-0.01003"
"46.88500","-147.73099","-0.00034"
"46.95300","-147.73099","-0.00502"
"47.05000","-147.73099","0.00451"
"47.14200","-147.73099","-0.01662"
"47.22600","-147.73099","-0.00090"
"47.32800","-147.73099","0.01136"
"47.41200","-147.73099","0.00409"
"47.49400","-147.73099","-0.00467"
"47.55700","-147.73099","-0.00685"
"47.64600","-147.73099","0.00527"
"47.73600","-147.73099","0.00604"
"47.83200","-147.73099","-0.01373"
"47.91500","-147.73099","0.00510"
"48.01900","-147.73099","-0.01032"
"48.08600","-147.73099","-0.00238"
"48.16400","-147.73099","0.00194"
"48.25900","-147.73099","0.01207"
"48.33300","-147.73099","-0.01678"
"48.40500","-147.73099","0.00861"
"48.46700","-147.73099","0.00731"
"48.56900","-147.73099","0.00746"
"48.65100","-147.73099","0.00268"
"48.73100","-147.73099","-0.00035"
"48.82800","-147.73099","0.00000"
"48.92300","-147.73099","-0.00664"
"49.00200","-147.73099","-0.01145"
"49.07000","-147.73099","0.01143"
"49.15000","-147.73099","-0.01053"
"49.22100","-147.73099","-0.01062"
"49.31500","-147.73099","0.00903"
"49.39500","-147.73099","-0.00723"
"49.46300","-147.73099","-0.01928"
"49.54500","-147.73099","0.00698"
"49.62900","-147.73099","-0.01024"
"49.72000","-147.73099","-0.00631"
"49.80200","-147.73099","0.00970"
"49.89100","-147.73099","-0.00631"
"49.98800","-147.73099","-0.00475"
"50.06400","-147.73099","0.00637"
"50.17000","-147.73099","0.00445"
"50.24800","-147.73099","0.00139"
"50.31300","-147.73099","-0.00458"
"50.40300","-147.73099","0.00149"
"50.47600","-147.73099","0.00441"
"50.57000","-147.73099","-0.00190"
"50.64300","-147.73099","0.00413"
"50.72700","-147.73099","-0.00015"
"50.81000","-147.73099","0.00732"
"50.89000","-147.73099","-0.00033"
"50.95900","-147.73099","-0.00284"
"51.03100","-147.73099","0.00248"
"51.12100","-147.73099","0.00696"
"51.19600","-147.73099","-0.00542"
"51.26500","-147.73099","0.00463"
"51.33600","-147.73099","0.00084"
"51.41900","-147.73099","0.00417"
"51.49300","-147.73099","-0.01688"
"51.58100","-147.73099","-0.00725"
"51.67200","-147.73099","0.00405"
"51.76500","-147.73099","-0.01322"
"51.87000","-147.73099","-0.00770"
"51.93900","-147.73099","-0.00779"
"52.01900","-147.73099","-0.01087"
"52.08100","-147.73099","-0.01101"
"52.14500","-147.73099","0.01244"
"52.22700","-147.73099","0.00686"
"52.31600","-147.73099","-0.00401"
"52.41800","-147.73099","0.00302"
"52.48900","-147.73099","-0.00887"
"52.57800","-147.73099","0.01201"
"52.65600","-147.73099","-0.01054"
"52.73500","-147.73099","-0.00417"
"52.79700","-147.73099","-0.00006"
"52.88600","-147.73099","0.00782"
"52.96700","-147.73099","0.00502"
"53.02800","-147.73099","0.00738"
"53.11300","-147.73099","-0.00613"
"53.19200","-147.73099","-0.01056"
"53.27700","-147.73099","-0.02599"
"53.36800","-147.73099","-0.01017"
"53.44800","-147.73099","-0.01506"
"53.54000","-147.73099","-0.00122"
"53.62300","-147.73099","0.00499"
"53.71600","-147.73099","-0.00377"
"53.80000","-147.73099","-0.01222"
"53.88500","-147.73099","-0.00475"
"53.95300","-147.73099","-0.02099"
"54.04300","-147.73099","0.00721"
"54.13000","-147.73099","0.00594"
"54.21300","-147.73099","-0.00328"
"54.29100","-147.73099","-0.00835"
"54.34700","-147.73099","0.00040"
"54.43000","-147.73099","0.00357"
"54.51400","-147.73099","-0.00656"
"54.60100","-147.73099","-0.00149"
"54.69200","-147.73099","-0.00828"
"54.77900","-147.73099","-0.01660"
"54.85900","-147.73099","-0.00255"
"54.91100","-147.73099","0.01131"
"54.98900","-147.73099","-0.00128"
"55.05600","-147.73099","-0.01262"
"55.15600","-147.73099","-0.01645"
"55.24200","-147.73099","0.01073"
"55.32000","-147.73099","-0.00190"
"55.41300","-147.73099","-0.01357"
"55.51200","-147.73099","0.00329"
"55.58700","-147.73099","0.00868"
"55.65900","-147.73099","-0.01215"
"55.75900","-147.73099","-0.00691"
"55.86800","-147.73099","-0.00331"
"55.92700","-147.73099","-0.00370"
"56.02100","-147.73099","0.00930"
"56.10200","-147.73099","-0.01307"
"56.16200","-147.73099","0.00972"
"56.25400","-147.73099","0.00388"
"56.34500","-147.73099","-0.01167"
"56.41900","-147.73099","0.00350"
"56.50100","-147.73099","-0.01122"
"56.58400","-147.73099","0.02347"
"56.65400","-147.73099","0.00653"
"56.72700","-147.73099","-0.00052"
"56.81000","-147.73099","-0.00823"
"56.91000","-147.73099","-0.00687"
"56.97900","-147.73099","-0.00668"
"57.05200","-147.73099","0.00093"
"57.14100","-147.73099","-0.00397"
"57.22900","-147.73099","-0.00402"
"57.30900","-147.73099","0.01844"
"57.40700","-147.73099","0.00547"
"57.48600","-147.73099","0.00434"
"57.54400","-147.73099","0.00511"
"57.62800","-147.73099","0.00527"
"57.71100","-147.73099","-0.00980"
"57.79000","-147.73099","-0.01121"
"57.86700","-147.73099","-0.01482"
"57.93000","-147.73099","0.01537"
"58.02400","-147.73099","-0.01785"
"58.11900","-147.73099","-0.00704"
"58.20000","-147.73099","0.00550"
"58.27800","-147.73099","-0.00617"
"58.36400","-147.73099","0.00167"
"58.44900","-147.73099","-0.01521"
"58.51700","-147.73099","-0.01214"
"58.59100","-147.73099","-0.01692"
"58.66300","-147.73099","0.00952"
"58.73200","-147.73099","-0.01635"
"58.80500","-147.73099","0.00040"
"58.89600","-147.73099","-0.01421"
"58.98000","-147.73099","-0.00563"
"59.04900","-147.73099","-0.00234"
"59.13000","-147.73099","-0.13978"
"59.20000","-147.73099","-0.19674"
"59.28500","-147.73099","-0.15641"
"59.35200","-147.73099","-0.15478"
"59.42900","-147.73099","-0.13730"
"59.52100","-147.73099","-0.14624"
"59.61800","-147.73099","-0.12755"
"59.69400","-147.73099","-0.11195"
"59.79700","-147.73099","-0.11142"
"59.87900","-147.73099","-0.14508"
"59.96300","-147.73099","-0.10140"
"60.03600","-147.73099","-0.11959"
"60.11100","-147.73099","-0.11988"
"60.17900","-147.73099","-0.11061"
"60.26800","-147.73099","-0.11354"
"60.36200","-147.73099","-0.11053"
"60.44800","-147.73099","-0.05162"
"60.53400","-147.73099","-0.04276"
"60.60200","-147.73099","-0.03689"
"60.68400","-147.73099","-0.02079"
"60.77300","-147.73099","-0.02918"
"60.85300","-147.73099","-0.01028"
"60.91900","-147.73099","-0.02106"
"61.01300","-147.73099","-0.02671"
"61.09800","-147.73099","-0.00801"
"61.17100","-147.73099","-0.02627"
"61.24900","-147.73099","-0.00872"
"61.33400","-147.73099","-0.01874"
"61.39400","-147.73099","-0.00366"
"61.47600","-147.73099","-0.01564"
"61.57600","-147.73099","-0.00592"
"61.66700","-147.73099","-0.01081"
"61.77300","-147.73099","-0.00808"
"61.85300","-147.73099","-0.01498"
"61.96200","-147.73099","-0.01100"
"62.03500","-147.73099","-0.00262"
"62.11100","-147.73099","0.00845"
"62.17400","-147.73099","-0.00941"
"62.26300","-147.73099","-0.00673"
"62.34700","-147.73099","-0.01499"
"62.42900","-147.73099","-0.00871"
"62.49800","-147.73099","0.00142"
"62.57900","-147.73099","-0.00792"
"62.63600","-147.73099","-0.00711"
"62.70600","-147.73099","-0.00317"
"62.78300","-147.73099","0.00304"
"62.86900","-147.73099","-0.01303"
"62.93500","-147.73099","-0.01066"
"63.01900","-147.73099","-0.00445"
"63.08500","-147.73099","0.00622"
"63.15200","-147.73099","0.00188"
"63.24500","-147.73099","0.01588"
"63.32700","-147.73099","-0.01255"
"63.40300","-147.73099","-0.00379"
"63.47900","-147.73099","-0.00572"
"63.55300","-147.73099","0.00707"
"63.63100","-147.73099","0.00683"
"63.70600","-147.73099","0.00490"
"63.79600","-147.73099","-0.00651"
"63.88800","-147.73099","-0.00396"
"63.99100","-147.73099","-0.01555"
"64.06300","-147.73099","0.00259"
"64.13400","-147.73099","0.00724"
"64.22000","-147.73099","-0.00218"
"64.29300","-147.73099","-0.01515"
"64.39400","-147.73099","0.00180"
"64.49100","-147.73099","-0.00109"
"64.58300","-147.73099","-0.01592"
"64.65900","-147.73099","-0.00537"
"64.73400","-147.73099","-0.01624"
"64.82300","-147.73099","-0.01144"
"64.88800","-147.73099","0.00823"
"64.97100","-147.73099","-0.01289"
"65.06400","-147.73099","-0.00706"
"65.14600","-147.73099","0.00567"
"65.21800","-147.73099","0.00074"
"65.30300","-147.73099","-0.00156"
"65.37200","-147.73099","-0.00304"
"65.45700","-147.73099","0.00626"
"65.55700","-147.73099","0.00019"
"65.63200","-147.73099","0.00429"
"65.72900","-147.73099","-0.00649"
"65.78600","-147.73099","0.00500"
"65.86100","-147.73099","-0.01619"
"65.93500","-147.73099","0.00411"
"66.03700","-147.73099","0.00773"
"66.11100","-147.73099","-0.00214"
"66.17500","-147.73099","-0.02005"
"66.26000","-147.73099","0.00186"
"66.35600","-147.73099","-0.01287"
"66.43000","-147.73099","-0.01398"
"66.50600","-147.73099","-0.00922"
"66.61300","-147.73099","0.01003"
"66.67200","-147.73099","0.00625"
"66.75800","-147.73099","-0.00035"
"66.81800","-147.73099","0.00585"
"66.88700","-147.73099","-0.00829"
"66.97000","-147.73099","-0.00334"
"67.04500","-147.73099","-0.00182"
"67.12400","-147.73099","0.00085"
"67.21600","-147.73099","-0.00372"
"67.28200","-147.73099","-0.00423"
"67.34600","-147.73099","-0.00963"
"67.41900","-147.73099","-0.00947"
"67.51000","-147.73099","0.00534"
"67.59800","-147.73099","-0.01015"
"67.66600","-147.73099","-0.00422"
"67.75400","-147.73099","-0.01393"
"67.83300","-147.73099","0.00335"
"67.91500","-147.73099","0.01539"
"68.01000","-147.73099","-0.00059"
"68.09800","-147.73099","-0.01994"
"68.19600","-147.73099","0.01242"
"68.25100","-147.73099","-0.00407"
"68.33300","-147.73099","-0.01594"
"68.42000","-147.73099","-0.00220"
"68.51800","-147.73099","-0.00833"
"68.60400","-147.73099","0.00142"
"68.69600","-147.73099","0.00805"
"68.80000","-147.73099","-0.01319"
"68.88100","-147.73099","-0.01719"
"68.95600","-147.73099","-0.01394"
"69.05000","-147.73099","-0.00232"
"69.13300","-147.73099","-0.00246"
"69.22300","-147.73099","0.00817"
"69.31800","-147.73099","0.00873"
"69.40200","-147.73099","-0.00130"
"69.50100","-147.73099","-0.00971"
"69.59100","-147.73099","-0.00759"
"69.67100","-147.73099","0.00612"
"69.75800","-147.73099","-0.01333"
"69.84300","-147.73099","0.00946"
"69.92600","-147.73099","-0.01170"
"70.01300","-147.73099","-0.00162"
"70.09900","-147.73099","0.01183"
"70.15900","-147.73099","0.00865"
"70.23800","-147.73099","-0.01901"
"70.30900","-147.73099","-0.00180"
"70.40400","-147.73099","-0.00977"
"70.48700","-147.73099","0.00638"
"70.59300","-147.73099","-0.00327"
"70.69000","-147.73099","0.01076"
"70.78500","-147.73099","-0.00303"
"70.88200","-147.73099","-0.00598"
"70.96400","-147.73099","0.00456"
"71.03000","-147.73099","-0.00413"
"71.13800","-147.73099","-0.00673"
"71.22300","-147.73099","0.00836"
"71.30900","-147.73099","-0.01144"
"71.37300","-147.73099","-0.00425"
"71.43600","-147.73099","0.00488"
"71.51900","-147.73099","0.00525"
"71.59700","-147.73099","-0.00322"
"71.69400","-147.73099","-0.01540"
"71.75500","-147.73099","-0.00024"
"71.84300","-147.73099","0.00001"
"71.92600","-147.73099","0.00747"
"71.98600","-147.73099","-0.01765"
"72.04400","-147.73099","0.01739"
"72.11700","-147.73099","-0.00430"
"72.21300","-147.73099","-0.00087"
"72.28500","-147.73099","-0.00025"
"72.35000","-147.73099","-0.00865"
"72.43500","-147.73099","0.00310"
"72.51700","-147.73099","0.00260"
"72.58700","-147.73099","-0.02167"
"72.66800","-147.73099","0.00034"
"72.75000","-147.73099","0.01150"
"72.83600","-147.73099","0.00273"
"72.91300","-147.73099","-0.00546"
"72.99500","-147.73099","0.00235"
"73.09700","-147.73099","-0.01432"
"73.18000","-147.73099","-0.01815"
"73.26500","-147.73099","-0.00164"
"73.32900","-147.73099","0.01587"
"73.41100","-147.73099","-0.00709"
"73.49100","-147.73099","0.00069"
"73.57200","-147.73099","-0.00994"
"73.66000","-147.73099","-0.01365"
"73.76000","-147.73099","0.00319"
"73.86000","-147.73099","0.00657"
"73.94100","-147.73099","-0.00969"
"74.02200","-147.73099","-0.00923"
"74.09900","-147.73099","0.00410"
"74.19000","-147.73099","-0.00553"
"74.29800","-147.73099","0.00220"
"74.38300","-147.73099","0.00968"
"74.46000","-147.73099","-0.00667"
"74.52700","-147.73099","0.00133"
"74.61800","-147.73099","-0.00172"
"74.71100","-147.73099","0.00358"
"74.79300","-147.73099","-0.00712"
"74.86900","-147.73099","-0.01488"
"74.95400","-147.73099","-0.00381"
"75.03500","-147.73099","0.00779"
"75.11800","-147.73099","-0.00002"
"75.19400","-147.73099","0.00386"
"75.28100","-147.73099","-0.00574"
"75.36300","-147.73099","-0.00100"
"75.44300","-147.73099","0.00191"
"75.52400","-147.73099","0.00355"
"75.59300","-147.73099","-0.01346"
"75.67000","-147.73099","0.00141"
"75.73500","-147.73099","0.01915"
"75.81100","-147.73099","0.00138"
"75.89200","-147.73099","-0.00219"
"75.97200","-147.73099","-0.00324"
"76.05500","-147.73099","-0.01032"
"76.13700","-147.73099","0.00158"
"76.22300","-147.73099","0.00670"
"76.30500","-147.73099","-0.00137"
"76.38200","-147.73099","-0.00060"
"76.48500","-147.73099","-0.01208"
"76.56400","-147.73099","-0.01237"
"76.63300","-147.73099","-0.00248"
"76.74300","-147.73099","-0.01530"
"76.82000","-147.73099","0.00319"
"76.89800","-147.73099","-0.01546"
"76.98200","-147.73099","0.01308"
"77.04600","-147.73099","-0.01101"
"77.12500","-147.73099","-0.00498"
"77.21300","-147.73099","0.00197"
"77.28300","-147.73099","0.00758"
"77.34400","-147.73099","-0.00647"
"77.41000","-147.73099","-0.00090"
"77.49000","-147.73099","-0.01286"
"77.57500","-147.73099","-0.00588"
"77.65600","-147.73099","0.00256"
"77.74300","-147.73099","-0.00629"
"77.83200","-147.73099","0.00620"
"77.91900","-147.73099","0.00689"
"77.99500","-147.73099","-0.01991"
"78.06700","-147.73099","0.00087"
"78.14800","-147.73099","-0.00948"
"78.23700","-147.73099","-0.01576"
"78.33900","-147.73099","-0.02101"
"78.43500","-147.73099","0.00381"
"78.51900","-147.73099","0.00889"
"78.62000","-147.73099","-0.00610"
"78.69600","-147.73099","-0.00004"
"78.76100","-147.73099","-0.01547"
"78.84900","-147.73099","-0.01961"
"78.93400","-147.73099","-0.00050"
"79.01400","-147.73099","-0.01617"
"79.08600","-147.73099","0.00007"
"79.18500","-147.73099","-0.00927"
"79.27000","-147.73099","-0.00155"
"79.34000","-147.73099","-0.02249"
"79.41100","-147.73099","-0.00553"
"79.51300","-147.73099","0.00755"
"79.58500","-147.73099","-0.00481"
"79.66400","-147.73099","0.00636"
"79.74500","-147.73099","0.00551"
"79.82800","-147.73099","-0.00161"
"79.90900","-147.73099","-0.01476"
"79.98100","-147.73099","0.01464"
"80.05700","-147.73099","-0.00086"
"80.12000","-147.73099","-0.01614"
"80.20800","-147.73099","-0.00331"
"80.28400","-147.73099","-0.00966"
"80.36000","-147.73099","-0.00701"
"80.42000","-147.73099","-0.00494"
"80.47200","-147.73099","-0.03695"
"80.54700","-147.73099","-0.19862"
"80.62300","-147.73099","-0.34487"
"80.69300","-147.73099","-0.30832"
"80.77200","-147.73099","-0.28155"
"80.85300","-147.73099","-0.28051"
"80.91300","-147.73099","-0.26715"
"81.00400","-147.73099","-0.25386"
"81.10300","-147.73099","-0.20502"
"81.18000","-147.73099","-0.16851"
"81.25800","-147.73099","-0.16940"
"81.34300","-147.73099","-0.14980"
"81.41200","-147.73099","-0.13874"
"81.51300","-147.73099","-0.11939"
"81.61900","-147.73099","-0.10549"
"81.68900","-147.73099","-0.11133"
"81.77800","-147.73099","-0.09874"
"81.87400","-147.73099","-0.09111"
"81.95300","-147.73099","-0.07851"
"82.03400","-147.73099","-0.07941"
"82.11900","-147.73099","-0.06167"
"82.20000","-147.73099","-0.06853"
"82.26800","-147.73099","-0.07745"
"82.32900","-147.73099","-0.03872"
"82.41100","-147.73099","-0.06098"
"82.49100","-147.73099","-0.05879"
"82.55100","-147.73099","-0.04110"
"82.65900","-147.73099","-0.05035"
"82.74000","-147.73099","-0.05322"
"82.83400","-147.73099","-0.03897"
"82.89600","-147.73099","-0.04061"
"82.97000","-147.73099","-0.04658"
"83.06600","-147.73099","-0.03439"
"83.15200","-147.73099","-0.04188"
"83.23900","-147.73099","-0.05589"
"83.33500","-147.73099","-0.03944"
"83.45600","-147.73099","-0.04318"
"83.51800","-147.73099","-0.03809"
"83.61900","-147.73099","-0.05134"
"83.71800","-147.73099","-0.03748"
"83.78900","-147.73099","-0.03006"
"83.88900","-147.73099","-0.03491"
"83.96700","-147.73099","-0.01943"
"84.04200","-147.73099","-0.03641"
"84.12900","-147.73099","-0.04139"
"84.21400","-147.73099","-0.01688"
"84.30200","-147.73099","-0.03750"
"84.36800","-147.73099","-0.01707"
"84.47100","-147.73099","-0.01877"
"84.55300","-147.73099","-0.03614"
"84.65200","-147.73099","-0.02586"
"84.73400","-147.73099","-0.02089"
"84.79900","-147.73099","-0.02420"
"84.89100","-147.73099","-0.00850"
"85.01000","-147.73099","-0.03129"
"85.11800","-147.73099","-0.01756"
"85.19000","-147.73099","-0.03396"
"85.28600","-147.73099","-0.02225"
"85.36800","-147.73099","-0.01795"
"85.44200","-147.73099","-0.01381"
"85.51900","-147.73099","-0.00475"
"85.59800","-147.73099","-0.01592"
"85.68700","-147.73099","-0.00939"
"85.76500","-147.73099","-0.00893"
"85.84400","-147.73099","-0.01565"
"85.91900","-147.73099","-0.00884"
"86.00100","-147.73099","-0.00279"
"86.07300","-147.73099","-0.03529"
"86.14200","-147.73099","-0.01104"
"86.22000","-147.73099","-0.02305"
"86.31400","-147.73099","-0.01885"
"86.41900","-147.73099","-0.00954"
"86.49200","-147.73099","-0.00399"
"86.58600","-147.73099","-0.01890"
"86.68400","-147.73099","-0.00839"
"86.76600","-147.73099","-0.00670"
"86.85200","-147.73099","-0.02746"
"86.93500","-147.73099","-0.00455"
"87.02500","-147.73099","-0.01153"
"87.08800","-147.73099","-0.02784"
"87.17800","-147.73099","-0.01822"
"87.23900","-147.73099","-0.02142"
"87.31600","-147.73099","-0.02256"
"87.40800","-147.73099","-0.00710"
"87.50700","-147.73099","-0.00802"
"87.59500","-147.73099","-0.01608"
"87.67500","-147.73099","-0.01751"
"87.77000","-147.73099","-0.01791"
"87.85100","-147.73099","-0.00775"
"87.94100","-147.73099","-0.01488"
"87.99200","-147.73099","-0.02345"
"88.08600","-147.73099","-0.02178"
"88.17500","-147.73099","0.00768"
"88.25700","-147.73099","-0.00762"
"88.34900","-147.73099","-0.01015"
"88.43400","-147.73099","-0.00945"
"88.52300","-147.73099","-0.01273"
"88.60300","-147.73099","0.00611"
"88.67600","-147.73099","-0.01420"
"88.76100","-147.73099","-0.01633"
"88.84700","-147.73099","-0.01496"
"88.92600","-147.73099","-0.00775"
"89.00000","-147.73099","-0.01169"
"89.09400","-147.73099","-0.01037"
"89.15800","-147.73099","-0.00341"
"89.25000","-147.73099","-0.01036"
"89.32200","-147.73099","-0.00565"
"89.39600","-147.73099","-0.01060"
"89.46200","-147.73099","-0.01048"
"89.55800","-147.73099","-0.01992"
"89.64400","-147.73099","-0.01326"
"89.74500","-147.73099","-0.02578"
"89.80200","-147.73099","-0.01992"
"89.88800","-147.73099","-0.01433"
"89.99200","-147.73099","-0.01235"
"90.07000","-147.73099","-0.01024"
"90.14800","-147.73099","-0.01442"
"90.21700","-147.73099","-0.00008"
"90.31700","-147.73099","-0.01619"
"90.38700","-147.73099","-0.00285"
"90.44200","-147.73099","-0.01161"
"90.51400","-147.73099","-0.01905"
"90.59100","-147.73099","-0.02467"
"90.65700","-147.73099","-0.00241"
"90.74700","-147.73099","-0.00905"
"90.83100","-147.73099","-0.02162"
"90.91700","-147.73099","-0.02036"
"91.00900","-147.73099","-0.01959"
"91.09500","-147.73099","0.00599"
"91.17400","-147.73099","-0.01593"
"91.23700","-147.73099","-0.00326"
"91.30800","-147.73099","-0.00667"
"91.36700","-147.73099","-0.01821"
"91.46200","-147.73099","-0.00400"
"91.55300","-147.73099","-0.00987"
"91.62900","-147.73099","-0.00705"
"91.71800","-147.73099","0.00001"
"91.78700","-147.73099","-0.01721"
"91.87300","-147.73099","0.00792"
"91.94800","-147.73099","-0.03246"
"92.02400","-147.73099","-0.02233"
"92.11100","-147.73099","-0.01554"
"92.18800","-147.73099","-0.00718"
"92.25800","-147.73099","-0.01962"
"92.33100","-147.73099","-0.01166"
"92.42300","-147.73099","-0.00673"
"92.47600","-147.73099","-0.00632"
"92.53500","-147.73099","-0.01697"
"92.61300","-147.73099","-0.00153"
"92.70400","-147.73099","-0.02455"
"92.80500","-147.73099","-0.01979"
"92.88400","-147.73099","-0.01038"
"92.96300","-147.73099","-0.01778"
"93.02600","-147.73099","-0.01717"
"93.10700","-147.73099","-0.01625"
"93.17300","-147.73099","-0.02058"
"93.25600","-147.73099","-0.00652"
"93.34900","-147.73099","0.00358"
"93.41600","-147.73099","-0.00237"
"93.49900","-147.73099","-0.00770"
"93.58700","-147.73099","-0.02527"
"93.65100","-147.73099","0.01131"
"93.74500","-147.73099","-0.02175"
"93.83500","-147.73099","-0.00920"
"93.90200","-147.73099","-0.02896"
"93.99400","-147.73099","-0.01952"
"94.09800","-147.73099","-0.00720"
"94.16400","-147.73099","-0.00586"
"94.24900","-147.73099","-0.00926"
"94.33100","-147.73099","-0.01131"
"94.41200","-147.73099","-0.01812"
"94.51800","-147.73099","-0.01184"
"94.60000","-147.73099","-0.00350"
"94.66600","-147.73099","-0.00381"
"94.74200","-147.73099","-0.00944"
"94.84000","-147.73099","-0.02050"
"94.92600","-147.73099","-0.00053"
"95.00600","-147.73099","-0.01628"
"95.09600","-147.73099","-0.01500"
"95.18000","-147.73099","-0.00070"
"95.24800","-147.73099","-0.00493"
"95.31600","-147.73099","-0.01426"
"95.36900","-147.73099","-0.01640"
"95.46100","-147.73099","-0.00371"
"95.54200","-147.73099","-0.01806"
"95.60500","-147.73099","-0.02458"
"95.68900","-147.73099","-0.00915"
"95.78500","-147.73099","-0.00302"
"95.85400","-147.73099","-0.01078"
"95.93700","-147.73099","-0.02396"
"96.03500","-147.73099","-0.01692"
"96.12800","-147.73099","-0.00776"
"96.20700","-147.73099","-0.01112"
"96.29400","-147.73099","-0.02201"
"96.38700","-147.73099","-0.00804"
"96.45400","-147.73099","-0.00631"
"96.53200","-147.73099","-0.01038"
"96.61300","-147.73099","-0.00770"
"96.70200","-147.73099","0.00042"
"96.79000","-147.73099","-0.00626"
"96.87500","-147.73099","-0.02698"
"96.93500","-147.73099","-0.00654"
"97.02300","-147.73099","-0.02120"
"97.10200","-147.73099","-0.00252"
"97.19500","-147.73099","-0.00992"
"97.25800","-147.73099","-0.08674"
"97.33700","-147.73099","-0.28329"
"97.42900","-147.73099","-0.31158"
"97.49500","-147.73099","-0.34189"
"97.57300","-147.73099","-0.32915"
"97.64200","-147.73099","-0.31664"
"97.74000","-147.73099","-0.29225"
"97.82800","-147.73099","-0.30418"
"97.88600","-147.73099","-0.28822"
"97.97800","-147.73099","-0.29291"
"98.04200","-147.73099","-0.28083"
"98.13300","-147.73099","-0.27864"
"98.19600","-147.73099","-0.27533"
"98.26000","-147.73099","-0.27281"
"98.34400","-147.73099","-0.28084"
"98.43700","-147.73099","-0.27680"
"98.52300","-147.73099","-0.26292"
"98.59800","-147.73099","-0.24670"
"98.63600","-147.73099","-0.19011"
"98.72900","-147.73099","-0.18407"
"98.81000","-147.73099","-0.18813"
"98.89900","-147.73099","-0.19693"
"98.98600","-147.73099","-0.19289"
"99.08400","-147.73099","-0.17875"
"99.15300","-147.73099","-0.11123"
"99.23900","-147.73099","-0.08683"
"99.32300","-147.73099","-0.09616"
"99.38500","-147.73099","-0.07913"
"99.45800","-147.73099","-0.09010"
"99.53500","-147.73099","-0.07900"
"99.59000","-147.73099","-0.08728"
"99.69500","-147.73099","-0.07416"
"99.78100","-147.73099","-0.07275"
"99.84500","-147.73099","-0.09126"
"99.92900","-147.73099","-0.07359"
"100.01900","-147.73099","-0.07505"
"100.09800","-147.73099","-0.06752"
"100.18300","-147.73099","-0.07947"
"100.28300","-147.73099","-0.08770"
"100.37600","-147.73099","-0.06943"
"100.44300","-147.73099","-0.05617"
"100.51200","-147.73099","-0.06724"
"100.61000","-147.73099","-0.05698"
"100.70500","-147.73099","-0.05238"
"100.77400","-147.73099","-0.06601"
"100.84700","-147.73099","-0.05994"
"100.95900","-147.73099","-0.04668"
"101.03900","-147.73099","-0.04955"
"101.14200","-147.73099","-0.04687"
"101.22600","-147.73099","-0.04684"
"101.31100","-147.73099","-0.05728"
"101.40400","-147.73099","-0.07284"
"101.48600","-147.73099","-0.04152"
"101.56500","-147.73099","-0.04528"
"101.63900","-147.73099","-0.06058"
"101.71500","-147.73099","-0.05370"
"101.81700","-147.73099","-0.05284"
"101.89100","-147.73099","-0.05136"
"101.97700","-147.73099","-0.04512"
"102.06100","-147.73099","-0.04268"
"102.15500","-147.73099","-0.04465"
"102.23300","-147.73099","-0.03934"
"102.30800","-147.73099","-0.05940"
"102.38400","-147.73099","-0.02527"
"102.45300","-147.73099","-0.03977"
"102.52000","-147.73099","-0.05465"
"102.60500","-147.73099","-0.03238"
"102.68100","-147.73099","-0.04064"
"102.77200","-147.73099","-0.03032"
"102.85300","-147.73099","-0.03452"
"102.95000","-147.73099","-0.03982"
"103.03500","-147.73099","-0.03278"
"103.13800","-147.73099","-0.03901"
"103.23600","-147.73099","-0.05186"
"103.33600","-147.73099","-0.03910"
"103.42100","-147.73099","-0.03717"
"103.50000","-147.73099","-0.03893"
"103.56900","-147.73099","-0.03664"
"103.63200","-147.73099","-0.03392"
"103.69600","-147.73099","-0.05169"
"103.78000","-147.73099","-0.03523"
"103.84600","-147.73099","-0.03753"
"103.93000","-147.73099","-0.04943"
"104.01800","-147.73099","-0.04841"
"104.12000","-147.73099","-0.03191"
"104.19900","-147.73099","-0.03154"
"104.28700","-147.73099","-0.03843"
"104.37100","-147.73099","-0.01931"
"104.45800","-147.73099","-0.04103"
"104.53100","-147.73099","-0.03710"
"104.61500","-147.73099","-0.02406"
"104.66900","-147.73099","-0.03966"
"104.73900","-147.73099","-0.03304"
"104.80900","-147.73099","-0.03437"
"104.90200","-147.73099","-0.02335"
"104.99500","-147.73099","-0.03905"
"105.06900","-147.73099","-0.03289"
"105.14600","-147.73099","-0.03429"
"105.23900","-147.73099","-0.03369"
"105.32900","-147.73099","-0.05201"
"105.41400","-147.73099","-0.03549"
"105.48700","-147.73099","-0.04407"
"105.58500","-147.73099","-0.01710"
"105.65500","-147.73099","-0.03894"
"105.73100","-147.73099","-0.01168"
"105.81900","-147.73099","-0.02144"
"105.93000","-147.73099","-0.02079"
"106.00400","-147.73099","-0.04308"
"106.06900","-147.73099","-0.05235"
"106.14700","-147.73099","-0.03507"
"106.23800","-147.73099","-0.03477"
"106.31500","-147.73099","-0.05345"
"106.40400","-147.73099","-0.02517"
"106.48000","-147.73099","-0.02776"
"106.53900","-147.73099","-0.04364"
"106.62300","-147.73099","-0.02907"
"106.70300","-147.73099","-0.02330"
"106.78500","-147.73099","-0.03732"
"106.86400","-147.73099","-0.03939"
"106.95700","-147.73099","-0.01879"
"107.02700","-147.73099","-0.02701"
"107.09700","-147.73099","-0.02731"
"107.18700","-147.73099","-0.01808"
"107.27500","-147.73099","-0.02182"
"107.35400","-147.73099","-0.02546"
"107.43600","-147.73099","-0.01796"
"107.54000","-147.73099","-0.02186"
"107.62300","-147.73099","-0.03338"
"107.70600","-147.73099","-0.01887"
"107.76900","-147.73099","-0.02732"
"107.83600","-147.73099","-0.04639"
"107.93700","-147.73099","-0.03415"
"108.00800","-147.73099","-0.03126"
"108.09200","-147.73099","-0.02791"
"108.16000","-147.73099","-0.02998"
"108.25000","-147.73099","-0.04148"
"108.34300","-147.73099","-0.03014"
"108.41600","-147.73099","-0.03217"
"108.51400","-147.73099","-0.02898"
"108.60900","-147.73099","-0.03239"
"108.69800","-147.73099","-0.02240"
"108.78400","-147.73099","-0.02316"
"108.86000","-147.73099","-0.02653"
"108.94100","-147.73099","-0.01568"
"109.01700","-147.73099","-0.01043"
"109.09200","-147.73099","-0.02725"
"109.17600","-147.73099","-0.01419"
"109.25600","-147.73099","-0.01927"
"109.32600","-147.73099","-0.02554"
"109.42300","-147.73099","-0.01380"
"109.49300","-147.73099","-0.03591"
"109.57100","-147.73099","-0.03413"
"109.63800","-147.73099","-0.02783"
"109.71700","-147.73099","-0.03784"
"109.80100","-147.73099","-0.01727"
"109.88100","-147.73099","-0.01497"
"109.97000","-147.73099","-0.02284"
"110.03900","-147.73099","-0.00803"
"110.11000","-147.73099","-0.03414"
"110.18800","-147.73099","-0.04515"
"110.25100","-147.73099","-0.02338"
"110.32800","-147.73099","-0.02367"
"110.40000","-147.73099","-0.02906"
"110.47500","-147.73099","-0.02742"
"110.56500","-147.73099","-0.01743"
"110.67000","-147.73099","-0.01756"
"110.76700","-147.73099","-0.02743"
"110.85800","-147.73099","-0.02189"
"110.89100","-147.73099","-0.01603"